Workbook

Sheet PR당사안
A3: 見 積 書
A4: 수 신: LG에너지솔루션
B5: 대전 업무지원팀 / 김규환님 귀하
A7: 견 적 일 자 | D7: 2025 | E7: 년 | F7: 10 | G7: 월 | H7: 1 | I7: 일 | K7: 공 급 자 | L7: 등록번호 | M7: 707-86-02-404 | N7: 전 화 | O7: 02-6924-5539
A8: 견 적 담 당 | D8: 이종근 | H8: 파트너 | L8: 상 호 | M8: ㈜에스앤아이코퍼레이션 | N8: 대 표 | O8: 서 현
A9: 견적유효기간 | D9: 견적 제출 후 30일 까지 | L9: 주 소 | M9: 서울특별시 강서구 마곡중앙로150
A10: 납 기 | D10: 발주 후 개별 협의 | L10: 업 태 | M10: 부동산, 서비스 | N10: 종 목 | O10: 임대 및 관리
B13: 기숙사 AB동 지하 주차장 유인휀 교체 | N13: 견적을 제출 합니다
B15: ="견 적 금 액 : 一金"&NUMBERSTRING(M32,1) & "원정""(\"& TEXT(M32,"#,###")&"원) [VAT 별도]" -> 견 적 금 액 : 一金일천이백팔십팔만칠천일백원정"(\12,887,100원) [VAT 별도]
A17: NO | B17: 구 분 | H17: 수량 | I17: 단위 | J17: 금 액 | N17: 비 고
A18: 1 | B18: 재료비 | H18: 1 | I18: 식 | J18: =IFERROR(LOOKUP(2, 1/(TRIM('내역서(표준단가)'!O4:O100)<>""), '내역서(표준단가)'!O4:O100), "-") -> 473907.52
A19: 2 | B19: 노무비 | H19: 1 | I19: 식 | J19: =IFERROR(LOOKUP(2, 1/(TRIM('내역서(표준단가)'!Q4:Q100)<>""), '내역서(표준단가)'!Q4:Q100), "-") -> 3692810.9
A20: 3 | B20: 경 비 | H20: 1 | I20: 식 | J20: =IFERROR(SUM(J21:M29),"-") -> 7616458.5
C21: 기계 및 기타경비 | H21: 1 | I21: 식 | J21: =IFERROR(LOOKUP(2, 1/(TRIM('내역서(표준단가)'!S4:S100)<>""), '내역서(표준단가)'!S4:S100) + LOOKUP(2, 1/(TRIM('내역서(표준단가)'!U4:U100)<>""), '내역서(표준단가)'!U4:U100), "-") -> 6994536 | N21: 중장비 사용 등
C22: 안전관리비 | H22: 3.11 | I22: % | J22: =IFERROR((J18+J19)*H22%,"-") -> 129584.94 | N22: (재료비+노무비)*3.11%
C23: 산재 보험료 | H23: 3.56 | I23: % | J23: =IFERROR(J19*H23%,"-") -> 131464.07 | N23: 노무비*3.56%
C24: 고용보험료 | H24: 1.01 | I24: % | J24: =IFERROR(J19*H24%,"-") -> 37297.39 | N24: 노무비*1.01%
C25: 국민건강 보험료 | H25: 3.545 | I25: % | J25: =IFERROR(J19*H25%,"-") -> 130910.15 | N25: 노무비*3.545%
C26: 국민연금 보험료 | H26: 4.5 | I26: % | J26: =IFERROR(J19*H26%,"-") -> 166176.49 | N26: 노무비*4.5%
C27: 노인장기요양 보험료 | H27: 12.95 | I27: % | J27: =IFERROR($H$27*J25%,"-") -> 16952.864 | N27: 건강보험료*12.95%
C28: 하도급대금지급보증증권 | H28: 0.081 | I28: % | J28: =IFERROR(IF(SUM(J21:J27,J18:J19)>=10000000,SUM(J21:J27,J18:J19)*H28%,"-"),"-") -> 9536.6486 | N28: 1천만원 이상 공사시 적용
C29: 폐기물처리 부담금 | H29: 1 | I29: 식 | J29: =34*0 -> 0 | N29: 폐기물발생 시 적용 (kg당 34원)
A30: 4 | C30: 일반관리비 | H30: 5 | I30: % | J30: =IFERROR(IF(ISNUMBER(H30), SUM(J18:M20) * (H30 / 100), "-"), "-") -> 589158.85 | N30: (재료비 + 노무비 + 경비)*5%
A31: 5 | C31: 이 윤 | H31: 7.5 | I31: % | J31: =IFERROR(SUM(J18:M20, J30) * (H31 / 100), "-")+-413160 -> 514765.18 | N31: (재료비+노무비+경비+일반관리비)*7.5%
A32: 공사금액 | M32: =IFERROR(ROUNDDOWN(SUM(J18:M20)+J30+J31,0),"-") -> 12887100
A33: *유첨 : 견적서 내역서 1부 ─ 끝 ─

Sheet 내역서(표준단가)
O1: ▼낙찰율 | Q1: ▼낙찰율 | S1: ▼낙찰율 | U1: ▼낙찰율
O2: 0.82 | Q2: 0.72 | S2: 1 | U2: 1
F3: ▶ 표준 Code(표준단가/품셈/물정/노임) 순서별 입력(Upload 자동반영) | J3: 주요내역 | L3: 단위 | M3: 수량 | N3: 재료비 | P3: 노무비 | R3: 기계경비 | T3: 기타경비(부자재비) | V3: 합계 | W3: 노무비 할증 | X3: 할증기준
E4: 합계 | F4: 표준단가 D | G4: 표준품셈 E | H4: 물가정보 M | I4: 노임단가 L | J4: 품목 | K4: 규격 | N4: 품셈/표단 | O4: 금액 | P4: 단가 | Q4: 금액 | R4: 단가 | S4: 금액 | T4: 단가 | U4: 금액
J5: 지하주차장 유인팬 교체
E6: =F6&G6&H6&I6 -> 999999 | H6: 999999 | J6: 유인팬(LONG FAN) | K6: 2700CMH*140W | L6: EA | M6: =20 -> 20 | O6: =+M6*N6*$O$2 -> 0 | Q6: =M6*P6*$Q$2*W6 -> 0 | R6: 340000 | S6: =ROUND(R6*M6*$S$2,0) -> 6800000 | U6: =ROUND(T6*M6*$U$2,0) -> 0 | V6: =SUM(O6+Q6)+S6+U6 -> 6800000
E7: =F7&G7&H7&I7 -> E00000806004020402 | G7: E00000806004020402 | J7: 무덕트 배기팬 설치 | K7: 풍량 2,400㎥/h이하 | L7: (대당) | M7: =20 -> 20 | N7: 0 | O7: =+M7*N7*$O$2 -> 0 | P7: 87624 | Q7: =M7*P7*$Q$2*W7 -> 1261785.6 | R7: 0 | S7: =ROUND(R7*M7*$S$2,0) -> 0 | U7: =ROUND(T7*M7*$U$2,0) -> 0 | V7: =SUM(O7+Q7)+S7+U7 -> 1261785.6 | W7: 1
E8: =F8&G8&H8&I8 -> E00000806004020402 | G8: E00000806004020402 | J8: 무덕트 배기팬 설치 (철거) | K8: 풍량 2,400㎥/h이하 | L8: (대당) | M8: =20 -> 20 | N8: 0 | O8: =+M8*N8*$O$2 -> 0 | P8: 87624 | Q8: =M8*P8*$Q$2*W8 -> 630892.8 | R8: 0 | S8: =ROUND(R8*M8*$S$2,0) -> 0 | U8: =ROUND(T8*M8*$U$2,0) -> 0 | V8: =SUM(O8+Q8)+S8+U8 -> 630892.8 | W8: 0.5 | X8: H01
E9: =F9&G9&H9&I9 -> M010332810030101 | H9: M010332810030101 | J9: 전산볼트 | K9: M10(도금) (길이 1m) | L9: 개 | M9: =2*4*20 -> 160 | N9: 1226 | O9: =+M9*N9*$O$2 -> 160851.2 | Q9: =M9*P9*$Q$2*W9 -> 0 | S9: =ROUND(R9*M9*$S$2,0) -> 0 | U9: =ROUND(T9*M9*$U$2,0) -> 0 | V9: =SUM(O9+Q9)+S9+U9 -> 160851.2
E10: =F10&G10&H10&I10 -> M01525GR10400101 | H10: M01525GR10400101 | J10: 셋트앙카 | K10: ø9㎜×6㎝ | L10: 개 | M10: =4*20 -> 80 | N10: 1400 | O10: =+M10*N10*$O$2 -> 91840 | Q10: =M10*P10*$Q$2*W10 -> 0 | S10: =ROUND(R10*M10*$S$2,0) -> 0 | U10: =ROUND(T10*M10*$U$2,0) -> 0 | V10: =SUM(O10+Q10)+S10+U10 -> 91840
E11: =F11&G11&H11&I11 -> E00000808374071205 | G11: E00000808374071205 | J11: 부대공사(앙카볼트 설치 등) - 앙카볼트설치 | K11: ø13㎜ 이하 | L11: (개당) | M11: =4*20 -> 80 | O11: =+M11*N11*$O$2 -> 0 | P11: 10691 | Q11: =M11*P11*$Q$2*W11 -> 615801.6 | S11: =ROUND(R11*M11*$S$2,0) -> 0 | U11: =ROUND(T11*M11*$U$2,0) -> 0 | V11: =SUM(O11+Q11)+S11+U11 -> 615801.6 | W11: 1
E12: =F12&G12&H12&I12 -> E00000808374071205 | G12: E00000808374071205 | J12: 부대공사(앙카볼트 설치 등) - 앙카볼트설치 (철거) | K12: ø13㎜ 이하 | L12: (개당) | M12: =4*20 -> 80 | O12: =+M12*N12*$O$2 -> 0 | P12: 10691 | Q12: =M12*P12*$Q$2*W12 -> 307900.8 | S12: =ROUND(R12*M12*$S$2,0) -> 0 | U12: =ROUND(T12*M12*$U$2,0) -> 0 | V12: =SUM(O12+Q12)+S12+U12 -> 307900.8 | W12: 0.5 | X12: H01
E13: =F13&G13&H13&I13 -> M020251411610101 | H13: M020251411610101 | J13: 프리미엄 그린실 808 | K13: 1액형 실리콘, 다목적 건축실링용, 유리글레이징, 친환경 인증 | L13: 270㎖ | M13: =1 -> 1 | N13: 5000 | O13: =+M13*N13*$O$2 -> 4100 | Q13: =M13*P13*$Q$2*W13 -> 0 | S13: =ROUND(R13*M13*$S$2,0) -> 0 | U13: =ROUND(T13*M13*$U$2,0) -> 0 | V13: =SUM(O13+Q13)+S13+U13 -> 4100
E14: =F14&G14&H14&I14 -> E00000803051260301 | G14: E00000803051260301 | J14: 코킹 | K14: 코킹 | L14: (10m 당) | M14: =1 -> 1 | N14: 0 | O14: =+M14*N14*$O$2 -> 0 | P14: 41678 | Q14: =M14*P14*$Q$2*W14 -> 30008.16 | S14: =ROUND(R14*M14*$S$2,0) -> 0 | U14: =ROUND(T14*M14*$U$2,0) -> 0 | V14: =SUM(O14+Q14)+S14+U14 -> 30008.16 | W14: 1
E15: =F15&G15&H15&I15 -> 999999 | H15: 999999 | J15: 화물차 | K15: 5TON | L15: HR | M15: =8 -> 8 | N15: 19461 | O15: =+M15*N15*$O$2 -> 127664.16 | P15: 49479 | Q15: =M15*P15*$Q$2*W15 -> 284999.04 | R15: 15235 | S15: =ROUND(R15*M15*$S$2,0) -> 121880 | U15: =ROUND(T15*M15*$U$2,0) -> 0 | V15: =SUM(O15+Q15)+S15+U15 -> 534543.2 | W15: 1
E16: =F16&G16&H16&I16 -> E00000805033430105 | G16: E00000805033430105 | J16: 지게차 | K16: 7.55ton | L16: (시간당) | M16: =8 -> 8 | N16: 13636 | O16: =+M16*N16*$O$2 -> 89452.16 | P16: 55699 | Q16: =M16*P16*$Q$2*W16 -> 320826.24 | R16: 9082 | S16: =ROUND(R16*M16*$S$2,0) -> 72656 | U16: =ROUND(T16*M16*$U$2,0) -> 0 | V16: =SUM(O16+Q16)+S16+U16 -> 482934.4 | W16: 1
E17: =F17&G17&H17&I17 -> L002 | I17: L002 | J17: 보통인부 | K17: 사다리보조자 | L17: 인 | M17: 1 | O17: =+M17*N17*$O$2 -> 0 | P17: 167081 | Q17: =M17*P17*$Q$2*W17 -> 120298.32 | S17: =ROUND(R17*M17*$S$2,0) -> 0 | U17: =ROUND(T17*M17*$U$2,0) -> 0 | V17: =SUM(O17+Q17)+S17+U17 -> 120298.32 | W17: 1
E18: =F18&G18&H18&I18 -> L002 | I18: L002 | J18: 보통인부 | K18: 신호수 | L18: 인 | M18: 1 | O18: =+M18*N18*$O$2 -> 0 | P18: 167081 | Q18: =M18*P18*$Q$2*W18 -> 120298.32 | S18: =ROUND(R18*M18*$S$2,0) -> 0 | U18: =ROUND(T18*M18*$U$2,0) -> 0 | V18: =SUM(O18+Q18)+S18+U18 -> 120298.32 | W18: 1
E19: =F19&G19&H19&I19
E20: =F20&G20&H20&I20
E21: =F21&G21&H21&I21
O22: =SUM(O5:O21) -> 473907.52 | Q22: =SUM(Q5:Q21) -> 3692810.9 | S22: =SUM(S5:S21) -> 6994536 | U22: =SUM(U5:U21) -> 0 | V22: =SUM(O22+Q22)+S22+U22 -> 11161254

Sheet Upload(시중가)-별도입력
A1: 표준내역코드 | B1: 세부공종 | C1: 품명 | D1: 규격 | E1: 단위 | F1: 수량 | G1: 재료비단가 | H1: 재료비소계 | I1: 노무비단가 | J1: 노무비소계 | K1: 기계경비단가 | L1: 기계경비소계 | M1: 기타경비단가 | N1: 기타경비소계 | O1: 할증코드 | P1: 재료비할증율 | Q1: 노무비할증율 | R1: 할증내용
B2: 999999 | C2: 유인팬(LONG FAN) | D2: 2700CMH*140W | E2: EA | F2: 20 | H2: 0 | J2: 0 | K2: 340000 | L2: =K2*F2 -> 6800000 | N2: =M2*F2 -> 0
B3: 999999 | C3: 화물차 | D3: 5TON | E3: HR | F3: 8 | G3: 19461 | H3: 127664.16 | I3: 49479 | J3: 284999.04 | K3: 15235 | L3: 121880 | N3: =M3*F3 -> 0
H4: =G4*F4 -> 0 | J4: =I4*F4 -> 0 | L4: =K4*F4 -> 0 | N4: =M4*F4 -> 0
H5: =G5*F5 -> 0 | J5: =I5*F5 -> 0 | L5: =K5*F5 -> 0 | N5: =M5*F5 -> 0
H6: =G6*F6 -> 0 | J6: =I6*F6 -> 0 | L6: =K6*F6 -> 0 | N6: =M6*F6 -> 0
H7: =G7*F7 -> 0 | J7: =I7*F7 -> 0 | L7: =K7*F7 -> 0 | N7: =M7*F7 -> 0
H8: =G8*F8 -> 0 | J8: =I8*F8 -> 0 | L8: =K8*F8 -> 0 | N8: =M8*F8 -> 0
H9: =G9*F9 -> 0 | J9: =I9*F9 -> 0 | L9: =K9*F9 -> 0 | N9: =M9*F9 -> 0
H10: =G10*F10 -> 0 | J10: =I10*F10 -> 0 | L10: =K10*F10 -> 0 | N10: =M10*F10 -> 0
H11: =G11*F11 -> 0 | J11: =I11*F11 -> 0 | L11: =K11*F11 -> 0 | N11: =M11*F11 -> 0
H12: =G12*F12 -> 0 | J12: =I12*F12 -> 0 | L12: =K12*F12 -> 0 | N12: =M12*F12 -> 0
H13: =G13*F13 -> 0 | J13: =I13*F13 -> 0 | L13: =K13*F13 -> 0 | N13: =M13*F13 -> 0
H14: =G14*F14 -> 0 | J14: =I14*F14 -> 0 | L14: =K14*F14 -> 0 | N14: =M14*F14 -> 0
H15: =G15*F15 -> 0 | J15: =I15*F15 -> 0 | L15: =K15*F15 -> 0 | N15: =M15*F15 -> 0
H16: =G16*F16 -> 0 | J16: =I16*F16 -> 0 | L16: =K16*F16 -> 0 | N16: =M16*F16 -> 0
A18: ■시중가 입력시 (5가지중 1가지 첨부)_유사한 코드가 있으면 대체 적용하며, 불가피 한경우만 시중가 사용함_불가피 할경우 아래 5가지 중 1개 첨부 1. 업체 비교견적서 첨부 최소 2개사 (자재 거래처(자재상)_공사업체 는 제외해당) 2. 기실적 단가 3. 세금계산서 및 거래명세서 첨부 4. 단독취급 MAKER 자재의 경우 1개사 견적서 처리 가능함(대리점 포함, 사코_감압변 등 독자 메이커만 취급 하는 경우에 해당함) 5. 물가자료 책자 정보 증빙 첨부 (물가자료 책자 스캔 후 표시 증빙 첨부) 6. 기타사항 (협의후)
B40: 유인팬 | F40: 화물차

Sheet Upload
A1: 구분 | B1: 표준단가 | C1: 표준품셈 | D1: 물가정보 | E1: 노임단가 | F1: 수량 | H1: ★ 작성방법
A2: ='내역서(표준단가)'!E5 -> 0 | B2: ='내역서(표준단가)'!F5 -> 0 | C2: ='내역서(표준단가)'!G5 -> 0 | D2: ='내역서(표준단가)'!H5 -> 0 | E2: ='내역서(표준단가)'!I5 -> 0 | F2: ='내역서(표준단가)'!M5 -> 0 | H2: ① 내역서(엑셀) 내 품목코드, 수량 입력시 upload자료 내 자동반영됨
A3: ='내역서(표준단가)'!E6 -> 999999 | B3: ='내역서(표준단가)'!F6 -> 0 | C3: ='내역서(표준단가)'!G6 -> 0 | D3: ='내역서(표준단가)'!H6 -> 999999 | E3: ='내역서(표준단가)'!I6 -> 0 | F3: ='내역서(표준단가)'!M6 -> 20 | H3: ③ 시중가/할증은 atG 화면 내 별도입력(본 탭 내에는 표준 Code만 입력)
A4: ='내역서(표준단가)'!E7 -> E00000806004020402 | B4: ='내역서(표준단가)'!F7 -> 0 | C4: ='내역서(표준단가)'!G7 -> E00000806004020402 | D4: ='내역서(표준단가)'!H7 -> 0 | E4: ='내역서(표준단가)'!I7 -> 0 | F4: ='내역서(표준단가)'!M7 -> 20
A5: ='내역서(표준단가)'!E8 -> E00000806004020402 | B5: ='내역서(표준단가)'!F8 -> 0 | C5: ='내역서(표준단가)'!G8 -> E00000806004020402 | D5: ='내역서(표준단가)'!H8 -> 0 | E5: ='내역서(표준단가)'!I8 -> 0 | F5: ='내역서(표준단가)'!M8 -> 20
A6: ='내역서(표준단가)'!E9 -> M010332810030101 | B6: ='내역서(표준단가)'!F9 -> 0 | C6: ='내역서(표준단가)'!G9 -> 0 | D6: ='내역서(표준단가)'!H9 -> M010332810030101 | E6: ='내역서(표준단가)'!I9 -> 0 | F6: ='내역서(표준단가)'!M9 -> 160
A7: ='내역서(표준단가)'!E10 -> M01525GR10400101 | B7: ='내역서(표준단가)'!F10 -> 0 | C7: ='내역서(표준단가)'!G10 -> 0 | D7: ='내역서(표준단가)'!H10 -> M01525GR10400101 | E7: ='내역서(표준단가)'!I10 -> 0 | F7: ='내역서(표준단가)'!M10 -> 80
A8: ='내역서(표준단가)'!E11 -> E00000808374071205 | B8: ='내역서(표준단가)'!F11 -> 0 | C8: ='내역서(표준단가)'!G11 -> E00000808374071205 | D8: ='내역서(표준단가)'!H11 -> 0 | E8: ='내역서(표준단가)'!I11 -> 0 | F8: ='내역서(표준단가)'!M11 -> 80
A9: ='내역서(표준단가)'!E12 -> E00000808374071205 | B9: ='내역서(표준단가)'!F12 -> 0 | C9: ='내역서(표준단가)'!G12 -> E00000808374071205 | D9: ='내역서(표준단가)'!H12 -> 0 | E9: ='내역서(표준단가)'!I12 -> 0 | F9: ='내역서(표준단가)'!M12 -> 80
A10: ='내역서(표준단가)'!E13 -> M020251411610101 | B10: ='내역서(표준단가)'!F13 -> 0 | C10: ='내역서(표준단가)'!G13 -> 0 | D10: ='내역서(표준단가)'!H13 -> M020251411610101 | E10: ='내역서(표준단가)'!I13 -> 0 | F10: ='내역서(표준단가)'!M13 -> 1
A11: ='내역서(표준단가)'!E14 -> E00000803051260301 | B11: ='내역서(표준단가)'!F14 -> 0 | C11: ='내역서(표준단가)'!G14 -> E00000803051260301 | D11: ='내역서(표준단가)'!H14 -> 0 | E11: ='내역서(표준단가)'!I14 -> 0 | F11: ='내역서(표준단가)'!M14 -> 1
A12: ='내역서(표준단가)'!E15 -> 999999 | B12: ='내역서(표준단가)'!F15 -> 0 | C12: ='내역서(표준단가)'!G15 -> 0 | D12: ='내역서(표준단가)'!H15 -> 999999 | E12: ='내역서(표준단가)'!I15 -> 0 | F12: ='내역서(표준단가)'!M15 -> 8
A13: ='내역서(표준단가)'!E16 -> E00000805033430105 | B13: ='내역서(표준단가)'!F16 -> 0 | C13: ='내역서(표준단가)'!G16 -> E00000805033430105 | D13: ='내역서(표준단가)'!H16 -> 0 | E13: ='내역서(표준단가)'!I16 -> 0 | F13: ='내역서(표준단가)'!M16 -> 8
A14: ='내역서(표준단가)'!E17 -> L002 | B14: ='내역서(표준단가)'!F17 -> 0 | C14: ='내역서(표준단가)'!G17 -> 0 | D14: ='내역서(표준단가)'!H17 -> 0 | E14: ='내역서(표준단가)'!I17 -> L002 | F14: ='내역서(표준단가)'!M17 -> 1
A15: ='내역서(표준단가)'!E18 -> L002 | B15: ='내역서(표준단가)'!F18 -> 0 | C15: ='내역서(표준단가)'!G18 -> 0 | D15: ='내역서(표준단가)'!H18 -> 0 | E15: ='내역서(표준단가)'!I18 -> L002 | F15: ='내역서(표준단가)'!M18 -> 1
... A24: ='내역서(표준단가)'!E27 -> 0 | B24: ='내역서(표준단가)'!F27 -> 0 | C24: ='내역서(표준단가)'!G27 -> 0 | D24: ='내역서(표준단가)'!H27 -> 0 | E24: ='내역서(표준단가)'!I27 -> 0 | F24: ='내역서(표준단가)'!M27 -> 0
A25: ='내역서(표준단가)'!E24 -> 0 | B25: ='내역서(표준단가)'!F24 -> 0 | C25: ='내역서(표준단가)'!G24 -> 0 | D25: ='내역서(표준단가)'!H24 -> 0 | E25: ='내역서(표준단가)'!I24 -> 0 | F25: ='내역서(표준단가)'!M24 -> 0
A26: ='내역서(표준단가)'!E25 -> 0 | B26: ='내역서(표준단가)'!F25 -> 0 | C26: ='내역서(표준단가)'!G25 -> 0 | D26: ='내역서(표준단가)'!H25 -> 0 | E26: ='내역서(표준단가)'!I25 -> 0 | F26: ='내역서(표준단가)'!M25 -> 0
A27: ='내역서(표준단가)'!E32 -> 0 | B27: ='내역서(표준단가)'!F32 -> 0 | C27: ='내역서(표준단가)'!G32 -> 0 | D27: ='내역서(표준단가)'!H32 -> 0 | E27: ='내역서(표준단가)'!I32 -> 0 | F27: ='내역서(표준단가)'!M32 -> 0
A28: ='내역서(표준단가)'!E33 -> 0 | B28: ='내역서(표준단가)'!F33 -> 0 | C28: ='내역서(표준단가)'!G33 -> 0 | D28: ='내역서(표준단가)'!H33 -> 0 | E28: ='내역서(표준단가)'!I33 -> 0 | F28: ='내역서(표준단가)'!M33 -> 0
A29: ='내역서(표준단가)'!E34 -> 0 | B29: ='내역서(표준단가)'!F34 -> 0 | C29: ='내역서(표준단가)'!G34 -> 0 | D29: ='내역서(표준단가)'!H34 -> 0 | E29: ='내역서(표준단가)'!I34 -> 0 | F29: ='내역서(표준단가)'!M34 -> 0
A30: ='내역서(표준단가)'!E35 -> 0 | B30: ='내역서(표준단가)'!F35 -> 0 | C30: ='내역서(표준단가)'!G35 -> 0 | D30: ='내역서(표준단가)'!H35 -> 0 | E30: ='내역서(표준단가)'!I35 -> 0 | F30: ='내역서(표준단가)'!M35 -> 0
A31: ='내역서(표준단가)'!E36 -> 0 | B31: ='내역서(표준단가)'!F36 -> 0 | C31: ='내역서(표준단가)'!G36 -> 0 | D31: ='내역서(표준단가)'!H36 -> 0 | E31: ='내역서(표준단가)'!I36 -> 0 | F31: ='내역서(표준단가)'!M36 -> 0
A32: ='내역서(표준단가)'!E37 -> 0 | B32: ='내역서(표준단가)'!F37 -> 0 | C32: ='내역서(표준단가)'!G37 -> 0 | D32: ='내역서(표준단가)'!H37 -> 0 | E32: ='내역서(표준단가)'!I37 -> 0 | F32: ='내역서(표준단가)'!M37 -> 0
A33: ='내역서(표준단가)'!E38 -> 0 | B33: ='내역서(표준단가)'!F38 -> 0 | C33: ='내역서(표준단가)'!G38 -> 0 | D33: ='내역서(표준단가)'!H38 -> 0 | E33: ='내역서(표준단가)'!I38 -> 0 | F33: ='내역서(표준단가)'!M38 -> 0
A34: ='내역서(표준단가)'!E39 -> 0 | B34: ='내역서(표준단가)'!F39 -> 0 | C34: ='내역서(표준단가)'!G39 -> 0 | D34: ='내역서(표준단가)'!H39 -> 0 | E34: ='내역서(표준단가)'!I39 -> 0 | F34: ='내역서(표준단가)'!M39 -> 0
A35: ='내역서(표준단가)'!E40 -> 0 | B35: ='내역서(표준단가)'!F40 -> 0 | C35: ='내역서(표준단가)'!G40 -> 0 | D35: ='내역서(표준단가)'!H40 -> 0 | E35: ='내역서(표준단가)'!I40 -> 0 | F35: ='내역서(표준단가)'!M40 -> 0
A36: ='내역서(표준단가)'!E41 -> 0 | B36: ='내역서(표준단가)'!F41 -> 0 | C36: ='내역서(표준단가)'!G41 -> 0 | D36: ='내역서(표준단가)'!H41 -> 0 | E36: ='내역서(표준단가)'!I41 -> 0 | F36: ='내역서(표준단가)'!M41 -> 0
A37: ='내역서(표준단가)'!E42 -> 0 | B37: ='내역서(표준단가)'!F42 -> 0 | C37: ='내역서(표준단가)'!G42 -> 0 | D37: ='내역서(표준단가)'!H42 -> 0 | E37: ='내역서(표준단가)'!I42 -> 0 | F37: ='내역서(표준단가)'!M42 -> 0
A38: ='내역서(표준단가)'!E43 -> 0 | B38: ='내역서(표준단가)'!F43 -> 0 | C38: ='내역서(표준단가)'!G43 -> 0 | D38: ='내역서(표준단가)'!H43 -> 0 | E38: ='내역서(표준단가)'!I43 -> 0 | F38: ='내역서(표준단가)'!M43 -> 0
... A318: ='내역서(표준단가)'!E323 -> 0 | B318: ='내역서(표준단가)'!F323 -> 0 | C318: ='내역서(표준단가)'!G323 -> 0 | D318: ='내역서(표준단가)'!H323 -> 0 | E318: ='내역서(표준단가)'!I323 -> 0 | F318: ='내역서(표준단가)'!M323 -> 0
A319: ='내역서(표준단가)'!E143 -> 0 | B319: ='내역서(표준단가)'!F143 -> 0 | C319: ='내역서(표준단가)'!G143 -> 0 | D319: ='내역서(표준단가)'!H143 -> 0 | E319: ='내역서(표준단가)'!I143 -> 0 | F319: ='내역서(표준단가)'!M143 -> 0
A320: ='내역서(표준단가)'!E144 -> 0 | B320: ='내역서(표준단가)'!F144 -> 0 | C320: ='내역서(표준단가)'!G144 -> 0 | D320: ='내역서(표준단가)'!H144 -> 0 | E320: ='내역서(표준단가)'!I144 -> 0 | F320: ='내역서(표준단가)'!M144 -> 0
A321: ='내역서(표준단가)'!E145 -> 0 | B321: ='내역서(표준단가)'!F145 -> 0 | C321: ='내역서(표준단가)'!G145 -> 0 | D321: ='내역서(표준단가)'!H145 -> 0 | E321: ='내역서(표준단가)'!I145 -> 0 | F321: ='내역서(표준단가)'!M145 -> 0
A322: ='내역서(표준단가)'!E146 -> 0 | B322: ='내역서(표준단가)'!F146 -> 0 | C322: ='내역서(표준단가)'!G146 -> 0 | D322: ='내역서(표준단가)'!H146 -> 0 | E322: ='내역서(표준단가)'!I146 -> 0 | F322: ='내역서(표준단가)'!M146 -> 0
A323: ='내역서(표준단가)'!E147 -> 0 | B323: ='내역서(표준단가)'!F147 -> 0 | C323: ='내역서(표준단가)'!G147 -> 0 | D323: ='내역서(표준단가)'!H147 -> 0 | E323: ='내역서(표준단가)'!I147 -> 0 | F323: ='내역서(표준단가)'!M147 -> 0
A324: ='내역서(표준단가)'!E148 -> 0 | B324: ='내역서(표준단가)'!F148 -> 0 | C324: ='내역서(표준단가)'!G148 -> 0 | D324: ='내역서(표준단가)'!H148 -> 0 | E324: ='내역서(표준단가)'!I148 -> 0 | F324: ='내역서(표준단가)'!M148 -> 0
A325: ='내역서(표준단가)'!E149 -> 0 | B325: ='내역서(표준단가)'!F149 -> 0 | C325: ='내역서(표준단가)'!G149 -> 0 | D325: ='내역서(표준단가)'!H149 -> 0 | E325: ='내역서(표준단가)'!I149 -> 0 | F325: ='내역서(표준단가)'!M149 -> 0
A326: ='내역서(표준단가)'!E150 -> 0 | B326: ='내역서(표준단가)'!F150 -> 0 | C326: ='내역서(표준단가)'!G150 -> 0 | D326: ='내역서(표준단가)'!H150 -> 0 | E326: ='내역서(표준단가)'!I150 -> 0 | F326: ='내역서(표준단가)'!M150 -> 0
A327: ='내역서(표준단가)'!E151 -> 0 | B327: ='내역서(표준단가)'!F151 -> 0 | C327: ='내역서(표준단가)'!G151 -> 0 | D327: ='내역서(표준단가)'!H151 -> 0 | E327: ='내역서(표준단가)'!I151 -> 0 | F327: ='내역서(표준단가)'!M151 -> 0
...

Sheet 할증기준
A1: ■ atG 할증기준

Sheet 공사수립계획서
B1: 공사수립계획서
B4: 업 체 명 | C4: 주식회사수안이엔지 | D4: 일 시 | E4: =#REF! -> #REF!
B5: 공 사 명 | C5: =#REF! -> #REF!
B6: 공사 업체 | C6: ■ 공사기간 : 입찰시스템 계약기간에 준함
C7: ■ 인원투입계획 : 총 명(주말 : 명)
C8: ■ 시공방법
C9: -. 화물차 사용, 신호수 배치
C10: -. 기 설치된 유인팬 및 전산볼트 철거
C11: -. 앙카 설치 후 전산볼트 설치
C12: -. 유인팬 교체 설치
C13: -. 사다리 작업 시 사다리 보조자 투입
C14: -. 전산볼트 커팅시 화기작업, 화기감시자 배치
C15: -. 주변정리
C20: ■ 위험작업 유무 : 유(고소,화기,신호수)
C21: ■ 안전확보 방안 :
C22: -. 작업전 작업내용 숙지 및 작업 순서 확인.
... C31: ■ 주요 사용물질 : 산소 0kg, 알곤 20kg, 질소 0kg, 냉매(R-22) 0kg 등
B35: 수안이엔지 | C35: 성명 : 김 용 도 | D35: (인감/서명)
B36: S&I | C36: 성명 : | D36: 서명

Sheet 산출서
A1: 주요 물량 산출서
A3: =#REF! -> #REF!
A4: 품명 | B4: 규격 | C4: 단위 | D4: 수량 | E4: 산출근거 | F4: 내역도면번호 | G4: 비고
A5: ='내역서(표준단가)'!J5 -> 지하주차장 유인팬 교체 | B5: ='내역서(표준단가)'!K5 -> 0 | C5: ='내역서(표준단가)'!L5 -> 0 | D5: ='내역서(표준단가)'!M5 -> 0
A6: ='내역서(표준단가)'!J6 -> 유인팬(LONG FAN) | B6: ='내역서(표준단가)'!K6 -> 2700CMH*140W | C6: ='내역서(표준단가)'!L6 -> EA | D6: ='내역서(표준단가)'!M6 -> 20 | E6: =20
A7: ='내역서(표준단가)'!J7 -> 무덕트 배기팬 설치 | B7: ='내역서(표준단가)'!K7 -> 풍량 2,400㎥/h이하 | C7: ='내역서(표준단가)'!L7 -> (대당) | D7: ='내역서(표준단가)'!M7 -> 20 | E7: =20
A8: ='내역서(표준단가)'!J8 -> 무덕트 배기팬 설치 (철거) | B8: ='내역서(표준단가)'!K8 -> 풍량 2,400㎥/h이하 | C8: ='내역서(표준단가)'!L8 -> (대당) | D8: ='내역서(표준단가)'!M8 -> 20 | E8: =20
A9: ='내역서(표준단가)'!J9 -> 전산볼트 | B9: ='내역서(표준단가)'!K9 -> M10(도금) (길이 1m) | C9: ='내역서(표준단가)'!L9 -> 개 | D9: ='내역서(표준단가)'!M9 -> 160 | E9: =2*4*20
A10: ='내역서(표준단가)'!J10 -> 셋트앙카 | B10: ='내역서(표준단가)'!K10 -> ø9㎜×6㎝ | C10: ='내역서(표준단가)'!L10 -> 개 | D10: ='내역서(표준단가)'!M10 -> 80 | E10: =4*20
A11: ='내역서(표준단가)'!J11 -> 부대공사(앙카볼트 설치 등) - 앙카볼트설치 | B11: ='내역서(표준단가)'!K11 -> ø13㎜ 이하 | C11: ='내역서(표준단가)'!L11 -> (개당) | D11: ='내역서(표준단가)'!M11 -> 80 | E11: =4*20
A12: ='내역서(표준단가)'!J12 -> 부대공사(앙카볼트 설치 등) - 앙카볼트설치 (철거) | B12: ='내역서(표준단가)'!K12 -> ø13㎜ 이하 | C12: ='내역서(표준단가)'!L12 -> (개당) | D12: ='내역서(표준단가)'!M12 -> 80 | E12: =4*20
A13: ='내역서(표준단가)'!J13 -> 프리미엄 그린실 808 | B13: ='내역서(표준단가)'!K13 -> 1액형 실리콘, 다목적 건축실링용, 유리글레이징, 친환경 인증 | C13: ='내역서(표준단가)'!L13 -> 270㎖ | D13: ='내역서(표준단가)'!M13 -> 1 | E13: =1
A14: ='내역서(표준단가)'!J14 -> 코킹 | B14: ='내역서(표준단가)'!K14 -> 코킹 | C14: ='내역서(표준단가)'!L14 -> (10m 당) | D14: ='내역서(표준단가)'!M14 -> 1 | E14: =1
A15: ='내역서(표준단가)'!J15 -> 화물차 | B15: ='내역서(표준단가)'!K15 -> 5TON | C15: ='내역서(표준단가)'!L15 -> HR | D15: ='내역서(표준단가)'!M15 -> 8 | E15: =8
A16: ='내역서(표준단가)'!J16 -> 지게차 | B16: ='내역서(표준단가)'!K16 -> 7.55ton | C16: ='내역서(표준단가)'!L16 -> (시간당) | D16: ='내역서(표준단가)'!M16 -> 8 | E16: =8
A17: ='내역서(표준단가)'!J17 -> 보통인부 | B17: ='내역서(표준단가)'!K17 -> 사다리보조자 | C17: ='내역서(표준단가)'!L17 -> 인 | D17: ='내역서(표준단가)'!M17 -> 1 | E17: =3
A18: ='내역서(표준단가)'!J18 -> 보통인부 | B18: ='내역서(표준단가)'!K18 -> 신호수 | C18: ='내역서(표준단가)'!L18 -> 인 | D18: ='내역서(표준단가)'!M18 -> 1 | E18: =2
A19: ='내역서(표준단가)'!J19 -> 0 | B19: ='내역서(표준단가)'!K19 -> 0 | C19: ='내역서(표준단가)'!L19 -> 0 | D19: ='내역서(표준단가)'!M19 -> 0
A20: ='내역서(표준단가)'!J20 -> 0 | B20: ='내역서(표준단가)'!K20 -> 0 | C20: ='내역서(표준단가)'!L20 -> 0 | D20: ='내역서(표준단가)'!M20 -> 0
A21: ='내역서(표준단가)'!J21 -> 0 | B21: ='내역서(표준단가)'!K21 -> 0 | C21: ='내역서(표준단가)'!L21 -> 0 | D21: ='내역서(표준단가)'!M21 -> 0
A22: ='내역서(표준단가)'!J22 -> 0 | B22: ='내역서(표준단가)'!K22 -> 0 | C22: ='내역서(표준단가)'!L22 -> 0 | D22: ='내역서(표준단가)'!M22 -> 0
A23: ='내역서(표준단가)'!J23 -> 0 | B23: ='내역서(표준단가)'!K23 -> 0 | C23: ='내역서(표준단가)'!L23 -> 0 | D23: ='내역서(표준단가)'!M23 -> 0
A24: ='내역서(표준단가)'!J24 -> 0 | B24: ='내역서(표준단가)'!K24 -> 0 | C24: ='내역서(표준단가)'!L24 -> 0 | D24: ='내역서(표준단가)'!M24 -> 0
A25: ='내역서(표준단가)'!J25 -> 0 | B25: ='내역서(표준단가)'!K25 -> 0 | C25: ='내역서(표준단가)'!L25 -> 0 | D25: ='내역서(표준단가)'!M25 -> 0
A26: ='내역서(표준단가)'!J28 -> 0 | B26: ='내역서(표준단가)'!K28 -> 0 | C26: ='내역서(표준단가)'!L28 -> 0 | D26: ='내역서(표준단가)'!M28 -> 0
A27: ='내역서(표준단가)'!J29 -> 0 | B27: ='내역서(표준단가)'!K29 -> 0 | C27: ='내역서(표준단가)'!L29 -> 0 | D27: ='내역서(표준단가)'!M29 -> 0
A28: ='내역서(표준단가)'!J30 -> 0 | B28: ='내역서(표준단가)'!K30 -> 0 | C28: ='내역서(표준단가)'!L30 -> 0 | D28: ='내역서(표준단가)'!M30 -> 0
A29: ='내역서(표준단가)'!J31 -> 0 | B29: ='내역서(표준단가)'!K31 -> 0 | C29: ='내역서(표준단가)'!L31 -> 0 | D29: ='내역서(표준단가)'!M31 -> 0
A30: ='내역서(표준단가)'!J32 -> 0 | B30: ='내역서(표준단가)'!K32 -> 0 | C30: ='내역서(표준단가)'!L32 -> 0 | D30: ='내역서(표준단가)'!M32 -> 0
A31: ='내역서(표준단가)'!J33 -> 0 | B31: ='내역서(표준단가)'!K33 -> 0 | C31: ='내역서(표준단가)'!L33 -> 0 | D31: ='내역서(표준단가)'!M33 -> 0
A32: ='내역서(표준단가)'!J34 -> 0 | B32: ='내역서(표준단가)'!K34 -> 0 | C32: ='내역서(표준단가)'!L34 -> 0 | D32: ='내역서(표준단가)'!M34 -> 0
A33: ='내역서(표준단가)'!J35 -> 0 | B33: ='내역서(표준단가)'!K35 -> 0 | C33: ='내역서(표준단가)'!L35 -> 0 | D33: ='내역서(표준단가)'!M35 -> 0
A34: ='내역서(표준단가)'!J36 -> 0 | B34: ='내역서(표준단가)'!K36 -> 0 | C34: ='내역서(표준단가)'!L36 -> 0 | D34: ='내역서(표준단가)'!M36 -> 0
A35: ='내역서(표준단가)'!J37 -> 0 | B35: ='내역서(표준단가)'!K37 -> 0 | C35: ='내역서(표준단가)'!L37 -> 0 | D35: ='내역서(표준단가)'!M37 -> 0
A36: ='내역서(표준단가)'!J38 -> 0 | B36: ='내역서(표준단가)'!K38 -> 0 | C36: ='내역서(표준단가)'!L38 -> 0 | D36: ='내역서(표준단가)'!M38 -> 0
A37: ='내역서(표준단가)'!J39 -> 0 | B37: ='내역서(표준단가)'!K39 -> 0 | C37: ='내역서(표준단가)'!L39 -> 0 | D37: ='내역서(표준단가)'!M39 -> 0
... A74: ='내역서(표준단가)'!J76 -> 0 | B74: ='내역서(표준단가)'!K76 -> 0 | C74: ='내역서(표준단가)'!L76 -> 0 | D74: ='내역서(표준단가)'!M76 -> 0
D75: =ROUND(dhtextevaluate(E75),1) -> #NAME?
D76: =ROUND(dhtextevaluate(E76),1) -> #NAME?
D77: =ROUND(dhtextevaluate(E77),1) -> #NAME?
...
