Workbook

Sheet 갑지
A2: 견 적 서
A5: 수신인 : 주식회사 에스엔아이 코퍼레이션 | F5: 등록번호 | G5: 314-86-35718
F6: 상 호 | G6: ㈜일성건축
A7: 공사명 : 기숙사 및 사택 긴급 보수작업(건축)-7차 | F7: 대표 이사 | G7: 상 석 희
F8: 사업장 | G8: 대전 서구 도마6길 107 (도마동)
A9: 견적일 : 2025년 10월 일 | F9: 업 태 | G9: 건설업
F10: 종 목 | G10: 실내건축,인테리어공사
F11: TEL, FAX | G11: 042)527-0995, 042)527-0996
A12: 금액: | B12: =NUMBERSTRING(F31,1) -> 육백육십팔만사천 | D12: 원정
A14: NO | B14: 품명 | C14: 규격 | D14: 수량 | E14: 단위 | F14: 금액 | G14: 비고
B15: 직접비
B16: 재료비 | F16: ='내역서(표준단가)-7차'!O15 -> 2362974
B17: 노무비 | F17: ='내역서(표준단가)-7차'!Q15 -> 3479527.7
B18: 기계/기타경비 | F18: ='내역서(표준단가)-7차'!S15+'내역서(표준단가)-7차'!U15 -> 0
B19: 소계 | F19: =F16+F17+F18 -> 5842501.7
B20: 간접비
B21: 국민연금 | C21: 노무비*4.5% | D21: 1 | E21: 식 | F21: =F17*4.5% -> 156578.74 | G21: 모든공사에 적용
B22: 건강보험료 | C22: 노무비*3.545% | D22: 1 | E22: 식 | F22: =F17*3.545% -> 123349.26 | G22: 모든공사에 적용
B23: 장기요양보험료 | C23: 건강보험료*12.95% | D23: 1 | E23: 식 | F23: =F22*12.95% -> 15973.729 | G23: 모든공사에 적용
B24: 고용보험료 | C24: 노무비*1.01% | D24: 1 | E24: 식 | F24: =F17*1.01% -> 35143.229 | G24: 모든공사에 적용
B25: 산재보험료 | C25: 노무비*3.56% | D25: 1 | E25: 식 | F25: =F17*3.56% -> 123871.18 | G25: 모든공사에 적용
B26: 산업안전보건관리비 | C26: (재료비+노무비)*3.11% | D26: 1 | E26: 식 | F26: =(F16+F17)*3.11% -> 181701.8 | G26: 모든공사에 적용
B27: 일반관리비/이윤 | C27: (노무비+간접공사비)*5% | D27: 1 | E27: 식 | F27: =SUM(F17+F21+F22+F23+F24+F25+F26)*5% -> 205807.28
B28: 소계 | F28: =F21+F22+F23+F24+F25+F26+F27 -> 842425.23
F30: =F19+F28+F29 -> 6684926.9
B31: 합계(단수조정) | F31: =ROUNDDOWN(F30,-3) -> 6684000
B32: VAT별도 | G32: 매입계약 : 4,556,000

Sheet 내역서(표준단가)-7차
O1: ▼낙찰율 | Q1: ▼낙찰율 | S1: ▼낙찰율 | U1: ▼낙찰율
O2: 0.835 | Q2: 0.835 | S2: 0.835 | U2: 0.835
F3: ▶ 표준 Code(표준단가/품셈/물정/노임) 순서별 입력(Upload 자동반영) | J3: 주요내역 | L3: 단위 | M3: 수량 | N3: 재료비 | P3: 노무비 | R3: 기계경비 | T3: 기타경비(부자재비) | V3: 합계 | W3: 노무비 할증 | X3: 할증기준
A4: 합계 | F4: 표준단가 D | G4: 표준품셈 E | H4: 물가정보 M | I4: 노임단가 L | J4: 품목 | K4: 규격 | N4: 품셈/표단 | O4: 금액 | P4: 단가 | Q4: 금액 | R4: 단가 | S4: 금액 | T4: 단가 | U4: 금액
A5: =F5&G5&H5&I5 -> L003 | I5: L003 | J5: 긴급보수 대응 | K5: 특별인부 | L5: M/D | M5: 19 | O5: =SUM(N5:N5)*M5*$O$2 -> 0 | P5: 219321 | Q5: =(P5*M5)*Q2 -> 3479527.7 | S5: =R5*M5*$S$2 -> 0 | U5: =T5*M5*$U$2 -> 0 | V5: =SUM(O5+Q5)+S5+U5 -> 3479527.7
A6: =F6&G6&H6&I6 -> M020450310340103 | H6: M020450310340103 | J6: 방충망 AL | K6: MFA, 1,000×1,000㎜, AL도장 | L6: ㎡ | M6: ='관리소 접수 입력'!P80+'관리소 접수 입력'!P93+'관리소 접수 입력'!P114 -> 60.27 | N6: 36500 | O6: =SUM(N6:N6)*M6*$O$2 -> 1836878.9 | Q6: =(P6*M6)*$Q$2 -> 0 | S6: =R6*M6*$S$2 -> 0 | U6: =T6*M6*$U$2 -> 0 | V6: =SUM(O6+Q6)+S6+U6 -> 1836878.9 | X6: 4차분 이월 방충망 2.62개 정산 5차분 정산 방충망 3.73개 6차분 이월 방충망 20.27(5차 이월분)+10.94
A7: =F7&G7&H7&I7 -> M020251411670101 | H7: M020251411670101 | J7: 다우실 1000 | K7: 1액형 실리콘, 발코니 창호 주위 조인트용(창틀용) | L7: 270㎖ | M7: ='관리소 접수 입력'!Q114+'관리소 접수 입력'!Q93+'관리소 접수 입력'!Q80 -> 45 | N7: 5000 | O7: =SUM(N7:N7)*M7*$O$2 -> 187875 | Q7: =(P7*M7)*$Q$2 -> 0 | S7: =R7*M7*$S$2 -> 0 | U7: =T7*M7*$U$2 -> 0 | V7: =SUM(O7+Q7)+S7+U7 -> 187875
A8: =F8&G8&H8&I8 -> M020533113070101 | H8: M020533113070101 | J8: 걸레받이 | K8: SHWB-100, W:100×2T | L8: m | M8: ='관리소 접수 입력'!R80+'관리소 접수 입력'!R93+'관리소 접수 입력'!R114 -> 44 | N8: 3400 | O8: =SUM(N8:N8)*M8*$O$2 -> 124916 | Q8: =(P8*M8)*$Q$2 -> 0 | S8: =R8*M8*$S$2 -> 0 | U8: =T8*M8*$U$2 -> 0 | V8: =SUM(O8+Q8)+S8+U8 -> 124916
A9: =F9&G9&H9&I9 -> M020852810150101 | H9: M020852810150101 | J9: 롤스크린(단면암막) | K9: 방염, 기본면적: 2㎡ | L9: ㎡ | M9: ='관리소 접수 입력'!S80 -> 1 | N9: 55000 | O9: =SUM(N9:N9)*M9*$O$2 -> 45925 | Q9: =(P9*M9)*$Q$2 -> 0 | S9: =R9*M9*$S$2 -> 0 | U9: =T9*M9*$U$2 -> 0 | V9: =SUM(O9+Q9)+S9+U9 -> 45925
A10: 999999 | J10: 씽크대 문짝 교체 | K10: 7동 107호 | L10: L/S | M10: 1 | N10: 50000 | O10: =SUM(N10:N10)*M10*$O$2 -> 41750 | V10: =SUM(O10+Q10)+S10+U10 -> 41750
A11: 999999 | J11: 방화실리콘 및 강화몰탈 | K11: 20kg | L11: L/S | M11: 1 | N11: 51364 | O11: =SUM(N11:N11)*M11*$O$2 -> 42888.94 | Q11: =(P11*M11)*$Q$2 -> 0 | S11: =R11*M11*$S$2 -> 0 | U11: =T11*M11*$U$2 -> 0 | V11: =SUM(O11+Q11)+S11+U11 -> 42888.94
A12: 999999 | J12: 우레탄폼 | L12: L/S | M12: 1 | N12: 54545 | O12: =SUM(N12:N12)*M12*$O$2 -> 45545.075 | Q12: =(P12*M12)*$Q$2 -> 0 | S12: =R12*M12*$S$2 -> 0 | U12: =T12*M12*$U$2 -> 0 | V12: =SUM(O12+Q12)+S12+U12 -> 45545.075
A13: 999999 | J13: 방화패드 1매 | L13: L/S | M13: 1 | N13: 28636 | O13: =SUM(N13:N13)*M13*$O$2 -> 23911.06 | Q13: =(P13*M13)*$Q$2 -> 0 | S13: =R13*M13*$S$2 -> 0 | U13: =T13*M13*$U$2 -> 0 | V13: =SUM(O13+Q13)+S13+U13 -> 23911.06
A14: 999999 | J14: 강화몰탈 | K14: 20kg | L14: L/S | M14: 1 | N14: 15909 | O14: =SUM(N14:N14)*M14*$O$2 -> 13284.015 | Q14: =(P14*M14)*$Q$2 -> 0 | S14: =R14*M14*$S$2 -> 0 | U14: =T14*M14*$U$2 -> 0 | V14: =SUM(O14+Q14)+S14+U14 -> 13284.015
O15: =SUM(O5:O14) -> 2362974 | Q15: =SUM(Q5:Q14) -> 3479527.7 | S15: =SUM(S5:S6) -> 0 | U15: =SUM(U5:U6) -> 0 | V15: =SUM(V5:W14) -> 5842501.7

Sheet 관리소 접수 입력
B2: 샘플> | C2: 일성 | D2: 3 (관리제외) | E2: 1월1일 | F2: 14시30분 | G2: 1월2일 | H2: 15시30분 | K2: 사택 5동 | L2: 201 | M2: 관리소 담당자 | N2: - 문끌림 4개소/ 방충망 7개소/ 신발장 시트지 1개소 - 빨래건조 4개소 / 누수 천장 임시 철거 및 보수 | P2: =>금회 이월 | S2: =>금회 정산
B3: 건수 | C3: 업체명 | D3: 근로자 (직접 서명) | E3: 시작 | G3: 종료 | I3: 작업시간(인당) | J3: 전체 시간 | K3: 건물동 | L3: 호실 | M3: 작업지시 | N3: 보수 내용 | O3: 특별인부 (시공사 입력) | P3: 자재 내역 | Z3: 비고
E4: 일자 | F4: 시간 | G4: 일자 | H4: 시간 | I4: (종료-시간) | J4: (인원*작업시간) | P4: 방충망 (㎡=개) | Q4: 코킹재 (개) | R4: 걸레받이 (m) | S4: 블라인드 개소 (5㎡) | T4: 이보드 23t (m2) | U4: 열반사 단열재 (m2) | V4: 석고보드 12.5t(매) | W4: 신발장 필름 (6m2) | X4: 빨레 건조대 | Y4: 씽크대 보수
B5: 1차분 (정산 완료)
B6: 1 | C6: 일성건축 | D6: 2 | E6: 45679 | F6: 0.375 | G6: 45679 | H6: 0.69444444 | I6: =H6-F6 -> 0.31944444 | J6: =I6*D6 -> 0.63888889 | K6: 8 9 | L6: 206 303 | M6: 남해원 | N6: 뒤베란다 창고 누수점검 및 실리콘 작업 완료 뒤베란다 창고문 철거 완료 화장실 우측방 입구 바닥 평탄작업 완료 화장실문 시트지 보수 1개소 완료 | O6: 2 | Q6: 4
B7: 2 | C7: 일성건축 | D7: 2 | E7: 45680 | F7: 0.375 | G7: 45680 | H7: 0.6875 | I7: =H7-F7 -> 0.3125 | J7: =I7*D7 -> 0.625 | K7: 9 102 | L7: 303 201 | M7: 남해원 | N7: 화장실문 시트지 보수 1개소 완료 안방 걸레받이 들뜸 보수 완료 문보수1개소 완료 거실 걸레받이 2개소 교체 완료 | O7: 2 | Q7: 2 | R7: 3 | Z7: 문보수용 엣지 필름 구매(10매) 전동 대패날 교체(1set)
B8: 3 | C8: 일성건축 | D8: 2 | E8: 45681 | F8: 0.375 | G8: 45681 | H8: 0.69444444 | I8: =H8-F8 -> 0.31944444 | J8: =I8*D8 -> 0.63888889 | K8: A | L8: 401-6 503-4 504-2 504-5 | M8: 남해원 | N8: 화장실 도어 보수완료 방 도어 보수완료 화장실 도어 , 방 도어보수2개소 완료 화장실 도어 , 방 도어보수2개소 완료 | O8: 2
B9: 4 | C9: 일성건축 | D9: 2 | E9: 45691 | F9: 0.375 | G9: 45691 | H9: 0.6875 | I9: =H9-F9 -> 0.3125 | J9: =I9*D9 -> 0.625 | K9: A B | L9: 703-3 703-4 902-3 | M9: 남해원 | N9: 화장실 도어 , 방 도어보수2개소 완료 화장실 도어 , 방 도어보수2개소 완료 방 도어 보수완료 | O9: 2
B10: 5 | C10: 일성건축 | D10: 2 | E10: 45692 | F10: 0.375 | G10: 45692 | H10: 0.6875 | I10: =H10-F10 -> 0.3125 | J10: =I10*D10 -> 0.625 | K10: A B 8 | L10: 503-4 702-1 206 | M10: 남해원 | N10: 블라인드 설치 완료 방도어 보수완료 뒤베란다 창고 문틀 설치작업 방충망7개소 완료 | O10: 1.5 | P10: 7 | S10: 1 | V10: 1
B11: 6 | C11: 일성건축 | D11: 2 | E11: 45694 | F11: 0.375 | G11: 45694 | H11: 0.6875 | I11: =H11-F11 -> 0.3125 | J11: =I11*D11 -> 0.625 | K11: 8 | L11: 206 703-4 902-3 | M11: 남해원 | N11: 뒤베란다 창고문 재설치 완료 방충망7개소 완료 앞베란다 내.외부 실리콘 제거 및 재시공 완료 | O11: 1.5 | P11: 7 | Q11: 7
B12: 7 | C12: 일성건축 | D12: 2 | E12: 45695 | F12: 0.375 | G12: 45695 | H12: 0.6875 | I12: =H12-F12 -> 0.3125 | J12: =I12*D12 -> 0.625 | K12: 8 9 | L12: 501 401 303 | M12: 남해원 | N12: 현관문 도어 가스켓 교체 완료 현관문 도어 가스켓 교체 완료 방충망 7개소 완료 | O12: 1.5 | P12: 7 | Z12: 방화문 가스켓 구매 (3세대)
B13: 8 | C13: 일성건축 | D13: 2 | E13: 45698 | F13: 0.54166667 | G13: 45698 | H13: 0.6875 | I13: =H13-F13 -> 0.14583333 | J13: =I13*D13 -> 0.29166667 | K13: 8 5 | L13: 503 501 | M13: 남해원 | N13: 문보수 1개소 완료, 방충망 7개소 완료 뒤베란다 천장 패임 보수 작업 완료 문보수 1개소 완료 | O13: 1.5 | P13: 7
B14: 9 | C14: 일성건축 | D14: 2 | E14: 45699 | F14: 0.375 | G14: 45699 | H14: 0.67361111 | I14: =H14-F14 -> 0.29861111 | J14: =I14*D14 -> 0.59722222 | K14: 2 | L14: 203 | M14: 남해원 | N14: 방충망 3개소 완료 화장실문 시트지 교체 완료 뒤베란다 벽면 및 바닥 크렉보수,실리콘 작업 문보수 1개소 완료 | O14: 2 | P14: 3
B15: 10 | C15: 일성건축 | D15: 2 | E15: 45701 | F15: 0.375 | G15: 45701 | H15: 0.6875 | I15: =H15-F15 -> 0.3125 | J15: =I15*D15 -> 0.625 | K15: 102 | L15: 205 | M15: 남해원 | N15: 걸레받이 파손 2개소 교체 완료 도어보수 2개소 보수완료 안방 문틀 보수 완료 방충망 3개소 교체 완료 | O15: 2 | P15: 3 | Q15: 1 | R15: 0.3 (2.7) 전회이월
B16: 11 | C16: 일성건축 | D16: 2 | E16: 45702 | F16: 0.375 | G16: 45702 | H16: 0.5 | I16: =H16-F16 -> 0.125 | J16: =I16*D16 -> 0.25 | K16: 5 | L16: 301 | M16: 남해원 | N16: 누수 탐지(미래설비) 대기 인원 (일성건축) → 씽크대 철거,원복 하지 않음 | O16: 2
B17: 12 | C17: 일성건축 | D17: 1 | E17: 45707 | F17: 0.54166667 | G17: 45692 | H17: 0.64583333 | I17: =H17-F17 -> 0.10416667 | J17: =I17*D17 -> 0.10416667 | K17: 5 | L17: 501 | M17: 남해원 | N17: 방충망 7개소 완료 | P17: 7
B18: 소 계 | D18: =SUM(D6:D17) -> 23 | O18: =SUM(O6:O17) -> 20 | P18: =SUM(P5:P17) -> 41 | Q18: =SUM(Q5:Q17) -> 14 | R18: =SUM(R5:R17) -> 3
O19: =O18-D18 -> -3 | P19: 절감
B21: 2차분 (정산 완료)
B22: 13 | C22: 일성건축 | D22: 2 | E22: 45741 | F22: 0.375 | G22: 45741 | H22: 0.67708333 | I22: =H22-F22 -> 0.30208333 | J22: =I22*D22 -> 0.60416667 | K22: 7 | L22: 506 | M22: 남해원 | N22: 앞뒤 베란다 천장.벽면 들뜸보수 및 크랙 전체보수 앞뒤 베란다 창고 곰팡이 제거 및 천장 단열작업 | O22: =D22 -> 2 | Q22: 4 | T22: 2.5 | U22: 2.5 | Z22: 이보드(23T) 1장, 열반사 단열재 2.5m2
B23: 14 | C23: 일성건축 | D23: 2 | E23: 45744 | F23: 0.375 | G23: 45744 | H23: 0.68055556 | I23: =H23-F23 -> 0.30555556 | J23: =I23*D23 -> 0.61111111 | K23: A | L23: 903-4 701-5 503-5 401-3 303-5 | M23: 남해원 | N23: 방 및 화장실 도어 보수 방 도어 보수 방 도어 보수 화장실 도어 보수 방 도어 보수 | O23: =D23 -> 2
B24: 15 | C24: 일성건축 | D24: 2 | E24: 45747 | F24: 0.375 | G24: 45747 | H24: 0.6875 | I24: =H24-F24 -> 0.3125 | J24: =I24*D24 -> 0.625 | K24: A B | L24: 303-5 901-4 704-4 | M24: 남해원 | N24: 화장실 도어 보수 화장실 도어 보수 방 및 화장실 도어 보수 버티컬 설치 완료 | O24: =D24 -> 2 | S24: (5) m2 금회이월
B25: 16 | C25: 일성건축 | D25: 2 | E25: 45749 | F25: 0.375 | G25: 45749 | H25: 0.6875 | I25: =H25-F25 -> 0.3125 | J25: =I25*D25 -> 0.625 | K25: A B | L25: 701-5 702-1 1002-2 | M25: 남해원 | N25: 화장실 우측 석고보드 교체 버티컬 설치 완료 화장실 우측 석고 보드 교체 완료 발코니 창문 우측벽 단열재 들뜸 보수 | O25: =D25 -> 2 | S25: (3.62) m2 금회이월 | V25: 2 | Z25: 석고보드 (12.5T) 2장
B26: 17 | C26: 일성건축 | D26: 2 | E26: 45750 | F26: 0.375 | G26: 45750 | H26: 0.6875 | I26: =H26-F26 -> 0.3125 | J26: =I26*D26 -> 0.625 | K26: 8 | L26: 502 | M26: 남해원 | N26: 화장실 좌측방 천장 누수 점검 및 보수 씽크대 상판 전체 실리콘 제거후 재설치 작업 | O26: =D26 -> 2 | Q26: 2
B27: 18 | C27: 일성건축 | D27: 2 | E27: 45755 | F27: 0.375 | G27: 45755 | H27: 0.6875 | I27: =H27-F27 -> 0.3125 | J27: =I27*D27 -> 0.625 | K27: 2 | L27: 108 | M27: 남해원 | N27: 걸레받이 8군데 교체 완료 씽크대 상판 실리콘 제거후 재설치 작업 뒤베란다 벽면 크랙 보수 완료 화장실 벽면 모서리 4군데 실리콘 작업 | O27: =D27 -> 2 | Q27: 6 | R27: 9
B29: 소 계 | D29: =SUM(D13:D16,D22:D27) -> 20 | O29: =SUM(O13:O28) -> 36.5 | P29: =SUM(P22:P28) -> 0 | Q29: =SUM(Q22:Q28) -> 12 | R29: 9.3 | S29: 1.38 (m2) | T29: =SUM(T22:T28) -> 2.5 | U29: =SUM(U22:U28) -> 2.5 | V29: =SUM(V22:V28) -> 2
O30: 0 | P30: 절감
B32: 3차분 (정산 완료)
B33: 19 | C33: 일성건축 | D33: 2 | E33: 45756 | F33: 0.375 | G33: 45756 | H33: 0.6875 | I33: =H33-F33 -> 0.3125 | J33: =I33*D33 -> 0.625 | K33: 2 103 | L33: 108 303 | M33: 남해원 | N33: 안방,작은방 코너 단열작업 화장실 벽타일 보수 완료 걸레받이 2개소 교체 완료 방충망 3개소 완료 | O33: =D33 -> 2 | P33: 3 | Q33: 3 | R33: 3 | T33: 5 | U33: 5 | Z33: 이보드(13T) 2장, 열반사 단열재 5.0m2
B34: 20 | C34: 일성건축 | D34: 2 | E34: 45757 | F34: 0.375 | G34: 45757 | H34: 0.6875 | I34: =H34-F34 -> 0.3125 | J34: =I34*D34 -> 0.625 | K34: 103 9 2 | L34: 303 304 108 | M34: 남해원 | N34: 씽크대 상판 실리콘 재코킹 작업 완료 창문 시트지 6개소 제거 완료 방충망 3개소 교체 완료 도어보수 2개소 완료 방충망 4개소 완료 빨래건조대 설치 완료 | O34: 1.5 | P34: 7 | Q34: 2 | X34: 1 | Z34: 빨래건조대 1개(설비 업체 미지정으로 대응) (영수증 첨부)
B35: 21 | C35: 일성건축 | D35: 1 | E35: 45765 | F35: 0.4375 | G35: 45765 | H35: 0.47916667 | I35: =H35-F35 -> 0.041666667 | J35: =I35*D35 -> 0.041666667 | K35: 5 | L35: 104 | M35: 남해원 | N35: 누수 부분 도배 | O35: 0.5
B36: 22 | C36: 일성건축 | D36: 2 | E36: 45775 | F36: 0.375 | G36: 45775 | H36: 0.69444444 | I36: =H36-F36 -> 0.31944444 | J36: =I36*D36 -> 0.63888889 | K36: 8 | L36: 401 | M36: 남해원 | N36: 도어 보수2개소 완료 씽크대 상판 실리콘 재코킹 작업 완료 앞베란다 외부샤시 바닥 실리콘 작업 완료 방충망 3개소 완료 | O36: 2 | P36: 3 | Q36: 4
B37: 23 | C37: 일성건축 | D37: 2 | E37: 45776 | F37: 0.375 | G37: 45776 | H37: 0.6875 | I37: =H37-F37 -> 0.3125 | J37: =I37*D37 -> 0.625 | K37: 8 103 | L37: 401 204 | M37: 남해원 | N37: 도어보수 1개소 완료 방충망 2개소 완료 방충망 1개소 완료 작은방 커텐박스 아티론+이보드 작업 완료 작은방 창문 하단 실리콘 재시공 완료 걸레받이 3개소 교체 완료 | O37: 2 | P37: 3 | Q37: 3 | R37: 6
B38: 24 | C38: 일성건축 | D38: 2 | E38: 45777 | F38: 0.375 | G38: 45777 | H38: 0.6875 | I38: =H38-F38 -> 0.3125 | J38: =I38*D38 -> 0.625 | K38: 103 A A 102 | L38: 204 701-6 303-1 205 | M38: 남해원 | N38: 방충망 3개소 완료 도어보수 1개소 완료 화장실 좌측 석고보드 들뜸 교체 완료 화장실 도어 보수 완료 화장실 도어 보수 완료 씽크대 측판 교체 (이동원) | O38: 2 | P38: 3 (-0.09) [감액] | V38: 1 | Y38: 1 | Z38: 102-205 씽크대 가스렌지 다이 양측판 교체 (세금계산서 첨부)
B39: 25 | C39: 일성건축 | D39: 2 | E39: 45784 | F39: 0.375 | G39: 45784 | H39: 0.6875 | I39: =H39-F39 -> 0.3125 | J39: =I39*D39 -> 0.625 | K39: A B | L39: 301-1 1001-3 | M39: 남해원 | N39: 화장실 좌측,우측 석고보드 들뜸보수 2개소 완료 버티컬 교체 완료 벽단열재 들뜸 재시공 완료 | O39: 2 | S39: 5 | V39: 2
B40: 26 | C40: 일성건축 | D40: 2 | E40: 45789 | F40: 0.375 | G40: 45789 | H40: 0.6875 | I40: =H40-F40 -> 0.3125 | J40: =I40*D40 -> 0.625 | K40: 2 | L40: 404 | M40: 남해원 | N40: 씽크대 상판 실리콘 재코킹 천장 곰팡이 제거 방충망 5개소 완료 앞뒤 베란다 전체 크랙 보수 화장실문 시트지 재시공 | O40: 2 | P40: 5 | Q40: 3 | Z40: 기숙사 AB동 문보수용 엣지 필름 구매 (영수증 첨부)
B41: 27 | C41: 일성건축 | D41: 2 | E41: 45790 | F41: 0.375 | G41: 45790 | H41: 0.6875 | I41: =H41-F41 -> 0.3125 | J41: =I41*D41 -> 0.625 | K41: 2 | L41: 301 | M41: 남해원 | N41: 앞뒤 베란다 전체 크랙 보수 완료 붙박이장 시트지 보수 3개소 완료 도어 보수 3개소 완료 | O41: 2 | Q41: 2 | Z41: 문보수용 경첩피스 구매 (영수증 첨부)
B42: 28 | C42: 일성건축 | D42: 2 | E42: 45792 | F42: 0.5625 | G42: 45792 | H42: 0.625 | I42: =H42-F42 -> 0.0625 | J42: =I42*D42 -> 0.125 | K42: 9 | L42: 306 | M42: 남해원 | N42: 방충망 7개소 완료 | O42: 0 | P42: 7
B43: 29 | C43: 일성건축 | D43: 2 | E43: 45796 | F43: 0.375 | G43: 45796 | H43: 0.6875 | I43: =H43-F43 -> 0.3125 | J43: =I43*D43 -> 0.625 | K43: 8 | L43: 209 | M43: 남해원 | N43: 뒤베란다 창고앞 외부샤시 천장 누수점검 및 실리콘 작업 완료 앞베란다 샤시 천장 실리콘 작업 완료 문보수 3개소 완료(합판들뜸 포함) 씽크대 상판 보수 완료 방충망 4개소 완료 | O43: 2 | P43: 4 | Q43: 4
B44: 30 | C44: 일성건축 | D44: 2 | E44: 45797 | F44: 0.375 | G44: 45797 | H44: 0.68055556 | I44: =H44-F44 -> 0.30555556 | J44: =I44*D44 -> 0.61111111 | K44: 8 5 | L44: 209 204 | M44: 남해원 | N44: 방충망 3개소 완료 뒤베란다 창고옆 벽면 창틀 누수점검및 실리콘 작업 앞베란다 외부샤시 하단 실리콘 작업 완료 문보수 2개소 완료 방충망 6개소 완료 | O44: 1.5 | P44: 9 | Q44: 4
...

Sheet 시중가 근거서류 
A3: 첨부 1 | H3: 첨부 2 | O3: 첨부 5
A32: 첨부 3 | H32: 첨부 4
