Workbook

Sheet 갑지
A2: 견 적 서
A5: 수신인 : 주식회사 에스엔아이 코퍼레이션 | F5: 등록번호 | G5: 314-86-35718
F6: 상 호 | G6: ㈜일성건축
A7: 공사명 : 사택 104-303 수장공사(기타작업 포함) | F7: 대표 이사 | G7: 상 석 희
F8: 사업장 | G8: 대전 서구 도마6길 107 (도마동)
A9: 견적일 : 2025년 01월 21일 | F9: 업 태 | G9: 건설업
F10: 종 목 | G10: 실내건축,인테리어공사
F11: TEL, FAX | G11: 042)527-0995, 042)527-0996
A12: 금액: | B12: =NUMBERSTRING(F31,1) -> 육백삼십칠만오천 | D12: 원정
A14: NO | B14: 품명 | C14: 규격 | D14: 수량 | E14: 단위 | F14: 금액 | G14: 비고
B15: 직접비
B16: 재료비 | F16: ='내역서(표준단가)'!O22 -> 1729068.8
B17: 노무비 | F17: ='내역서(표준단가)'!Q22 -> 3771405.8
B18: 기계/기타경비 | F18: ='내역서(표준단가)'!S22+'내역서(표준단가)'!U22 -> 0
B19: 소계 | F19: =F16+F17+F18 -> 5500474.6
B20: 간접비
B21: 국민연금 | C21: 노무비*4.5% | D21: 1 | E21: 식 | F21: =F17*4.5% -> 169713.26 | G21: 모든공사에 적용
B22: 건강보험료 | C22: 노무비*3.545% | D22: 1 | E22: 식 | F22: =F17*3.545% -> 133696.34 | G22: 모든공사에 적용
B23: 장기요양보험료 | C23: 건강보험료*12.95% | D23: 1 | E23: 식 | F23: =F22*12.95% -> 17313.675 | G23: 모든공사에 적용
B24: 고용보험료 | C24: 노무비*1.01% | D24: 1 | E24: 식 | F24: =F17*1.01% -> 38091.198 | G24: 모든공사에 적용
B25: 산재보험료 | C25: 노무비*3.56% | D25: 1 | E25: 식 | F25: =F17*3.56% -> 134262.05 | G25: 모든공사에 적용
B26: 산업안전보건관리비 | C26: (재료비+노무비)*2.93% | D26: 1 | E26: 식 | F26: =(F16+F17)*2.93% -> 161163.91 | G26: 모든공사에 적용
B27: 일반관리비/이윤 | C27: (노무비+간접공사비)*5% | D27: 1 | E27: 식 | F27: =SUM(F17+F21+F22+F23+F24+F25+F26)*5% -> 221282.31
B28: 소계 | F28: =F21+F22+F23+F24+F25+F26+F27 -> 875522.73
F30: =F19+F28+F29 -> 6375997.3
B31: 합계(단수조정) | F31: =ROUNDDOWN(F30,-3) -> 6375000
B32: VAT별도

Sheet 내역서(표준단가)
O1: ▼낙찰율 | Q1: ▼낙찰율 | S1: ▼낙찰율 | U1: ▼낙찰율
O2: 0.835 | Q2: 0.835 | S2: 0.835 | U2: 0.835
F3: ▶ 표준 Code(표준단가/품셈/물정/노임) 순서별 입력(Upload 자동반영) | J3: 주요내역 | L3: 단위 | M3: 수량 | N3: 재료비 | P3: 노무비 | R3: 기계경비 | T3: 기타경비(부자재비) | V3: 합계 | W3: 노무비 할증 | X3: 할증기준
A4: 합계 | F4: 표준단가 D | G4: 표준품셈 E | H4: 물가정보 M | I4: 노임단가 L | J4: 품목 | K4: 규격 | N4: 품셈/표단 | O4: 금액 | P4: 단가 | Q4: 금액 | R4: 단가 | S4: 금액 | T4: 단가 | U4: 금액
A5: =F5&G5&H5&I5 -> D02641 | F5: D02641 | J5: 제 1호표 도배바름(벽면) | K5: 합판·석고보드면 | L5: ㎡ | M5: 186 | O5: =SUM(N5:N5)*M5*$O$2 -> 0 | P5: 6691 | Q5: =(P5*M5)*$Q$2 -> 1039179.2 | S5: =R5*M5*$S$2 -> 0 | U5: =T5*M5*$U$2 -> 0 | V5: =SUM(O5+Q5)+S5+U5 -> 1039179.2
A6: =F6&G6&H6&I6 -> D02642 | F6: D02642 | J6: 제 1호표 도배바름(천장) | K6: 합판·석고보드면 | L6: ㎡ | M6: 66 | O6: =SUM(N6:N6)*M6*$O$2 -> 0 | P6: 8698 | Q6: =(P6*M6)*$Q$2 -> 479346.78 | S6: =R6*M6*$S$2 -> 0 | U6: =T6*M6*$U$2 -> 0 | V6: =SUM(O6+Q6)+S6+U6 -> 479346.78
A7: =F7&G7&H7&I7 -> D02873 | F7: D02873 | J7: 제 6호표 건축물 구조체별 철거(벽) | K7: 벽지떼어내기 | L7: ㎡ | M7: 76 | O7: =SUM(N7:N7)*M7*$O$2 -> 0 | P7: 1618 | Q7: =(P7*M7)*$Q$2 -> 102678.28 | S7: =R7*M7*$S$2 -> 0 | U7: =T7*M7*$U$2 -> 0 | V7: =SUM(O7+Q7)+S7+U7 -> 102678.28
A8: =F8&G8&H8&I8 -> D02859 | F8: D02859 | J8: 제 3호표 건축물 구조체별 철거(바닥 및 수장부분) | K8: 리노륨 | L8: ㎡ | M8: 50 | O8: =SUM(N8:N8)*M8*$O$2 -> 0 | P8: 4855 | Q8: =(P8*M8)*$Q$2 -> 202696.25 | S8: =R8*M8*$S$2 -> 0 | U8: =T8*M8*$U$2 -> 0 | V8: =SUM(O8+Q8)+S8+U8 -> 202696.25
A9: =F9&G9&H9&I9 -> D02558 | F9: D02558 | J9: 제 3호표 PVC계 바닥재 설치(바닥 깔기) | K9: 시트(부분접합 방식) | L9: ㎡ | M9: 50 | O9: =SUM(N9:N9)*M9*$O$2 -> 0 | P9: 4453 | Q9: =(P9*M9)*$Q$2 -> 185912.75 | S9: =R9*M9*$S$2 -> 0 | U9: =T9*M9*$U$2 -> 0 | V9: =SUM(O9+Q9)+S9+U9 -> 185912.75
A10: =F10&G10&H10&I10 -> D02825 | F10: D02825 | J10: 제 2호표 석고보드면 바탕만들기 | K10: 벽체(줄퍼티) | L10: ㎡ | M10: 28 | N10: 528 | O10: =SUM(N10:N10)*M10*$O$2 -> 12344.64 | P10: 10367 | Q10: =(P10*M10)*$Q$2 -> 242380.46 | S10: =R10*M10*$S$2 -> 0 | U10: =T10*M10*$U$2 -> 0 | V10: =SUM(O10+Q10)+S10+U10 -> 254725.1
A11: =F11&G11&H11&I11 -> D02832 | F11: D02832 | J11: 제 1호표 수성페인트 붓칠 | K11: 내벽 | L11: ㎡ | M11: 28 | N11: 461 | O11: =SUM(N11:N11)*M11*$O$2 -> 10778.18 | P11: 6146 | Q11: =(P11*M11)*$Q$2 -> 143693.48 | S11: =R11*M11*$S$2 -> 0 | U11: =T11*M11*$U$2 -> 0 | V11: =SUM(O11+Q11)+S11+U11 -> 154471.66
A12: =F12&G12&H12&I12 -> M012003400500101 | H12: M012003400500101 | J12: 진양륨펫트 72″ | K12: 주택용 바닥재 1.6T×1,830㎜ | L12: ㎡ | M12: 50 | N12: 15000 | O12: =SUM(N12:N12)*M12*$O$2 -> 626250 | Q12: =(P12*M12)*$Q$2 -> 0 | S12: =R12*M12*$S$2 -> 0 | U12: =T12*M12*$U$2 -> 0 | V12: =SUM(O12+Q12)+S12+U12 -> 626250
A13: =F13&G13&H13&I13 -> M010602702400101 | H13: M010602702400101 | J13: IPALG 조인트용 접착제(TB-100) | K13: 시트용 접착제, | L13: ㎏ | M13: 6 | N13: 15000 | O13: =SUM(N13:N13)*M13*$O$2 -> 75150 | Q13: =(P13*M13)*$Q$2 -> 0 | S13: =R13*M13*$S$2 -> 0 | U13: =T13*M13*$U$2 -> 0 | V13: =SUM(O13+Q13)+S13+U13 -> 75150
A14: =F14&G14&H14&I14 -> L002 | I14: L002 | J14: 씽크대 상판교체, 현장정리 및 보양 | K14: 보통인부 | L14: 인 | M14: 1 | O14: =SUM(N14:N14)*M14*$O$2 -> 0 | P14: 161858 | Q14: =M14*P14 -> 161858 | S14: =R14*M14*$S$2 -> 0 | U14: =T14*M14*$U$2 -> 0 | V14: =SUM(O14+Q14)+S14+U14 -> 161858
A15: =F15&G15&H15&I15 -> L003 | I15: L003 | J15: 방충망 교체 4개소 | K15: 뒤베란다, 주방, 가운데방, 현관입구방, 특별인부, 자재비 포함 | L15: 인 | M15: 1 | P15: 208527 | Q15: =M15*P15 -> 208527 | V15: =SUM(O15+Q15)+S15+U15 -> 208527
A16: =F16&G16&H16&I16 -> L003 | I16: L003 | J16: 창문샤시측 벽면(곰팡이제거포함) 걸레받이 교체- 15곳(안방(2곳), 거실(4곳), 가운데방(6곳), 현관입구(3곳)), 주방 벽타일 상부 마감재 몰딩 보수 또는 교체, 씽크대 상판 실리콘 재코킹작업-자재비 포함 | K16: 특별인부 | L16: 인 | M16: 2 | P16: 208527 | Q16: =M16*P16 -> 417054 | V16: =SUM(O16+Q16)+S16+U16 -> 417054
A17: =F17&G17&H17&I17 -> L002 | I17: L002 | J17: 창문샤시측 벽면(곰팡이제거포함) 걸레받이 교체- 15곳(안방(2곳), 거실(4곳), 가운데방(6곳), 현관입구(3곳)), 주방 벽타일 상부 마감재 몰딩 보수 또는 교체, 씽크대 상판 실리콘 재코킹작업 | K17: 보통인부 | L17: 인 | M17: 1 | P17: 161858 | Q17: =M17*P17 -> 161858 | V17: =SUM(O17+Q17)+S17+U17 -> 161858
J18: 씽크대 상판교체-아일랜드 식탁 상판 제외 | K18: 전문업체 견적서 첨부 | L18: set | M18: 1 | N18: 731000 | O18: =M18*N18 -> 731000 | Q18: =(P18*M18)*$Q$2 -> 0 | S18: =R18*M18*$S$2 -> 0 | U18: =T18*M18*$U$2 -> 0 | V18: =SUM(O18+Q18)+S18+U18 -> 731000
J19: ="시중가_"&K19&")" -> 시중가_합지벽지(LG하우시스 휘앙세)) | K19: 합지벽지(LG하우시스 휘앙세) | L19: ㎡ | M19: 252 | N19: 1300 | O19: =SUM(N19:N19)*M19*$O$2 -> 273546 | Q19: =(P19*M19)*$Q$2 -> 0 | S19: =R19*M19*$S$2 -> 0 | U19: =T19*M19*$U$2 -> 0 | V19: =SUM(O19+Q19)+S19+U19 -> 273546
J20: ="시중가_"&K20&"" -> 시중가_청소, 실내건축 일위대가 적용 | K20: 청소, 실내건축 일위대가 적용 | L20: ㎡ | M20: 65 | O20: =SUM(N20:N20)*M20*$O$2 -> 0 | P20: 7853 | Q20: =(P20*M20)*$Q$2 -> 426221.57 | S20: =R20*M20*$S$2 -> 0 | U20: =T20*M20*$U$2 -> 0 | V20: =SUM(O20+Q20)+S20+U20 -> 426221.57
A21: =F21&G21&H21&I21 | O21: =SUM(N21:N21)*M21*$O$2 -> 0 | Q21: =(P21*M21)*$Q$2 -> 0 | S21: =R21*M21*$S$2 -> 0 | U21: =T21*M21*$U$2 -> 0 | V21: =SUM(O21+Q21)+S21+U21 -> 0
O22: =SUM(O5:O21) -> 1729068.8 | Q22: =SUM(Q5:Q21) -> 3771405.8 | S22: =SUM(S5:S21) -> 0 | U22: =SUM(U5:U21) -> 0 | V22: =SUM(V5:V21) -> 5500474.6

Sheet 상세내역
A1: 내 역 서
A2: 품 명 | B2: 규 격 | C2: 단위 | D2: 수 량 | E2: 재 료 비 | G2: 노 무 비 | I2: 기계경비 | K2: 기타경비(부자재비) | M2: 합 계 | O2: 비 고
E3: 단 가 | F3: 금 액 | G3: 단 가 | H3: 금 액 | K3: 단 가 | L3: 금 액 | M3: 단 가 | N3: 금 액
A4: 사택 104-303 수장공사(기타작업 포함)
A5: 1.도배 | B5: 거실 벽면 | C5: ㎡ | D5: 85 | E5: 1086 | F5: =D5*E5 -> 92310 | G5: 5587 | H5: =D5*G5 -> 474895 | N5: =F5+H5+J5+L5 -> 567205 | O5: 광폭합지 벽지(LX하우시스, 휘앙세), 23년 11월 물가자료
B6: 거실 천정 | C6: ㎡ | D6: 40 | E6: 1086 | F6: =D6*E6 -> 43440 | G6: 7263 | H6: =D6*G6 -> 290520 | N6: =F6+H6+J6+L6 -> 333960
B7: 방A 벽면 | C7: ㎡ | D7: 38 | E7: 1086 | F7: =D7*E7 -> 41268 | G7: 5587 | H7: =D7*G7 -> 212306 | N7: =F7+H7+J7+L7 -> 253574
B8: 방A 천정 | C8: ㎡ | D8: 10 | E8: 1086 | F8: =D8*E8 -> 10860 | G8: 7263 | H8: =D8*G8 -> 72630 | N8: =F8+H8+J8+L8 -> 83490
B9: 방B 벽면 | C9: ㎡ | D9: 32 | E9: 1086 | F9: =D9*E9 -> 34752 | G9: 5587 | H9: =D9*G9 -> 178784 | N9: =F9+H9+J9+L9 -> 213536
B10: 방B 천정 | C10: ㎡ | D10: 8 | E10: 1086 | F10: =D10*E10 -> 8688 | G10: 7263 | H10: =D10*G10 -> 58104 | N10: =F10+H10+J10+L10 -> 66792
B11: 방C 벽면 | C11: ㎡ | D11: 31 | E11: 1086 | F11: =D11*E11 -> 33666 | G11: 5587 | H11: =D11*G11 -> 173197 | N11: =F11+H11+J11+L11 -> 206863
B12: 방C 천정 | C12: ㎡ | D12: 8 | E12: 1086 | F12: =D12*E12 -> 8688 | G12: 7263 | H12: =D12*G12 -> 58104 | N12: =F12+H12+J12+L12 -> 66792
B13: 벽지 떼어내기 30% 적용 | C13: ㎡ | D13: =SUM(D5:D12)*30% -> 75.6 | G13: 1351 | H13: =D13*G13 -> 102135.6 | N13: =F13+H13+J13+L13 -> 102135.6
A14: 소 계 | D14: =SUM(D5:D12) -> 252 | F14: =SUM(F5:F13) -> 273672 | H14: =SUM(H5:H13) -> 1620675.6 | J14: =SUM(J5:J13) -> 0 | L14: =SUM(L5:L13) -> 0 | N14: =SUM(N5:N13) -> 1894347.6
A15: 2.바닥재 | B15: 거실 바닥 철거 | C15: ㎡ | D15: 27 | G15: 4054 | H15: =D15*G15 -> 109458 | N15: =F15+H15+J15+L15 -> 109458 | O15: LX하우시스, 청맥 1.8T
B16: 방A 바닥 철거 | C16: ㎡ | D16: 9 | G16: 4054 | H16: =D16*G16 -> 36486 | N16: =F16+H16+J16+L16 -> 36486
B17: 방B 바닥 철거 | C17: ㎡ | D17: 7 | G17: 4054 | H17: =D17*G17 -> 28378 | N17: =F17+H17+J17+L17 -> 28378
B18: 방C 바닥 철거 | C18: ㎡ | D18: 7 | G18: 4054 | H18: =D18*G18 -> 28378 | N18: =F18+H18+J18+L18 -> 28378
B19: 접착제(부분접착) | C19: kg | D19: 6 | E19: 12525 | F19: =D19*E19 -> 75150 | N19: =F19+H19+J19+L19 -> 75150
B20: 거실 바닥 | C20: ㎡ | D20: 27 | E20: 12525 | F20: =D20*E20 -> 338175 | G20: 3718 | H20: =D20*G20 -> 100386 | N20: =F20+H20+J20+L20 -> 438561
B21: 방A 바닥 | C21: ㎡ | D21: 9 | E21: 12525 | F21: =D21*E21 -> 112725 | G21: 3718 | H21: =D21*G21 -> 33462 | N21: =F21+H21+J21+L21 -> 146187
B22: 방B 바닥 | C22: ㎡ | D22: 7 | E22: 12525 | F22: =D22*E22 -> 87675 | G22: 3718 | H22: =D22*G22 -> 26026 | N22: =F22+H22+J22+L22 -> 113701
B23: 방C 바닥 | C23: ㎡ | D23: 7 | E23: 12525 | F23: =D23*E23 -> 87675 | G23: 3718 | H23: =D23*G23 -> 26026 | N23: =F23+H23+J23+L23 -> 113701
A24: 소 계 | D24: =SUM(D20:D23) -> 50 | F24: =SUM(F15:F23) -> 701400 | H24: =SUM(H15:H23) -> 388600 | J24: =SUM(J15:J23) -> 0 | L24: =SUM(L15:L23) -> 0 | N24: =SUM(N15:N23) -> 1090000
A25: 3.도장
A26: 베란다 수성페인트(전면) | B26: 석고보드면 바탕만들기(줄퍼티) | C26: ㎡ | D26: 17 | E26: 441 | F26: =D26*E26 -> 7497 | G26: 8656 | H26: =D26*G26 -> 147152 | N26: =F26+H26+J26+L26 -> 154649
B27: 붓칠,내벽 | C27: ㎡ | D27: 17 | E27: 385 | F27: =D27*E27 -> 6545 | G27: 5132 | H27: =D27*G27 -> 87244 | N27: =F27+H27+J27+L27 -> 93789
A28: 베란다 수성페인트(후면) | B28: 석고보드면 바탕만들기(줄퍼티) | C28: ㎡ | D28: 11 | E28: 441 | F28: =D28*E28 -> 4851 | G28: 8656 | H28: =D28*G28 -> 95216 | N28: =F28+H28+J28+L28 -> 100067
B29: 붓칠,내벽 | C29: ㎡ | D29: 11 | E29: 385 | F29: =D29*E29 -> 4235 | G29: 5132 | H29: =D29*G29 -> 56452 | N29: =F29+H29+J29+L29 -> 60687
A30: 소 계 | F30: =SUM(F25:F29) -> 23128 | H30: =SUM(H25:H29) -> 386064 | J30: =SUM(J25:J29) -> 0 | L30: =SUM(L25:L29) -> 0 | N30: =SUM(N25:N29) -> 409192
A31: 4.청소 | B31: 준공청소(특별인부) | C31: ㎡ | D31: 65 | G31: 6557 | H31: =D31*G31 -> 426205 | N31: =F31+H31+J31+L31 -> 426205 | O31: 2023년 실내건축 일위대가
A32: 소 계 | H32: =SUM(H31:H31) -> 426205 | J32: =SUM(J31:J31) -> 0 | L32: =SUM(L31:L31) -> 0 | N32: =SUM(N31:N31) -> 426205
A33: 5.씽크대 상판교체
A34: 현장정리 및 보양 | B34: 보통인부 | C34: 인 | D34: 1 | G34: 161858 | H34: =D34*G34 -> 161858 | N34: =F34+H34+J34+L34 -> 161858
A35: 씽크대 상판교체 | B35: 전문업체 견적서 참조 | C35: set | D35: 1 | E35: 731000 | F35: =D35*E35 -> 731000 | H35: =D35*G35 -> 0 | N35: =F35+H35+J35+L35 -> 731000
A36: 소 계 | F36: =SUM(F34:F35) -> 731000 | H36: =SUM(H34:H35) -> 161858 | J36: =SUM(J35:J35) -> 0 | L36: =SUM(L35:L35) -> 0 | N36: =SUM(N34:N35) -> 892858
A37: 6.기타작업
A38: 방충망 교체 4개소 | B38: 뒤베란다, 주방, 가운데방, 현관입구방, 특별인부, 자재비 포함 | C38: 인 | D38: 1 | G38: 208527 | H38: =D38*G38 -> 208527 | N38: =F38+H38+J38+L38 -> 208527
A39: 창문샤시측 벽면(곰팡이제거포함) 걸레받이 교체- 15곳(안방(2곳), 거실(4곳), 가운데방(6곳), 현관입구(3곳)), 주방 벽타일 상부 마감재 몰딩 보수 또는 교체, 씽크대 상판 실리콘 재코킹작업 | B39: 특별인부, 자재비 포함 | C39: 인 | D39: 2 | G39: 208527 | H39: =D39*G39 -> 417054 | N39: =F39+H39+J39+L39 -> 417054
B40: 보통인부, | C40: 인 | D40: 1 | G40: 161858 | H40: =D40*G40 -> 161858 | N40: =F40+H40+J40+L40 -> 161858
...

Sheet 시중가 근거서류
A2: ■ 벽지 자재비 근거서류(999999)
A3: 코드 | B3: 품목 | C3: 규격 | D3: 단가(m2) | E3: 적용기준
A4: 999999 | B4: 벽지(LG 휘앙세) | C4: 장폭합지 | D4: 1300 | E4: 물가자료 2023.11

Sheet Upload
A1: 표준내역코드 | B1: 세부공종 | C1: 품명 | D1: 규격 | E1: 단위 | F1: 수량 | G1: 재료비단가 | H1: 재료비소계 | I1: 노무비단가 | J1: 노무비소계 | K1: 기계경비단가 | L1: 기계경비소계 | M1: 기타경비단가 | N1: 기타경비소계 | O1: 할증코드 | P1: 재료비할증율 | Q1: 노무비할증율 | R1: 할증내용
A2: 999999 | B2: 영선,건축 | C2: 합지벽지, 23년 11월 물가자료 | D2: LX하우시스, 휘앙세 93*17.75, M2당 | E2: ㎡ | F2: 252 | G2: 1086
A3: 999999 | B3: 영선,건축 | C3: 청소 | D3: 2023년 실내건축 일위대가 적용 | E3: ㎡ | F3: 65 | I3: 6557
A4: 999999 | B4: 영선,건축 | C4: 씽크대 상판교체 | D4: 전문업체 견적서 첨부 | E4: set | F4: 1 | G4: 731000

Sheet Upload-RS
A1: 구분 | B1: 표준단가 | C1: 표준품셈 | D1: 물가정보 | E1: 노임단가 | F1: 수량
A2: ='내역서(표준단가)'!A5 -> D02641 | B2: ='내역서(표준단가)'!F5 -> D02641 | C2: ='내역서(표준단가)'!G5 -> 0 | D2: ='내역서(표준단가)'!H5 -> 0 | E2: ='내역서(표준단가)'!I5 -> 0 | F2: ='내역서(표준단가)'!M5 -> 186
A3: ='내역서(표준단가)'!A6 -> D02642 | B3: ='내역서(표준단가)'!F6 -> D02642 | C3: ='내역서(표준단가)'!G6 -> 0 | D3: ='내역서(표준단가)'!H6 -> 0 | E3: ='내역서(표준단가)'!I6 -> 0 | F3: ='내역서(표준단가)'!M6 -> 66
A4: ='내역서(표준단가)'!A7 -> D02873 | B4: ='내역서(표준단가)'!F7 -> D02873 | C4: ='내역서(표준단가)'!G7 -> 0 | D4: ='내역서(표준단가)'!H7 -> 0 | E4: ='내역서(표준단가)'!I7 -> 0 | F4: ='내역서(표준단가)'!M7 -> 76
A5: ='내역서(표준단가)'!A8 -> D02859 | B5: ='내역서(표준단가)'!F8 -> D02859 | C5: ='내역서(표준단가)'!G8 -> 0 | D5: ='내역서(표준단가)'!H8 -> 0 | E5: ='내역서(표준단가)'!I8 -> 0 | F5: ='내역서(표준단가)'!M8 -> 50
A6: ='내역서(표준단가)'!A9 -> D02558 | B6: ='내역서(표준단가)'!F9 -> D02558 | C6: ='내역서(표준단가)'!G9 -> 0 | D6: ='내역서(표준단가)'!H9 -> 0 | E6: ='내역서(표준단가)'!I9 -> 0 | F6: ='내역서(표준단가)'!M9 -> 50
A7: ='내역서(표준단가)'!A10 -> D02825 | B7: ='내역서(표준단가)'!F10 -> D02825 | C7: ='내역서(표준단가)'!G10 -> 0 | D7: ='내역서(표준단가)'!H10 -> 0 | E7: ='내역서(표준단가)'!I10 -> 0 | F7: ='내역서(표준단가)'!M10 -> 28
A8: ='내역서(표준단가)'!A11 -> D02832 | B8: ='내역서(표준단가)'!F11 -> D02832 | C8: ='내역서(표준단가)'!G11 -> 0 | D8: ='내역서(표준단가)'!H11 -> 0 | E8: ='내역서(표준단가)'!I11 -> 0 | F8: ='내역서(표준단가)'!M11 -> 28
A9: ='내역서(표준단가)'!A12 -> M012003400500101 | B9: ='내역서(표준단가)'!F12 -> 0 | C9: ='내역서(표준단가)'!G12 -> 0 | D9: ='내역서(표준단가)'!H12 -> M012003400500101 | E9: ='내역서(표준단가)'!I12 -> 0 | F9: ='내역서(표준단가)'!M12 -> 50
A10: ='내역서(표준단가)'!A13 -> M010602702400101 | B10: ='내역서(표준단가)'!F13 -> 0 | C10: ='내역서(표준단가)'!G13 -> 0 | D10: ='내역서(표준단가)'!H13 -> M010602702400101 | E10: ='내역서(표준단가)'!I13 -> 0 | F10: ='내역서(표준단가)'!M13 -> 6
A11: ='내역서(표준단가)'!A14 -> L002 | B11: ='내역서(표준단가)'!F14 -> 0 | C11: ='내역서(표준단가)'!G14 -> 0 | D11: ='내역서(표준단가)'!H14 -> 0 | E11: ='내역서(표준단가)'!I14 -> L002 | F11: ='내역서(표준단가)'!M14 -> 1
A12: ='내역서(표준단가)'!A15 -> L003 | B12: ='내역서(표준단가)'!F15 -> 0 | C12: ='내역서(표준단가)'!G15 -> 0 | D12: ='내역서(표준단가)'!H15 -> 0 | E12: ='내역서(표준단가)'!I15 -> L003 | F12: ='내역서(표준단가)'!M15 -> 1
A13: ='내역서(표준단가)'!A16 -> L003 | B13: ='내역서(표준단가)'!F16 -> 0 | C13: ='내역서(표준단가)'!G16 -> 0 | D13: ='내역서(표준단가)'!H16 -> 0 | E13: ='내역서(표준단가)'!I16 -> L003 | F13: ='내역서(표준단가)'!M16 -> 2
A14: ='내역서(표준단가)'!A17 -> L002 | B14: ='내역서(표준단가)'!F17 -> 0 | C14: ='내역서(표준단가)'!G17 -> 0 | D14: ='내역서(표준단가)'!H17 -> 0 | E14: ='내역서(표준단가)'!I17 -> L002 | F14: ='내역서(표준단가)'!M17 -> 1
