Workbook

Sheet 갑지
A2: 견 적 서
A5: 수신인 : (주)에스앤아이코퍼레이션 | F5: 등록번호 | G5: 305-86-01887
F6: 상 호 | G6: 주식회사수안이엔지
A7: 공사명 : 사택 긴급공사 | F7: 대표 이사 | G7: 김용도
F8: 사업장 | G8: 대전광역시 동구 태전로 157번길 58, 2층
A9: 견적일 : 2026년 07월 27일 | F9: 업 태 | G9: 건설업
F10: 종 목 | G10: 기계설비공사
F11: TEL, FAX | G11: 042-224-0252 / 042-224-5424
A12: 금액: | B12: =NUMBERSTRING(F32,1) -> 육백일십오만오천 | D12: 원정
A14: NO | B14: 품명 | C14: 규격 | D14: 수량 | E14: 단위 | F14: 금액 | G14: 비고
B15: 직접비
B16: 재료비 | F16: =내역서!K50 -> 2395522
B17: 노무비 | F17: =내역서!M50 -> 3010136
B18: 기계/기타경비 | F18: =내역서!O50+내역서!Q50 -> 0
B19: 건설기계대여금 | F19: 0
B20: 소계 | F20: =F16+F17+F18+F19 -> 5405658
B21: 간접비
B22: 안전관리비 | C22: (재료비+노무비)*3.11% | D22: 1 | E22: 식 | F22: =(F16+F17)*3.11% -> 168115.97 | G22: 모든공사에 적용
B23: 산재보험료 | C23: 노무비*3.56% | D23: 1 | E23: 식 | F23: =F17*3.56% -> 107160.84 | G23: 모든공사에 적용
B24: 고용보험료 | C24: 노무비*1.01% | D24: 1 | E24: 식 | F24: =F17*1.01% -> 30402.374 | G24: 모든공사에 적용
B25: 국민건강 보험료 | C25: 노무비*3.595% | D25: 1 | E25: 식 | F25: =F17*3.595% -> 108214.39 | G25: 모든공사에 적용
B26: 국민연금 보험료 | C26: 노무비*4.75% | D26: 1 | E26: 식 | F26: =F17*4.75% -> 142981.46 | G26: 모든공사에 적용
B27: 노인장기요양 보험료 | C27: 국민건강보험료*13.14% | D27: 1 | E27: 식 | F27: =F25*13.14% -> 14219.371 | G27: 모든공사에 적용
B28: 일반관리비/이윤 | C28: (노무비+간접공사비)*5% | D28: 1 | E28: 식 | F28: =SUM(F17+F22+F23+F24+F25+F26+F27)*5% -> 179061.52
B29: 소계 | F29: =SUM(F22,F23,F24,F25,F26,F27,F28) -> 750155.92
F31: =F20+F29+F30 -> 6155814
B32: 합계(단수조정) | F32: =ROUNDDOWN(F31,-3) -> 6155000
B33: VAT별도

Sheet 내역서
K1: ▼낙찰율 | M1: ▼낙찰율 | O1: ▼낙찰율 | Q1: ▼낙찰율
K2: 0.82 | M2: 0.72 | O2: 1 | Q2: 1
B3: ▶ 표준 Code(표준단가/품셈/물정/노임) 순서별 입력(Upload 자동반영) | F3: 주요내역 | H3: 단위 | I3: 수량 | J3: 재료비 | L3: 노무비 | N3: 기계경비 | P3: 기타경비(부자재비) | R3: 합계 | S3: 노무비 할증 | T3: 할증기준
A4: 합계 | B4: 표준단가 D | C4: 표준품셈 E | D4: 물가정보 M | E4: 노임단가 L | F4: 품목 | G4: 규격 | J4: 품셈/표단 | K4: 금액 | L4: 단가 | M4: 금액 | N4: 단가 | O4: 금액 | P4: 단가 | Q4: 금액
F5: 사택 긴급공사
A6: =B6&C6&D6&E6 -> L039 | E6: L039 | F6: 긴급 보수 대응 | G6: 배관공 | H6: M/D | I6: ='상반기 증빙'!O22 -> 9 | L6: 239439 | M6: =L6*I6 -> 2154951 | R6: =SUM(K6+M6)+O6+Q6 -> 2154951
A7: =B7&C7&D7&E7 -> L002 | E7: L002 | F7: 긴급 보수 대응 | G7: 보통 | H7: M/D | I7: ='상반기 증빙'!P22 -> 5 | L7: 171037 | M7: =L7*I7 -> 855185 | R7: =SUM(K7+M7)+O7+Q7 -> 855185
F8: 2동 208호, 8동 308호 , 8동 410호 , 9동 501호 , 9동 505호 (빨건조대 설치)=>5월8일~6월11일까지 총 5세대
A9: =B9&C9&D9&E9 | F9: 빨래건조대 | H9: 개 | I9: 5 | J9: 33000 | K9: =J9*I9 -> 165000 | N9: =ROUND((M9*I9),0) -> 0 | P9: =ROUND(O9*I9*$P$2,0) -> 0 | R9: =SUM(K9+M9)+O9+Q9 -> 165000
F10: GS편의점 천장속 누수 보수=>(5월8일)
A11: =B11&C11&D11&E11 -> M025021212650101 | D11: M025021212650101 | F11: PVC DRF 100A Y 소켓 배관 | H11: 개 | I11: 1 | J11: 14070 | K11: =J11*I11*K2 -> 11537.4 | N11: =ROUND((M11*I11),0) -> 0 | P11: =ROUND(O11*I11*$P$2,0) -> 0 | R11: =SUM(K11+M11)+O11+Q11 -> 11537.4
F12: 2동 105호
A13: =B13&C13&D13&E13 | F13: 온수분배기 | G13: 4구 | H13: 개 | I13: 1 | J13: 100000 | K13: =J13*I13 -> 100000 | N13: =ROUND((M13*I13),0) -> 0 | P13: =ROUND(O13*I13*$P$2,0) -> 0 | R13: =SUM(K13+M13)+O13+Q13 -> 100000
A14: =B14&C14&D14&E14 -> M025019113680101 | D14: M025019113680101 | F14: 스테인리스관이음쇠-부싱 | G14: 25×20(나사식) | H14: 개 | I14: =2 -> 2 | J14: 5097 | K14: =+I14*J14*$K$2 -> 8359.08 | R14: =SUM(K14+M14)+O14+Q14 -> 8359.08
A15: =B15&C15&D15&E15 -> M025019112440101 | D15: M025019112440101 | F15: 스테인리스관이음쇠-플러그 | G15: 25A(나사식) | H15: 개 | I15: =2 -> 2 | J15: 4347 | K15: =+I15*J15*$K$2 -> 7129.08 | R15: =SUM(K15+M15)+O15+Q15 -> 7129.08
A16: =B16&C16&D16&E16 -> M02501QV10760101 | D16: M02501QV10760101 | F16: 스텐소켓 | G16: 25A, 43㎜ | H16: 개 | I16: =4 -> 4 | J16: 3080 | K16: =+I16*J16*$K$2 -> 10102.4 | R16: =SUM(K16+M16)+O16+Q16 -> 10102.4
A17: =B17&C17&D17&E17 -> M02502Q710020101 | D17: M02502Q710020101 | F17: XL온돌파이프이음관 | G17: ø15, 밸브소켓 | H17: 개 | I17: =8 -> 8 | J17: 1870 | K17: =+I17*J17*$K$2 -> 12267.2 | R17: =SUM(K17+M17)+O17+Q17 -> 12267.2
A18: =B18&C18&D18&E18 | F18: 8동203호 , 8동 308호 , 8동 410호 , 8동 107호 , 9동 301호 9동 501호 (난방분배기 교체)=>5월8일~6월11일까지 총 6세대 | R18: =SUM(K18+M18)+O18+Q18 -> 0
A19: =B19&C19&D19&E19 | F19: 온수분배기 | G19: 5구 | H19: 개 | I19: =1*6 -> 6 | J19: 120000 | K19: =J19*I19 -> 720000 | N19: =ROUND((M19*I19),0) -> 0 | P19: =ROUND(O19*I19*$P$2,0) -> 0 | R19: =SUM(K19+M19)+O19+Q19 -> 720000
A20: =B20&C20&D20&E20 -> M025019113680101 | D20: M025019113680101 | F20: 스테인리스관이음쇠-부싱 | G20: 25×20(나사식) | H20: 개 | I20: =2*6 -> 12 | J20: 5097 | K20: =+I20*J20*$K$2 -> 50154.48 | R20: =SUM(K20+M20)+O20+Q20 -> 50154.48
A21: =B21&C21&D21&E21 -> M025019112440101 | D21: M025019112440101 | F21: 스테인리스관이음쇠-플러그 | G21: 25A(나사식) | H21: 개 | I21: =2*6 -> 12 | J21: 4347 | K21: =+I21*J21*$K$2 -> 42774.48 | R21: =SUM(K21+M21)+O21+Q21 -> 42774.48
A22: =B22&C22&D22&E22 -> M02501QV10760101 | D22: M02501QV10760101 | F22: 스텐소켓 | G22: 25A, 43㎜ | H22: 개 | I22: =5*6 -> 30 | J22: 3080 | K22: =+I22*J22*$K$2 -> 75768 | R22: =SUM(K22+M22)+O22+Q22 -> 75768
A23: =B23&C23&D23&E23 -> M02502Q710020101 | D23: M02502Q710020101 | F23: XL온돌파이프이음관 | G23: ø15, 밸브소켓 | H23: 개 | I23: =10*6 -> 60 | J23: 1870 | K23: =+I23*J23*$K$2 -> 92004 | R23: =SUM(K23+M23)+O23+Q23 -> 92004
F24: 8동 207호 (난방분배기교체,빨래건조대,냉온수배관 교체,양변기교체) | K24: =+I24*J24*$K$2 -> 0 | R24: =SUM(K24+M24)+O24+Q24 -> 0
A25: =B25&C25&D25&E25 | F25: 온수분배기 | G25: 5구 | H25: 개 | I25: =1 -> 1 | J25: 120000 | K25: =J25*I25 -> 120000 | N25: =ROUND((M25*I25),0) -> 0 | P25: =ROUND(O25*I25*$P$2,0) -> 0 | R25: =SUM(K25+M25)+O25+Q25 -> 120000
A26: =B26&C26&D26&E26 | F26: 빨래건조대 | H26: 개 | I26: =1 -> 1 | J26: 33000 | K26: =J26*I26 -> 33000 | N26: =ROUND((M26*I26),0) -> 0 | P26: =ROUND(O26*I26*$P$2,0) -> 0 | R26: =SUM(K26+M26)+O26+Q26 -> 33000
D27: M025502512450101 | F27: 서양식 탱크 밀결형 사이펀변기 | G27: IC714E,, ㉿C1210CR | H27: 조 | I27: =1 -> 1 | J27: 246000 | K27: =+I27*J27*$K$2 -> 201720 | R27: =SUM(K27+M27)+O27+Q27 -> 201720
A28: =B28&C28&D28&E28 -> M025019113680101 | D28: M025019113680101 | F28: 스테인리스관이음쇠-부싱 | G28: 25×20(나사식) | H28: 개 | I28: =2 -> 2 | J28: 5097 | K28: =+I28*J28*$K$2 -> 8359.08 | R28: =SUM(K28+M28)+O28+Q28 -> 8359.08
A29: =B29&C29&D29&E29 -> M025019112440101 | D29: M025019112440101 | F29: 스테인리스관이음쇠-플러그 | G29: 25A(나사식) | H29: 개 | I29: =2 -> 2 | J29: 4347 | K29: =+I29*J29*$K$2 -> 7129.08 | R29: =SUM(K29+M29)+O29+Q29 -> 7129.08
A30: =B30&C30&D30&E30 -> M02501QV10760101 | D30: M02501QV10760101 | F30: 스텐소켓 | G30: 25A, 43㎜ | H30: 개 | I30: =5 -> 5 | J30: 3080 | K30: =+I30*J30*$K$2 -> 12628 | R30: =SUM(K30+M30)+O30+Q30 -> 12628
A31: =B31&C31&D31&E31 -> M02502Q710020101 | D31: M02502Q710020101 | F31: XL온돌파이프이음관 | G31: ø15, 밸브소켓 | H31: 개 | I31: =10 -> 10 | J31: 1870 | K31: =+I31*J31*$K$2 -> 15334 | R31: =SUM(K31+M31)+O31+Q31 -> 15334
A32: =B32&C32&D32&E32 -> M025502214740101 | D32: M025502214740101 | F32: 기타수전부속 및 밸브류 | G32: 가로꼭지, KF-600(3/4 | H32: 개 | I32: =2 -> 2 | J32: 28000 | K32: =+I32*J32*$K$2 -> 45920 | M32: =I32*L32*$M$2*S32 -> 0 | O32: =ROUND(N32*I32*$O$2,0) -> 0 | Q32: =ROUND(P32*I32*$Q$2,0) -> 0 | R32: =SUM(K32+M32)+O32+Q32 -> 45920
A33: =B33&C33&D33&E33 -> M02502P912190101 | D33: M02502P912190101 | F33: 수도용 급수전소켓 | G33: 20㎜ | H33: 개 | I33: =2 -> 2 | J33: 2700 | K33: =+I33*J33*$K$2 -> 4428 | M33: =I33*L33*$M$2*S33 -> 0 | O33: =ROUND(N33*I33*$O$2,0) -> 0 | Q33: =ROUND(P33*I33*$Q$2,0) -> 0 | R33: =SUM(K33+M33)+O33+Q33 -> 4428
A34: =B34&C34&D34&E34 -> M025014910040102 | D34: M025014910040102 | F34: 동파이프(K형) | G34: 호칭경20A, 외경22.22㎜, 두께1.65㎜, 중량0.953㎏/m | H34: m | I34: =1*2 -> 2 | J34: 17570 | K34: =+I34*J34*$K$2 -> 28814.8 | M34: =I34*L34*$M$2*S34 -> 0 | O34: =ROUND(N34*I34*$O$2,0) -> 0 | Q34: =ROUND(P34*I34*$Q$2,0) -> 0 | R34: =SUM(K34+M34)+O34+Q34 -> 28814.8
A35: =B35&C35&D35&E35 -> M010551210390101 | D35: M010551210390101 | F35: 초속경시멘트 | G35: 3시간에 1종시멘트 7일강도 발현(20kg) | H35: 포 | I35: =1 -> 1 | J35: 30000 | K35: =+I35*J35*$K$2 -> 24600 | M35: =I35*L35*$M$2*S35 -> 0 | O35: =ROUND(N35*I35*$O$2,0) -> 0 | Q35: =ROUND(P35*I35*$Q$2,0) -> 0 | R35: =SUM(K35+M35)+O35+Q35 -> 24600
F36: 8동 504호 (난방분배기교체) | K36: =+I36*J36*$K$2 -> 0 | R36: =SUM(K36+M36)+O36+Q36 -> 0
A37: =B37&C37&D37&E37 | F37: 온수분배기 | G37: 5구 | H37: 개 | I37: =1 -> 1 | J37: 120000 | K37: =J37*I37 -> 120000 | N37: =ROUND((M37*I37),0) -> 0 | P37: =ROUND(O37*I37*$P$2,0) -> 0 | R37: =SUM(K37+M37)+O37+Q37 -> 120000
A38: =B38&C38&D38&E38 -> M025019113680101 | D38: M025019113680101 | F38: 스테인리스관이음쇠-부싱 | G38: 25×20(나사식) | H38: 개 | I38: =2 -> 2 | J38: 5097 | K38: =+I38*J38*$K$2 -> 8359.08 | R38: =SUM(K38+M38)+O38+Q38 -> 8359.08
A39: =B39&C39&D39&E39 -> M025019112440101 | D39: M025019112440101 | F39: 스테인리스관이음쇠-플러그 | G39: 25A(나사식) | H39: 개 | I39: =2 -> 2 | J39: 4347 | K39: =+I39*J39*$K$2 -> 7129.08 | R39: =SUM(K39+M39)+O39+Q39 -> 7129.08
A40: =B40&C40&D40&E40 -> M02501QV10760101 | D40: M02501QV10760101 | F40: 스텐소켓 | G40: 25A, 43㎜ | H40: 개 | I40: =5 -> 5 | J40: 3080 | K40: =+I40*J40*$K$2 -> 12628 | R40: =SUM(K40+M40)+O40+Q40 -> 12628
...

Sheet Upload
A1: 구분 | B1: 표준단가 | C1: 표준품셈 | D1: 물가정보 | E1: 노임단가 | F1: 수량 | H1: ★ 작성방법
A2: =내역서!A5 -> 0 | B2: =내역서!B5 -> 0 | C2: =내역서!C5 -> 0 | D2: =내역서!D5 -> 0 | E2: =내역서!E5 -> 0 | F2: =내역서!I5 -> 0 | H2: ① 내역서(엑셀) 내 품목코드, 수량 입력시 upload자료 내 자동반영됨
A3: =내역서!A12 -> 0 | B3: =내역서!B12 -> 0 | C3: =내역서!C12 -> 0 | D3: =내역서!D12 -> 0 | E3: =내역서!E12 -> 0 | F3: =내역서!I12 -> 0 | H3: ③ 시중가/할증은 atG 화면 내 별도입력(본 탭 내에는 표준 Code만 입력)
A4: =내역서!A13 | B4: =내역서!B13 -> 0 | C4: =내역서!C13 -> 0 | D4: =내역서!D13 -> 0 | E4: =내역서!E13 -> 0 | F4: =내역서!I13 -> 1
A5: =내역서!A14 -> M025019113680101 | B5: =내역서!B14 -> 0 | C5: =내역서!C14 -> 0 | D5: =내역서!D14 -> M025019113680101 | E5: =내역서!E14 -> 0 | F5: =내역서!I14 -> 2
A6: =내역서!A15 -> M025019112440101 | B6: =내역서!B15 -> 0 | C6: =내역서!C15 -> 0 | D6: =내역서!D15 -> M025019112440101 | E6: =내역서!E15 -> 0 | F6: =내역서!I15 -> 2
A7: =내역서!A16 -> M02501QV10760101 | B7: =내역서!B16 -> 0 | C7: =내역서!C16 -> 0 | D7: =내역서!D16 -> M02501QV10760101 | E7: =내역서!E16 -> 0 | F7: =내역서!I16 -> 4
A8: =내역서!A17 -> M02502Q710020101 | B8: =내역서!B17 -> 0 | C8: =내역서!C17 -> 0 | D8: =내역서!D17 -> M02502Q710020101 | E8: =내역서!E17 -> 0 | F8: =내역서!I17 -> 8
A9: =내역서!A18 | B9: =내역서!B18 -> 0 | C9: =내역서!C18 -> 0 | D9: =내역서!D18 -> 0 | E9: =내역서!E18 -> 0 | F9: =내역서!I18 -> 0
A10: =내역서!A19 | B10: =내역서!B19 -> 0 | C10: =내역서!C19 -> 0 | D10: =내역서!D19 -> 0 | E10: =내역서!E19 -> 0 | F10: =내역서!I19 -> 6
A11: =내역서!A20 -> M025019113680101 | B11: =내역서!B20 -> 0 | C11: =내역서!C20 -> 0 | D11: =내역서!D20 -> M025019113680101 | E11: =내역서!E20 -> 0 | F11: =내역서!I20 -> 12
A12: =내역서!A21 -> M025019112440101 | B12: =내역서!B21 -> 0 | C12: =내역서!C21 -> 0 | D12: =내역서!D21 -> M025019112440101 | E12: =내역서!E21 -> 0 | F12: =내역서!I21 -> 12
A13: =내역서!A22 -> M02501QV10760101 | B13: =내역서!B22 -> 0 | C13: =내역서!C22 -> 0 | D13: =내역서!D22 -> M02501QV10760101 | E13: =내역서!E22 -> 0 | F13: =내역서!I22 -> 30
A14: =내역서!A23 -> M02502Q710020101 | B14: =내역서!B23 -> 0 | C14: =내역서!C23 -> 0 | D14: =내역서!D23 -> M02502Q710020101 | E14: =내역서!E23 -> 0 | F14: =내역서!I23 -> 60
A15: =내역서!A24 -> 0 | B15: =내역서!B24 -> 0 | C15: =내역서!C24 -> 0 | D15: =내역서!D24 -> 0 | E15: =내역서!E24 -> 0 | F15: =내역서!I24 -> 0
... A40: =내역서!A49 -> 0 | B40: =내역서!B49 -> 0 | C40: =내역서!C49 -> 0 | D40: =내역서!D49 -> M025502512450101 | E40: =내역서!E49 -> 0 | F40: =내역서!I49 -> 1
A41: =내역서!#REF! -> #REF! | B41: =내역서!#REF! -> #REF! | C41: =내역서!#REF! -> #REF! | D41: =내역서!#REF! -> #REF! | E41: =내역서!#REF! -> #REF! | F41: =내역서!#REF! -> #REF!
A42: =내역서!A50 -> 0 | B42: =내역서!B50 -> 0 | C42: =내역서!C50 -> 0 | D42: =내역서!D50 -> 0 | E42: =내역서!E50 -> 0 | F42: =내역서!I50 -> 0
A43: =내역서!A51 -> 0 | B43: =내역서!B51 -> 0 | C43: =내역서!C51 -> 0 | D43: =내역서!D51 -> 0 | E43: =내역서!E51 -> 0 | F43: =내역서!I51 -> 0
A44: =내역서!A52 -> 0 | B44: =내역서!B52 -> 0 | C44: =내역서!C52 -> 0 | D44: =내역서!D52 -> 0 | E44: =내역서!E52 -> 0 | F44: =내역서!I52 -> 0
A45: =내역서!A53 -> 0 | B45: =내역서!B53 -> 0 | C45: =내역서!C53 -> 0 | D45: =내역서!D53 -> 0 | E45: =내역서!E53 -> 0 | F45: =내역서!I53 -> 0
A46: =내역서!A54 -> 0 | B46: =내역서!B54 -> 0 | C46: =내역서!C54 -> 0 | D46: =내역서!D54 -> 0 | E46: =내역서!E54 -> 0 | F46: =내역서!I54 -> 0
A47: =내역서!A55 -> 0 | B47: =내역서!B55 -> 0 | C47: =내역서!C55 -> 0 | D47: =내역서!D55 -> 0 | E47: =내역서!E55 -> 0 | F47: =내역서!I55 -> 0
A48: =내역서!A56 -> 0 | B48: =내역서!B56 -> 0 | C48: =내역서!C56 -> 0 | D48: =내역서!D56 -> 0 | E48: =내역서!E56 -> 0 | F48: =내역서!I56 -> 0
A49: =내역서!A57 -> 0 | B49: =내역서!B57 -> 0 | C49: =내역서!C57 -> 0 | D49: =내역서!D57 -> 0 | E49: =내역서!E57 -> 0 | F49: =내역서!I57 -> 0
A50: =내역서!A58 -> 0 | B50: =내역서!B58 -> 0 | C50: =내역서!C58 -> 0 | D50: =내역서!D58 -> 0 | E50: =내역서!E58 -> 0 | F50: =내역서!I58 -> 0
A51: =내역서!A59 -> 0 | B51: =내역서!B59 -> 0 | C51: =내역서!C59 -> 0 | D51: =내역서!D59 -> 0 | E51: =내역서!E59 -> 0 | F51: =내역서!I59 -> 0
A52: =내역서!A60 -> 0 | B52: =내역서!B60 -> 0 | C52: =내역서!C60 -> 0 | D52: =내역서!D60 -> 0 | E52: =내역서!E60 -> 0 | F52: =내역서!I60 -> 0
A53: =내역서!A61 -> 0 | B53: =내역서!B61 -> 0 | C53: =내역서!C61 -> 0 | D53: =내역서!D61 -> 0 | E53: =내역서!E61 -> 0 | F53: =내역서!I61 -> 0
A54: =내역서!A85 -> 0 | B54: =내역서!B85 -> 0 | C54: =내역서!C85 -> 0 | D54: =내역서!D85 -> 0 | E54: =내역서!E85 -> 0 | F54: =내역서!I85 -> 0
A55: =내역서!A86 -> 0 | B55: =내역서!B86 -> 0 | C55: =내역서!C86 -> 0 | D55: =내역서!D86 -> 0 | E55: =내역서!E86 -> 0 | F55: =내역서!I86 -> 0
A56: =내역서!A87 -> 0 | B56: =내역서!B87 -> 0 | C56: =내역서!C87 -> 0 | D56: =내역서!D87 -> 0 | E56: =내역서!E87 -> 0 | F56: =내역서!I87 -> 0
A57: =내역서!A88 -> 0 | B57: =내역서!B88 -> 0 | C57: =내역서!C88 -> 0 | D57: =내역서!D88 -> 0 | E57: =내역서!E88 -> 0 | F57: =내역서!I88 -> 0
A58: =내역서!A89 -> 0 | B58: =내역서!B89 -> 0 | C58: =내역서!C89 -> 0 | D58: =내역서!D89 -> 0 | E58: =내역서!E89 -> 0 | F58: =내역서!I89 -> 0
A59: =내역서!A90 -> 0 | B59: =내역서!B90 -> 0 | C59: =내역서!C90 -> 0 | D59: =내역서!D90 -> 0 | E59: =내역서!E90 -> 0 | F59: =내역서!I90 -> 0
A60: =내역서!A91 -> 0 | B60: =내역서!B91 -> 0 | C60: =내역서!C91 -> 0 | D60: =내역서!D91 -> 0 | E60: =내역서!E91 -> 0 | F60: =내역서!I91 -> 0
A61: =내역서!A92 -> 0 | B61: =내역서!B92 -> 0 | C61: =내역서!C92 -> 0 | D61: =내역서!D92 -> 0 | E61: =내역서!E92 -> 0 | F61: =내역서!I92 -> 0
A62: =내역서!A93 -> 0 | B62: =내역서!B93 -> 0 | C62: =내역서!C93 -> 0 | D62: =내역서!D93 -> 0 | E62: =내역서!E93 -> 0 | F62: =내역서!I93 -> 0
A63: =내역서!A94 -> 0 | B63: =내역서!B94 -> 0 | C63: =내역서!C94 -> 0 | D63: =내역서!D94 -> 0 | E63: =내역서!E94 -> 0 | F63: =내역서!I94 -> 0
A64: =내역서!A95 -> 0 | B64: =내역서!B95 -> 0 | C64: =내역서!C95 -> 0 | D64: =내역서!D95 -> 0 | E64: =내역서!E95 -> 0 | F64: =내역서!I95 -> 0
...

Sheet 상반기 증빙
A1: 기계 긴급 대응 목록 | N1: 긴급 투입인원 환산
A2: 상반기 이월분 : - 건 / 유상 : -건 / 무상(묶음) : -건
A3: 번호 | B3: 일자 | C3: 호실 | D3: 노즐 | E3: 누수탐지 | F3: 누수위치 | G3: 보수내용 | H3: 보수업체 | I3: 보수인원 | J3: 특이사항 | K3: 정산 현황 | N3: 구분 | O3: 배관공 | P3: 보통인부 | Q3: 보온공 | R3: 화기감시 (보통인부) | S3: 안전관찰자 (보통인부) | T3: 누수탐지
A4: 1 | B4: 46150 | C4: N/A | D4: N/A | G4: GS편의점 천장속 배관 100A YT 소켓 교체(누수) | H4: 수안이엔지 | I4: 2 | N4: =I4 -> 2 | O4: 1 | P4: 1
C5: 8-203 | D5: 5 | G5: 난방분배기 교체
C6: 8-410 | D6: 5 | G6: 난방분배기 교체
A7: 2 | B7: 46163 | C7: 2-208 | D7: N/A | G7: 앞베란다 빨래건조대 설치 | H7: 수안이엔지 | I7: 2 | N7: =I7 -> 2 | O7: 1 | P7: 1
C8: 8-410 | D8: N/A | G8: 앞레반다 빨래건조대 설치
C9: 8-107 | D9: 5 | G9: 난방분배기 교체
A10: 3 | B10: 46175 | C10: 8-308 | D10: 5 | G10: 난방분배기 교체 및 앞베란다 빨래건조대 설치 | H10: 수안이엔지 | I10: 3 | N10: =I10 -> 3 | O10: 2 | P10: 1
C11: 9-505 | D11: N/A | G11: 앞베란다 빨래건조대 설치
C12: 9-501 | D12: 5 | G12: 난방분배기 교체 및 앞베란다 빨래건조대 설치
A13: 4 | B13: 45087 | C13: 7-104 | D13: N/A | E13: X | F13: X | G13: 양변기 교체 | H13: 수안이엔지 | I13: 4 | N13: =I13 -> 4 | O13: 3 | P13: 1
C14: 8-107 | D14: N/A | G14: 냉온수 수전 교체 + 양변기 교체
C15: 8-207 | D15: 5 | G15: 냉온수 수전 교체 + 양변기 교체 난방 분배기 교체 + 빨래건조대 설치
C16: 8-504 | D16: 5 | G16: 난방 분배기 교체
A17: 5 | B17: 45088 | C17: 2-105 | D17: 4 | G17: 난방 분배기 교체 | H17: 수안이엔지 | I17: 3 | N17: =I17 -> 3 | O17: 2 | P17: 1
C18: 7-104 | D18: N/A | E18: X | F18: X | G18: 양변기 교체
C19: 8-107 | D19: N/A | G19: 냉온수 수전 교체 + 양변기 교체
C20: 8-207 | D20: 5 | G20: 냉온수 수전 교체 + 양변기 교체 난방 분배기 교체 + 빨래건조대 설치
C21: 9-301 | D21: 5 | G21: 난방 분배기 교체
O22: =SUM(O4:O21) -> 9 | P22: =SUM(P4:P21) -> 5

Sheet Upload(시중가)-별도입력
A1: 표준내역코드 | B1: 세부공종 | C1: 품명 | D1: 규격 | E1: 단위 | F1: 수량 | G1: 재료비단가 | H1: 재료비소계 | I1: 노무비단가 | J1: 노무비소계 | K1: 기계경비단가 | L1: 기계경비소계 | M1: 기타경비단가 | N1: 기타경비소계 | O1: 할증코드 | P1: 재료비할증율 | Q1: 노무비할증율 | R1: 할증내용
C2: 온수난방분배기 | D2: 5구 | E2: EA | F2: 1 | G2: 120000 | H2: =G2*F2 -> 120000
C3: 온수난방분배기 | D3: 4구 | E3: EA | F3: 1 | G3: 100000 | H3: =G3*F3 -> 100000
C4: 건조대 | E4: EA | F4: 1 | G4: 33000 | H4: =G4*F4 -> 33000
A25: ■시중가 입력시 (5가지중 1가지 첨부)_유사한 코드가 있으면 대체 적용하며, 불가피 한경우만 시중가 사용함_불가피 할경우 아래 5가지 중 1개 첨부 1. 업체 비교견적서 첨부 최소 2개사 (자재 거래처(자재상)_공사업체 는 제외해당) 2. 기실적 단가 3. 세금계산서 및 거래명세서 첨부 4. 단독취급 MAKER 자재의 경우 1개사 견적서 처리 가능함(대리점 포함, 사코_감압변 등 독자 메이커만 취급 하는 경우에 해당함) 5. 물가자료 책자 정보 증빙 첨부 (물가자료 책자 스캔 후 표시 증빙 첨부) 6. 기타사항 (협의후)
A45: 온수난방분배기 | D45: 건조대

Sheet 공사수립계획서
B1: 공사수립계획서
B4: 업 체 명 | C4: 주식회사수안이엔지 | D4: 일 시 | E4: =갑지!A9 -> 견적일 : 2026년 07월 27일
B5: 공 사 명 | C5: =갑지!A7 -> 공사명 : 사택 긴급공사
B6: 공사 업체 | C6: ■ 공사기간 : 입찰시스템 계약기간에 준함
C7: ■ 인원투입계획 : 총 명(주말 : 명)
C8: ■ 시공방법
C9: - 냉온수전 철거 / 신규설치
C10: - 냉온수전 교체로 인한 콘크리트 할설 및 타설
C11: - 배관 교체로 인한 화기작업
C12: - 세면기 철거 / 신규설치
C13: - 양변기 철거 / 신규설치
C14: - 분배기 철거
C15: - 신규 분배기설치 및 주변배관 보수
C16: - 공사 후 주변정리 및 마감
C20: ■ 위험작업 유무 : 유(고소,화기,신호수)
C21: ■ 안전확보 방안 :
... C31: ■ 주요 사용물질 : 산소 0kg, 알곤 20kg, 질소 0kg, 냉매(R-22) 0kg 등
B35: 수안이엔지 | C35: 성명 : 김 용 도 | D35: (인감/서명)
B36: S&I | C36: 성명 : | D36: 서명
