Workbook
Name _: #REF!
Name ___A52762: #REF!
Name ___A82761: #REF!
Name __A52762: #REF!
Name __A82761: #REF!
Name __HW66000: #REF!
Name __jak10: #N/A
Name __jak11: #N/A
Name __jak12: #N/A
Name __jak13: #N/A
Name __jak2: #N/A
Name __jak3: #N/A
Name __jak4: #N/A
Name __jak5: #N/A
Name __jak6: #N/A
Name __jak7: #N/A
Name __jak9: #N/A
Name __PB1: #REF!
Name __PB2: #REF!
Name __PB3: #REF!
Name _\D: [3]조건표!$P$4
Name _\X: [3]조건표!$P$4:$U$4
Name _0: [4]직재!#REF!
Name _1: #N/A
Name _1.전기공사: #REF!
Name _10_3_0Criteria: #REF!
Name _15A: [5]가격조사서!$D$4:$D$11
Name _15G_0Extr: #REF!
Name _1차_94년: #N/A
Name _2: [6]J直材4!$F$5:$G$5
Name _20G_0Extract: #REF!
Name _21단: #REF!
Name _2차결제일: #N/A
Name _3: #N/A
Name _4: #N/A
Name _5: '[7]설직재-1'!#REF!
Name _5_3_0Crite: #REF!
Name _6: '[8]C-직노1'!#REF!
Name _7: '[7]설직재-1'!#REF!
Name _A16800: #REF!
Name _A20000: [9]전계가!#REF!
Name _A52762: #REF!
Name _A82761: #REF!
Name _B1: #REF!
Name _B22: [10]일위대가!$1400:$1413=[10]일위대가!$A$1400
Name _C: #REF!
Name _CVC2: #N/A
Name _DAN1: [11]단가산출1!$1:$24
Name _DAN10: [11]단가산출1!$217:$240
Name _DAN100: #REF!
Name _DAN101: #REF!
Name _DAN102: #REF!
Name _DAN103: #REF!
Name _DAN104: #REF!
Name _DAN105: #REF!
Name _DAN106: #REF!
Name _DAN107: #REF!
Name _DAN108: #REF!
Name _DAN109: #REF!
Name _DAN11: [11]단가산출1!$241:$264

Sheet 갑지(엑셀)
A2: 견 적 서
A5: 수신인: | B5: ㈜S&I CORP
G6: 서울특별시 관악구 쑥고개로75, 7층
A7: 공사명: | B7: LG사원아파트 CCTV 보수 공사 | G7: (청룡동,광장빌딩) (우 : 08785)
G8: TEL:02-872-0766, FAX:02-872-0767
A9: 견적일: 2025년 07월 03일 | G9: 이유솔루션 주식회사
A10: . | G10: 대표이사 장 지 호
A12: 금액: | B12: =NUMBERSTRING(F31,1) -> 일백칠십육만팔천 | D12: 원정
A14: NO | B14: 품명 | C14: 규격 | D14: 수량 | E14: 단위 | F14: 금액 | G14: 비고
B15: 직접비
B16: 재료비 | F16: ='내역서(엑셀)'!G17 -> 709518
B17: 노무비 | F17: ='내역서(엑셀)'!I17 -> 863147.93
B18: 기계/기타경비
B19: 소계 | F19: =F16+F17+F18 -> 1572665.9
B20: 간접비
B21: 국민연금 | C21: 노무비*4.5% | D21: 1 | E21: 식 | F21: =F17*4.5% -> 38841.657 | G21: 모든공사에 적용
B22: 건강보험료 | C22: 노무비*3.545% | D22: 1 | E22: 식 | F22: =F17*3.545% -> 30598.594 | G22: 모든공사에 적용
B23: 장기요양보험료 | C23: 건강보험료*12.95% | D23: 1 | E23: 식 | F23: =F22*12.95% -> 3962.5179 | G23: 모든공사에 적용
B24: 고용보험료 | C24: 노무비*1.01% | D24: 1 | E24: 식 | F24: =F17*1.01% -> 8717.7941 | G24: 모든공사에 적용
B25: 산재보험료 | C25: 노무비*3.56% | D25: 1 | E25: 식 | F25: =F17*3.56% -> 30728.066 | G25: 모든공사에 적용
B26: 산업안전보건관리비 | C26: (재료비+노무비)*2.07% | D26: 1 | E26: 식 | F26: =(F16+F17)*2.07% -> 32554.185 | G26: 모든공사에 적용
B27: 일반관리비/이윤 | C27: (노무비+간접공사비)*5% | D27: 1 | E27: 식 | F27: =SUM(F17+F21+F22+F23+F24+F25+F26)*5% -> 50427.537
B28: 소계 | F28: =F21+F22+F23+F24+F25+F26+F27 -> 195830.35
F30: =F19+F28+F29 -> 1768496.3
B31: 합계(단수조정) | F31: =ROUNDDOWN(F30,-3) -> 1768000
B32: VAT별도

Sheet 내역서(엑셀)
G1: ▼낙찰율 | I1: ▼낙찰율 | K1: ▼낙찰율 | M1: ▼낙찰율
G2: 0.76 | I2: 0.29 | K2: 0.709 | M2: 0.879
A3: 표준 Code | B3: 주요내역 | D3: 단위 | E3: 수량 | F3: 재료비 | H3: 노무비 | J3: 기계경비 | L3: 기타경비(부자재비) | N3: 합계 | O3: 비고
B4: 품목 | C4: 규격 | F4: 단가 | G4: 금액 | H4: 단가 | I4: 금액 | J4: 단가 | K4: 금액 | L4: 단가 | M4: 금액 | O4: 할증율(%) | P4: 기준
A5: 999999 | B5: UTP케이블 포설 | C5: CAT6(LS) | D5: m | E5: 90 | F5: 519 | G5: =F5*E5 -> 46710 | H5: =IFERROR(VLOOKUP(A5,#REF!,19,FALSE),"") | N5: =SUM(G5+I5)+K5+M5 -> 46710 | O5: 1
A6: 999999 | B6: RJ45 JACK 접속 | C6: CAT6 | D6: EA | E6: 2 | F6: 1404 | G6: =F6*E6 -> 2808 | N6: =SUM(G6+I6)+K6+M6 -> 2808 | O6: 1
A7: 999999 | B7: BOX CCTV | C7: HNH-231V5I | D7: EA | E7: 1 | F7: 660000 | G7: =F7*E7 -> 660000 | N7: =SUM(G7+I7)+K7+M7 -> 660000 | O7: 1
A8: E10316005001001001 | B8: 제 1호표 꼬임 케이블 포설 | C8: UTP, STP, FTP(구내) 4Pr | D8: 10m | E8: 9 | G8: =F8*E8 -> 0 | H8: 61136.25 | I8: =(H8*E8*O8)*$I$2 -> 159565.61 | N8: =SUM(G8+I8)+K8+M8 -> 159565.61 | O8: 1
A9: E10316005001001001 | B9: 제 1호표 꼬임 케이블 포설 | C9: UTP, STP, FTP(구내) 4Pr | D9: 10m | E9: =E5*0.1 -> 9 | G9: =F9*E9 -> 0 | H9: 61136.25 | I9: =(H9*E9*O9)*$I$2 -> 79782.806 | N9: =SUM(G9+I9)+K9+M9 -> 79782.806 | O9: 0.5 | P9: 기존 케이블 철거
A10: E10316005002001006 | B10: 제 6호표 꼬임 케이블(커넥터 및 Jack 접속) | C10: Modular(RJ45-8Pin Plug) | D10: 10ea | E10: =E6*0.1 -> 0.2 | H10: 44773 | I10: =(H10*E10*O10)*$I$2 -> 2596.834 | N10: =SUM(G10+I10)+K10+M10 -> 2596.834 | O10: 1
A11: E10410040001001001 | B11: 제 1호표 CCTV 시스템 촬상부(카메라설치) | C11: 일반형 | D11: 대 | E11: =E7 -> 1 | G11: =F11*E11 -> 0 | H11: 221569 | I11: =(H11*E11*O11)*$I$2 -> 64255.01 | N11: =SUM(G11+I11)+K11+M11 -> 64255.01 | O11: 1
A12: E10410040001014001 | B12: 제 1호표 CCTV System 시험(종합시험) | C12: - | D12: CH 또는 Set | E12: 1 | G12: =F12*E12 -> 0 | H12: 275563 | I12: =(H12*E12*O12)*$I$2 -> 79913.27 | N12: =SUM(G12+I12)+K12+M12 -> 79913.27 | O12: 1
A13: E10316005003008001 | B13: 제 1호표 꼬임 케이블(회선시험) | C13: - | D13: Port(또는 4P) | E13: =E7 -> 1 | G13: =F13*E13 -> 0 | H13: 25234.49 | I13: =(H13*E13*O13)*$I$2 -> 7318.0021 | N13: =SUM(G13+I13)+K13+M13 -> 7318.0021 | O13: 1
A14: E10313002001009001 | B14: 제 1호표 CCTV 시스템(시험) | C14: 송수신 제어신호 및 영상 Level 조정 | D14: Set | E14: 1 | G14: =F14*E14 -> 0 | H14: 342522.05 | I14: =(H14*E14*O14)*$I$2 -> 99331.394 | N14: =SUM(G14+I14)+K14+M14 -> 99331.394 | O14: 1
A15: L002 | B15: 사다리 보조자 | C15: 보통인부 | D15: 인 | E15: 1 | G15: =E15*F15*$G$2 -> 0 | H15: 161858 | I15: =(H15*E15*O15) -> 161858 | N15: =SUM(G15+I15)+K15+M15 -> 161858 | O15: 1
A16: L003 | B16: 안전관찰자 | C16: 특별인부 | D16: 인 | E16: 1 | G16: =E16*F16*$G$2 -> 0 | H16: 208527 | I16: =(H16*E16*O16) -> 208527 | N16: =SUM(G16+I16)+K16+M16 -> 208527 | O16: 1
G17: =SUM(G5:G16) -> 709518 | I17: =SUM(I5:I16) -> 863147.93 | K17: =SUM(K5:K15) -> 0 | M17: =SUM(M5:M15) -> 0 | N17: =SUM(N5:N16) -> 1572665.9

Sheet Upload
A1: 구분 | B1: 표준단가 | C1: 표준품셈 | D1: 물가정보 | E1: 노임단가 | F1: 수량
A2: ='Upload(참조)'!Q2 | B2: ='Upload(참조)'!R2 -> 999999 | C2: ='Upload(참조)'!S2 -> 999999 | D2: ='Upload(참조)'!T2 -> 999999 | E2: ='Upload(참조)'!U2 -> 999999 | F2: ='Upload(참조)'!V2 -> 90
A3: ='Upload(참조)'!Q3 | B3: ='Upload(참조)'!R3 -> 999999 | C3: ='Upload(참조)'!S3 -> 999999 | D3: ='Upload(참조)'!T3 -> 999999 | E3: ='Upload(참조)'!U3 -> 999999 | F3: ='Upload(참조)'!V3 -> 2
A4: ='Upload(참조)'!Q4 | B4: ='Upload(참조)'!R4 -> 999999 | C4: ='Upload(참조)'!S4 -> 999999 | D4: ='Upload(참조)'!T4 -> 999999 | E4: ='Upload(참조)'!U4 -> 999999 | F4: ='Upload(참조)'!V4 -> 1
A5: ='Upload(참조)'!Q5 -> E10316005001001001 | B5: ='Upload(참조)'!R5 | C5: ='Upload(참조)'!S5 -> E10316005001001001 | D5: ='Upload(참조)'!T5 | E5: ='Upload(참조)'!U5 | F5: ='Upload(참조)'!V5 -> 9
A6: ='Upload(참조)'!Q6 -> E10316005001001001 | B6: ='Upload(참조)'!R6 | C6: ='Upload(참조)'!S6 -> E10316005001001001 | D6: ='Upload(참조)'!T6 | E6: ='Upload(참조)'!U6 | F6: ='Upload(참조)'!V6 -> 9
A7: ='Upload(참조)'!Q7 -> E10316005002001006 | B7: ='Upload(참조)'!R7 | C7: ='Upload(참조)'!S7 -> E10316005002001006 | D7: ='Upload(참조)'!T7 | E7: ='Upload(참조)'!U7 | F7: ='Upload(참조)'!V7 -> 0.2
A8: ='Upload(참조)'!Q8 -> E10410040001001001 | B8: ='Upload(참조)'!R8 | C8: ='Upload(참조)'!S8 -> E10410040001001001 | D8: ='Upload(참조)'!T8 | E8: ='Upload(참조)'!U8 | F8: ='Upload(참조)'!V8 -> 1
A9: ='Upload(참조)'!Q9 -> E10410040001014001 | B9: ='Upload(참조)'!R9 | C9: ='Upload(참조)'!S9 -> E10410040001014001 | D9: ='Upload(참조)'!T9 | E9: ='Upload(참조)'!U9 | F9: ='Upload(참조)'!V9 -> 1
A10: ='Upload(참조)'!Q10 -> E10316005003008001 | B10: ='Upload(참조)'!R10 | C10: ='Upload(참조)'!S10 -> E10316005003008001 | D10: ='Upload(참조)'!T10 | E10: ='Upload(참조)'!U10 | F10: ='Upload(참조)'!V10 -> 1
A11: ='Upload(참조)'!Q11 -> E10313002001009001 | B11: ='Upload(참조)'!R11 | C11: ='Upload(참조)'!S11 -> E10313002001009001 | D11: ='Upload(참조)'!T11 | E11: ='Upload(참조)'!U11 | F11: ='Upload(참조)'!V11 -> 1
A12: ='Upload(참조)'!Q12 -> L002 | B12: ='Upload(참조)'!R12 | C12: ='Upload(참조)'!S12 | D12: ='Upload(참조)'!T12 | E12: ='Upload(참조)'!U12 -> L002 | F12: ='Upload(참조)'!V12 -> 1
A13: ='Upload(참조)'!Q13 -> L003 | B13: ='Upload(참조)'!R13 | C13: ='Upload(참조)'!S13 | D13: ='Upload(참조)'!T13 | E13: ='Upload(참조)'!U13 -> L003 | F13: ='Upload(참조)'!V13 -> 1
... A956: ='Upload(참조)'!Q956 | B956: ='Upload(참조)'!R956 | C956: ='Upload(참조)'!S956 | D956: ='Upload(참조)'!T956 | E956: ='Upload(참조)'!U956 | F956: ='Upload(참조)'!V956 -> 0

Sheet Upload시중별도입력
A1: 표준내역코드 | B1: 세부공종 | C1: 품명 | D1: 규격 | E1: 단위 | F1: 수량 | G1: 재료비단가 | H1: 재료비소계 | I1: 노무비단가 | J1: 노무비소계 | K1: 기계경비단가 | L1: 기계경비소계 | M1: 기타경비단가 | N1: 기타경비소계 | O1: 할증코드 | P1: 재료비할증율 | Q1: 노무비할증율 | R1: 할증내용
A2: 999999 | B2: 통신 | C2: UTP케이블 포설 | D2: CAT6(LS) | E2: m | F2: 90 | G2: 519 | H2: =G2*F2 -> 46710
A3: 999999 | B3: 통신 | C3: RJ45 JACK 접속 | D3: CAT6 | E3: EA | F3: 2 | G3: 1404 | H3: =G3*F3 -> 2808
A4: 999999 | B4: 통신 | C4: BOX CCTV | D4: HNH-231V5I | E4: EA | F4: 1 | G4: 660000 | H4: =G4*F4 -> 660000

Sheet 작성 Guide
B2: ※ 견적작성 Guide
B4: ① 표준단가 코드(D Code), 품셈(E Code), 물정(M Code), 노임단가(L Code)입력기준 품명/규격/단가 입력(1열 입력)
B5: ② 내역 기준 표준단가 낙찰율/ 할증기준 반영
B6: ③ 시중가는 999999로 입력(업로드 파일 제외됨)
B7: ④ 업로드 파일 검토(오류시 Upload검토 순번 재정렬)☞ 숨기기 되어 있음
B8: ④ 담당자 제출 후 시중가/할증 별도 입력 요청

Sheet Upload(참조)
A1: 구분 | B1: 표준단가 | C1: 표준품셈 | D1: 물가정보 | E1: 노임단가 | F1: 수량 | I1: 예가내역서 코드 | J1: 코드구분 | L1: 표준단가 | M1: 표준품셈 | N1: 물가정보 | O1: 노임단가 | Q1: 최종구분 | R1: 표준단가 | S1: 표준품셈 | T1: 물가정보 | U1: 노임단가 | V1: 수량 | W1: 표준단가 | X1: 표준품셈 | Y1: *(공란) | Z1: ><(텍스트) | AA1: <>(수식모두)
I2: =IF('내역서(엑셀)'!A5<>"",'내역서(엑셀)'!A5,"") -> 999999 | J2: =LEFT(I2,1) -> 9 | L2: =IF(OR(J2="E",J2="L",J2="M"),"",I2) -> 999999 | M2: =IF(OR(J2="D",J2="L",J2="M"),"",I2) -> 999999 | N2: =IF(OR(J2="D",J2="E",J2="L"),"",I2) -> 999999 | O2: =IF(OR(J2="D",J2="E",J2="M"),"",I2) -> 999999 | Q2: =IF(Z2=0,"",IF(Z2=1,R2&S2&T2&U2,"E99999")) | R2: =IF(L2="","",L2) -> 999999 | S2: =IF(M2="","",M2) -> 999999 | T2: =IF(W2=1,"",N2) -> 999999 | U2: =IF(OR(W2=1,X2=1),"",O2) -> 999999 | V2: ='내역서(엑셀)'!E5 -> 90 | W2: =COUNTIFS(R2,"><") -> 0 | X2: =COUNTIFS(S2,"><") -> 0 | Y2: =COUNTIFS(R2:U2,"*") -> 0 | Z2: =COUNTIFS(R2:U2,"><") -> 0 | AA2: =COUNTIFS(R2:U2,"<>") -> 4
I3: =IF('내역서(엑셀)'!A6<>"",'내역서(엑셀)'!A6,"") -> 999999 | J3: =LEFT(I3,1) -> 9 | L3: =IF(OR(J3="E",J3="L",J3="M"),"",I3) -> 999999 | M3: =IF(OR(J3="D",J3="L",J3="M"),"",I3) -> 999999 | N3: =IF(OR(J3="D",J3="E",J3="L"),"",I3) -> 999999 | O3: =IF(OR(J3="D",J3="E",J3="M"),"",I3) -> 999999 | Q3: =IF(Z3=0,"",IF(Z3=1,R3&S3&T3&U3,"E99999")) | R3: =IF(L3="","",L3) -> 999999 | S3: =IF(M3="","",M3) -> 999999 | T3: =IF(W3=1,"",N3) -> 999999 | U3: =IF(OR(W3=1,X3=1),"",O3) -> 999999 | V3: ='내역서(엑셀)'!E6 -> 2 | W3: =COUNTIFS(R3,"><") -> 0 | X3: =COUNTIFS(S3,"><") -> 0 | Y3: =COUNTIFS(R3:U3,"*") -> 0 | Z3: =COUNTIFS(R3:U3,"><") -> 0 | AA3: =COUNTIFS(R3:U3,"<>") -> 4
I4: =IF('내역서(엑셀)'!A7<>"",'내역서(엑셀)'!A7,"") -> 999999 | J4: =LEFT(I4,1) -> 9 | L4: =IF(OR(J4="E",J4="L",J4="M"),"",I4) -> 999999 | M4: =IF(OR(J4="D",J4="L",J4="M"),"",I4) -> 999999 | N4: =IF(OR(J4="D",J4="E",J4="L"),"",I4) -> 999999 | O4: =IF(OR(J4="D",J4="E",J4="M"),"",I4) -> 999999 | Q4: =IF(Z4=0,"",IF(Z4=1,R4&S4&T4&U4,"E99999")) | R4: =IF(L4="","",L4) -> 999999 | S4: =IF(M4="","",M4) -> 999999 | T4: =IF(W4=1,"",N4) -> 999999 | U4: =IF(OR(W4=1,X4=1),"",O4) -> 999999 | V4: ='내역서(엑셀)'!E7 -> 1 | W4: =COUNTIFS(R4,"><") -> 0 | X4: =COUNTIFS(S4,"><") -> 0 | Y4: =COUNTIFS(R4:U4,"*") -> 0 | Z4: =COUNTIFS(R4:U4,"><") -> 0 | AA4: =COUNTIFS(R4:U4,"<>") -> 4
I5: =IF('내역서(엑셀)'!A8<>"",'내역서(엑셀)'!A8,"") -> E10316005001001001 | J5: =LEFT(I5,1) -> E | L5: =IF(OR(J5="E",J5="L",J5="M"),"",I5) | M5: =IF(OR(J5="D",J5="L",J5="M"),"",I5) -> E10316005001001001 | N5: =IF(OR(J5="D",J5="E",J5="L"),"",I5) | O5: =IF(OR(J5="D",J5="E",J5="M"),"",I5) | Q5: =IF(Z5=0,"",IF(Z5=1,R5&S5&T5&U5,"E99999")) -> E10316005001001001 | R5: =IF(L5="","",L5) | S5: =IF(M5="","",M5) -> E10316005001001001 | T5: =IF(W5=1,"",N5) | U5: =IF(OR(W5=1,X5=1),"",O5) | V5: ='내역서(엑셀)'!E8 -> 9 | W5: =COUNTIFS(R5,"><") -> 0 | X5: =COUNTIFS(S5,"><") -> 1 | Y5: =COUNTIFS(R5:U5,"*") -> 4 | Z5: =COUNTIFS(R5:U5,"><") -> 1 | AA5: =COUNTIFS(R5:U5,"<>") -> 4
I6: =IF('내역서(엑셀)'!A9<>"",'내역서(엑셀)'!A9,"") -> E10316005001001001 | J6: =LEFT(I6,1) -> E | L6: =IF(OR(J6="E",J6="L",J6="M"),"",I6) | M6: =IF(OR(J6="D",J6="L",J6="M"),"",I6) -> E10316005001001001 | N6: =IF(OR(J6="D",J6="E",J6="L"),"",I6) | O6: =IF(OR(J6="D",J6="E",J6="M"),"",I6) | Q6: =IF(Z6=0,"",IF(Z6=1,R6&S6&T6&U6,"E99999")) -> E10316005001001001 | R6: =IF(L6="","",L6) | S6: =IF(M6="","",M6) -> E10316005001001001 | T6: =IF(W6=1,"",N6) | U6: =IF(OR(W6=1,X6=1),"",O6) | V6: ='내역서(엑셀)'!E9 -> 9 | W6: =COUNTIFS(R6,"><") -> 0 | X6: =COUNTIFS(S6,"><") -> 1 | Y6: =COUNTIFS(R6:U6,"*") -> 4 | Z6: =COUNTIFS(R6:U6,"><") -> 1 | AA6: =COUNTIFS(R6:U6,"<>") -> 4
I7: =IF('내역서(엑셀)'!A10<>"",'내역서(엑셀)'!A10,"") -> E10316005002001006 | J7: =LEFT(I7,1) -> E | L7: =IF(OR(J7="E",J7="L",J7="M"),"",I7) | M7: =IF(OR(J7="D",J7="L",J7="M"),"",I7) -> E10316005002001006 | N7: =IF(OR(J7="D",J7="E",J7="L"),"",I7) | O7: =IF(OR(J7="D",J7="E",J7="M"),"",I7) | Q7: =IF(Z7=0,"",IF(Z7=1,R7&S7&T7&U7,"E99999")) -> E10316005002001006 | R7: =IF(L7="","",L7) | S7: =IF(M7="","",M7) -> E10316005002001006 | T7: =IF(W7=1,"",N7) | U7: =IF(OR(W7=1,X7=1),"",O7) | V7: ='내역서(엑셀)'!E10 -> 0.2 | W7: =COUNTIFS(R7,"><") -> 0 | X7: =COUNTIFS(S7,"><") -> 1 | Y7: =COUNTIFS(R7:U7,"*") -> 4 | Z7: =COUNTIFS(R7:U7,"><") -> 1 | AA7: =COUNTIFS(R7:U7,"<>") -> 4
I8: =IF('내역서(엑셀)'!A11<>"",'내역서(엑셀)'!A11,"") -> E10410040001001001 | J8: =LEFT(I8,1) -> E | L8: =IF(OR(J8="E",J8="L",J8="M"),"",I8) | M8: =IF(OR(J8="D",J8="L",J8="M"),"",I8) -> E10410040001001001 | N8: =IF(OR(J8="D",J8="E",J8="L"),"",I8) | O8: =IF(OR(J8="D",J8="E",J8="M"),"",I8) | Q8: =IF(Z8=0,"",IF(Z8=1,R8&S8&T8&U8,"E99999")) -> E10410040001001001 | R8: =IF(L8="","",L8) | S8: =IF(M8="","",M8) -> E10410040001001001 | T8: =IF(W8=1,"",N8) | U8: =IF(OR(W8=1,X8=1),"",O8) | V8: ='내역서(엑셀)'!E11 -> 1 | W8: =COUNTIFS(R8,"><") -> 0 | X8: =COUNTIFS(S8,"><") -> 1 | Y8: =COUNTIFS(R8:U8,"*") -> 4 | Z8: =COUNTIFS(R8:U8,"><") -> 1 | AA8: =COUNTIFS(R8:U8,"<>") -> 4
I9: =IF('내역서(엑셀)'!A12<>"",'내역서(엑셀)'!A12,"") -> E10410040001014001 | J9: =LEFT(I9,1) -> E | L9: =IF(OR(J9="E",J9="L",J9="M"),"",I9) | M9: =IF(OR(J9="D",J9="L",J9="M"),"",I9) -> E10410040001014001 | N9: =IF(OR(J9="D",J9="E",J9="L"),"",I9) | O9: =IF(OR(J9="D",J9="E",J9="M"),"",I9) | Q9: =IF(Z9=0,"",IF(Z9=1,R9&S9&T9&U9,"E99999")) -> E10410040001014001 | R9: =IF(L9="","",L9) | S9: =IF(M9="","",M9) -> E10410040001014001 | T9: =IF(W9=1,"",N9) | U9: =IF(OR(W9=1,X9=1),"",O9) | V9: ='내역서(엑셀)'!E12 -> 1 | W9: =COUNTIFS(R9,"><") -> 0 | X9: =COUNTIFS(S9,"><") -> 1 | Y9: =COUNTIFS(R9:U9,"*") -> 4 | Z9: =COUNTIFS(R9:U9,"><") -> 1 | AA9: =COUNTIFS(R9:U9,"<>") -> 4
I10: =IF('내역서(엑셀)'!A13<>"",'내역서(엑셀)'!A13,"") -> E10316005003008001 | J10: =LEFT(I10,1) -> E | L10: =IF(OR(J10="E",J10="L",J10="M"),"",I10) | M10: =IF(OR(J10="D",J10="L",J10="M"),"",I10) -> E10316005003008001 | N10: =IF(OR(J10="D",J10="E",J10="L"),"",I10) | O10: =IF(OR(J10="D",J10="E",J10="M"),"",I10) | Q10: =IF(Z10=0,"",IF(Z10=1,R10&S10&T10&U10,"E99999")) -> E10316005003008001 | R10: =IF(L10="","",L10) | S10: =IF(M10="","",M10) -> E10316005003008001 | T10: =IF(W10=1,"",N10) | U10: =IF(OR(W10=1,X10=1),"",O10) | V10: ='내역서(엑셀)'!E13 -> 1 | W10: =COUNTIFS(R10,"><") -> 0 | X10: =COUNTIFS(S10,"><") -> 1 | Y10: =COUNTIFS(R10:U10,"*") -> 4 | Z10: =COUNTIFS(R10:U10,"><") -> 1 | AA10: =COUNTIFS(R10:U10,"<>") -> 4
I11: =IF('내역서(엑셀)'!A14<>"",'내역서(엑셀)'!A14,"") -> E10313002001009001 | J11: =LEFT(I11,1) -> E | L11: =IF(OR(J11="E",J11="L",J11="M"),"",I11) | M11: =IF(OR(J11="D",J11="L",J11="M"),"",I11) -> E10313002001009001 | N11: =IF(OR(J11="D",J11="E",J11="L"),"",I11) | O11: =IF(OR(J11="D",J11="E",J11="M"),"",I11) | Q11: =IF(Z11=0,"",IF(Z11=1,R11&S11&T11&U11,"E99999")) -> E10313002001009001 | R11: =IF(L11="","",L11) | S11: =IF(M11="","",M11) -> E10313002001009001 | T11: =IF(W11=1,"",N11) | U11: =IF(OR(W11=1,X11=1),"",O11) | V11: ='내역서(엑셀)'!E14 -> 1 | W11: =COUNTIFS(R11,"><") -> 0 | X11: =COUNTIFS(S11,"><") -> 1 | Y11: =COUNTIFS(R11:U11,"*") -> 4 | Z11: =COUNTIFS(R11:U11,"><") -> 1 | AA11: =COUNTIFS(R11:U11,"<>") -> 4
I12: =IF('내역서(엑셀)'!A15<>"",'내역서(엑셀)'!A15,"") -> L002 | J12: =LEFT(I12,1) -> L | L12: =IF(OR(J12="E",J12="L",J12="M"),"",I12) | M12: =IF(OR(J12="D",J12="L",J12="M"),"",I12) | N12: =IF(OR(J12="D",J12="E",J12="L"),"",I12) | O12: =IF(OR(J12="D",J12="E",J12="M"),"",I12) -> L002 | Q12: =IF(Z12=0,"",IF(Z12=1,R12&S12&T12&U12,"E99999")) -> L002 | R12: =IF(L12="","",L12) | S12: =IF(M12="","",M12) | T12: =IF(W12=1,"",N12) | U12: =IF(OR(W12=1,X12=1),"",O12) -> L002 | V12: ='내역서(엑셀)'!E15 -> 1 | W12: =COUNTIFS(R12,"><") -> 0 | X12: =COUNTIFS(S12,"><") -> 0 | Y12: =COUNTIFS(R12:U12,"*") -> 4 | Z12: =COUNTIFS(R12:U12,"><") -> 1 | AA12: =COUNTIFS(R12:U12,"<>") -> 4
I13: =IF('내역서(엑셀)'!A16<>"",'내역서(엑셀)'!A16,"") -> L003 | J13: =LEFT(I13,1) -> L | L13: =IF(OR(J13="E",J13="L",J13="M"),"",I13) | M13: =IF(OR(J13="D",J13="L",J13="M"),"",I13) | N13: =IF(OR(J13="D",J13="E",J13="L"),"",I13) | O13: =IF(OR(J13="D",J13="E",J13="M"),"",I13) -> L003 | Q13: =IF(Z13=0,"",IF(Z13=1,R13&S13&T13&U13,"E99999")) -> L003 | R13: =IF(L13="","",L13) | S13: =IF(M13="","",M13) | T13: =IF(W13=1,"",N13) | U13: =IF(OR(W13=1,X13=1),"",O13) -> L003 | V13: ='내역서(엑셀)'!E16 -> 1 | W13: =COUNTIFS(R13,"><") -> 0 | X13: =COUNTIFS(S13,"><") -> 0 | Y13: =COUNTIFS(R13:U13,"*") -> 4 | Z13: =COUNTIFS(R13:U13,"><") -> 1 | AA13: =COUNTIFS(R13:U13,"<>") -> 4
... I70: =IF('내역서(엑셀)'!A73<>"",'내역서(엑셀)'!A73,"") | J70: =LEFT(I70,1) | L70: =IF(OR(J70="E",J70="L",J70="M"),"",I70) | M70: =IF(OR(J70="D",J70="L",J70="M"),"",I70) | N70: =IF(OR(J70="D",J70="E",J70="L"),"",I70) | O70: =IF(OR(J70="D",J70="E",J70="M"),"",I70) | Q70: =IF(Z70=0,"",IF(Z70=1,R70&S70&T70&U70,"E99999")) | R70: =IF(L70="","",L70) | S70: =IF(M70="","",M70) | T70: =IF(W70=1,"",N70) | U70: =IF(OR(W70=1,X70=1),"",O70) | V70: ='내역서(엑셀)'!E73 -> 0 | W70: =COUNTIFS(R70,"><") -> 0 | X70: =COUNTIFS(S70,"><") -> 0 | Y70: =COUNTIFS(R70:U70,"*") -> 4 | Z70: =COUNTIFS(R70:U70,"><") -> 0 | AA70: =COUNTIFS(R70:U70,"<>") -> 4
I71: =IF('내역서(엑셀)'!A54<>"",'내역서(엑셀)'!A54,"") | J71: =LEFT(I71,1) | L71: =IF(OR(J71="E",J71="L",J71="M"),"",I71) | M71: =IF(OR(J71="D",J71="L",J71="M"),"",I71) | N71: =IF(OR(J71="D",J71="E",J71="L"),"",I71) | O71: =IF(OR(J71="D",J71="E",J71="M"),"",I71) | Q71: =IF(Z71=0,"",IF(Z71=1,R71&S71&T71&U71,"E99999")) | R71: =IF(L71="","",L71) | S71: =IF(M71="","",M71) | T71: =IF(W71=1,"",N71) | U71: =IF(OR(W71=1,X71=1),"",O71) | V71: ='내역서(엑셀)'!E54 -> 0 | W71: =COUNTIFS(R71,"><") -> 0 | X71: =COUNTIFS(S71,"><") -> 0 | Y71: =COUNTIFS(R71:U71,"*") -> 4 | Z71: =COUNTIFS(R71:U71,"><") -> 0 | AA71: =COUNTIFS(R71:U71,"<>") -> 4
I72: =IF('내역서(엑셀)'!A55<>"",'내역서(엑셀)'!A55,"") | J72: =LEFT(I72,1) | L72: =IF(OR(J72="E",J72="L",J72="M"),"",I72) | M72: =IF(OR(J72="D",J72="L",J72="M"),"",I72) | N72: =IF(OR(J72="D",J72="E",J72="L"),"",I72) | O72: =IF(OR(J72="D",J72="E",J72="M"),"",I72) | Q72: =IF(Z72=0,"",IF(Z72=1,R72&S72&T72&U72,"E99999")) | R72: =IF(L72="","",L72) | S72: =IF(M72="","",M72) | T72: =IF(W72=1,"",N72) | U72: =IF(OR(W72=1,X72=1),"",O72) | V72: ='내역서(엑셀)'!E55 -> 0 | W72: =COUNTIFS(R72,"><") -> 0 | X72: =COUNTIFS(S72,"><") -> 0 | Y72: =COUNTIFS(R72:U72,"*") -> 4 | Z72: =COUNTIFS(R72:U72,"><") -> 0 | AA72: =COUNTIFS(R72:U72,"<>") -> 4
I73: =IF('내역서(엑셀)'!A56<>"",'내역서(엑셀)'!A56,"") | J73: =LEFT(I73,1) | L73: =IF(OR(J73="E",J73="L",J73="M"),"",I73) | M73: =IF(OR(J73="D",J73="L",J73="M"),"",I73) | N73: =IF(OR(J73="D",J73="E",J73="L"),"",I73) | O73: =IF(OR(J73="D",J73="E",J73="M"),"",I73) | Q73: =IF(Z73=0,"",IF(Z73=1,R73&S73&T73&U73,"E99999")) | R73: =IF(L73="","",L73) | S73: =IF(M73="","",M73) | T73: =IF(W73=1,"",N73) | U73: =IF(OR(W73=1,X73=1),"",O73) | V73: ='내역서(엑셀)'!E56 -> 0 | W73: =COUNTIFS(R73,"><") -> 0 | X73: =COUNTIFS(S73,"><") -> 0 | Y73: =COUNTIFS(R73:U73,"*") -> 4 | Z73: =COUNTIFS(R73:U73,"><") -> 0 | AA73: =COUNTIFS(R73:U73,"<>") -> 4
I74: =IF('내역서(엑셀)'!A57<>"",'내역서(엑셀)'!A57,"") | J74: =LEFT(I74,1) | L74: =IF(OR(J74="E",J74="L",J74="M"),"",I74) | M74: =IF(OR(J74="D",J74="L",J74="M"),"",I74) | N74: =IF(OR(J74="D",J74="E",J74="L"),"",I74) | O74: =IF(OR(J74="D",J74="E",J74="M"),"",I74) | Q74: =IF(Z74=0,"",IF(Z74=1,R74&S74&T74&U74,"E99999")) | R74: =IF(L74="","",L74) | S74: =IF(M74="","",M74) | T74: =IF(W74=1,"",N74) | U74: =IF(OR(W74=1,X74=1),"",O74) | V74: ='내역서(엑셀)'!E57 -> 0 | W74: =COUNTIFS(R74,"><") -> 0 | X74: =COUNTIFS(S74,"><") -> 0 | Y74: =COUNTIFS(R74:U74,"*") -> 4 | Z74: =COUNTIFS(R74:U74,"><") -> 0 | AA74: =COUNTIFS(R74:U74,"<>") -> 4
I75: =IF('내역서(엑셀)'!A58<>"",'내역서(엑셀)'!A58,"") | J75: =LEFT(I75,1) | L75: =IF(OR(J75="E",J75="L",J75="M"),"",I75) | M75: =IF(OR(J75="D",J75="L",J75="M"),"",I75) | N75: =IF(OR(J75="D",J75="E",J75="L"),"",I75) | O75: =IF(OR(J75="D",J75="E",J75="M"),"",I75) | Q75: =IF(Z75=0,"",IF(Z75=1,R75&S75&T75&U75,"E99999")) | R75: =IF(L75="","",L75) | S75: =IF(M75="","",M75) | T75: =IF(W75=1,"",N75) | U75: =IF(OR(W75=1,X75=1),"",O75) | V75: ='내역서(엑셀)'!E58 -> 0 | W75: =COUNTIFS(R75,"><") -> 0 | X75: =COUNTIFS(S75,"><") -> 0 | Y75: =COUNTIFS(R75:U75,"*") -> 4 | Z75: =COUNTIFS(R75:U75,"><") -> 0 | AA75: =COUNTIFS(R75:U75,"<>") -> 4
I76: =IF('내역서(엑셀)'!A59<>"",'내역서(엑셀)'!A59,"") | J76: =LEFT(I76,1) | L76: =IF(OR(J76="E",J76="L",J76="M"),"",I76) | M76: =IF(OR(J76="D",J76="L",J76="M"),"",I76) | N76: =IF(OR(J76="D",J76="E",J76="L"),"",I76) | O76: =IF(OR(J76="D",J76="E",J76="M"),"",I76) | Q76: =IF(Z76=0,"",IF(Z76=1,R76&S76&T76&U76,"E99999")) | R76: =IF(L76="","",L76) | S76: =IF(M76="","",M76) | T76: =IF(W76=1,"",N76) | U76: =IF(OR(W76=1,X76=1),"",O76) | V76: ='내역서(엑셀)'!E59 -> 0 | W76: =COUNTIFS(R76,"><") -> 0 | X76: =COUNTIFS(S76,"><") -> 0 | Y76: =COUNTIFS(R76:U76,"*") -> 4 | Z76: =COUNTIFS(R76:U76,"><") -> 0 | AA76: =COUNTIFS(R76:U76,"<>") -> 4
I77: =IF('내역서(엑셀)'!A60<>"",'내역서(엑셀)'!A60,"") | J77: =LEFT(I77,1) | L77: =IF(OR(J77="E",J77="L",J77="M"),"",I77) | M77: =IF(OR(J77="D",J77="L",J77="M"),"",I77) | N77: =IF(OR(J77="D",J77="E",J77="L"),"",I77) | O77: =IF(OR(J77="D",J77="E",J77="M"),"",I77) | Q77: =IF(Z77=0,"",IF(Z77=1,R77&S77&T77&U77,"E99999")) | R77: =IF(L77="","",L77) | S77: =IF(M77="","",M77) | T77: =IF(W77=1,"",N77) | U77: =IF(OR(W77=1,X77=1),"",O77) | V77: ='내역서(엑셀)'!E60 -> 0 | W77: =COUNTIFS(R77,"><") -> 0 | X77: =COUNTIFS(S77,"><") -> 0 | Y77: =COUNTIFS(R77:U77,"*") -> 4 | Z77: =COUNTIFS(R77:U77,"><") -> 0 | AA77: =COUNTIFS(R77:U77,"<>") -> 4
I78: =IF('내역서(엑셀)'!A61<>"",'내역서(엑셀)'!A61,"") | J78: =LEFT(I78,1) | L78: =IF(OR(J78="E",J78="L",J78="M"),"",I78) | M78: =IF(OR(J78="D",J78="L",J78="M"),"",I78) | N78: =IF(OR(J78="D",J78="E",J78="L"),"",I78) | O78: =IF(OR(J78="D",J78="E",J78="M"),"",I78) | Q78: =IF(Z78=0,"",IF(Z78=1,R78&S78&T78&U78,"E99999")) | R78: =IF(L78="","",L78) | S78: =IF(M78="","",M78) | T78: =IF(W78=1,"",N78) | U78: =IF(OR(W78=1,X78=1),"",O78) | V78: ='내역서(엑셀)'!E61 -> 0 | W78: =COUNTIFS(R78,"><") -> 0 | X78: =COUNTIFS(S78,"><") -> 0 | Y78: =COUNTIFS(R78:U78,"*") -> 4 | Z78: =COUNTIFS(R78:U78,"><") -> 0 | AA78: =COUNTIFS(R78:U78,"<>") -> 4
I79: =IF('내역서(엑셀)'!A62<>"",'내역서(엑셀)'!A62,"") | J79: =LEFT(I79,1) | L79: =IF(OR(J79="E",J79="L",J79="M"),"",I79) | M79: =IF(OR(J79="D",J79="L",J79="M"),"",I79) | N79: =IF(OR(J79="D",J79="E",J79="L"),"",I79) | O79: =IF(OR(J79="D",J79="E",J79="M"),"",I79) | Q79: =IF(Z79=0,"",IF(Z79=1,R79&S79&T79&U79,"E99999")) | R79: =IF(L79="","",L79) | S79: =IF(M79="","",M79) | T79: =IF(W79=1,"",N79) | U79: =IF(OR(W79=1,X79=1),"",O79) | V79: ='내역서(엑셀)'!E62 -> 0 | W79: =COUNTIFS(R79,"><") -> 0 | X79: =COUNTIFS(S79,"><") -> 0 | Y79: =COUNTIFS(R79:U79,"*") -> 4 | Z79: =COUNTIFS(R79:U79,"><") -> 0 | AA79: =COUNTIFS(R79:U79,"<>") -> 4
I80: =IF('내역서(엑셀)'!A63<>"",'내역서(엑셀)'!A63,"") | J80: =LEFT(I80,1) | L80: =IF(OR(J80="E",J80="L",J80="M"),"",I80) | M80: =IF(OR(J80="D",J80="L",J80="M"),"",I80) | N80: =IF(OR(J80="D",J80="E",J80="L"),"",I80) | O80: =IF(OR(J80="D",J80="E",J80="M"),"",I80) | Q80: =IF(Z80=0,"",IF(Z80=1,R80&S80&T80&U80,"E99999")) | R80: =IF(L80="","",L80) | S80: =IF(M80="","",M80) | T80: =IF(W80=1,"",N80) | U80: =IF(OR(W80=1,X80=1),"",O80) | V80: ='내역서(엑셀)'!E63 -> 0 | W80: =COUNTIFS(R80,"><") -> 0 | X80: =COUNTIFS(S80,"><") -> 0 | Y80: =COUNTIFS(R80:U80,"*") -> 4 | Z80: =COUNTIFS(R80:U80,"><") -> 0 | AA80: =COUNTIFS(R80:U80,"<>") -> 4
I81: =IF('내역서(엑셀)'!A64<>"",'내역서(엑셀)'!A64,"") | J81: =LEFT(I81,1) | L81: =IF(OR(J81="E",J81="L",J81="M"),"",I81) | M81: =IF(OR(J81="D",J81="L",J81="M"),"",I81) | N81: =IF(OR(J81="D",J81="E",J81="L"),"",I81) | O81: =IF(OR(J81="D",J81="E",J81="M"),"",I81) | Q81: =IF(Z81=0,"",IF(Z81=1,R81&S81&T81&U81,"E99999")) | R81: =IF(L81="","",L81) | S81: =IF(M81="","",M81) | T81: =IF(W81=1,"",N81) | U81: =IF(OR(W81=1,X81=1),"",O81) | V81: ='내역서(엑셀)'!E64 -> 0 | W81: =COUNTIFS(R81,"><") -> 0 | X81: =COUNTIFS(S81,"><") -> 0 | Y81: =COUNTIFS(R81:U81,"*") -> 4 | Z81: =COUNTIFS(R81:U81,"><") -> 0 | AA81: =COUNTIFS(R81:U81,"<>") -> 4
I82: =IF('내역서(엑셀)'!A65<>"",'내역서(엑셀)'!A65,"") | J82: =LEFT(I82,1) | L82: =IF(OR(J82="E",J82="L",J82="M"),"",I82) | M82: =IF(OR(J82="D",J82="L",J82="M"),"",I82) | N82: =IF(OR(J82="D",J82="E",J82="L"),"",I82) | O82: =IF(OR(J82="D",J82="E",J82="M"),"",I82) | Q82: =IF(Z82=0,"",IF(Z82=1,R82&S82&T82&U82,"E99999")) | R82: =IF(L82="","",L82) | S82: =IF(M82="","",M82) | T82: =IF(W82=1,"",N82) | U82: =IF(OR(W82=1,X82=1),"",O82) | V82: ='내역서(엑셀)'!E65 -> 0 | W82: =COUNTIFS(R82,"><") -> 0 | X82: =COUNTIFS(S82,"><") -> 0 | Y82: =COUNTIFS(R82:U82,"*") -> 4 | Z82: =COUNTIFS(R82:U82,"><") -> 0 | AA82: =COUNTIFS(R82:U82,"<>") -> 4
... I137: =IF('내역서(엑셀)'!A120<>"",'내역서(엑셀)'!A120,"") | J137: =LEFT(I137,1) | L137: =IF(OR(J137="E",J137="L",J137="M"),"",I137) | M137: =IF(OR(J137="D",J137="L",J137="M"),"",I137) | N137: =IF(OR(J137="D",J137="E",J137="L"),"",I137) | O137: =IF(OR(J137="D",J137="E",J137="M"),"",I137) | Q137: =IF(Z137=0,"",IF(Z137=1,R137&S137&T137&U137,"E99999")) | R137: =IF(L137="","",L137) | S137: =IF(M137="","",M137) | T137: =IF(W137=1,"",N137) | U137: =IF(OR(W137=1,X137=1),"",O137) | V137: ='내역서(엑셀)'!E120 -> 0 | W137: =COUNTIFS(R137,"><") -> 0 | X137: =COUNTIFS(S137,"><") -> 0 | Y137: =COUNTIFS(R137:U137,"*") -> 4 | Z137: =COUNTIFS(R137:U137,"><") -> 0 | AA137: =COUNTIFS(R137:U137,"<>") -> 4
I138: =IF('내역서(엑셀)'!A123<>"",'내역서(엑셀)'!A123,"") | J138: =LEFT(I138,1) | L138: =IF(OR(J138="E",J138="L",J138="M"),"",I138) | M138: =IF(OR(J138="D",J138="L",J138="M"),"",I138) | N138: =IF(OR(J138="D",J138="E",J138="L"),"",I138) | O138: =IF(OR(J138="D",J138="E",J138="M"),"",I138) | Q138: =IF(Z138=0,"",IF(Z138=1,R138&S138&T138&U138,"E99999")) | R138: =IF(L138="","",L138) | S138: =IF(M138="","",M138) | T138: =IF(W138=1,"",N138) | U138: =IF(OR(W138=1,X138=1),"",O138) | V138: ='내역서(엑셀)'!E123 -> 0 | W138: =COUNTIFS(R138,"><") -> 0 | X138: =COUNTIFS(S138,"><") -> 0 | Y138: =COUNTIFS(R138:U138,"*") -> 4 | Z138: =COUNTIFS(R138:U138,"><") -> 0 | AA138: =COUNTIFS(R138:U138,"<>") -> 4
I139: =IF('내역서(엑셀)'!A124<>"",'내역서(엑셀)'!A124,"") | J139: =LEFT(I139,1) | L139: =IF(OR(J139="E",J139="L",J139="M"),"",I139) | M139: =IF(OR(J139="D",J139="L",J139="M"),"",I139) | N139: =IF(OR(J139="D",J139="E",J139="L"),"",I139) | O139: =IF(OR(J139="D",J139="E",J139="M"),"",I139) | Q139: =IF(Z139=0,"",IF(Z139=1,R139&S139&T139&U139,"E99999")) | R139: =IF(L139="","",L139) | S139: =IF(M139="","",M139) | T139: =IF(W139=1,"",N139) | U139: =IF(OR(W139=1,X139=1),"",O139) | V139: ='내역서(엑셀)'!E124 -> 0 | W139: =COUNTIFS(R139,"><") -> 0 | X139: =COUNTIFS(S139,"><") -> 0 | Y139: =COUNTIFS(R139:U139,"*") -> 4 | Z139: =COUNTIFS(R139:U139,"><") -> 0 | AA139: =COUNTIFS(R139:U139,"<>") -> 4
I140: =IF('내역서(엑셀)'!A125<>"",'내역서(엑셀)'!A125,"") | J140: =LEFT(I140,1) | L140: =IF(OR(J140="E",J140="L",J140="M"),"",I140) | M140: =IF(OR(J140="D",J140="L",J140="M"),"",I140) | N140: =IF(OR(J140="D",J140="E",J140="L"),"",I140) | O140: =IF(OR(J140="D",J140="E",J140="M"),"",I140) | Q140: =IF(Z140=0,"",IF(Z140=1,R140&S140&T140&U140,"E99999")) | R140: =IF(L140="","",L140) | S140: =IF(M140="","",M140) | T140: =IF(W140=1,"",N140) | U140: =IF(OR(W140=1,X140=1),"",O140) | V140: ='내역서(엑셀)'!E125 -> 0 | W140: =COUNTIFS(R140,"><") -> 0 | X140: =COUNTIFS(S140,"><") -> 0 | Y140: =COUNTIFS(R140:U140,"*") -> 4 | Z140: =COUNTIFS(R140:U140,"><") -> 0 | AA140: =COUNTIFS(R140:U140,"<>") -> 4
I141: =IF('내역서(엑셀)'!A126<>"",'내역서(엑셀)'!A126,"") | J141: =LEFT(I141,1) | L141: =IF(OR(J141="E",J141="L",J141="M"),"",I141) | M141: =IF(OR(J141="D",J141="L",J141="M"),"",I141) | N141: =IF(OR(J141="D",J141="E",J141="L"),"",I141) | O141: =IF(OR(J141="D",J141="E",J141="M"),"",I141) | Q141: =IF(Z141=0,"",IF(Z141=1,R141&S141&T141&U141,"E99999")) | R141: =IF(L141="","",L141) | S141: =IF(M141="","",M141) | T141: =IF(W141=1,"",N141) | U141: =IF(OR(W141=1,X141=1),"",O141) | V141: ='내역서(엑셀)'!E126 -> 0 | W141: =COUNTIFS(R141,"><") -> 0 | X141: =COUNTIFS(S141,"><") -> 0 | Y141: =COUNTIFS(R141:U141,"*") -> 4 | Z141: =COUNTIFS(R141:U141,"><") -> 0 | AA141: =COUNTIFS(R141:U141,"<>") -> 4
I142: =IF('내역서(엑셀)'!A127<>"",'내역서(엑셀)'!A127,"") | J142: =LEFT(I142,1) | L142: =IF(OR(J142="E",J142="L",J142="M"),"",I142) | M142: =IF(OR(J142="D",J142="L",J142="M"),"",I142) | N142: =IF(OR(J142="D",J142="E",J142="L"),"",I142) | O142: =IF(OR(J142="D",J142="E",J142="M"),"",I142) | Q142: =IF(Z142=0,"",IF(Z142=1,R142&S142&T142&U142,"E99999")) | R142: =IF(L142="","",L142) | S142: =IF(M142="","",M142) | T142: =IF(W142=1,"",N142) | U142: =IF(OR(W142=1,X142=1),"",O142) | V142: ='내역서(엑셀)'!E127 -> 0 | W142: =COUNTIFS(R142,"><") -> 0 | X142: =COUNTIFS(S142,"><") -> 0 | Y142: =COUNTIFS(R142:U142,"*") -> 4 | Z142: =COUNTIFS(R142:U142,"><") -> 0 | AA142: =COUNTIFS(R142:U142,"<>") -> 4
I143: =IF('내역서(엑셀)'!A128<>"",'내역서(엑셀)'!A128,"") | J143: =LEFT(I143,1) | L143: =IF(OR(J143="E",J143="L",J143="M"),"",I143) | M143: =IF(OR(J143="D",J143="L",J143="M"),"",I143) | N143: =IF(OR(J143="D",J143="E",J143="L"),"",I143) | O143: =IF(OR(J143="D",J143="E",J143="M"),"",I143) | Q143: =IF(Z143=0,"",IF(Z143=1,R143&S143&T143&U143,"E99999")) | R143: =IF(L143="","",L143) | S143: =IF(M143="","",M143) | T143: =IF(W143=1,"",N143) | U143: =IF(OR(W143=1,X143=1),"",O143) | V143: ='내역서(엑셀)'!E128 -> 0 | W143: =COUNTIFS(R143,"><") -> 0 | X143: =COUNTIFS(S143,"><") -> 0 | Y143: =COUNTIFS(R143:U143,"*") -> 4 | Z143: =COUNTIFS(R143:U143,"><") -> 0 | AA143: =COUNTIFS(R143:U143,"<>") -> 4
I144: =IF('내역서(엑셀)'!A129<>"",'내역서(엑셀)'!A129,"") | J144: =LEFT(I144,1) | L144: =IF(OR(J144="E",J144="L",J144="M"),"",I144) | M144: =IF(OR(J144="D",J144="L",J144="M"),"",I144) | N144: =IF(OR(J144="D",J144="E",J144="L"),"",I144) | O144: =IF(OR(J144="D",J144="E",J144="M"),"",I144) | Q144: =IF(Z144=0,"",IF(Z144=1,R144&S144&T144&U144,"E99999")) | R144: =IF(L144="","",L144) | S144: =IF(M144="","",M144) | T144: =IF(W144=1,"",N144) | U144: =IF(OR(W144=1,X144=1),"",O144) | V144: ='내역서(엑셀)'!E129 -> 0 | W144: =COUNTIFS(R144,"><") -> 0 | X144: =COUNTIFS(S144,"><") -> 0 | Y144: =COUNTIFS(R144:U144,"*") -> 4 | Z144: =COUNTIFS(R144:U144,"><") -> 0 | AA144: =COUNTIFS(R144:U144,"<>") -> 4
I145: =IF('내역서(엑셀)'!A130<>"",'내역서(엑셀)'!A130,"") | J145: =LEFT(I145,1) | L145: =IF(OR(J145="E",J145="L",J145="M"),"",I145) | M145: =IF(OR(J145="D",J145="L",J145="M"),"",I145) | N145: =IF(OR(J145="D",J145="E",J145="L"),"",I145) | O145: =IF(OR(J145="D",J145="E",J145="M"),"",I145) | Q145: =IF(Z145=0,"",IF(Z145=1,R145&S145&T145&U145,"E99999")) | R145: =IF(L145="","",L145) | S145: =IF(M145="","",M145) | T145: =IF(W145=1,"",N145) | U145: =IF(OR(W145=1,X145=1),"",O145) | V145: ='내역서(엑셀)'!E130 -> 0 | W145: =COUNTIFS(R145,"><") -> 0 | X145: =COUNTIFS(S145,"><") -> 0 | Y145: =COUNTIFS(R145:U145,"*") -> 4 | Z145: =COUNTIFS(R145:U145,"><") -> 0 | AA145: =COUNTIFS(R145:U145,"<>") -> 4
I146: =IF('내역서(엑셀)'!A131<>"",'내역서(엑셀)'!A131,"") | J146: =LEFT(I146,1) | L146: =IF(OR(J146="E",J146="L",J146="M"),"",I146) | M146: =IF(OR(J146="D",J146="L",J146="M"),"",I146) | N146: =IF(OR(J146="D",J146="E",J146="L"),"",I146) | O146: =IF(OR(J146="D",J146="E",J146="M"),"",I146) | Q146: =IF(Z146=0,"",IF(Z146=1,R146&S146&T146&U146,"E99999")) | R146: =IF(L146="","",L146) | S146: =IF(M146="","",M146) | T146: =IF(W146=1,"",N146) | U146: =IF(OR(W146=1,X146=1),"",O146) | V146: ='내역서(엑셀)'!E131 -> 0 | W146: =COUNTIFS(R146,"><") -> 0 | X146: =COUNTIFS(S146,"><") -> 0 | Y146: =COUNTIFS(R146:U146,"*") -> 4 | Z146: =COUNTIFS(R146:U146,"><") -> 0 | AA146: =COUNTIFS(R146:U146,"<>") -> 4
I147: =IF('내역서(엑셀)'!A132<>"",'내역서(엑셀)'!A132,"") | J147: =LEFT(I147,1) | L147: =IF(OR(J147="E",J147="L",J147="M"),"",I147) | M147: =IF(OR(J147="D",J147="L",J147="M"),"",I147) | N147: =IF(OR(J147="D",J147="E",J147="L"),"",I147) | O147: =IF(OR(J147="D",J147="E",J147="M"),"",I147) | Q147: =IF(Z147=0,"",IF(Z147=1,R147&S147&T147&U147,"E99999")) | R147: =IF(L147="","",L147) | S147: =IF(M147="","",M147) | T147: =IF(W147=1,"",N147) | U147: =IF(OR(W147=1,X147=1),"",O147) | V147: ='내역서(엑셀)'!E132 -> 0 | W147: =COUNTIFS(R147,"><") -> 0 | X147: =COUNTIFS(S147,"><") -> 0 | Y147: =COUNTIFS(R147:U147,"*") -> 4 | Z147: =COUNTIFS(R147:U147,"><") -> 0 | AA147: =COUNTIFS(R147:U147,"<>") -> 4
I148: =IF('내역서(엑셀)'!A133<>"",'내역서(엑셀)'!A133,"") | J148: =LEFT(I148,1) | L148: =IF(OR(J148="E",J148="L",J148="M"),"",I148) | M148: =IF(OR(J148="D",J148="L",J148="M"),"",I148) | N148: =IF(OR(J148="D",J148="E",J148="L"),"",I148) | O148: =IF(OR(J148="D",J148="E",J148="M"),"",I148) | Q148: =IF(Z148=0,"",IF(Z148=1,R148&S148&T148&U148,"E99999")) | R148: =IF(L148="","",L148) | S148: =IF(M148="","",M148) | T148: =IF(W148=1,"",N148) | U148: =IF(OR(W148=1,X148=1),"",O148) | V148: ='내역서(엑셀)'!E133 -> 0 | W148: =COUNTIFS(R148,"><") -> 0 | X148: =COUNTIFS(S148,"><") -> 0 | Y148: =COUNTIFS(R148:U148,"*") -> 4 | Z148: =COUNTIFS(R148:U148,"><") -> 0 | AA148: =COUNTIFS(R148:U148,"<>") -> 4
I149: =IF('내역서(엑셀)'!A134<>"",'내역서(엑셀)'!A134,"") | J149: =LEFT(I149,1) | L149: =IF(OR(J149="E",J149="L",J149="M"),"",I149) | M149: =IF(OR(J149="D",J149="L",J149="M"),"",I149) | N149: =IF(OR(J149="D",J149="E",J149="L"),"",I149) | O149: =IF(OR(J149="D",J149="E",J149="M"),"",I149) | Q149: =IF(Z149=0,"",IF(Z149=1,R149&S149&T149&U149,"E99999")) | R149: =IF(L149="","",L149) | S149: =IF(M149="","",M149) | T149: =IF(W149=1,"",N149) | U149: =IF(OR(W149=1,X149=1),"",O149) | V149: ='내역서(엑셀)'!E134 -> 0 | W149: =COUNTIFS(R149,"><") -> 0 | X149: =COUNTIFS(S149,"><") -> 0 | Y149: =COUNTIFS(R149:U149,"*") -> 4 | Z149: =COUNTIFS(R149:U149,"><") -> 0 | AA149: =COUNTIFS(R149:U149,"<>") -> 4
I150: =IF('내역서(엑셀)'!A124<>"",'내역서(엑셀)'!A124,"") | J150: =LEFT(I150,1) | L150: =IF(OR(J150="E",J150="L",J150="M"),"",I150) | M150: =IF(OR(J150="D",J150="L",J150="M"),"",I150) | N150: =IF(OR(J150="D",J150="E",J150="L"),"",I150) | O150: =IF(OR(J150="D",J150="E",J150="M"),"",I150) | Q150: =IF(Z150=0,"",IF(Z150=1,R150&S150&T150&U150,"E99999")) | R150: =IF(L150="","",L150) | S150: =IF(M150="","",M150) | T150: =IF(W150=1,"",N150) | U150: =IF(OR(W150=1,X150=1),"",O150) | V150: ='내역서(엑셀)'!E124 -> 0 | W150: =COUNTIFS(R150,"><") -> 0 | X150: =COUNTIFS(S150,"><") -> 0 | Y150: =COUNTIFS(R150:U150,"*") -> 4 | Z150: =COUNTIFS(R150:U150,"><") -> 0 | AA150: =COUNTIFS(R150:U150,"<>") -> 4
...
