Workbook

Sheet 갑지
A2: 견 적 서
A5: 수신인: | B5: (주)에스앤아이코퍼레이션 | F5: 주 식 회 사 대 양 이 엔 씨 대 표 박 찬 현
A7: 공사명: | B7: 사택 조명 교체 | F7: 대전광역시 대덕구 아리랑로 125번길 11
A9: 견적일: | B9: 2025년 01월 일 | F9: 전화 : 042-628-8301 /FAX : 042-628-8304
A12: 금액: | B12: =NUMBERSTRING(F31,1) -> 일백오십구만일천 | D12: 원정
A14: NO | B14: 품명 | C14: 규격 | D14: 수량 | E14: 단위 | F14: 금액 | G14: 비고
B15: 직접비
B16: 재료비 | F16: ='내역서(표준단가)'!O3471 -> 897230
B17: 노무비 | F17: ='내역서(표준단가)'!Q3471 -> 544820.4
B18: 기계/기타경비 | F18: ='내역서(표준단가)'!S3471 -> 0
B19: 소계 | F19: =F16+F17+F18 -> 1442050.4
B20: 간접비
B21: 국민연금 | C21: 노무비*4.5% | D21: 1 | E21: 식 | F21: =F17*4.5% -> 24516.918 | G21: 모든공사에 적용
B22: 건강보험료 | C22: 노무비*3.545% | D22: 1 | E22: 식 | F22: =F17*3.545% -> 19313.883 | G22: 모든공사에 적용
B23: 장기요양보험료 | C23: 건강보험료*12.95% | D23: 1 | E23: 식 | F23: =F22*12.95% -> 2501.1479 | G23: 모든공사에 적용
B24: 고용보험료 | C24: 노무비*1.01% | D24: 1 | E24: 식 | F24: =F17*1.01% -> 5502.686 | G24: 모든공사에 적용
B25: 산재보험료 | C25: 노무비*3.56% | D25: 1 | E25: 식 | F25: =F17*3.56% -> 19395.606 | G25: 모든공사에 적용
B26: 산업안전보건관리비 | C26: (재료비+노무비)*3.11% | D26: 1 | E26: 식 | F26: =(F16+F17)*3.11% -> 44847.767 | G26: 모든공사에 적용
B27: 일반관리비/이윤 | C27: (노무비+간접공사비)*5% | D27: 1 | E27: 식 | F27: =SUM(F17+F21+F22+F23+F24+F25+F26)*5% -> 33044.92
B28: 소계 | F28: =F21+F22+F23+F24+F25+F26+F27 -> 149122.93
F30: =F19+F28+F29 -> 1591173.3
B31: 합계(단수조정) | F31: =ROUNDDOWN(F30,-3) -> 1591000
B32: VAT별도

Sheet 내역서(표준단가)
O2: ▼낙찰율 | Q2: ▼낙찰율 | S2: ▼낙찰율 | U2: ▼낙찰율 | W2: ▼할증율
H3: 공사명: | J3: =갑지!B7 -> 사택 조명 교체 | O3: 0.83 | Q3: 0.4 | S3: 0.6 | U3: 0.6 | W3: 1 | X3: 기본
H4: 표준 Code | J4: 주요내역 | L4: 단위 | M4: 수량 | N4: 재료비 | P4: 노무비 | R4: 기계경비 | T4: 기타경비(부자재비) | V4: 합계 | W4: 비고
I5: 일대위가명 | J5: 품목 | K5: 규격 | N5: 단가 | O5: 금액 | P5: 단가 | Q5: 금액 | R5: 단가 | S5: 금액 | T5: 단가 | U5: 금액 | W5: 할증율(%) | X5: 기준
H7: E999999 | I7: 절연난연PVC시스케이블(F-CV, TFR-CV) | J7: F-CV케이블 | K7: 6/10KV 1C 50㎟ | L7: m | N7: 7931 | O7: =M7*N7 -> 0 | V7: =SUM(O7+Q7)+S7+U7 -> 0
H8: E10410003001001004 | I8: 제 4호표 전력케이블 구내 설치(P.V.C 및 고무절연외장)600V 50㎟이하 X 1C | J8: 제 4호표 전력케이블 구내 설치(P.V.C 및 고무절연외장) | K8: 600V 50㎟이하 X 1C | L8: m | P8: 12484.319 | Q8: =IF(W8="",M8*P8*$Q$3*$W$3,M8*P8*$Q$3*W8) -> 0 | V8: =SUM(O8+Q8)+S8+U8 -> 0
H9: E999999 | I9: 절연난연PVC시스케이블(F-CV, TFR-CV) | J9: F-CV케이블 | K9: 0.6/1KV 1C 70㎟ | L9: m | N9: 11233 | O9: =M9*N9 -> 0 | V9: =SUM(O9+Q9)+S9+U9 -> 0
H10: E10410003001001006 | I10: 제 6호표 전력케이블 구내 설치(P.V.C 및 고무절연외장)600V 70㎟이하 X 1C | J10: 제 6호표 전력케이블 구내 설치(P.V.C 및 고무절연외장) | K10: 600V 70㎟이하 X 1C | L10: m | P10: 16548.981 | Q10: =IF(W10="",M10*P10*$Q$3*$W$3,M10*P10*$Q$3*W10) -> 0 | V10: =SUM(O10+Q10)+S10+U10 -> 0
H11: E999999 | I11: 절연난연PVC시스케이블(F-CV, TFR-CV) | J11: F-CV케이블 | K11: 0.6/1KV 1C 95㎟ | L11: m | N11: 15486 | O11: =M11*N11 -> 0 | V11: =SUM(O11+Q11)+S11+U11 -> 0
H12: E10410003001001008 | I12: 제 8호표 전력케이블 구내 설치(P.V.C 및 고무절연외장)600V 100㎟이하 X 1C | J12: 제 8호표 전력케이블 구내 설치(P.V.C 및 고무절연외장) | K12: 600V 100㎟이하 X 1C | L12: m | P12: 20613.643 | Q12: =IF(W12="",M12*P12*$Q$3*$W$3,M12*P12*$Q$3*W12) -> 0 | V12: =SUM(O12+Q12)+S12+U12 -> 0
H13: E999999 | I13: 절연난연PVC시스케이블(F-CV, TFR-CV) | J13: F-CV케이블 | K13: 6/10KV 1C 120㎟ | L13: m | N13: 19348 | O13: =M13*N13 -> 0 | V13: =SUM(O13+Q13)+S13+U13 -> 0
H14: E10410003001001009 | I14: 제 9호표 전력케이블 구내 설치(P.V.C 및 고무절연외장)600V 125㎟이하 X 1C | J14: 제 9호표 전력케이블 구내 설치(P.V.C 및 고무절연외장) | K14: 600V 125㎟이하 X 1C | L14: m | P14: 24387.972 | Q14: =IF(W14="",M14*P14*$Q$3*$W$3,M14*P14*$Q$3*W14) -> 0 | V14: =SUM(O14+Q14)+S14+U14 -> 0
H15: E999999 | I15: 절연난연PVC시스케이블(F-CV, TFR-CV) | J15: F-CV케이블 | K15: 6/10KV 1C 150㎟ | L15: m | N15: 23518 | O15: =M15*N15 -> 0 | V15: =SUM(O15+Q15)+S15+U15 -> 0
H16: E10410003001001010 | I16: 제 10호표 전력케이블 구내 설치(P.V.C 및 고무절연외장)600V 150㎟이하 X 1C | J16: 제 10호표 전력케이블 구내 설치(P.V.C 및 고무절연외장) | K16: 600V 150㎟이하 X 1C | L16: m | P16: 28162.301 | Q16: =IF(W16="",M16*P16*$Q$3*$W$3,M16*P16*$Q$3*W16) -> 0 | V16: =SUM(O16+Q16)+S16+U16 -> 0
H17: E999999 | I17: 절연난연PVC시스케이블(F-CV, TFR-CV) | J17: F-CV케이블 | K17: 6/10KV 1C 185㎟ | L17: m | N17: 29026 | O17: =M17*N17 -> 0 | V17: =SUM(O17+Q17)+S17+U17 -> 0
H18: E10410003001001011 | I18: 제 11호표 전력케이블 구내 설치(P.V.C 및 고무절연외장)600V 185㎟이하 X 1C | J18: 제 11호표 전력케이블 구내 설치(P.V.C 및 고무절연외장) | K18: 600V 185㎟이하 X 1C | L18: m | P18: 31355.964 | Q18: =IF(W18="",M18*P18*$Q$3*$W$3,M18*P18*$Q$3*W18) -> 0 | V18: =SUM(O18+Q18)+S18+U18 -> 0
H19: E999999 | I19: 절연난연PVC시스케이블(F-CV, TFR-CV) | J19: F-CV케이블 | K19: 0.6/1KV 1C 240㎟ | L19: m | N19: 37986 | O19: =M19*N19 -> 0 | V19: =SUM(O19+Q19)+S19+U19 -> 0
H20: E10410003001001013 | I20: 제 13호표 전력케이블 구내 설치(P.V.C 및 고무절연외장)600V 240㎟이하 X 1C | J20: 제 13호표 전력케이블 구내 설치(P.V.C 및 고무절연외장) | K20: 600V 240㎟이하 X 1C | L20: m | P20: 39485.288 | Q20: =IF(W20="",M20*P20*$Q$3*$W$3,M20*P20*$Q$3*W20) -> 0 | V20: =SUM(O20+Q20)+S20+U20 -> 0
H21: E999999 | I21: 절연난연PVC시스케이블(F-CV, TFR-CV) | J21: F-CV케이블 | K21: 0.6/1KV 1C 300㎟ | L21: m | O21: =M21*N21 -> 0 | V21: =SUM(O21+Q21)+S21+U21 -> 0
H22: E10410003001001015 | I22: 제 15호표 전력케이블 구내 설치(P.V.C 및 고무절연외장)600V 300㎟이하 X 1C | J22: 제 15호표 전력케이블 구내 설치(P.V.C 및 고무절연외장) | K22: 600V 300㎟이하 X 1C | L22: m | P22: 46162.947 | Q22: =IF(W22="",M22*P22*$Q$3*$W$3,M22*P22*$Q$3*W22) -> 0 | V22: =SUM(O22+Q22)+S22+U22 -> 0
H23: E999999 | I23: 절연난연PVC시스케이블(F-CV, TFR-CV) | J23: F-CV케이블 | K23: 0.6/1KV 3C 4㎟ | L23: m | N23: 2544 | O23: =M23*N23 -> 0 | V23: =SUM(O23+Q23)+S23+U23 -> 0
H24: E10410005001011002 | I24: 제 2호표 제어용 케이블 설치(3C)4㎟ 이하 | J24: 제 2호표 제어용 케이블 설치(3C) | K24: 4㎟ 이하 | L24: m | P24: 6387.326 | Q24: =IF(W24="",M24*P24*$Q$3*$W$3,M24*P24*$Q$3*W24) -> 0 | V24: =SUM(O24+Q24)+S24+U24 -> 0
H25: E999999 | I25: 절연난연PVC시스케이블(F-CV, TFR-CV) | J25: F-CV케이블 | K25: 0.6/1KV 3C 6㎟ | L25: m | N25: 3397 | O25: =M25*N25 -> 0 | V25: =SUM(O25+Q25)+S25+U25 -> 0
H26: E10410005001011003 | I26: 제 3호표 제어용 케이블 설치(3C)6㎟ 이하 | J26: 제 3호표 제어용 케이블 설치(3C) | K26: 6㎟ 이하 | L26: m | P26: 7548.658 | Q26: =IF(W26="",M26*P26*$Q$3*$W$3,M26*P26*$Q$3*W26) -> 0 | V26: =SUM(O26+Q26)+S26+U26 -> 0
H27: E999999 | I27: 절연난연PVC시스케이블(F-CV, TFR-CV) | J27: F-CV케이블 | K27: 0.6/1KV 3C 10㎟ | L27: m | N27: 5506 | O27: =M27*N27 -> 0 | V27: =SUM(O27+Q27)+S27+U27 -> 0
H28: E10410005001011005 | I28: 제 5호표 제어용 케이블 설치(3C)10㎟ 이하 | J28: 제 5호표 제어용 케이블 설치(3C) | K28: 10㎟ 이하 | L28: m | P28: 10451.988 | Q28: =IF(W28="",M28*P28*$Q$3*$W$3,M28*P28*$Q$3*W28) -> 0 | V28: =SUM(O28+Q28)+S28+U28 -> 0
H29: E999999 | I29: 절연난연PVC시스케이블(F-CV, TFR-CV) | J29: F-CV케이블 | K29: 0.6/1KV 3C 16㎟ | L29: m | N29: 8312 | O29: =M29*N29 -> 0 | V29: =SUM(O29+Q29)+S29+U29 -> 0
H30: E10410003001001001 | I30: 제 1호표 전력케이블 구내 설치(P.V.C 및 고무절연외장)600V 16㎟이하 X 1C | J30: 제 1호표 전력케이블 구내 설치(P.V.C 및 고무절연외장) | K30: 600V 16㎟이하 X 1C | L30: m | P30: 6677.659 | Q30: =IF(W30="",M30*P30*$Q$3*$W$3,M30*P30*$Q$3*W30) -> 0 | V30: =SUM(O30+Q30)+S30+U30 -> 0 | W30: 2 | X30: 3P할증200%
H31: E999999 | I31: 절연난연PVC시스케이블(F-CV, TFR-CV) | J31: F-CV케이블 | K31: 0.6/1KV 3C 25㎟ | L31: m | N31: 12903 | O31: =M31*N31 -> 0 | V31: =SUM(O31+Q31)+S31+U31 -> 0
H32: E10410003001001002 | I32: 제 2호표 전력케이블 구내 설치(P.V.C 및 고무절연외장)600V 25㎟이하 X 1C | J32: 제 2호표 전력케이블 구내 설치(P.V.C 및 고무절연외장) | K32: 600V 25㎟이하 X 1C | L32: m | P32: 8709.99 | Q32: =IF(W32="",M32*P32*$Q$3*$W$3,M32*P32*$Q$3*W32) -> 0 | V32: =SUM(O32+Q32)+S32+U32 -> 0 | W32: 2 | X32: 3P할증200%
H33: E999999 | I33: 절연난연PVC시스케이블(F-CV, TFR-CV) | J33: F-CV케이블 | K33: 0.6/1KV 3C 35㎟ | L33: m | N33: 17802 | O33: =M33*N33 -> 0 | V33: =SUM(O33+Q33)+S33+U33 -> 0
H34: E10410003001001003 | I34: 제 3호표 전력케이블 구내 설치(P.V.C 및 고무절연외장)600V 38㎟이하 X 1C | J34: 제 3호표 전력케이블 구내 설치(P.V.C 및 고무절연외장) | K34: 600V 38㎟이하 X 1C | L34: m | P34: 10451.988 | Q34: =IF(W34="",M34*P34*$Q$3*$W$3,M34*P34*$Q$3*W34) -> 0 | V34: =SUM(O34+Q34)+S34+U34 -> 0 | W34: 2 | X34: 3P할증200%
H35: E999999 | I35: 절연난연PVC시스케이블(F-CV, TFR-CV) | J35: F-CV케이블 | K35: 0.6/1KV 4C 2.5㎟ | L35: m | N35: 2284 | O35: =M35*N35 -> 0 | V35: =SUM(O35+Q35)+S35+U35 -> 0
H36: E10410005001012001 | I36: 제 1호표 제어용 케이블 설치(4C)2.5㎟ 이하 | J36: 제 1호표 제어용 케이블 설치(4C) | K36: 2.5㎟ 이하 | L36: m | P36: 7548.658 | Q36: =IF(W36="",M36*P36*$Q$3*$W$3,M36*P36*$Q$3*W36) -> 0 | V36: =SUM(O36+Q36)+S36+U36 -> 0
H37: E999999 | I37: 절연난연PVC시스케이블(F-CV, TFR-CV) | J37: F-CV케이블 | K37: 0.6/1KV 4C 4㎟ | L37: m | N37: 3280 | O37: =M37*N37 -> 0 | V37: =SUM(O37+Q37)+S37+U37 -> 0
H38: E10410005001012002 | I38: 제 2호표 제어용 케이블 설치(4C)4㎟ 이하 | J38: 제 2호표 제어용 케이블 설치(4C) | K38: 4㎟ 이하 | L38: m | P38: 8419.657 | Q38: =IF(W38="",M38*P38*$Q$3*$W$3,M38*P38*$Q$3*W38) -> 0 | V38: =SUM(O38+Q38)+S38+U38 -> 0
H39: E999999 | I39: 절연난연PVC시스케이블(F-CV, TFR-CV) | J39: F-CV케이블 | K39: 0.6/1KV 4C 6㎟ | L39: m | N39: 4511 | O39: =M39*N39 -> 0 | V39: =SUM(O39+Q39)+S39+U39 -> 0
H40: E10410005001012003 | I40: 제 3호표 제어용 케이블 설치(4C)6㎟ 이하 | J40: 제 3호표 제어용 케이블 설치(4C) | K40: 6㎟ 이하 | L40: m | P40: 9871.322 | Q40: =IF(W40="",M40*P40*$Q$3*$W$3,M40*P40*$Q$3*W40) -> 0 | V40: =SUM(O40+Q40)+S40+U40 -> 0
H41: E999999 | I41: 절연난연PVC시스케이블(F-CV, TFR-CV) | J41: F-CV케이블 | K41: 0.6/1KV 4C 10㎟ | L41: m | N41: 7317 | O41: =M41*N41 -> 0 | V41: =SUM(O41+Q41)+S41+U41 -> 0
H42: E10410005001012005 | I42: 제 5호표 제어용 케이블 설치(4C)10㎟ 이하 | J42: 제 5호표 제어용 케이블 설치(4C) | K42: 10㎟ 이하 | L42: m | P42: 14226.317 | Q42: =IF(W42="",M42*P42*$Q$3*$W$3,M42*P42*$Q$3*W42) -> 0 | V42: =SUM(O42+Q42)+S42+U42 -> 0
...

Sheet 주요물량산출서
A1: 주요 물량 산출서
A3: 공사명: | B3: =갑지!B7 -> 사택 조명 교체
A4: 품명 | B4: 규격 | C4: 단위 | D4: 수량 | E4: 산출근거 | F4: 내역도면번호 | G4: 비고
A5: F-CV케이블 | B5: 0.6/1KV 3C 4㎟ | C5: M | D5: 60 | E5: 높이5+길이20+높이5=30*2=60

Sheet 공사수립계획서
B1: 공사수립계획서
B4: 업 체 명 | C4: 대양이엔씨 | D4: 일 시 | E4: =갑지!B9 -> 2025년 01월 일
B5: 공 사 명 | C5: =갑지!B7 -> 사택 조명 교체
B6: 공사 업체 | C6: ■ 공사기간 : 입찰시스템 계약기간에 준함
C7: ■ 인원투입계획 : 총 3명(주말 : 명)
C8: ■ 시공방법
C12: LED조명 교체
C20: ■ 위험작업 유무 : 고소작업.전기작업
C21: ■ 안전확보 방안 :
C22: -. 고소작업시 2인1조 작업
C23: -. 천정작업시 안전로프 설치
C24: -. 분전반 결선시 위험표지판 설치 및 차단기 락 설치
C25: ■ 주요 사용물질 :
B29: 대양이엔씨 | C29: 성명 : 홍정운 | D29: (인감/서명)
B30: ㈜ S&I Corp. | C30: 성명 : | D30: 서명

Sheet 내역서업로드
G2: ▼낙찰율 | I2: ▼낙찰율 | K2: ▼낙찰율 | M2: ▼낙찰율
B3: ="공사명"&" "&":"&" "&갑지!B7 -> 공사명 : 사택 조명 교체 | G3: % | I3: % | K3: 0.86 | M3: 0.8
A4: 표준 Code | B4: 주요내역 | D4: 단위 | E4: 수량 | F4: 재료비 | H4: 노무비 | J4: 기계경비 | L4: 기타경비(부자재비) | N4: 합계 | O4: 비고
B5: 품목 | C5: 규격 | F5: 단가 | G5: 금액 | H5: 단가 | I5: 금액 | J5: 단가 | K5: 금액 | L5: 단가 | M5: 금액 | O5: 할증율(%) | P5: 기준
A6: M045573819460101 | B6: LED 실내조명등기구 | C6: HB-DL6IN15DO, LED 6인치 다운라이트, 15W | D6: 개 | E6: 6 | J6: 295464.15
A7: E00000807041850405 | B7: LED 등기구설치 (매입 및 반매입) | C7: 55W이하 | D7: (등당) | E7: 6 | J7: 131653
A8: M045573819390101 | B8: LED 실내조명등기구 | C8: HB-PE66050ES, LED 면조명, 50W | D8: 개 | E8: 5 | J8: 1909218
A9: E00000807041850105 | B9: LED 등기구설치 (직부등) | C9: 55W이하 | D9: (등당) | E9: 5 | J9: -1044.4
A10: M045573819330101 | B10: LED 실내조명등기구 | C10: HB-PE63025ES, LED 면조명, 25W | D10: 개 | E10: 1 | J10: -178344
A11: E00000807041850105 | B11: LED 등기구설치 (직부등) | C11: 55W이하 | D11: (등당) | E11: 1 | J11: 276580
J12: 2631262.8
J13: 2917000
J14: 20750
J15: 175081
J16: 153960
J17: 142201
J18: 285813
J19: 218105
G99: =SUM(G6:G98) -> 0 | I99: =SUM(I6:I98) -> 0 | K99: =SUM(K6:K98) -> 0 | M99: =SUM(M6:M98) -> 0

Sheet Upload
A1: 구분 | B1: 표준단가 | C1: 표준품셈 | D1: 물가정보 | E1: 노임단가 | F1: 수량
A2: ='Upload(참조) (2)'!Q2 | B2: ='Upload(참조) (2)'!R2 | C2: ='Upload(참조) (2)'!S2 | D2: ='Upload(참조) (2)'!T2 | E2: ='Upload(참조) (2)'!U2 | F2: ='Upload(참조) (2)'!V2 -> 0
A3: ='Upload(참조) (2)'!Q4 -> M045573819460101 | B3: ='Upload(참조) (2)'!R4 | C3: ='Upload(참조) (2)'!S4 | D3: ='Upload(참조) (2)'!T4 -> M045573819460101 | E3: ='Upload(참조) (2)'!U4 | F3: ='Upload(참조) (2)'!V4 -> 6
A4: ='Upload(참조) (2)'!Q5 -> E00000807041850405 | B4: ='Upload(참조) (2)'!R5 | C4: ='Upload(참조) (2)'!S5 -> E00000807041850405 | D4: ='Upload(참조) (2)'!T5 | E4: ='Upload(참조) (2)'!U5 | F4: ='Upload(참조) (2)'!V5 -> 6
A5: ='Upload(참조) (2)'!Q6 -> M045573819390101 | B5: ='Upload(참조) (2)'!R6 | C5: ='Upload(참조) (2)'!S6 | D5: ='Upload(참조) (2)'!T6 -> M045573819390101 | E5: ='Upload(참조) (2)'!U6 | F5: ='Upload(참조) (2)'!V6 -> 5
A6: ='Upload(참조) (2)'!Q7 -> E00000807041850105 | B6: ='Upload(참조) (2)'!R7 | C6: ='Upload(참조) (2)'!S7 -> E00000807041850105 | D6: ='Upload(참조) (2)'!T7 | E6: ='Upload(참조) (2)'!U7 | F6: ='Upload(참조) (2)'!V7 -> 5
A7: ='Upload(참조) (2)'!Q8 -> M045573819330101 | B7: ='Upload(참조) (2)'!R8 | C7: ='Upload(참조) (2)'!S8 | D7: ='Upload(참조) (2)'!T8 -> M045573819330101 | E7: ='Upload(참조) (2)'!U8 | F7: ='Upload(참조) (2)'!V8 -> 1
A8: ='Upload(참조) (2)'!Q9 -> E00000807041850105 | B8: ='Upload(참조) (2)'!R9 | C8: ='Upload(참조) (2)'!S9 -> E00000807041850105 | D8: ='Upload(참조) (2)'!T9 | E8: ='Upload(참조) (2)'!U9 | F8: ='Upload(참조) (2)'!V9 -> 1
A9: ='Upload(참조) (2)'!Q11 | B9: ='Upload(참조) (2)'!R11 | C9: ='Upload(참조) (2)'!S11 | D9: ='Upload(참조) (2)'!T11 | E9: ='Upload(참조) (2)'!U11 | F9: ='Upload(참조) (2)'!V11 -> 0
A10: ='Upload(참조) (2)'!Q12 | B10: ='Upload(참조) (2)'!R12 | C10: ='Upload(참조) (2)'!S12 | D10: ='Upload(참조) (2)'!T12 | E10: ='Upload(참조) (2)'!U12 | F10: ='Upload(참조) (2)'!V12 -> 0
A11: ='Upload(참조) (2)'!Q13 | B11: ='Upload(참조) (2)'!R13 | C11: ='Upload(참조) (2)'!S13 | D11: ='Upload(참조) (2)'!T13 | E11: ='Upload(참조) (2)'!U13 | F11: ='Upload(참조) (2)'!V13 -> 0
A12: ='Upload(참조) (2)'!Q14 | B12: ='Upload(참조) (2)'!R14 | C12: ='Upload(참조) (2)'!S14 | D12: ='Upload(참조) (2)'!T14 | E12: ='Upload(참조) (2)'!U14 | F12: ='Upload(참조) (2)'!V14 -> 0
A13: ='Upload(참조) (2)'!Q15 | B13: ='Upload(참조) (2)'!R15 | C13: ='Upload(참조) (2)'!S15 | D13: ='Upload(참조) (2)'!T15 | E13: ='Upload(참조) (2)'!U15 | F13: ='Upload(참조) (2)'!V15 -> 0
A14: ='Upload(참조) (2)'!Q16 | B14: ='Upload(참조) (2)'!R16 | C14: ='Upload(참조) (2)'!S16 | D14: ='Upload(참조) (2)'!T16 | E14: ='Upload(참조) (2)'!U16 | F14: ='Upload(참조) (2)'!V16 -> 0
A15: ='Upload(참조) (2)'!Q17 | B15: ='Upload(참조) (2)'!R17 | C15: ='Upload(참조) (2)'!S17 | D15: ='Upload(참조) (2)'!T17 | E15: ='Upload(참조) (2)'!U17 | F15: ='Upload(참조) (2)'!V17 -> 0
A16: ='Upload(참조) (2)'!Q18 | B16: ='Upload(참조) (2)'!R18 | C16: ='Upload(참조) (2)'!S18 | D16: ='Upload(참조) (2)'!T18 | E16: ='Upload(참조) (2)'!U18 | F16: ='Upload(참조) (2)'!V18 -> 0
A17: ='Upload(참조) (2)'!Q19 | B17: ='Upload(참조) (2)'!R19 | C17: ='Upload(참조) (2)'!S19 | D17: ='Upload(참조) (2)'!T19 | E17: ='Upload(참조) (2)'!U19 | F17: ='Upload(참조) (2)'!V19 -> 0
A18: ='Upload(참조) (2)'!Q20 | B18: ='Upload(참조) (2)'!R20 | C18: ='Upload(참조) (2)'!S20 | D18: ='Upload(참조) (2)'!T20 | E18: ='Upload(참조) (2)'!U20 | F18: ='Upload(참조) (2)'!V20 -> 0
A19: ='Upload(참조) (2)'!Q21 | B19: ='Upload(참조) (2)'!R21 | C19: ='Upload(참조) (2)'!S21 | D19: ='Upload(참조) (2)'!T21 | E19: ='Upload(참조) (2)'!U21 | F19: ='Upload(참조) (2)'!V21 -> 0
A20: ='Upload(참조) (2)'!Q22 | B20: ='Upload(참조) (2)'!R22 | C20: ='Upload(참조) (2)'!S22 | D20: ='Upload(참조) (2)'!T22 | E20: ='Upload(참조) (2)'!U22 | F20: ='Upload(참조) (2)'!V22 -> 0
... A85: ='Upload(참조) (2)'!Q87 | B85: ='Upload(참조) (2)'!R87 | C85: ='Upload(참조) (2)'!S87 | D85: ='Upload(참조) (2)'!T87 | E85: ='Upload(참조) (2)'!U87 | F85: ='Upload(참조) (2)'!V87 -> 0

Sheet 할증기준
A1: ■ atG 할증기준

Sheet Upload(참조) (2)
A1: 구분 | B1: 표준단가 | C1: 표준품셈 | D1: 물가정보 | E1: 노임단가 | F1: 수량 | I1: 예가내역서 코드 | J1: 코드구분 | L1: 표준단가 | M1: 표준품셈 | N1: 물가정보 | O1: 노임단가 | Q1: 최종구분 | R1: 표준단가 | S1: 표준품셈 | T1: 물가정보 | U1: 노임단가 | V1: 수량 | W1: 표준단가 | X1: 표준품셈 | Y1: *(공란) | Z1: ><(텍스트) | AA1: <>(수식모두)
F2: 2 | G2: 표준단가 품목 | H2: 노무비 | I2: =IF(내역서업로드!A5<>"",내역서업로드!A5,"") | J2: =LEFT(I2,1) | L2: =IF(OR(J2="E",J2="L",J2="M"),"",I2) | M2: =IF(OR(J2="D",J2="L",J2="M"),"",I2) | N2: =IF(OR(J2="D",J2="E",J2="L"),"",I2) | O2: =IF(OR(J2="D",J2="E",J2="M"),"",I2) | Q2: =IF(Z2=0,"",IF(Z2=1,R2&S2&T2&U2,"E99999")) | R2: =IF(L2="","",L2) | S2: =IF(M2="","",M2) | T2: =IF(W2=1,"",N2) | U2: =IF(OR(W2=1,X2=1),"",O2) | V2: =내역서업로드!E5 -> 0 | W2: =COUNTIFS(R2,"><") -> 0 | X2: =COUNTIFS(S2,"><") -> 0 | Y2: =COUNTIFS(R2:U2,"*") -> 4 | Z2: =COUNTIFS(R2:U2,"><") -> 0 | AA2: =COUNTIFS(R2:U2,"<>") -> 4
F3: 3 | G3: 표준품셈+물가정보 품목 | H3: 자재비 | I3: =IF(내역서업로드!#REF!<>"",내역서업로드!#REF!,"") -> #REF! | J3: =LEFT(I3,1) -> #REF! | L3: =IF(OR(J3="E",J3="L",J3="M"),"",I3) -> #REF! | M3: =IF(OR(J3="D",J3="L",J3="M"),"",I3) -> #REF! | N3: =IF(OR(J3="D",J3="E",J3="L"),"",I3) -> #REF! | O3: =IF(OR(J3="D",J3="E",J3="M"),"",I3) -> #REF! | Q3: =IF(Z3=0,"",IF(Z3=1,R3&S3&T3&U3,"E99999")) | R3: =IF(L3="","",L3) -> #REF! | S3: =IF(M3="","",M3) -> #REF! | T3: =IF(W3=1,"",N3) -> #REF! | U3: =IF(OR(W3=1,X3=1),"",O3) -> #REF! | V3: =내역서업로드!#REF! -> #REF! | W3: =COUNTIFS(R3,"><") -> 0 | X3: =COUNTIFS(S3,"><") -> 0 | Y3: =COUNTIFS(R3:U3,"*") -> 0 | Z3: =COUNTIFS(R3:U3,"><") -> 0 | AA3: =COUNTIFS(R3:U3,"<>") -> 4
F4: 4 | G4: 표준품셈만 있을떄 | H4: 표준단가 | I4: =IF(내역서업로드!A6<>"",내역서업로드!A6,"") -> M045573819460101 | J4: =LEFT(I4,1) -> M | L4: =IF(OR(J4="E",J4="L",J4="M"),"",I4) | M4: =IF(OR(J4="D",J4="L",J4="M"),"",I4) | N4: =IF(OR(J4="D",J4="E",J4="L"),"",I4) -> M045573819460101 | O4: =IF(OR(J4="D",J4="E",J4="M"),"",I4) | Q4: =IF(Z4=0,"",IF(Z4=1,R4&S4&T4&U4,"E99999")) -> M045573819460101 | R4: =IF(L4="","",L4) | S4: =IF(M4="","",M4) | T4: =IF(W4=1,"",N4) -> M045573819460101 | U4: =IF(OR(W4=1,X4=1),"",O4) | V4: =내역서업로드!E6 -> 6 | W4: =COUNTIFS(R4,"><") -> 0 | X4: =COUNTIFS(S4,"><") -> 0 | Y4: =COUNTIFS(R4:U4,"*") -> 4 | Z4: =COUNTIFS(R4:U4,"><") -> 1 | AA4: =COUNTIFS(R4:U4,"<>") -> 4
F5: 5 | G5: 물가정보만 있을때 | H5: 표준품셈 | I5: =IF(내역서업로드!A7<>"",내역서업로드!A7,"") -> E00000807041850405 | J5: =LEFT(I5,1) -> E | L5: =IF(OR(J5="E",J5="L",J5="M"),"",I5) | M5: =IF(OR(J5="D",J5="L",J5="M"),"",I5) -> E00000807041850405 | N5: =IF(OR(J5="D",J5="E",J5="L"),"",I5) | O5: =IF(OR(J5="D",J5="E",J5="M"),"",I5) | Q5: =IF(Z5=0,"",IF(Z5=1,R5&S5&T5&U5,"E99999")) -> E00000807041850405 | R5: =IF(L5="","",L5) | S5: =IF(M5="","",M5) -> E00000807041850405 | T5: =IF(W5=1,"",N5) | U5: =IF(OR(W5=1,X5=1),"",O5) | V5: =내역서업로드!E7 -> 6 | W5: =COUNTIFS(R5,"><") -> 0 | X5: =COUNTIFS(S5,"><") -> 1 | Y5: =COUNTIFS(R5:U5,"*") -> 4 | Z5: =COUNTIFS(R5:U5,"><") -> 1 | AA5: =COUNTIFS(R5:U5,"<>") -> 4
F6: 6 | G6: 노임단가만 있을떄 | I6: =IF(내역서업로드!A8<>"",내역서업로드!A8,"") -> M045573819390101 | J6: =LEFT(I6,1) -> M | L6: =IF(OR(J6="E",J6="L",J6="M"),"",I6) | M6: =IF(OR(J6="D",J6="L",J6="M"),"",I6) | N6: =IF(OR(J6="D",J6="E",J6="L"),"",I6) -> M045573819390101 | O6: =IF(OR(J6="D",J6="E",J6="M"),"",I6) | Q6: =IF(Z6=0,"",IF(Z6=1,R6&S6&T6&U6,"E99999")) -> M045573819390101 | R6: =IF(L6="","",L6) | S6: =IF(M6="","",M6) | T6: =IF(W6=1,"",N6) -> M045573819390101 | U6: =IF(OR(W6=1,X6=1),"",O6) | V6: =내역서업로드!E8 -> 5 | W6: =COUNTIFS(R6,"><") -> 0 | X6: =COUNTIFS(S6,"><") -> 0 | Y6: =COUNTIFS(R6:U6,"*") -> 4 | Z6: =COUNTIFS(R6:U6,"><") -> 1 | AA6: =COUNTIFS(R6:U6,"<>") -> 4
I7: =IF(내역서업로드!A9<>"",내역서업로드!A9,"") -> E00000807041850105 | J7: =LEFT(I7,1) -> E | L7: =IF(OR(J7="E",J7="L",J7="M"),"",I7) | M7: =IF(OR(J7="D",J7="L",J7="M"),"",I7) -> E00000807041850105 | N7: =IF(OR(J7="D",J7="E",J7="L"),"",I7) | O7: =IF(OR(J7="D",J7="E",J7="M"),"",I7) | Q7: =IF(Z7=0,"",IF(Z7=1,R7&S7&T7&U7,"E99999")) -> E00000807041850105 | R7: =IF(L7="","",L7) | S7: =IF(M7="","",M7) -> E00000807041850105 | T7: =IF(W7=1,"",N7) | U7: =IF(OR(W7=1,X7=1),"",O7) | V7: =내역서업로드!E9 -> 5 | W7: =COUNTIFS(R7,"><") -> 0 | X7: =COUNTIFS(S7,"><") -> 1 | Y7: =COUNTIFS(R7:U7,"*") -> 4 | Z7: =COUNTIFS(R7:U7,"><") -> 1 | AA7: =COUNTIFS(R7:U7,"<>") -> 4
G8: 표준단가 D | I8: =IF(내역서업로드!A10<>"",내역서업로드!A10,"") -> M045573819330101 | J8: =LEFT(I8,1) -> M | L8: =IF(OR(J8="E",J8="L",J8="M"),"",I8) | M8: =IF(OR(J8="D",J8="L",J8="M"),"",I8) | N8: =IF(OR(J8="D",J8="E",J8="L"),"",I8) -> M045573819330101 | O8: =IF(OR(J8="D",J8="E",J8="M"),"",I8) | Q8: =IF(Z8=0,"",IF(Z8=1,R8&S8&T8&U8,"E99999")) -> M045573819330101 | R8: =IF(L8="","",L8) | S8: =IF(M8="","",M8) | T8: =IF(W8=1,"",N8) -> M045573819330101 | U8: =IF(OR(W8=1,X8=1),"",O8) | V8: =내역서업로드!E10 -> 1 | W8: =COUNTIFS(R8,"><") -> 0 | X8: =COUNTIFS(S8,"><") -> 0 | Y8: =COUNTIFS(R8:U8,"*") -> 4 | Z8: =COUNTIFS(R8:U8,"><") -> 1 | AA8: =COUNTIFS(R8:U8,"<>") -> 4
I9: =IF(내역서업로드!A11<>"",내역서업로드!A11,"") -> E00000807041850105 | J9: =LEFT(I9,1) -> E | L9: =IF(OR(J9="E",J9="L",J9="M"),"",I9) | M9: =IF(OR(J9="D",J9="L",J9="M"),"",I9) -> E00000807041850105 | N9: =IF(OR(J9="D",J9="E",J9="L"),"",I9) | O9: =IF(OR(J9="D",J9="E",J9="M"),"",I9) | Q9: =IF(Z9=0,"",IF(Z9=1,R9&S9&T9&U9,"E99999")) -> E00000807041850105 | R9: =IF(L9="","",L9) | S9: =IF(M9="","",M9) -> E00000807041850105 | T9: =IF(W9=1,"",N9) | U9: =IF(OR(W9=1,X9=1),"",O9) | V9: =내역서업로드!E11 -> 1 | W9: =COUNTIFS(R9,"><") -> 0 | X9: =COUNTIFS(S9,"><") -> 1 | Y9: =COUNTIFS(R9:U9,"*") -> 4 | Z9: =COUNTIFS(R9:U9,"><") -> 1 | AA9: =COUNTIFS(R9:U9,"<>") -> 4
I10: =IF(내역서업로드!#REF!<>"",내역서업로드!#REF!,"") -> #REF! | J10: =LEFT(I10,1) -> #REF! | L10: =IF(OR(J10="E",J10="L",J10="M"),"",I10) -> #REF! | M10: =IF(OR(J10="D",J10="L",J10="M"),"",I10) -> #REF! | N10: =IF(OR(J10="D",J10="E",J10="L"),"",I10) -> #REF! | O10: =IF(OR(J10="D",J10="E",J10="M"),"",I10) -> #REF! | Q10: =IF(Z10=0,"",IF(Z10=1,R10&S10&T10&U10,"E99999")) | R10: =IF(L10="","",L10) -> #REF! | S10: =IF(M10="","",M10) -> #REF! | T10: =IF(W10=1,"",N10) -> #REF! | U10: =IF(OR(W10=1,X10=1),"",O10) -> #REF! | V10: =내역서업로드!#REF! -> #REF! | W10: =COUNTIFS(R10,"><") -> 0 | X10: =COUNTIFS(S10,"><") -> 0 | Y10: =COUNTIFS(R10:U10,"*") -> 0 | Z10: =COUNTIFS(R10:U10,"><") -> 0 | AA10: =COUNTIFS(R10:U10,"<>") -> 4
I11: =IF(내역서업로드!A12<>"",내역서업로드!A12,"") | J11: =LEFT(I11,1) | L11: =IF(OR(J11="E",J11="L",J11="M"),"",I11) | M11: =IF(OR(J11="D",J11="L",J11="M"),"",I11) | N11: =IF(OR(J11="D",J11="E",J11="L"),"",I11) | O11: =IF(OR(J11="D",J11="E",J11="M"),"",I11) | Q11: =IF(Z11=0,"",IF(Z11=1,R11&S11&T11&U11,"E99999")) | R11: =IF(L11="","",L11) | S11: =IF(M11="","",M11) | T11: =IF(W11=1,"",N11) | U11: =IF(OR(W11=1,X11=1),"",O11) | V11: =내역서업로드!E12 -> 0 | W11: =COUNTIFS(R11,"><") -> 0 | X11: =COUNTIFS(S11,"><") -> 0 | Y11: =COUNTIFS(R11:U11,"*") -> 4 | Z11: =COUNTIFS(R11:U11,"><") -> 0 | AA11: =COUNTIFS(R11:U11,"<>") -> 4
I12: =IF(내역서업로드!A13<>"",내역서업로드!A13,"") | J12: =LEFT(I12,1) | L12: =IF(OR(J12="E",J12="L",J12="M"),"",I12) | M12: =IF(OR(J12="D",J12="L",J12="M"),"",I12) | N12: =IF(OR(J12="D",J12="E",J12="L"),"",I12) | O12: =IF(OR(J12="D",J12="E",J12="M"),"",I12) | Q12: =IF(Z12=0,"",IF(Z12=1,R12&S12&T12&U12,"E99999")) | R12: =IF(L12="","",L12) | S12: =IF(M12="","",M12) | T12: =IF(W12=1,"",N12) | U12: =IF(OR(W12=1,X12=1),"",O12) | V12: =내역서업로드!E13 -> 0 | W12: =COUNTIFS(R12,"><") -> 0 | X12: =COUNTIFS(S12,"><") -> 0 | Y12: =COUNTIFS(R12:U12,"*") -> 4 | Z12: =COUNTIFS(R12:U12,"><") -> 0 | AA12: =COUNTIFS(R12:U12,"<>") -> 4
I13: =IF(내역서업로드!A14<>"",내역서업로드!A14,"") | J13: =LEFT(I13,1) | L13: =IF(OR(J13="E",J13="L",J13="M"),"",I13) | M13: =IF(OR(J13="D",J13="L",J13="M"),"",I13) | N13: =IF(OR(J13="D",J13="E",J13="L"),"",I13) | O13: =IF(OR(J13="D",J13="E",J13="M"),"",I13) | Q13: =IF(Z13=0,"",IF(Z13=1,R13&S13&T13&U13,"E99999")) | R13: =IF(L13="","",L13) | S13: =IF(M13="","",M13) | T13: =IF(W13=1,"",N13) | U13: =IF(OR(W13=1,X13=1),"",O13) | V13: =내역서업로드!E14 -> 0 | W13: =COUNTIFS(R13,"><") -> 0 | X13: =COUNTIFS(S13,"><") -> 0 | Y13: =COUNTIFS(R13:U13,"*") -> 4 | Z13: =COUNTIFS(R13:U13,"><") -> 0 | AA13: =COUNTIFS(R13:U13,"<>") -> 4
I14: =IF(내역서업로드!A15<>"",내역서업로드!A15,"") | J14: =LEFT(I14,1) | L14: =IF(OR(J14="E",J14="L",J14="M"),"",I14) | M14: =IF(OR(J14="D",J14="L",J14="M"),"",I14) | N14: =IF(OR(J14="D",J14="E",J14="L"),"",I14) | O14: =IF(OR(J14="D",J14="E",J14="M"),"",I14) | Q14: =IF(Z14=0,"",IF(Z14=1,R14&S14&T14&U14,"E99999")) | R14: =IF(L14="","",L14) | S14: =IF(M14="","",M14) | T14: =IF(W14=1,"",N14) | U14: =IF(OR(W14=1,X14=1),"",O14) | V14: =내역서업로드!E15 -> 0 | W14: =COUNTIFS(R14,"><") -> 0 | X14: =COUNTIFS(S14,"><") -> 0 | Y14: =COUNTIFS(R14:U14,"*") -> 4 | Z14: =COUNTIFS(R14:U14,"><") -> 0 | AA14: =COUNTIFS(R14:U14,"<>") -> 4
I15: =IF(내역서업로드!A16<>"",내역서업로드!A16,"") | J15: =LEFT(I15,1) | L15: =IF(OR(J15="E",J15="L",J15="M"),"",I15) | M15: =IF(OR(J15="D",J15="L",J15="M"),"",I15) | N15: =IF(OR(J15="D",J15="E",J15="L"),"",I15) | O15: =IF(OR(J15="D",J15="E",J15="M"),"",I15) | Q15: =IF(Z15=0,"",IF(Z15=1,R15&S15&T15&U15,"E99999")) | R15: =IF(L15="","",L15) | S15: =IF(M15="","",M15) | T15: =IF(W15=1,"",N15) | U15: =IF(OR(W15=1,X15=1),"",O15) | V15: =내역서업로드!E16 -> 0 | W15: =COUNTIFS(R15,"><") -> 0 | X15: =COUNTIFS(S15,"><") -> 0 | Y15: =COUNTIFS(R15:U15,"*") -> 4 | Z15: =COUNTIFS(R15:U15,"><") -> 0 | AA15: =COUNTIFS(R15:U15,"<>") -> 4
I16: =IF(내역서업로드!A17<>"",내역서업로드!A17,"") | J16: =LEFT(I16,1) | L16: =IF(OR(J16="E",J16="L",J16="M"),"",I16) | M16: =IF(OR(J16="D",J16="L",J16="M"),"",I16) | N16: =IF(OR(J16="D",J16="E",J16="L"),"",I16) | O16: =IF(OR(J16="D",J16="E",J16="M"),"",I16) | Q16: =IF(Z16=0,"",IF(Z16=1,R16&S16&T16&U16,"E99999")) | R16: =IF(L16="","",L16) | S16: =IF(M16="","",M16) | T16: =IF(W16=1,"",N16) | U16: =IF(OR(W16=1,X16=1),"",O16) | V16: =내역서업로드!E17 -> 0 | W16: =COUNTIFS(R16,"><") -> 0 | X16: =COUNTIFS(S16,"><") -> 0 | Y16: =COUNTIFS(R16:U16,"*") -> 4 | Z16: =COUNTIFS(R16:U16,"><") -> 0 | AA16: =COUNTIFS(R16:U16,"<>") -> 4
I17: =IF(내역서업로드!A18<>"",내역서업로드!A18,"") | J17: =LEFT(I17,1) | L17: =IF(OR(J17="E",J17="L",J17="M"),"",I17) | M17: =IF(OR(J17="D",J17="L",J17="M"),"",I17) | N17: =IF(OR(J17="D",J17="E",J17="L"),"",I17) | O17: =IF(OR(J17="D",J17="E",J17="M"),"",I17) | Q17: =IF(Z17=0,"",IF(Z17=1,R17&S17&T17&U17,"E99999")) | R17: =IF(L17="","",L17) | S17: =IF(M17="","",M17) | T17: =IF(W17=1,"",N17) | U17: =IF(OR(W17=1,X17=1),"",O17) | V17: =내역서업로드!E18 -> 0 | W17: =COUNTIFS(R17,"><") -> 0 | X17: =COUNTIFS(S17,"><") -> 0 | Y17: =COUNTIFS(R17:U17,"*") -> 4 | Z17: =COUNTIFS(R17:U17,"><") -> 0 | AA17: =COUNTIFS(R17:U17,"<>") -> 4
I18: =IF(내역서업로드!A19<>"",내역서업로드!A19,"") | J18: =LEFT(I18,1) | L18: =IF(OR(J18="E",J18="L",J18="M"),"",I18) | M18: =IF(OR(J18="D",J18="L",J18="M"),"",I18) | N18: =IF(OR(J18="D",J18="E",J18="L"),"",I18) | O18: =IF(OR(J18="D",J18="E",J18="M"),"",I18) | Q18: =IF(Z18=0,"",IF(Z18=1,R18&S18&T18&U18,"E99999")) | R18: =IF(L18="","",L18) | S18: =IF(M18="","",M18) | T18: =IF(W18=1,"",N18) | U18: =IF(OR(W18=1,X18=1),"",O18) | V18: =내역서업로드!E19 -> 0 | W18: =COUNTIFS(R18,"><") -> 0 | X18: =COUNTIFS(S18,"><") -> 0 | Y18: =COUNTIFS(R18:U18,"*") -> 4 | Z18: =COUNTIFS(R18:U18,"><") -> 0 | AA18: =COUNTIFS(R18:U18,"<>") -> 4
I19: =IF(내역서업로드!A20<>"",내역서업로드!A20,"") | J19: =LEFT(I19,1) | L19: =IF(OR(J19="E",J19="L",J19="M"),"",I19) | M19: =IF(OR(J19="D",J19="L",J19="M"),"",I19) | N19: =IF(OR(J19="D",J19="E",J19="L"),"",I19) | O19: =IF(OR(J19="D",J19="E",J19="M"),"",I19) | Q19: =IF(Z19=0,"",IF(Z19=1,R19&S19&T19&U19,"E99999")) | R19: =IF(L19="","",L19) | S19: =IF(M19="","",M19) | T19: =IF(W19=1,"",N19) | U19: =IF(OR(W19=1,X19=1),"",O19) | V19: =내역서업로드!E20 -> 0 | W19: =COUNTIFS(R19,"><") -> 0 | X19: =COUNTIFS(S19,"><") -> 0 | Y19: =COUNTIFS(R19:U19,"*") -> 4 | Z19: =COUNTIFS(R19:U19,"><") -> 0 | AA19: =COUNTIFS(R19:U19,"<>") -> 4
I20: =IF(내역서업로드!A21<>"",내역서업로드!A21,"") | J20: =LEFT(I20,1) | L20: =IF(OR(J20="E",J20="L",J20="M"),"",I20) | M20: =IF(OR(J20="D",J20="L",J20="M"),"",I20) | N20: =IF(OR(J20="D",J20="E",J20="L"),"",I20) | O20: =IF(OR(J20="D",J20="E",J20="M"),"",I20) | Q20: =IF(Z20=0,"",IF(Z20=1,R20&S20&T20&U20,"E99999")) | R20: =IF(L20="","",L20) | S20: =IF(M20="","",M20) | T20: =IF(W20=1,"",N20) | U20: =IF(OR(W20=1,X20=1),"",O20) | V20: =내역서업로드!E21 -> 0 | W20: =COUNTIFS(R20,"><") -> 0 | X20: =COUNTIFS(S20,"><") -> 0 | Y20: =COUNTIFS(R20:U20,"*") -> 4 | Z20: =COUNTIFS(R20:U20,"><") -> 0 | AA20: =COUNTIFS(R20:U20,"<>") -> 4
I21: =IF(내역서업로드!A22<>"",내역서업로드!A22,"") | J21: =LEFT(I21,1) | L21: =IF(OR(J21="E",J21="L",J21="M"),"",I21) | M21: =IF(OR(J21="D",J21="L",J21="M"),"",I21) | N21: =IF(OR(J21="D",J21="E",J21="L"),"",I21) | O21: =IF(OR(J21="D",J21="E",J21="M"),"",I21) | Q21: =IF(Z21=0,"",IF(Z21=1,R21&S21&T21&U21,"E99999")) | R21: =IF(L21="","",L21) | S21: =IF(M21="","",M21) | T21: =IF(W21=1,"",N21) | U21: =IF(OR(W21=1,X21=1),"",O21) | V21: =내역서업로드!E22 -> 0 | W21: =COUNTIFS(R21,"><") -> 0 | X21: =COUNTIFS(S21,"><") -> 0 | Y21: =COUNTIFS(R21:U21,"*") -> 4 | Z21: =COUNTIFS(R21:U21,"><") -> 0 | AA21: =COUNTIFS(R21:U21,"<>") -> 4
I22: =IF(내역서업로드!A23<>"",내역서업로드!A23,"") | J22: =LEFT(I22,1) | L22: =IF(OR(J22="E",J22="L",J22="M"),"",I22) | M22: =IF(OR(J22="D",J22="L",J22="M"),"",I22) | N22: =IF(OR(J22="D",J22="E",J22="L"),"",I22) | O22: =IF(OR(J22="D",J22="E",J22="M"),"",I22) | Q22: =IF(Z22=0,"",IF(Z22=1,R22&S22&T22&U22,"E99999")) | R22: =IF(L22="","",L22) | S22: =IF(M22="","",M22) | T22: =IF(W22=1,"",N22) | U22: =IF(OR(W22=1,X22=1),"",O22) | V22: =내역서업로드!E23 -> 0 | W22: =COUNTIFS(R22,"><") -> 0 | X22: =COUNTIFS(S22,"><") -> 0 | Y22: =COUNTIFS(R22:U22,"*") -> 4 | Z22: =COUNTIFS(R22:U22,"><") -> 0 | AA22: =COUNTIFS(R22:U22,"<>") -> 4
... I116: =IF(내역서업로드!A117<>"",내역서업로드!A117,"") | J116: =LEFT(I116,1) | L116: =IF(OR(J116="E",J116="L",J116="M"),"",I116) | M116: =IF(OR(J116="D",J116="L",J116="M"),"",I116) | N116: =IF(OR(J116="D",J116="E",J116="L"),"",I116) | O116: =IF(OR(J116="D",J116="E",J116="M"),"",I116) | Q116: =IF(Z116=0,"",IF(Z116=1,R116&S116&T116&U116,"E99999")) | R116: =IF(L116="","",L116) | S116: =IF(M116="","",M116) | T116: =IF(W116=1,"",N116) | U116: =IF(OR(W116=1,X116=1),"",O116) | V116: =내역서업로드!E117 -> 0 | W116: =COUNTIFS(R116,"><") -> 0 | X116: =COUNTIFS(S116,"><") -> 0 | Y116: =COUNTIFS(R116:U116,"*") -> 4 | Z116: =COUNTIFS(R116:U116,"><") -> 0 | AA116: =COUNTIFS(R116:U116,"<>") -> 4

Sheet Upload(참조)
A1: 구분 | B1: 표준단가 | C1: 표준품셈 | D1: 물가정보 | E1: 노임단가 | F1: 수량 | I1: 예가내역서 코드 | J1: 코드구분 | L1: 표준단가 | M1: 표준품셈 | N1: 물가정보 | O1: 노임단가 | Q1: 최종구분 | R1: 표준단가 | S1: 표준품셈 | T1: 물가정보 | U1: 노임단가 | V1: 수량 | W1: 표준단가 | X1: 표준품셈 | Y1: *(공란) | Z1: ><(텍스트) | AA1: <>(수식모두)
F2: 2 | G2: 표준단가 품목 | H2: 노무비 | I2: =IF(#REF!<>"",#REF!,"") -> #REF! | J2: =LEFT(I2,1) -> #REF! | L2: =IF(OR(J2="E",J2="L",J2="M"),"",I2) -> #REF! | M2: =IF(OR(J2="D",J2="L",J2="M"),"",I2) -> #REF! | N2: =IF(OR(J2="D",J2="E",J2="L"),"",I2) -> #REF! | O2: =IF(OR(J2="D",J2="E",J2="M"),"",I2) -> #REF! | Q2: =IF(Z2=0,"",IF(Z2=1,R2&S2&T2&U2,"E99999")) | R2: =IF(L2="","",L2) -> #REF! | S2: =IF(M2="","",M2) -> #REF! | T2: =IF(W2=1,"",N2) -> #REF! | U2: =IF(OR(W2=1,X2=1),"",O2) -> #REF! | V2: =#REF! -> #REF! | W2: =COUNTIFS(R2,"><") -> 0 | X2: =COUNTIFS(S2,"><") -> 0 | Y2: =COUNTIFS(R2:U2,"*") -> 0 | Z2: =COUNTIFS(R2:U2,"><") -> 0 | AA2: =COUNTIFS(R2:U2,"<>") -> 4
F3: 3 | G3: 표준품셈+물가정보 품목 | H3: 자재비 | I3: =IF(#REF!<>"",#REF!,"") -> #REF! | J3: =LEFT(I3,1) -> #REF! | L3: =IF(OR(J3="E",J3="L",J3="M"),"",I3) -> #REF! | M3: =IF(OR(J3="D",J3="L",J3="M"),"",I3) -> #REF! | N3: =IF(OR(J3="D",J3="E",J3="L"),"",I3) -> #REF! | O3: =IF(OR(J3="D",J3="E",J3="M"),"",I3) -> #REF! | Q3: =IF(Z3=0,"",IF(Z3=1,R3&S3&T3&U3,"E99999")) | R3: =IF(L3="","",L3) -> #REF! | S3: =IF(M3="","",M3) -> #REF! | T3: =IF(W3=1,"",N3) -> #REF! | U3: =IF(OR(W3=1,X3=1),"",O3) -> #REF! | V3: =#REF! -> #REF! | W3: =COUNTIFS(R3,"><") -> 0 | X3: =COUNTIFS(S3,"><") -> 0 | Y3: =COUNTIFS(R3:U3,"*") -> 0 | Z3: =COUNTIFS(R3:U3,"><") -> 0 | AA3: =COUNTIFS(R3:U3,"<>") -> 4
F4: 4 | G4: 표준품셈만 있을떄 | H4: 표준단가 | I4: =IF(#REF!<>"",#REF!,"") -> #REF! | J4: =LEFT(I4,1) -> #REF! | L4: =IF(OR(J4="E",J4="L",J4="M"),"",I4) -> #REF! | M4: =IF(OR(J4="D",J4="L",J4="M"),"",I4) -> #REF! | N4: =IF(OR(J4="D",J4="E",J4="L"),"",I4) -> #REF! | O4: =IF(OR(J4="D",J4="E",J4="M"),"",I4) -> #REF! | Q4: =IF(Z4=0,"",IF(Z4=1,R4&S4&T4&U4,"E99999")) | R4: =IF(L4="","",L4) -> #REF! | S4: =IF(M4="","",M4) -> #REF! | T4: =IF(W4=1,"",N4) -> #REF! | U4: =IF(OR(W4=1,X4=1),"",O4) -> #REF! | V4: =#REF! -> #REF! | W4: =COUNTIFS(R4,"><") -> 0 | X4: =COUNTIFS(S4,"><") -> 0 | Y4: =COUNTIFS(R4:U4,"*") -> 0 | Z4: =COUNTIFS(R4:U4,"><") -> 0 | AA4: =COUNTIFS(R4:U4,"<>") -> 4
F5: 5 | G5: 물가정보만 있을때 | H5: 표준품셈 | I5: =IF(#REF!<>"",#REF!,"") -> #REF! | J5: =LEFT(I5,1) -> #REF! | L5: =IF(OR(J5="E",J5="L",J5="M"),"",I5) -> #REF! | M5: =IF(OR(J5="D",J5="L",J5="M"),"",I5) -> #REF! | N5: =IF(OR(J5="D",J5="E",J5="L"),"",I5) -> #REF! | O5: =IF(OR(J5="D",J5="E",J5="M"),"",I5) -> #REF! | Q5: =IF(Z5=0,"",IF(Z5=1,R5&S5&T5&U5,"E99999")) | R5: =IF(L5="","",L5) -> #REF! | S5: =IF(M5="","",M5) -> #REF! | T5: =IF(W5=1,"",N5) -> #REF! | U5: =IF(OR(W5=1,X5=1),"",O5) -> #REF! | V5: =#REF! -> #REF! | W5: =COUNTIFS(R5,"><") -> 0 | X5: =COUNTIFS(S5,"><") -> 0 | Y5: =COUNTIFS(R5:U5,"*") -> 0 | Z5: =COUNTIFS(R5:U5,"><") -> 0 | AA5: =COUNTIFS(R5:U5,"<>") -> 4
F6: 6 | G6: 노임단가만 있을떄 | I6: =IF(#REF!<>"",#REF!,"") -> #REF! | J6: =LEFT(I6,1) -> #REF! | L6: =IF(OR(J6="E",J6="L",J6="M"),"",I6) -> #REF! | M6: =IF(OR(J6="D",J6="L",J6="M"),"",I6) -> #REF! | N6: =IF(OR(J6="D",J6="E",J6="L"),"",I6) -> #REF! | O6: =IF(OR(J6="D",J6="E",J6="M"),"",I6) -> #REF! | Q6: =IF(Z6=0,"",IF(Z6=1,R6&S6&T6&U6,"E99999")) | R6: =IF(L6="","",L6) -> #REF! | S6: =IF(M6="","",M6) -> #REF! | T6: =IF(W6=1,"",N6) -> #REF! | U6: =IF(OR(W6=1,X6=1),"",O6) -> #REF! | V6: =#REF! -> #REF! | W6: =COUNTIFS(R6,"><") -> 0 | X6: =COUNTIFS(S6,"><") -> 0 | Y6: =COUNTIFS(R6:U6,"*") -> 0 | Z6: =COUNTIFS(R6:U6,"><") -> 0 | AA6: =COUNTIFS(R6:U6,"<>") -> 4
I7: =IF(#REF!<>"",#REF!,"") -> #REF! | J7: =LEFT(I7,1) -> #REF! | L7: =IF(OR(J7="E",J7="L",J7="M"),"",I7) -> #REF! | M7: =IF(OR(J7="D",J7="L",J7="M"),"",I7) -> #REF! | N7: =IF(OR(J7="D",J7="E",J7="L"),"",I7) -> #REF! | O7: =IF(OR(J7="D",J7="E",J7="M"),"",I7) -> #REF! | Q7: =IF(Z7=0,"",IF(Z7=1,R7&S7&T7&U7,"E99999")) | R7: =IF(L7="","",L7) -> #REF! | S7: =IF(M7="","",M7) -> #REF! | T7: =IF(W7=1,"",N7) -> #REF! | U7: =IF(OR(W7=1,X7=1),"",O7) -> #REF! | V7: =#REF! -> #REF! | W7: =COUNTIFS(R7,"><") -> 0 | X7: =COUNTIFS(S7,"><") -> 0 | Y7: =COUNTIFS(R7:U7,"*") -> 0 | Z7: =COUNTIFS(R7:U7,"><") -> 0 | AA7: =COUNTIFS(R7:U7,"<>") -> 4
G8: 표준단가 D | I8: =IF(#REF!<>"",#REF!,"") -> #REF! | J8: =LEFT(I8,1) -> #REF! | L8: =IF(OR(J8="E",J8="L",J8="M"),"",I8) -> #REF! | M8: =IF(OR(J8="D",J8="L",J8="M"),"",I8) -> #REF! | N8: =IF(OR(J8="D",J8="E",J8="L"),"",I8) -> #REF! | O8: =IF(OR(J8="D",J8="E",J8="M"),"",I8) -> #REF! | Q8: =IF(Z8=0,"",IF(Z8=1,R8&S8&T8&U8,"E99999")) | R8: =IF(L8="","",L8) -> #REF! | S8: =IF(M8="","",M8) -> #REF! | T8: =IF(W8=1,"",N8) -> #REF! | U8: =IF(OR(W8=1,X8=1),"",O8) -> #REF! | V8: =#REF! -> #REF! | W8: =COUNTIFS(R8,"><") -> 0 | X8: =COUNTIFS(S8,"><") -> 0 | Y8: =COUNTIFS(R8:U8,"*") -> 0 | Z8: =COUNTIFS(R8:U8,"><") -> 0 | AA8: =COUNTIFS(R8:U8,"<>") -> 4
I9: =IF(#REF!<>"",#REF!,"") -> #REF! | J9: =LEFT(I9,1) -> #REF! | L9: =IF(OR(J9="E",J9="L",J9="M"),"",I9) -> #REF! | M9: =IF(OR(J9="D",J9="L",J9="M"),"",I9) -> #REF! | N9: =IF(OR(J9="D",J9="E",J9="L"),"",I9) -> #REF! | O9: =IF(OR(J9="D",J9="E",J9="M"),"",I9) -> #REF! | Q9: =IF(Z9=0,"",IF(Z9=1,R9&S9&T9&U9,"E99999")) | R9: =IF(L9="","",L9) -> #REF! | S9: =IF(M9="","",M9) -> #REF! | T9: =IF(W9=1,"",N9) -> #REF! | U9: =IF(OR(W9=1,X9=1),"",O9) -> #REF! | V9: =#REF! -> #REF! | W9: =COUNTIFS(R9,"><") -> 0 | X9: =COUNTIFS(S9,"><") -> 0 | Y9: =COUNTIFS(R9:U9,"*") -> 0 | Z9: =COUNTIFS(R9:U9,"><") -> 0 | AA9: =COUNTIFS(R9:U9,"<>") -> 4
I10: =IF(#REF!<>"",#REF!,"") -> #REF! | J10: =LEFT(I10,1) -> #REF! | L10: =IF(OR(J10="E",J10="L",J10="M"),"",I10) -> #REF! | M10: =IF(OR(J10="D",J10="L",J10="M"),"",I10) -> #REF! | N10: =IF(OR(J10="D",J10="E",J10="L"),"",I10) -> #REF! | O10: =IF(OR(J10="D",J10="E",J10="M"),"",I10) -> #REF! | Q10: =IF(Z10=0,"",IF(Z10=1,R10&S10&T10&U10,"E99999")) | R10: =IF(L10="","",L10) -> #REF! | S10: =IF(M10="","",M10) -> #REF! | T10: =IF(W10=1,"",N10) -> #REF! | U10: =IF(OR(W10=1,X10=1),"",O10) -> #REF! | V10: =#REF! -> #REF! | W10: =COUNTIFS(R10,"><") -> 0 | X10: =COUNTIFS(S10,"><") -> 0 | Y10: =COUNTIFS(R10:U10,"*") -> 0 | Z10: =COUNTIFS(R10:U10,"><") -> 0 | AA10: =COUNTIFS(R10:U10,"<>") -> 4
I11: =IF(#REF!<>"",#REF!,"") -> #REF! | J11: =LEFT(I11,1) -> #REF! | L11: =IF(OR(J11="E",J11="L",J11="M"),"",I11) -> #REF! | M11: =IF(OR(J11="D",J11="L",J11="M"),"",I11) -> #REF! | N11: =IF(OR(J11="D",J11="E",J11="L"),"",I11) -> #REF! | O11: =IF(OR(J11="D",J11="E",J11="M"),"",I11) -> #REF! | Q11: =IF(Z11=0,"",IF(Z11=1,R11&S11&T11&U11,"E99999")) | R11: =IF(L11="","",L11) -> #REF! | S11: =IF(M11="","",M11) -> #REF! | T11: =IF(W11=1,"",N11) -> #REF! | U11: =IF(OR(W11=1,X11=1),"",O11) -> #REF! | V11: =#REF! -> #REF! | W11: =COUNTIFS(R11,"><") -> 0 | X11: =COUNTIFS(S11,"><") -> 0 | Y11: =COUNTIFS(R11:U11,"*") -> 0 | Z11: =COUNTIFS(R11:U11,"><") -> 0 | AA11: =COUNTIFS(R11:U11,"<>") -> 4
I12: =IF(#REF!<>"",#REF!,"") -> #REF! | J12: =LEFT(I12,1) -> #REF! | L12: =IF(OR(J12="E",J12="L",J12="M"),"",I12) -> #REF! | M12: =IF(OR(J12="D",J12="L",J12="M"),"",I12) -> #REF! | N12: =IF(OR(J12="D",J12="E",J12="L"),"",I12) -> #REF! | O12: =IF(OR(J12="D",J12="E",J12="M"),"",I12) -> #REF! | Q12: =IF(Z12=0,"",IF(Z12=1,R12&S12&T12&U12,"E99999")) | R12: =IF(L12="","",L12) -> #REF! | S12: =IF(M12="","",M12) -> #REF! | T12: =IF(W12=1,"",N12) -> #REF! | U12: =IF(OR(W12=1,X12=1),"",O12) -> #REF! | V12: =#REF! -> #REF! | W12: =COUNTIFS(R12,"><") -> 0 | X12: =COUNTIFS(S12,"><") -> 0 | Y12: =COUNTIFS(R12:U12,"*") -> 0 | Z12: =COUNTIFS(R12:U12,"><") -> 0 | AA12: =COUNTIFS(R12:U12,"<>") -> 4
I13: =IF(#REF!<>"",#REF!,"") -> #REF! | J13: =LEFT(I13,1) -> #REF! | L13: =IF(OR(J13="E",J13="L",J13="M"),"",I13) -> #REF! | M13: =IF(OR(J13="D",J13="L",J13="M"),"",I13) -> #REF! | N13: =IF(OR(J13="D",J13="E",J13="L"),"",I13) -> #REF! | O13: =IF(OR(J13="D",J13="E",J13="M"),"",I13) -> #REF! | Q13: =IF(Z13=0,"",IF(Z13=1,R13&S13&T13&U13,"E99999")) | R13: =IF(L13="","",L13) -> #REF! | S13: =IF(M13="","",M13) -> #REF! | T13: =IF(W13=1,"",N13) -> #REF! | U13: =IF(OR(W13=1,X13=1),"",O13) -> #REF! | V13: =#REF! -> #REF! | W13: =COUNTIFS(R13,"><") -> 0 | X13: =COUNTIFS(S13,"><") -> 0 | Y13: =COUNTIFS(R13:U13,"*") -> 0 | Z13: =COUNTIFS(R13:U13,"><") -> 0 | AA13: =COUNTIFS(R13:U13,"<>") -> 4
I14: =IF(#REF!<>"",#REF!,"") -> #REF! | J14: =LEFT(I14,1) -> #REF! | L14: =IF(OR(J14="E",J14="L",J14="M"),"",I14) -> #REF! | M14: =IF(OR(J14="D",J14="L",J14="M"),"",I14) -> #REF! | N14: =IF(OR(J14="D",J14="E",J14="L"),"",I14) -> #REF! | O14: =IF(OR(J14="D",J14="E",J14="M"),"",I14) -> #REF! | Q14: =IF(Z14=0,"",IF(Z14=1,R14&S14&T14&U14,"E99999")) | R14: =IF(L14="","",L14) -> #REF! | S14: =IF(M14="","",M14) -> #REF! | T14: =IF(W14=1,"",N14) -> #REF! | U14: =IF(OR(W14=1,X14=1),"",O14) -> #REF! | V14: =#REF! -> #REF! | W14: =COUNTIFS(R14,"><") -> 0 | X14: =COUNTIFS(S14,"><") -> 0 | Y14: =COUNTIFS(R14:U14,"*") -> 0 | Z14: =COUNTIFS(R14:U14,"><") -> 0 | AA14: =COUNTIFS(R14:U14,"<>") -> 4
I15: =IF(#REF!<>"",#REF!,"") -> #REF! | J15: =LEFT(I15,1) -> #REF! | L15: =IF(OR(J15="E",J15="L",J15="M"),"",I15) -> #REF! | M15: =IF(OR(J15="D",J15="L",J15="M"),"",I15) -> #REF! | N15: =IF(OR(J15="D",J15="E",J15="L"),"",I15) -> #REF! | O15: =IF(OR(J15="D",J15="E",J15="M"),"",I15) -> #REF! | Q15: =IF(Z15=0,"",IF(Z15=1,R15&S15&T15&U15,"E99999")) | R15: =IF(L15="","",L15) -> #REF! | S15: =IF(M15="","",M15) -> #REF! | T15: =IF(W15=1,"",N15) -> #REF! | U15: =IF(OR(W15=1,X15=1),"",O15) -> #REF! | V15: =#REF! -> #REF! | W15: =COUNTIFS(R15,"><") -> 0 | X15: =COUNTIFS(S15,"><") -> 0 | Y15: =COUNTIFS(R15:U15,"*") -> 0 | Z15: =COUNTIFS(R15:U15,"><") -> 0 | AA15: =COUNTIFS(R15:U15,"<>") -> 4
I16: =IF(#REF!<>"",#REF!,"") -> #REF! | J16: =LEFT(I16,1) -> #REF! | L16: =IF(OR(J16="E",J16="L",J16="M"),"",I16) -> #REF! | M16: =IF(OR(J16="D",J16="L",J16="M"),"",I16) -> #REF! | N16: =IF(OR(J16="D",J16="E",J16="L"),"",I16) -> #REF! | O16: =IF(OR(J16="D",J16="E",J16="M"),"",I16) -> #REF! | Q16: =IF(Z16=0,"",IF(Z16=1,R16&S16&T16&U16,"E99999")) | R16: =IF(L16="","",L16) -> #REF! | S16: =IF(M16="","",M16) -> #REF! | T16: =IF(W16=1,"",N16) -> #REF! | U16: =IF(OR(W16=1,X16=1),"",O16) -> #REF! | V16: =#REF! -> #REF! | W16: =COUNTIFS(R16,"><") -> 0 | X16: =COUNTIFS(S16,"><") -> 0 | Y16: =COUNTIFS(R16:U16,"*") -> 0 | Z16: =COUNTIFS(R16:U16,"><") -> 0 | AA16: =COUNTIFS(R16:U16,"<>") -> 4
I17: =IF(#REF!<>"",#REF!,"") -> #REF! | J17: =LEFT(I17,1) -> #REF! | L17: =IF(OR(J17="E",J17="L",J17="M"),"",I17) -> #REF! | M17: =IF(OR(J17="D",J17="L",J17="M"),"",I17) -> #REF! | N17: =IF(OR(J17="D",J17="E",J17="L"),"",I17) -> #REF! | O17: =IF(OR(J17="D",J17="E",J17="M"),"",I17) -> #REF! | Q17: =IF(Z17=0,"",IF(Z17=1,R17&S17&T17&U17,"E99999")) | R17: =IF(L17="","",L17) -> #REF! | S17: =IF(M17="","",M17) -> #REF! | T17: =IF(W17=1,"",N17) -> #REF! | U17: =IF(OR(W17=1,X17=1),"",O17) -> #REF! | V17: =#REF! -> #REF! | W17: =COUNTIFS(R17,"><") -> 0 | X17: =COUNTIFS(S17,"><") -> 0 | Y17: =COUNTIFS(R17:U17,"*") -> 0 | Z17: =COUNTIFS(R17:U17,"><") -> 0 | AA17: =COUNTIFS(R17:U17,"<>") -> 4
I18: =IF(#REF!<>"",#REF!,"") -> #REF! | J18: =LEFT(I18,1) -> #REF! | L18: =IF(OR(J18="E",J18="L",J18="M"),"",I18) -> #REF! | M18: =IF(OR(J18="D",J18="L",J18="M"),"",I18) -> #REF! | N18: =IF(OR(J18="D",J18="E",J18="L"),"",I18) -> #REF! | O18: =IF(OR(J18="D",J18="E",J18="M"),"",I18) -> #REF! | Q18: =IF(Z18=0,"",IF(Z18=1,R18&S18&T18&U18,"E99999")) | R18: =IF(L18="","",L18) -> #REF! | S18: =IF(M18="","",M18) -> #REF! | T18: =IF(W18=1,"",N18) -> #REF! | U18: =IF(OR(W18=1,X18=1),"",O18) -> #REF! | V18: =#REF! -> #REF! | W18: =COUNTIFS(R18,"><") -> 0 | X18: =COUNTIFS(S18,"><") -> 0 | Y18: =COUNTIFS(R18:U18,"*") -> 0 | Z18: =COUNTIFS(R18:U18,"><") -> 0 | AA18: =COUNTIFS(R18:U18,"<>") -> 4
I19: =IF(#REF!<>"",#REF!,"") -> #REF! | J19: =LEFT(I19,1) -> #REF! | L19: =IF(OR(J19="E",J19="L",J19="M"),"",I19) -> #REF! | M19: =IF(OR(J19="D",J19="L",J19="M"),"",I19) -> #REF! | N19: =IF(OR(J19="D",J19="E",J19="L"),"",I19) -> #REF! | O19: =IF(OR(J19="D",J19="E",J19="M"),"",I19) -> #REF! | Q19: =IF(Z19=0,"",IF(Z19=1,R19&S19&T19&U19,"E99999")) | R19: =IF(L19="","",L19) -> #REF! | S19: =IF(M19="","",M19) -> #REF! | T19: =IF(W19=1,"",N19) -> #REF! | U19: =IF(OR(W19=1,X19=1),"",O19) -> #REF! | V19: =#REF! -> #REF! | W19: =COUNTIFS(R19,"><") -> 0 | X19: =COUNTIFS(S19,"><") -> 0 | Y19: =COUNTIFS(R19:U19,"*") -> 0 | Z19: =COUNTIFS(R19:U19,"><") -> 0 | AA19: =COUNTIFS(R19:U19,"<>") -> 4
I20: =IF(#REF!<>"",#REF!,"") -> #REF! | J20: =LEFT(I20,1) -> #REF! | L20: =IF(OR(J20="E",J20="L",J20="M"),"",I20) -> #REF! | M20: =IF(OR(J20="D",J20="L",J20="M"),"",I20) -> #REF! | N20: =IF(OR(J20="D",J20="E",J20="L"),"",I20) -> #REF! | O20: =IF(OR(J20="D",J20="E",J20="M"),"",I20) -> #REF! | Q20: =IF(Z20=0,"",IF(Z20=1,R20&S20&T20&U20,"E99999")) | R20: =IF(L20="","",L20) -> #REF! | S20: =IF(M20="","",M20) -> #REF! | T20: =IF(W20=1,"",N20) -> #REF! | U20: =IF(OR(W20=1,X20=1),"",O20) -> #REF! | V20: =#REF! -> #REF! | W20: =COUNTIFS(R20,"><") -> 0 | X20: =COUNTIFS(S20,"><") -> 0 | Y20: =COUNTIFS(R20:U20,"*") -> 0 | Z20: =COUNTIFS(R20:U20,"><") -> 0 | AA20: =COUNTIFS(R20:U20,"<>") -> 4
... I22: =IF(#REF!<>"",#REF!,"") -> #REF! | J22: =LEFT(I22,1) -> #REF! | L22: =IF(OR(J22="E",J22="L",J22="M"),"",I22) -> #REF! | M22: =IF(OR(J22="D",J22="L",J22="M"),"",I22) -> #REF! | N22: =IF(OR(J22="D",J22="E",J22="L"),"",I22) -> #REF! | O22: =IF(OR(J22="D",J22="E",J22="M"),"",I22) -> #REF! | Q22: =IF(Z22=0,"",IF(Z22=1,R22&S22&T22&U22,"E99999")) | R22: =IF(L22="","",L22) -> #REF! | S22: =IF(M22="","",M22) -> #REF! | T22: =IF(W22=1,"",N22) -> #REF! | U22: =IF(OR(W22=1,X22=1),"",O22) -> #REF! | V22: =#REF! -> #REF! | W22: =COUNTIFS(R22,"><") -> 0 | X22: =COUNTIFS(S22,"><") -> 0 | Y22: =COUNTIFS(R22:U22,"*") -> 0 | Z22: =COUNTIFS(R22:U22,"><") -> 0 | AA22: =COUNTIFS(R22:U22,"<>") -> 4
I23: =IF(#REF!<>"",#REF!,"") -> #REF! | J23: =LEFT(I23,1) -> #REF! | L23: =IF(OR(J23="E",J23="L",J23="M"),"",I23) -> #REF! | M23: =IF(OR(J23="D",J23="L",J23="M"),"",I23) -> #REF! | N23: =IF(OR(J23="D",J23="E",J23="L"),"",I23) -> #REF! | O23: =IF(OR(J23="D",J23="E",J23="M"),"",I23) -> #REF! | Q23: =IF(Z23=0,"",IF(Z23=1,R23&S23,"E99999")) | R23: =IF(L23="","",L23) -> #REF! | S23: =IF(M23="","",M23) -> #REF! | T23: =IF(W23=1,"",N23) -> #REF! | U23: =IF(OR(W23=1,X23=1),"",O23) -> #REF! | V23: =#REF! -> #REF! | W23: =COUNTIFS(R23,"><") -> 0 | X23: =COUNTIFS(S23,"><") -> 0 | Y23: =COUNTIFS(R23:U23,"*") -> 0 | Z23: =COUNTIFS(R23:U23,"><") -> 0 | AA23: =COUNTIFS(R23:U23,"<>") -> 4
I24: =IF(#REF!<>"",#REF!,"") -> #REF! | J24: =LEFT(I24,1) -> #REF! | L24: =IF(OR(J24="E",J24="L",J24="M"),"",I24) -> #REF! | M24: =IF(OR(J24="D",J24="L",J24="M"),"",I24) -> #REF! | N24: =IF(OR(J24="D",J24="E",J24="L"),"",I24) -> #REF! | O24: =IF(OR(J24="D",J24="E",J24="M"),"",I24) -> #REF! | Q24: =IF(Z24=0,"",IF(Z24=1,R24&S24,"E99999")) | R24: =IF(L24="","",L24) -> #REF! | S24: =IF(M24="","",M24) -> #REF! | T24: =IF(W24=1,"",N24) -> #REF! | U24: =IF(OR(W24=1,X24=1),"",O24) -> #REF! | V24: =#REF! -> #REF! | W24: =COUNTIFS(R24,"><") -> 0 | X24: =COUNTIFS(S24,"><") -> 0 | Y24: =COUNTIFS(R24:U24,"*") -> 0 | Z24: =COUNTIFS(R24:U24,"><") -> 0 | AA24: =COUNTIFS(R24:U24,"<>") -> 4
I25: =IF(#REF!<>"",#REF!,"") -> #REF! | J25: =LEFT(I25,1) -> #REF! | L25: =IF(OR(J25="E",J25="L",J25="M"),"",I25) -> #REF! | M25: =IF(OR(J25="D",J25="L",J25="M"),"",I25) -> #REF! | N25: =IF(OR(J25="D",J25="E",J25="L"),"",I25) -> #REF! | O25: =IF(OR(J25="D",J25="E",J25="M"),"",I25) -> #REF! | Q25: =IF(Z25=0,"",IF(Z25=1,R25&S25,"E99999")) | R25: =IF(L25="","",L25) -> #REF! | S25: =IF(M25="","",M25) -> #REF! | T25: =IF(W25=1,"",N25) -> #REF! | U25: =IF(OR(W25=1,X25=1),"",O25) -> #REF! | V25: =#REF! -> #REF! | W25: =COUNTIFS(R25,"><") -> 0 | X25: =COUNTIFS(S25,"><") -> 0 | Y25: =COUNTIFS(R25:U25,"*") -> 0 | Z25: =COUNTIFS(R25:U25,"><") -> 0 | AA25: =COUNTIFS(R25:U25,"<>") -> 4
I26: =IF(#REF!<>"",#REF!,"") -> #REF! | J26: =LEFT(I26,1) -> #REF! | L26: =IF(OR(J26="E",J26="L",J26="M"),"",I26) -> #REF! | M26: =IF(OR(J26="D",J26="L",J26="M"),"",I26) -> #REF! | N26: =IF(OR(J26="D",J26="E",J26="L"),"",I26) -> #REF! | O26: =IF(OR(J26="D",J26="E",J26="M"),"",I26) -> #REF! | Q26: =IF(Z26=0,"",IF(Z26=1,R26&S26,"E99999")) | R26: =IF(L26="","",L26) -> #REF! | S26: =IF(M26="","",M26) -> #REF! | T26: =IF(W26=1,"",N26) -> #REF! | U26: =IF(OR(W26=1,X26=1),"",O26) -> #REF! | V26: =#REF! -> #REF! | W26: =COUNTIFS(R26,"><") -> 0 | X26: =COUNTIFS(S26,"><") -> 0 | Y26: =COUNTIFS(R26:U26,"*") -> 0 | Z26: =COUNTIFS(R26:U26,"><") -> 0 | AA26: =COUNTIFS(R26:U26,"<>") -> 4
I27: =IF(#REF!<>"",#REF!,"") -> #REF! | J27: =LEFT(I27,1) -> #REF! | L27: =IF(OR(J27="E",J27="L",J27="M"),"",I27) -> #REF! | M27: =IF(OR(J27="D",J27="L",J27="M"),"",I27) -> #REF! | N27: =IF(OR(J27="D",J27="E",J27="L"),"",I27) -> #REF! | O27: =IF(OR(J27="D",J27="E",J27="M"),"",I27) -> #REF! | Q27: =IF(Z27=0,"",IF(Z27=1,R27&S27,"E99999")) | R27: =IF(L27="","",L27) -> #REF! | S27: =IF(M27="","",M27) -> #REF! | T27: =IF(W27=1,"",N27) -> #REF! | U27: =IF(OR(W27=1,X27=1),"",O27) -> #REF! | V27: =#REF! -> #REF! | W27: =COUNTIFS(R27,"><") -> 0 | X27: =COUNTIFS(S27,"><") -> 0 | Y27: =COUNTIFS(R27:U27,"*") -> 0 | Z27: =COUNTIFS(R27:U27,"><") -> 0 | AA27: =COUNTIFS(R27:U27,"<>") -> 4
I28: =IF(#REF!<>"",#REF!,"") -> #REF! | J28: =LEFT(I28,1) -> #REF! | L28: =IF(OR(J28="E",J28="L",J28="M"),"",I28) -> #REF! | M28: =IF(OR(J28="D",J28="L",J28="M"),"",I28) -> #REF! | N28: =IF(OR(J28="D",J28="E",J28="L"),"",I28) -> #REF! | O28: =IF(OR(J28="D",J28="E",J28="M"),"",I28) -> #REF! | Q28: =IF(Z28=0,"",IF(Z28=1,R28&S28,"E99999")) | R28: =IF(L28="","",L28) -> #REF! | S28: =IF(M28="","",M28) -> #REF! | T28: =IF(W28=1,"",N28) -> #REF! | U28: =IF(OR(W28=1,X28=1),"",O28) -> #REF! | V28: =#REF! -> #REF! | W28: =COUNTIFS(R28,"><") -> 0 | X28: =COUNTIFS(S28,"><") -> 0 | Y28: =COUNTIFS(R28:U28,"*") -> 0 | Z28: =COUNTIFS(R28:U28,"><") -> 0 | AA28: =COUNTIFS(R28:U28,"<>") -> 4
I29: =IF(#REF!<>"",#REF!,"") -> #REF! | J29: =LEFT(I29,1) -> #REF! | L29: =IF(OR(J29="E",J29="L",J29="M"),"",I29) -> #REF! | M29: =IF(OR(J29="D",J29="L",J29="M"),"",I29) -> #REF! | N29: =IF(OR(J29="D",J29="E",J29="L"),"",I29) -> #REF! | O29: =IF(OR(J29="D",J29="E",J29="M"),"",I29) -> #REF! | Q29: =IF(Z29=0,"",IF(Z29=1,R29&S29,"E99999")) | R29: =IF(L29="","",L29) -> #REF! | S29: =IF(M29="","",M29) -> #REF! | T29: =IF(W29=1,"",N29) -> #REF! | U29: =IF(OR(W29=1,X29=1),"",O29) -> #REF! | V29: =#REF! -> #REF! | W29: =COUNTIFS(R29,"><") -> 0 | X29: =COUNTIFS(S29,"><") -> 0 | Y29: =COUNTIFS(R29:U29,"*") -> 0 | Z29: =COUNTIFS(R29:U29,"><") -> 0 | AA29: =COUNTIFS(R29:U29,"<>") -> 4
I30: =IF(#REF!<>"",#REF!,"") -> #REF! | J30: =LEFT(I30,1) -> #REF! | L30: =IF(OR(J30="E",J30="L",J30="M"),"",I30) -> #REF! | M30: =IF(OR(J30="D",J30="L",J30="M"),"",I30) -> #REF! | N30: =IF(OR(J30="D",J30="E",J30="L"),"",I30) -> #REF! | O30: =IF(OR(J30="D",J30="E",J30="M"),"",I30) -> #REF! | Q30: =IF(Z30=0,"",IF(Z30=1,R30&S30,"E99999")) | R30: =IF(L30="","",L30) -> #REF! | S30: =IF(M30="","",M30) -> #REF! | T30: =IF(W30=1,"",N30) -> #REF! | U30: =IF(OR(W30=1,X30=1),"",O30) -> #REF! | V30: =#REF! -> #REF! | W30: =COUNTIFS(R30,"><") -> 0 | X30: =COUNTIFS(S30,"><") -> 0 | Y30: =COUNTIFS(R30:U30,"*") -> 0 | Z30: =COUNTIFS(R30:U30,"><") -> 0 | AA30: =COUNTIFS(R30:U30,"<>") -> 4
I31: =IF(#REF!<>"",#REF!,"") -> #REF! | J31: =LEFT(I31,1) -> #REF! | L31: =IF(OR(J31="E",J31="L",J31="M"),"",I31) -> #REF! | M31: =IF(OR(J31="D",J31="L",J31="M"),"",I31) -> #REF! | N31: =IF(OR(J31="D",J31="E",J31="L"),"",I31) -> #REF! | O31: =IF(OR(J31="D",J31="E",J31="M"),"",I31) -> #REF! | Q31: =IF(Z31=0,"",IF(Z31=1,R31&S31,"E99999")) | R31: =IF(L31="","",L31) -> #REF! | S31: =IF(M31="","",M31) -> #REF! | T31: =IF(W31=1,"",N31) -> #REF! | U31: =IF(OR(W31=1,X31=1),"",O31) -> #REF! | V31: =#REF! -> #REF! | W31: =COUNTIFS(R31,"><") -> 0 | X31: =COUNTIFS(S31,"><") -> 0 | Y31: =COUNTIFS(R31:U31,"*") -> 0 | Z31: =COUNTIFS(R31:U31,"><") -> 0 | AA31: =COUNTIFS(R31:U31,"<>") -> 4
I32: =IF(#REF!<>"",#REF!,"") -> #REF! | J32: =LEFT(I32,1) -> #REF! | L32: =IF(OR(J32="E",J32="L",J32="M"),"",I32) -> #REF! | M32: =IF(OR(J32="D",J32="L",J32="M"),"",I32) -> #REF! | N32: =IF(OR(J32="D",J32="E",J32="L"),"",I32) -> #REF! | O32: =IF(OR(J32="D",J32="E",J32="M"),"",I32) -> #REF! | Q32: =IF(Z32=0,"",IF(Z32=1,R32&S32,"E99999")) | R32: =IF(L32="","",L32) -> #REF! | S32: =IF(M32="","",M32) -> #REF! | T32: =IF(W32=1,"",N32) -> #REF! | U32: =IF(OR(W32=1,X32=1),"",O32) -> #REF! | V32: =#REF! -> #REF! | W32: =COUNTIFS(R32,"><") -> 0 | X32: =COUNTIFS(S32,"><") -> 0 | Y32: =COUNTIFS(R32:U32,"*") -> 0 | Z32: =COUNTIFS(R32:U32,"><") -> 0 | AA32: =COUNTIFS(R32:U32,"<>") -> 4
I33: =IF(#REF!<>"",#REF!,"") -> #REF! | J33: =LEFT(I33,1) -> #REF! | L33: =IF(OR(J33="E",J33="L",J33="M"),"",I33) -> #REF! | M33: =IF(OR(J33="D",J33="L",J33="M"),"",I33) -> #REF! | N33: =IF(OR(J33="D",J33="E",J33="L"),"",I33) -> #REF! | O33: =IF(OR(J33="D",J33="E",J33="M"),"",I33) -> #REF! | Q33: =IF(Z33=0,"",IF(Z33=1,R33&S33,"E99999")) | R33: =IF(L33="","",L33) -> #REF! | S33: =IF(M33="","",M33) -> #REF! | T33: =IF(W33=1,"",N33) -> #REF! | U33: =IF(OR(W33=1,X33=1),"",O33) -> #REF! | V33: =#REF! -> #REF! | W33: =COUNTIFS(R33,"><") -> 0 | X33: =COUNTIFS(S33,"><") -> 0 | Y33: =COUNTIFS(R33:U33,"*") -> 0 | Z33: =COUNTIFS(R33:U33,"><") -> 0 | AA33: =COUNTIFS(R33:U33,"<>") -> 4
I34: =IF(#REF!<>"",#REF!,"") -> #REF! | J34: =LEFT(I34,1) -> #REF! | L34: =IF(OR(J34="E",J34="L",J34="M"),"",I34) -> #REF! | M34: =IF(OR(J34="D",J34="L",J34="M"),"",I34) -> #REF! | N34: =IF(OR(J34="D",J34="E",J34="L"),"",I34) -> #REF! | O34: =IF(OR(J34="D",J34="E",J34="M"),"",I34) -> #REF! | Q34: =IF(Z34=0,"",IF(Z34=1,R34&S34,"E99999")) | R34: =IF(L34="","",L34) -> #REF! | S34: =IF(M34="","",M34) -> #REF! | T34: =IF(W34=1,"",N34) -> #REF! | U34: =IF(OR(W34=1,X34=1),"",O34) -> #REF! | V34: =#REF! -> #REF! | W34: =COUNTIFS(R34,"><") -> 0 | X34: =COUNTIFS(S34,"><") -> 0 | Y34: =COUNTIFS(R34:U34,"*") -> 0 | Z34: =COUNTIFS(R34:U34,"><") -> 0 | AA34: =COUNTIFS(R34:U34,"<>") -> 4
... I986: =IF(#REF!<>"",#REF!,"") -> #REF! | J986: =LEFT(I986,1) -> #REF! | L986: =IF(OR(J986="E",J986="L",J986="M"),"",I986) -> #REF! | M986: =IF(OR(J986="D",J986="L",J986="M"),"",I986) -> #REF! | N986: =IF(OR(J986="D",J986="E",J986="L"),"",I986) -> #REF! | O986: =IF(OR(J986="D",J986="E",J986="M"),"",I986) -> #REF! | Q986: =IF(Z986=0,"",IF(Z986=1,R986&S986,"E99999")) | R986: =IF(L986="","",L986) -> #REF! | S986: =IF(M986="","",M986) -> #REF! | T986: =IF(W986=1,"",N986) -> #REF! | U986: =IF(OR(W986=1,X986=1),"",O986) -> #REF! | V986: =#REF! -> #REF! | W986: =COUNTIFS(R986,"><") -> 0 | X986: =COUNTIFS(S986,"><") -> 0 | Y986: =COUNTIFS(R986:U986,"*") -> 0 | Z986: =COUNTIFS(R986:U986,"><") -> 0 | AA986: =COUNTIFS(R986:U986,"<>") -> 4
I987: =IF(#REF!<>"",#REF!,"") -> #REF! | J987: =LEFT(I987,1) -> #REF!
I988: =IF(#REF!<>"",#REF!,"") -> #REF! | J988: =LEFT(I988,1) -> #REF!
