Workbook

Sheet 갑지
A2: 견 적 서
A5: 수신인 : 주식회사 에스엔아이 코퍼레이션 | F5: 등록번호 | G5: 314-81-77668
F6: 상 호 | G6: 주식회사 준 마
A7: 공사명 : | B7: LG사택 보조펌프 교체_소방 | F7: 대표 이사 | G7: 대표자 김 상 진 (인)
F8: 사업장 | G8: 대전광역시 대덕구 석봉로18번길 31
A9: 견적일 : | B9: 2025 년 10 월 14 일 | F9: 업 태 | G9: 건설업, 제조업, 부동산, 서비스
F10: 종 목 | G10: 전기공사, 배전반, 소방시설공사, 대체에너지사업
F11: TEL, FAX | G11: (042) 934-9400~4, 935-9405
A12: 금액: | B12: =NUMBERSTRING(F31,1) -> 사백일십구만이천 | D12: 원정
A14: NO | B14: 품명 | C14: 규격 | D14: 수량 | E14: 단위 | F14: 금액 | G14: 비고
B15: 직접비
B16: 재료비 | F16: ='내역서(표준단가)'!O43 -> 2058104
B17: 노무비 | F17: ='내역서(표준단가)'!Q43 -> 1694218
B18: 기계/기타경비 | F18: ='내역서(표준단가)'!S43+'내역서(표준단가)'!U43 -> 0
B19: 소계 | F19: =F16+F17+F18 -> 3752322
B20: 간접비
B21: 안전관리비 | C21: (재료비+노무비)*3.11% | D21: 1 | E21: 식 | F21: =(F16+F17)*3.11% -> 116697.21 | G21: 모든공사에 적용
B22: 산재보험료 | C22: 노무비*3.56% | D22: 1 | E22: 식 | F22: =F17*3.56% -> 60314.161 | G22: 모든공사에 적용
B23: 고용보험료 | C23: 노무비*1.01% | D23: 1 | E23: 식 | F23: =F17*1.01% -> 17111.602 | G23: 모든공사에 적용
B24: 국민건강 보험료 | C24: 노무비*3.545% | D24: 1 | E24: 식 | F24: =F17*3.545% -> 60060.028 | G24: 모든공사에 적용
B25: 국민연금 보험료 | C25: 노무비*4.5% | D25: 1 | E25: 식 | F25: =F17*4.5% -> 76239.81 | G25: 모든공사에 적용
B26: 노인장기요양 보험료 | C26: 국민건강보험료*12.95% | D26: 1 | E26: 식 | F26: =F24*12.95% -> 7777.7736 | G26: 모든공사에 적용
B27: 일반관리비/이윤 | C27: (노무비+간접공사비)*5% | D27: 1 | E27: 식 | F27: =SUM(F17+F21+F22+F23+F24+F25+F26)*5% -> 101620.93
B28: 소계 | F28: =F21+F22+F23+F24+F25+F26+F27 -> 439821.52
F30: =F19+F28+F29 -> 4192143.5
B31: 합계(단수조정) | F31: =ROUNDDOWN(F30,-3) -> 4192000
B32: VAT별도

Sheet 내역서(표준단가)
E1: =F1&G1&H1&I1 | O1: ▼낙찰율 | Q1: ▼낙찰율 | S1: ▼낙찰율 | U1: ▼낙찰율
O2: 0.9 | Q2: 0.88 | S2: 1 | U2: 1
E3: 합 계 | F3: ▶ 표준 Code(표준단가/품셈/물정/노임) 순서별 입력(Upload 자동반영) | J3: 주 요 내 역 | L3: 단 위 | M3: 수 량 | N3: 재 료 비 | P3: 노 무 비 | R3: 기 계 경 비 | T3: 기 타 경 비(부 자 재 비) | V3: 합 계 | W3: 노무비 할증 | X3: 할증기준
F4: 표준단가 D | G4: 표준품셈 E | H4: 물가정보 M | I4: 노임단가 L | J4: 품 목 | K4: 규 격 | N4: 품 셈 / 표 단 | O4: 금 액 | P4: 단 가 | Q4: 금 액 | R4: 단 가 | S4: 금 액 | T4: 단 가 | U4: 금 액
E5: =F5&G5&H5&I5 | J5: =갑지!B7 -> LG사택 보조펌프 교체_소방
E6: =F6&G6&H6&I6 -> E00000806004010106 | G6: E00000806004010106 | J6: 일반펌프설치 | K6: 7.5㎾이하 | L6: (대당) | M6: 1 | N6: 14767 | O6: =ROUND(N6*O$2*M6,0) -> 13290 | P6: 492262 | Q6: =ROUND(P6*Q$2*M6*W6,0) -> 216595 | S6: =ROUND(R6*S$2*M6,0) -> 0 | U6: =ROUND(T6*U$2*M6,0) -> 0 | V6: =SUM(O6,Q6,S6,U6) -> 229885 | W6: 0.5 | X6: H01 | Y6: 철거
E7: =F7&G7&H7&I7 -> M025332910040101 | H7: M025332910040101 | J7: 웨스코펌프 | K7: PSW-4010, 40, 7.5, 120, 0.06 | L7: 대 | M7: 1 | N7: 1422000 | O7: =ROUND(N7*O$2*M7,0) -> 1279800 | Q7: =ROUND(P7*Q$2*M7*W7,0) -> 0 | S7: =ROUND(R7*S$2*M7,0) -> 0 | U7: =ROUND(T7*U$2*M7,0) -> 0 | V7: =SUM(O7,Q7,S7,U7) -> 1279800
E8: =F8&G8&H8&I8 -> E00000806004010106 | G8: E00000806004010106 | J8: 일반펌프설치 | K8: 7.5㎾이하 | L8: (대당) | M8: 1 | N8: 14767 | O8: =ROUND(N8*O$2*M8,0) -> 13290 | P8: 492262 | Q8: =ROUND(P8*Q$2*M8*W8,0) -> 433191 | S8: =ROUND(R8*S$2*M8,0) -> 0 | U8: =ROUND(T8*U$2*M8,0) -> 0 | V8: =SUM(O8,Q8,S8,U8) -> 446481 | W8: 1
E9: =F9&G9&H9&I9 -> E00000806004010306 | G9: E00000806004010306 | J9: 펌프 방진가대 설치 | K9: 7.5㎾이하 | L9: (대당) | M9: 1 | O9: =ROUND(N9*O$2*M9,0) -> 0 | P9: 255261 | Q9: =ROUND(P9*Q$2*M9*W9,0) -> 112315 | S9: =ROUND(R9*S$2*M9,0) -> 0 | U9: =ROUND(T9*U$2*M9,0) -> 0 | V9: =SUM(O9,Q9,S9,U9) -> 112315 | W9: 0.5 | X9: H01 | Y9: 철거
E10: =F10&G10&H10&I10 -> M055010611760101 | H10: M055010611760101 | J10: 펌프방진가대 | K10: KIB-7.5 HP | L10: Set | M10: 1 | N10: 414000 | O10: =ROUND(N10*O$2*M10,0) -> 372600 | Q10: =ROUND(P10*Q$2*M10*W10,0) -> 0 | S10: =ROUND(R10*S$2*M10,0) -> 0 | U10: =ROUND(T10*U$2*M10,0) -> 0 | V10: =SUM(O10,Q10,S10,U10) -> 372600
E11: =F11&G11&H11&I11 -> E00000806004010306 | G11: E00000806004010306 | J11: 펌프 방진가대 설치 | K11: 7.5㎾이하 | L11: (대당) | M11: 1 | O11: =ROUND(N11*O$2*M11,0) -> 0 | P11: 255261 | Q11: =ROUND(P11*Q$2*M11*W11,0) -> 224630 | S11: =ROUND(R11*S$2*M11,0) -> 0 | U11: =ROUND(T11*U$2*M11,0) -> 0 | V11: =SUM(O11,Q11,S11,U11) -> 224630 | W11: 1
E12: =F12&G12&H12&I12 -> E00000806005010102 | G12: E00000806005010102 | J12: 일반밸브 및 콕류 설치 | K12: 32~50㎜ | L12: (개당) | M12: 1 | O12: =ROUND(N12*O$2*M12,0) -> 0 | P12: 16981 | Q12: =ROUND(P12*Q$2*M12*W12,0) -> 7472 | S12: =ROUND(R12*S$2*M12,0) -> 0 | U12: =ROUND(T12*U$2*M12,0) -> 0 | V12: =SUM(O12,Q12,S12,U12) -> 7472 | W12: 0.5 | X12: H01 | Y12: 철거
E13: =F13&G13&H13&I13 -> M02502VG10050101 | H13: M02502VG10050101 | J13: 후렉시블조인트 | K13: 40A, FLEX-JOINT 철-10K | L13: 개 | M13: 1 | N13: 58000 | O13: =ROUND(N13*O$2*M13,0) -> 52200 | Q13: =ROUND(P13*Q$2*M13*W13,0) -> 0 | S13: =ROUND(R13*S$2*M13,0) -> 0 | U13: =ROUND(T13*U$2*M13,0) -> 0 | V13: =SUM(O13,Q13,S13,U13) -> 52200
E14: =F14&G14&H14&I14 -> E00000806005010102 | G14: E00000806005010102 | J14: 일반밸브 및 콕류 설치 | K14: 32~50㎜ | L14: (개당) | M14: 1 | O14: =ROUND(N14*O$2*M14,0) -> 0 | P14: 16981 | Q14: =ROUND(P14*Q$2*M14*W14,0) -> 14943 | S14: =ROUND(R14*S$2*M14,0) -> 0 | U14: =ROUND(T14*U$2*M14,0) -> 0 | V14: =SUM(O14,Q14,S14,U14) -> 14943 | W14: 1
E15: =F15&G15&H15&I15 -> E00000806010080503 | G15: E00000806010080503 | J15: 소화약제 소화설비설치(기계설비) - 기타 소화약제 소화기계설비 | K15: 압력스위치 | L15: (개당) | M15: 4 | O15: =ROUND(N15*O$2*M15,0) -> 0 | P15: 71139 | Q15: =ROUND(P15*Q$2*M15*W15,0) -> 125205 | S15: =ROUND(R15*S$2*M15,0) -> 0 | U15: =ROUND(T15*U$2*M15,0) -> 0 | V15: =SUM(O15,Q15,S15,U15) -> 125205 | W15: 0.5 | X15: H01 | Y15: 철거
E16: =F16&G16&H16&I16 -> M055015714470101 | H16: M055015714470101 | J16: NKFS-공통 | K16: 압력스위치, DC 24V | L16: 개 | M16: 4 | N16: 35000 | O16: =ROUND(N16*O$2*M16,0) -> 126000 | Q16: =ROUND(P16*Q$2*M16*W16,0) -> 0 | S16: =ROUND(R16*S$2*M16,0) -> 0 | U16: =ROUND(T16*U$2*M16,0) -> 0 | V16: =SUM(O16,Q16,S16,U16) -> 126000
E17: =F17&G17&H17&I17 -> E00000806010080503 | G17: E00000806010080503 | J17: 소화약제 소화설비설치(기계설비) - 기타 소화약제 소화기계설비 | K17: 압력스위치 | L17: (개당) | M17: 4 | O17: =ROUND(N17*O$2*M17,0) -> 0 | P17: 71139 | Q17: =ROUND(P17*Q$2*M17*W17,0) -> 250409 | S17: =ROUND(R17*S$2*M17,0) -> 0 | U17: =ROUND(T17*U$2*M17,0) -> 0 | V17: =SUM(O17,Q17,S17,U17) -> 250409 | W17: 1
E18: =F18&G18&H18&I18 -> E00000806005010102 | G18: E00000806005010102 | J18: 일반밸브 및 콕류 설치 | K18: 32~50㎜ | L18: (개당) | M18: 1 | O18: =ROUND(N18*O$2*M18,0) -> 0 | P18: 16981 | Q18: =ROUND(P18*Q$2*M18*W18,0) -> 7472 | S18: =ROUND(R18*S$2*M18,0) -> 0 | U18: =ROUND(T18*U$2*M18,0) -> 0 | V18: =SUM(O18,Q18,S18,U18) -> 7472 | W18: 0.5 | X18: H01 | Y18: 철거
E19: =F19&G19&H19&I19 -> M025129210820101 | H19: M025129210820101 | J19: Y-스트레이너 | K19: 프렌지식, 40A | L19: 개 | M19: 1 | N19: 78570 | O19: =ROUND(N19*O$2*M19,0) -> 70713 | Q19: =ROUND(P19*Q$2*M19*W19,0) -> 0 | S19: =ROUND(R19*S$2*M19,0) -> 0 | U19: =ROUND(T19*U$2*M19,0) -> 0 | V19: =SUM(O19,Q19,S19,U19) -> 70713
E20: =F20&G20&H20&I20 -> E00000806005010102 | G20: E00000806005010102 | J20: 일반밸브 및 콕류 설치 | K20: 32~50㎜ | L20: (개당) | M20: 1 | O20: =ROUND(N20*O$2*M20,0) -> 0 | P20: 16981 | Q20: =ROUND(P20*Q$2*M20*W20,0) -> 14943 | S20: =ROUND(R20*S$2*M20,0) -> 0 | U20: =ROUND(T20*U$2*M20,0) -> 0 | V20: =SUM(O20,Q20,S20,U20) -> 14943 | W20: 1
E21: =F21&G21&H21&I21 -> E00000806051113301 | G21: E00000806051113301 | J21: 밸브취부(Flange Type) 사용압력 10.5㎏/㎠ | K21: 50㎜ | L21: (개당) | M21: 1 | O21: =ROUND(N21*O$2*M21,0) -> 0 | P21: 41724 | Q21: =ROUND(P21*Q$2*M21*W21,0) -> 18359 | S21: =ROUND(R21*S$2*M21,0) -> 0 | U21: =ROUND(T21*U$2*M21,0) -> 0 | V21: =SUM(O21,Q21,S21,U21) -> 18359 | W21: 0.5 | X21: H01 | Y21: 철거
E22: =F22&G22&H22&I22 -> M025124911230102 | H22: M025124911230102 | J22: 스모렌스체크밸브 | K22: (10㎏), 50㎜ | L22: 개 | M22: 1 | N22: 61200 | O22: =ROUND(N22*O$2*M22,0) -> 55080 | Q22: =ROUND(P22*Q$2*M22*W22,0) -> 0 | S22: =ROUND(R22*S$2*M22,0) -> 0 | U22: =ROUND(T22*U$2*M22,0) -> 0 | V22: =SUM(O22,Q22,S22,U22) -> 55080
E23: =F23&G23&H23&I23 -> E00000806051113301 | G23: E00000806051113301 | J23: 밸브취부(Flange Type) 사용압력 10.5㎏/㎠ | K23: 50㎜ | L23: (개당) | M23: 1 | O23: =ROUND(N23*O$2*M23,0) -> 0 | P23: 41724 | Q23: =ROUND(P23*Q$2*M23*W23,0) -> 36717 | S23: =ROUND(R23*S$2*M23,0) -> 0 | U23: =ROUND(T23*U$2*M23,0) -> 0 | V23: =SUM(O23,Q23,S23,U23) -> 36717 | W23: 1
E24: =F24&G24&H24&I24 -> M02501KA10050102 | H24: M02501KA10050102 | J24: 일반배관용탄소강관 | K24: 백관(반제품), 호칭40A, 외경48.6㎜, 두께3.25㎜, 단중3.63㎏/m | L24: m | M24: 1 | N24: 7000 | O24: =ROUND(N24*O$2*M24,0) -> 6300 | Q24: =ROUND(P24*Q$2*M24*W24,0) -> 0 | S24: =ROUND(R24*S$2*M24,0) -> 0 | U24: =ROUND(T24*U$2*M24,0) -> 0 | V24: =SUM(O24,Q24,S24,U24) -> 6300
E25: =F25&G25&H25&I25 -> E00000806001010305 | G25: E00000806001010305 | J25: 나사식 접합 및 배관 | K25: 40㎜ | L25: m | M25: 1 | O25: =ROUND(N25*O$2*M25,0) -> 0 | P25: 22290 | Q25: =ROUND(P25*Q$2*M25*W25,0) -> 19615 | S25: =ROUND(R25*S$2*M25,0) -> 0 | U25: =ROUND(T25*U$2*M25,0) -> 0 | V25: =SUM(O25,Q25,S25,U25) -> 19615 | W25: 1
E26: =F26&G26&H26&I26 -> M025805910060112 | H26: M025805910060112 | J26: 가교발포폴리에틸렌보온재 | K26: 카이론, 강관 40, 20T(난연)색상보온재 | L26: m | M26: 1 | N26: 2703 | O26: =ROUND(N26*O$2*M26,0) -> 2433 | Q26: =ROUND(P26*Q$2*M26*W26,0) -> 0 | S26: =ROUND(R26*S$2*M26,0) -> 0 | U26: =ROUND(T26*U$2*M26,0) -> 0 | V26: =SUM(O26,Q26,S26,U26) -> 2433
E27: =F27&G27&H27&I27 -> 999999 | G27: 999999 | J27: 일반마감 배관보온 - 발포폴리에틸렌보온재 | K27: Ø40㎜ - 보온두께 : 25㎜이하(시공량 : 63m) | L27: (일당) | M27: 1 | O27: =ROUND(N27*O$2*M27,0) -> 0 | P27: 9112.9365 | Q27: =ROUND(P27*Q$2*M27*W27,0) -> 8019 | S27: =ROUND(R27*S$2*M27,0) -> 0 | U27: =ROUND(T27*U$2*M27,0) -> 0 | V27: =SUM(O27,Q27,S27,U27) -> 8019 | W27: 1
E28: =F28&G28&H28&I28 -> M025805910080112 | H28: M025805910080112 | J28: 가교발포폴리에틸렌보온재 | K28: 카이론, 강관 50, 20T(난연)색상보온재 | L28: m | M28: 0.5 | N28: 3075 | O28: =ROUND(N28*O$2*M28,0) -> 1384 | Q28: =ROUND(P28*Q$2*M28*W28,0) -> 0 | S28: =ROUND(R28*S$2*M28,0) -> 0 | U28: =ROUND(T28*U$2*M28,0) -> 0 | V28: =SUM(O28,Q28,S28,U28) -> 1384
E29: =F29&G29&H29&I29 -> 999999 | G29: 999999 | J29: 일반마감 배관보온 - 발포폴리에틸렌보온재 | K29: Ø50㎜ - 보온두께 : 25㎜이하(시공량 : 54m) | L29: (일당) | M29: 0.5 | O29: =ROUND(N29*O$2*M29,0) -> 0 | P29: 11482.3 | Q29: =ROUND(P29*Q$2*M29*W29,0) -> 5052 | S29: =ROUND(R29*S$2*M29,0) -> 0 | U29: =ROUND(T29*U$2*M29,0) -> 0 | V29: =SUM(O29,Q29,S29,U29) -> 5052 | W29: 1
E30: =F30&G30&H30&I30 -> M025805910160112 | H30: M025805910160112 | J30: 가교발포폴리에틸렌보온재 | K30: 카이론, 강관 250, 20T(난연)색상보온재 | L30: m | M30: 1 | N30: 15330 | O30: =ROUND(N30*O$2*M30,0) -> 13797 | Q30: =ROUND(P30*Q$2*M30*W30,0) -> 0 | S30: =ROUND(R30*S$2*M30,0) -> 0 | U30: =ROUND(T30*U$2*M30,0) -> 0 | V30: =SUM(O30,Q30,S30,U30) -> 13797
E31: =F31&G31&H31&I31 -> 999999 | G31: 999999 | J31: 일반마감 배관보온 - 발포폴리에틸렌보온재 | K31: Ø250㎜ - 보온두께 : 25㎜이하(시공량 : 14m) | L31: (일당) | M31: 1 | O31: =ROUND(N31*O$2*M31,0) -> 0 | P31: 41008.214 | Q31: =ROUND(P31*Q$2*M31*W31,0) -> 36087 | S31: =ROUND(R31*S$2*M31,0) -> 0 | U31: =ROUND(T31*U$2*M31,0) -> 0 | V31: =SUM(O31,Q31,S31,U31) -> 36087 | W31: 1
E32: =F32&G32&H32&I32 -> M025400210680101 | H32: M025400210680101 | J32: 플랜지패킹 | K32: 고무(RF)-10K, 40A | L32: 개 | M32: 4 | N32: 420 | O32: =ROUND(N32*O$2*M32,0) -> 1512 | Q32: =ROUND(P32*Q$2*M32*W32,0) -> 0 | S32: =ROUND(R32*S$2*M32,0) -> 0 | U32: =ROUND(T32*U$2*M32,0) -> 0 | V32: =SUM(O32,Q32,S32,U32) -> 1512 | W32: 1
E33: =F33&G33&H33&I33 -> M025400210690101 | H33: M025400210690101 | J33: 플랜지패킹 | K33: 고무(RF)-10K, 50A | L33: 개 | M33: 2 | N33: 470 | O33: =ROUND(N33*O$2*M33,0) -> 846 | Q33: =ROUND(P33*Q$2*M33*W33,0) -> 0 | S33: =ROUND(R33*S$2*M33,0) -> 0 | U33: =ROUND(T33*U$2*M33,0) -> 0 | V33: =SUM(O33,Q33,S33,U33) -> 846 | W33: 1
E34: =F34&G34&H34&I34 -> M02501E510050103 | H34: M02501E510050103 | J34: 철플랜지 | K34: 40A, 10K-SF390A-SOFF | L34: 개 | M34: 4 | N34: 3916 | O34: =ROUND(N34*O$2*M34,0) -> 14098 | Q34: =ROUND(P34*Q$2*M34*W34,0) -> 0 | S34: =ROUND(R34*S$2*M34,0) -> 0 | U34: =ROUND(T34*U$2*M34,0) -> 0 | V34: =SUM(O34,Q34,S34,U34) -> 14098 | W34: 1
E35: =F35&G35&H35&I35 -> M02501E510060103 | H35: M02501E510060103 | J35: 철플랜지 | K35: 50A, 10K-SF390A-SOFF | L35: 개 | M35: 2 | N35: 4670 | O35: =ROUND(N35*O$2*M35,0) -> 8406 | Q35: =ROUND(P35*Q$2*M35*W35,0) -> 0 | S35: =ROUND(R35*S$2*M35,0) -> 0 | U35: =ROUND(T35*U$2*M35,0) -> 0 | V35: =SUM(O35,Q35,S35,U35) -> 8406 | W35: 1
E36: =F36&G36&H36&I36 -> E00000806001010105 | G36: E00000806001010105 | J36: 용접접합 | K36: 40㎜ | L36: 용접개소 | M36: 4 | O36: =ROUND(N36*O$2*M36,0) -> 0 | P36: 18691 | Q36: =ROUND(P36*Q$2*M36*W36,0) -> 65792 | S36: =ROUND(R36*S$2*M36,0) -> 0 | U36: =ROUND(T36*U$2*M36,0) -> 0 | V36: =SUM(O36,Q36,S36,U36) -> 65792 | W36: 1
E37: =F37&G37&H37&I37 -> E00000806001010106 | G37: E00000806001010106 | J37: 용접접합 | K37: 50㎜ | L37: 용접개소 | M37: 2 | O37: =ROUND(N37*O$2*M37,0) -> 0 | P37: 22696 | Q37: =ROUND(P37*Q$2*M37*W37,0) -> 39945 | S37: =ROUND(R37*S$2*M37,0) -> 0 | U37: =ROUND(T37*U$2*M37,0) -> 0 | V37: =SUM(O37,Q37,S37,U37) -> 39945 | W37: 1
E38: =F38&G38&H38&I38 -> E00000806001030204 | G38: E00000806001030204 | J38: 용접접함 - 참고(&#8226; TIG용접 소모재료) | K38: Ø40㎜ | L38: 용접개소 | M38: 4 | N38: 1734 | O38: =ROUND(N38*O$2*M38,0) -> 6242 | Q38: =ROUND(P38*Q$2*M38*W38,0) -> 0 | S38: =ROUND(R38*S$2*M38,0) -> 0 | U38: =ROUND(T38*U$2*M38,0) -> 0 | V38: =SUM(O38,Q38,S38,U38) -> 6242
E39: =F39&G39&H39&I39 -> E00000806001030205 | G39: E00000806001030205 | J39: 용접접함 - 참고(&#8226; TIG용접 소모재료) | K39: Ø50㎜ | L39: 용접개소 | M39: 2 | N39: 2399 | O39: =ROUND(N39*O$2*M39,0) -> 4318 | Q39: =ROUND(P39*Q$2*M39*W39,0) -> 0 | S39: =ROUND(R39*S$2*M39,0) -> 0 | U39: =ROUND(T39*U$2*M39,0) -> 0 | V39: =SUM(O39,Q39,S39,U39) -> 4318
E40: =F40&G40&H40&I40 -> E00000807041490101 | G40: E00000807041490101 | J40: 전동기 결선 | K40: 전동기결선 7.5㎾ 이하 | L40: (대당) | M40: 1 | O40: =ROUND(N40*O$2*M40,0) -> 0 | P40: 43528 | Q40: =ROUND(P40*Q$2*M40*W40,0) -> 19152 | S40: =ROUND(R40*S$2*M40,0) -> 0 | U40: =ROUND(T40*U$2*M40,0) -> 0 | V40: =SUM(O40,Q40,S40,U40) -> 19152 | W40: 0.5 | X40: H01 | Y40: 철거
...

Sheet Upload
A1: 구분 | B1: 표준단가 | C1: 표준품셈 | D1: 물가정보 | E1: 노임단가 | F1: 수량 | H1: ★ 작성방법
A2: ='내역서(표준단가)'!E6 -> E00000806004010106 | B2: ='내역서(표준단가)'!F6 -> 0 | C2: ='내역서(표준단가)'!G6 -> E00000806004010106 | D2: ='내역서(표준단가)'!H6 -> 0 | E2: ='내역서(표준단가)'!I6 -> 0 | F2: ='내역서(표준단가)'!M6 -> 1
A3: ='내역서(표준단가)'!E7 -> M025332910040101 | B3: ='내역서(표준단가)'!F7 -> 0 | C3: ='내역서(표준단가)'!G7 -> 0 | D3: ='내역서(표준단가)'!H7 -> M025332910040101 | E3: ='내역서(표준단가)'!I7 -> 0 | F3: ='내역서(표준단가)'!M7 -> 1 | H3: ① 내역서(엑셀) 내 품목코드, 수량 입력시 upload자료 내 자동반영됨
A4: ='내역서(표준단가)'!E8 -> E00000806004010106 | B4: ='내역서(표준단가)'!F8 -> 0 | C4: ='내역서(표준단가)'!G8 -> E00000806004010106 | D4: ='내역서(표준단가)'!H8 -> 0 | E4: ='내역서(표준단가)'!I8 -> 0 | F4: ='내역서(표준단가)'!M8 -> 1 | H4: ② 일부항목 미입력시 업로드 안됨
A5: ='내역서(표준단가)'!E9 -> E00000806004010306 | B5: ='내역서(표준단가)'!F9 -> 0 | C5: ='내역서(표준단가)'!G9 -> E00000806004010306 | D5: ='내역서(표준단가)'!H9 -> 0 | E5: ='내역서(표준단가)'!I9 -> 0 | F5: ='내역서(표준단가)'!M9 -> 1 | H5: ③ 시중가/할증은 atG 화면 내 별도입력(본 탭 내에는 표준 Code만 입력)
A6: ='내역서(표준단가)'!E10 -> M055010611760101 | B6: ='내역서(표준단가)'!F10 -> 0 | C6: ='내역서(표준단가)'!G10 -> 0 | D6: ='내역서(표준단가)'!H10 -> M055010611760101 | E6: ='내역서(표준단가)'!I10 -> 0 | F6: ='내역서(표준단가)'!M10 -> 1
A7: ='내역서(표준단가)'!E11 -> E00000806004010306 | B7: ='내역서(표준단가)'!F11 -> 0 | C7: ='내역서(표준단가)'!G11 -> E00000806004010306 | D7: ='내역서(표준단가)'!H11 -> 0 | E7: ='내역서(표준단가)'!I11 -> 0 | F7: ='내역서(표준단가)'!M11 -> 1
A8: ='내역서(표준단가)'!E12 -> E00000806005010102 | B8: ='내역서(표준단가)'!F12 -> 0 | C8: ='내역서(표준단가)'!G12 -> E00000806005010102 | D8: ='내역서(표준단가)'!H12 -> 0 | E8: ='내역서(표준단가)'!I12 -> 0 | F8: ='내역서(표준단가)'!M12 -> 1
A9: ='내역서(표준단가)'!E13 -> M02502VG10050101 | B9: ='내역서(표준단가)'!F13 -> 0 | C9: ='내역서(표준단가)'!G13 -> 0 | D9: ='내역서(표준단가)'!H13 -> M02502VG10050101 | E9: ='내역서(표준단가)'!I13 -> 0 | F9: ='내역서(표준단가)'!M13 -> 1
A10: ='내역서(표준단가)'!E14 -> E00000806005010102 | B10: ='내역서(표준단가)'!F14 -> 0 | C10: ='내역서(표준단가)'!G14 -> E00000806005010102 | D10: ='내역서(표준단가)'!H14 -> 0 | E10: ='내역서(표준단가)'!I14 -> 0 | F10: ='내역서(표준단가)'!M14 -> 1
A11: ='내역서(표준단가)'!E15 -> E00000806010080503 | B11: ='내역서(표준단가)'!F15 -> 0 | C11: ='내역서(표준단가)'!G15 -> E00000806010080503 | D11: ='내역서(표준단가)'!H15 -> 0 | E11: ='내역서(표준단가)'!I15 -> 0 | F11: ='내역서(표준단가)'!M15 -> 4
A12: ='내역서(표준단가)'!E16 -> M055015714470101 | B12: ='내역서(표준단가)'!F16 -> 0 | C12: ='내역서(표준단가)'!G16 -> 0 | D12: ='내역서(표준단가)'!H16 -> M055015714470101 | E12: ='내역서(표준단가)'!I16 -> 0 | F12: ='내역서(표준단가)'!M16 -> 4
A13: ='내역서(표준단가)'!E17 -> E00000806010080503 | B13: ='내역서(표준단가)'!F17 -> 0 | C13: ='내역서(표준단가)'!G17 -> E00000806010080503 | D13: ='내역서(표준단가)'!H17 -> 0 | E13: ='내역서(표준단가)'!I17 -> 0 | F13: ='내역서(표준단가)'!M17 -> 4
A14: ='내역서(표준단가)'!E18 -> E00000806005010102 | B14: ='내역서(표준단가)'!F18 -> 0 | C14: ='내역서(표준단가)'!G18 -> E00000806005010102 | D14: ='내역서(표준단가)'!H18 -> 0 | E14: ='내역서(표준단가)'!I18 -> 0 | F14: ='내역서(표준단가)'!M18 -> 1
A15: ='내역서(표준단가)'!E19 -> M025129210820101 | B15: ='내역서(표준단가)'!F19 -> 0 | C15: ='내역서(표준단가)'!G19 -> 0 | D15: ='내역서(표준단가)'!H19 -> M025129210820101 | E15: ='내역서(표준단가)'!I19 -> 0 | F15: ='내역서(표준단가)'!M19 -> 1
A16: ='내역서(표준단가)'!E20 -> E00000806005010102 | B16: ='내역서(표준단가)'!F20 -> 0 | C16: ='내역서(표준단가)'!G20 -> E00000806005010102 | D16: ='내역서(표준단가)'!H20 -> 0 | E16: ='내역서(표준단가)'!I20 -> 0 | F16: ='내역서(표준단가)'!M20 -> 1
A17: ='내역서(표준단가)'!E21 -> E00000806051113301 | B17: ='내역서(표준단가)'!F21 -> 0 | C17: ='내역서(표준단가)'!G21 -> E00000806051113301 | D17: ='내역서(표준단가)'!H21 -> 0 | E17: ='내역서(표준단가)'!I21 -> 0 | F17: ='내역서(표준단가)'!M21 -> 1
... A38: ='내역서(표준단가)'!E42 -> M031002001100101 | B38: ='내역서(표준단가)'!F42 -> 0 | C38: ='내역서(표준단가)'!G42 -> 0 | D38: ='내역서(표준단가)'!H42 -> M031002001100101 | E38: ='내역서(표준단가)'!I42 -> 0 | F38: ='내역서(표준단가)'!M42 -> 9

Sheet 할증기준
A1: ■ atG 할증기준

Sheet 공사수립계획서
B1: 공사수립계획서
B4: 업 체 명 | C4: 주식회사 준 마 | D4: 일 시 | E4: =갑지!B9 -> 2025 년 10 월 14 일
B5: 공 사 명 | C5: =갑지!B7 -> LG사택 보조펌프 교체_소방
B6: 공사 업체 | C6: ■ 공사기간 : 입찰시스템 계약기간에 준함
C7: ■ 인원투입계획 : 총 4 명(주말 : 명)
C8: ■ 시공방법
C9: -. 충압펌프 철거 후 교체
C10: -. 압력스위치 철거 후 교체
C11: -. 펌프방진가대 철거 후 교체
C12: -. 후렉시블조인트 철거 후 교체
C13: -. 작업완료 후 동작 및 누수확인
C14: -. 현장 정리 정돈
C25: ■ 위험작업 유무 : 유(화기/고소/중장비 등)
C26: ■ 안전확보 방안 :
C27: -. 천장 상부 작업 시 조도 확보, 생명줄 설치 후 안전벨트 이중 고리 사용 후 작업 실시
C28: -. 사다리 작업 시 사다리 보조자 배치 및 안전벨트 이중 고리 사용 후 작업 실시
... C30: ■ 주요 사용물질 :
B34: =C4 -> 주식회사 준 마 | C34: 성명 : 민 상 진 | D34: (인감/서명)
B35: ㈜ S&I Corp. | C35: 성명 : 이 종 근 | D35: 서명
