Workbook

Sheet 갑지
A2: 견 적 서
A5: 수신인: | B5: (주)에스앤아이코퍼레이션 | F5: 주 식 회 사 대 양 이 엔 씨 대 표 박 찬 현
A7: 공사명: | B7: 사택 노후 차단기 교체1안 | F7: 대전광역시 대덕구 아리랑로 125번길 11
A9: 견적일: | B9: 2025년 03월 일 | F9: 전화 : 042-628-8301 /FAX : 042-628-8304
A12: 금액: | B12: =NUMBERSTRING(F31,1) -> 육백일십삼만구천 | D12: 원정
A14: NO | B14: 품명 | C14: 규격 | D14: 수량 | E14: 단위 | F14: 금액 | G14: 비고
B15: 직접비
B16: 재료비 | F16: =내역서_작업!H2156 -> 1681480.4
B17: 노무비 | F17: =내역서_작업!J2156 -> 3609118
B18: 기계/기타경비 | F18: =내역서_작업!L2156 -> 0
B19: 소계 | F19: =F16+F17+F18 -> 5290598.4
B20: 간접비
B21: 국민연금 | C21: 노무비*4.5% | D21: 1 | E21: 식 | F21: =F17*4.5% -> 162410.31 | G21: 모든공사에 적용
B22: 건강보험료 | C22: 노무비*3.545% | D22: 1 | E22: 식 | F22: =F17*3.545% -> 127943.23 | G22: 모든공사에 적용
B23: 장기요양보험료 | C23: 건강보험료*12.95% | D23: 1 | E23: 식 | F23: =F22*12.95% -> 16568.649 | G23: 모든공사에 적용
B24: 고용보험료 | C24: 노무비*1.01% | D24: 1 | E24: 식 | F24: =F17*1.01% -> 36452.092 | G24: 모든공사에 적용
B25: 산재보험료 | C25: 노무비*3.56% | D25: 1 | E25: 식 | F25: =F17*3.56% -> 128484.6 | G25: 모든공사에 적용
B26: 산업안전보건관리비 | C26: (재료비+노무비)*3.11% | D26: 1 | E26: 식 | F26: =(F16+F17)*3.11% -> 164537.61 | G26: 모든공사에 적용
B27: 일반관리비/이윤 | C27: (노무비+간접공사비)*5% | D27: 1 | E27: 식 | F27: =SUM(F17+F21+F22+F23+F24+F25+F26)*5% -> 212275.72
B28: 소계 | F28: =F21+F22+F23+F24+F25+F26+F27 -> 848672.22
F30: =F19+F28+F29 -> 6139270.6
B31: 합계(단수조정) | F31: =ROUNDDOWN(F30,-3) -> 6139000
B32: VAT별도

Sheet Upload
A1: 구분 | B1: 표준단가 | C1: 표준품셈 | D1: 물가정보 | E1: 노임단가 | F1: 수량
A2: ='Upload(참조) (2)'!Q2 | B2: ='Upload(참조) (2)'!R2 | C2: ='Upload(참조) (2)'!S2 | D2: ='Upload(참조) (2)'!T2 | E2: ='Upload(참조) (2)'!U2 | F2: ='Upload(참조) (2)'!V2 -> 0
A3: ='Upload(참조) (2)'!Q4 -> M045011410060101 | B3: ='Upload(참조) (2)'!R4 | C3: ='Upload(참조) (2)'!S4 | D3: ='Upload(참조) (2)'!T4 -> M045011410060101 | E3: ='Upload(참조) (2)'!U4 | F3: ='Upload(참조) (2)'!V4 -> 40
A4: ='Upload(참조) (2)'!Q5 -> E00000807041210101 | B4: ='Upload(참조) (2)'!R5 | C4: ='Upload(참조) (2)'!S5 -> E00000807041210101 | D4: ='Upload(참조) (2)'!T5 | E4: ='Upload(참조) (2)'!U5 | F4: ='Upload(참조) (2)'!V5 -> 40
A5: ='Upload(참조) (2)'!Q6 -> E00000808475160101 | B5: ='Upload(참조) (2)'!R6 | C5: ='Upload(참조) (2)'!S6 -> E00000808475160101 | D5: ='Upload(참조) (2)'!T6 | E5: ='Upload(참조) (2)'!U6 | F5: ='Upload(참조) (2)'!V6 -> 40
A6: ='Upload(참조) (2)'!Q7 -> M045330711190101 | B6: ='Upload(참조) (2)'!R7 | C6: ='Upload(참조) (2)'!S7 | D6: ='Upload(참조) (2)'!T7 -> M045330711190101 | E6: ='Upload(참조) (2)'!U7 | F6: ='Upload(참조) (2)'!V7 -> 20
A7: ='Upload(참조) (2)'!Q8 -> E00000807041290102 | B7: ='Upload(참조) (2)'!R8 | C7: ='Upload(참조) (2)'!S8 -> E00000807041290102 | D7: ='Upload(참조) (2)'!T8 | E7: ='Upload(참조) (2)'!U8 | F7: ='Upload(참조) (2)'!V8 -> 20
A8: ='Upload(참조) (2)'!Q9 -> M045330710020101 | B8: ='Upload(참조) (2)'!R9 | C8: ='Upload(참조) (2)'!S9 | D8: ='Upload(참조) (2)'!T9 -> M045330710020101 | E8: ='Upload(참조) (2)'!U9 | F8: ='Upload(참조) (2)'!V9 -> 50
A9: ='Upload(참조) (2)'!Q10 -> E00000807041290101 | B9: ='Upload(참조) (2)'!R10 | C9: ='Upload(참조) (2)'!S10 -> E00000807041290101 | D9: ='Upload(참조) (2)'!T10 | E9: ='Upload(참조) (2)'!U10 | F9: ='Upload(참조) (2)'!V10 -> 50
A10: ='Upload(참조) (2)'!Q11 | B10: ='Upload(참조) (2)'!R11 | C10: ='Upload(참조) (2)'!S11 | D10: ='Upload(참조) (2)'!T11 | E10: ='Upload(참조) (2)'!U11 | F10: ='Upload(참조) (2)'!V11 -> 0
A11: ='Upload(참조) (2)'!Q12 | B11: ='Upload(참조) (2)'!R12 | C11: ='Upload(참조) (2)'!S12 | D11: ='Upload(참조) (2)'!T12 | E11: ='Upload(참조) (2)'!U12 | F11: ='Upload(참조) (2)'!V12 -> 0
A12: ='Upload(참조) (2)'!Q13 | B12: ='Upload(참조) (2)'!R13 | C12: ='Upload(참조) (2)'!S13 | D12: ='Upload(참조) (2)'!T13 | E12: ='Upload(참조) (2)'!U13 | F12: ='Upload(참조) (2)'!V13 -> 0
A13: ='Upload(참조) (2)'!Q14 | B13: ='Upload(참조) (2)'!R14 | C13: ='Upload(참조) (2)'!S14 | D13: ='Upload(참조) (2)'!T14 | E13: ='Upload(참조) (2)'!U14 | F13: ='Upload(참조) (2)'!V14 -> 0
A14: ='Upload(참조) (2)'!Q15 | B14: ='Upload(참조) (2)'!R15 | C14: ='Upload(참조) (2)'!S15 | D14: ='Upload(참조) (2)'!T15 | E14: ='Upload(참조) (2)'!U15 | F14: ='Upload(참조) (2)'!V15 -> 0
... A86: ='Upload(참조) (2)'!Q87 | B86: ='Upload(참조) (2)'!R87 | C86: ='Upload(참조) (2)'!S87 | D86: ='Upload(참조) (2)'!T87 | E86: ='Upload(참조) (2)'!U87 | F86: ='Upload(참조) (2)'!V87 -> 0

Sheet 내역서_작업
H2: ▼낙찰율 | J2: ▼낙찰율 | L2: ▼낙찰율 | N2: ▼낙찰율 | P2: ▼할증율
A3: 공사명: | C3: =갑지!B7 -> 사택 노후 차단기 교체1안 | H3: 0.83 | J3: 0.4 | L3: 0.6 | N3: 0.6 | P3: 1 | Q3: 기본
A4: 표준 Code | C4: 주요내역 | E4: 단위 | F4: 수량 | G4: 재료비 | I4: 노무비 | K4: 기계경비 | M4: 기타경비(부자재비) | O4: 합계 | P4: 비고
C5: 품목 | D5: 규격 | G5: 단가 | H5: 금액 | I5: 단가 | J5: 금액 | K5: 단가 | L5: 금액 | M5: 단가 | N5: 금액 | P5: 할증율(%) | Q5: 기준
A6: M045041310630101 | B6: 케이블 | C6: FW-CV케이블 | D6: 0.6/1KV 3C 4㎟ | E6: m | G6: 2846 | H6: =F6*G6*$H$3 -> 0 | J6: =IF(P6="",F6*I6*$J$3*$P$3,F6*I6*$J$3*P6) -> 0 | O6: =SUM(H6+J6)+L6+N6 -> 0
A7: E00000807041230112 | B7: 케이블 | C7: 제어용 케이블 설치 | D7: 3C 4.0㎟ | E7: (m 당) | H7: =F7*G7*$H$3 -> 0 | I7: 6507 | J7: =IF(P7="",F7*I7*$J$3*$P$3,F7*I7*$J$3*P7) -> 0 | O7: =SUM(H7+J7)+L7+N7 -> 0
A8: M045041310640101 | B8: 케이블 | C8: FW-CV케이블 | D8: 0.6/1KV 3C 6㎟ | E8: m | G8: 3929 | H8: =F8*G8*$H$3 -> 0 | J8: =IF(P8="",F8*I8*$J$3*$P$3,F8*I8*$J$3*P8) -> 0 | O8: =SUM(H8+J8)+L8+N8 -> 0
A9: E00000807041230113 | B9: 케이블 | C9: 제어용 케이블 설치 | D9: 3C 6.0㎟ | E9: (m 당) | H9: =F9*G9*$H$3 -> 0 | I9: 7690 | J9: =IF(P9="",F9*I9*$J$3*$P$3,F9*I9*$J$3*P9) -> 0 | O9: =SUM(H9+J9)+L9+N9 -> 0
A10: M045041310650101 | B10: 케이블 | C10: FW-CV케이블 | D10: 0.6/1KV 3C 10㎟ | E10: m | G10: 6248 | H10: =F10*G10*$H$3 -> 0 | J10: =IF(P10="",F10*I10*$J$3*$P$3,F10*I10*$J$3*P10) -> 0 | O10: =SUM(H10+J10)+L10+N10 -> 0
A11: E00000807041230115 | B11: 케이블 | C11: 제어용 케이블 설치 | D11: 3C 10㎟이하 | E11: (m 당) | H11: =F11*G11*$H$3 -> 0 | I11: 10648 | J11: =IF(P11="",F11*I11*$J$3*$P$3,F11*I11*$J$3*P11) -> 0 | O11: =SUM(H11+J11)+L11+N11 -> 0
A12: M045041310660101 | B12: 케이블 | C12: FW-CV케이블 | D12: 0.6/1KV 3C 16㎟ | E12: m | G12: 9751 | H12: =F12*G12*$H$3 -> 0 | J12: =IF(P12="",F12*I12*$J$3*$P$3,F12*I12*$J$3*P12) -> 0 | O12: =SUM(H12+J12)+L12+N12 -> 0
A13: E00000807041210101 | B13: 케이블 | C13: 전력케이블 구내설치 (PVC 및 고무절연외장 케이블) | D13: 600V 16㎟이하×1C | E13: (m 당) | H13: =F13*G13*$H$3 -> 0 | I13: 6803 | J13: =IF(P13="",F13*I13*$J$3*$P$3,F13*I13*$J$3*P13) -> 0 | O13: =SUM(H13+J13)+L13+N13 -> 0 | P13: 2 | Q13: 3P할증200%
A14: M045041310670101 | B14: 케이블 | C14: FW-CV케이블 | D14: 0.6/1KV 3C 25㎟ | E14: m | G14: 15157 | H14: =F14*G14*$H$3 -> 0 | J14: =IF(P14="",F14*I14*$J$3*$P$3,F14*I14*$J$3*P14) -> 0 | O14: =SUM(H14+J14)+L14+N14 -> 0
A15: E00000807041210102 | B15: 케이블 | C15: 전력케이블 구내설치 (PVC 및 고무절연외장 케이블) | D15: 600V 25㎟이하×1C | E15: (m 당) | H15: =F15*G15*$H$3 -> 0 | I15: 8873 | J15: =IF(P15="",F15*I15*$J$3*$P$3,F15*I15*$J$3*P15) -> 0 | O15: =SUM(H15+J15)+L15+N15 -> 0 | P15: 2 | Q15: 3P할증200%
A16: M045041310680101 | B16: 케이블 | C16: FW-CV케이블 | D16: 0.6/1KV 3C 35㎟ | E16: m | G16: 20157 | H16: =F16*G16*$H$3 -> 0 | J16: =IF(P16="",F16*I16*$J$3*$P$3,F16*I16*$J$3*P16) -> 0 | O16: =SUM(H16+J16)+L16+N16 -> 0
A17: E00000807041210103 | B17: 케이블 | C17: 전력케이블 구내설치 (PVC 및 고무절연외장 케이블) | D17: 600V 38㎟이하×1C | E17: (m 당) | H17: =F17*G17*$H$3 -> 0 | I17: 10648 | J17: =IF(P17="",F17*I17*$J$3*$P$3,F17*I17*$J$3*P17) -> 0 | O17: =SUM(H17+J17)+L17+N17 -> 0 | P17: 2 | Q17: 3P할증200%
A18: M045041310690101 | B18: 케이블 | C18: FW-CV케이블 | D18: 0.6/1KV 3C 50㎟ | E18: m | G18: 27428 | H18: =F18*G18*$H$3 -> 0 | J18: =IF(P18="",F18*I18*$J$3*$P$3,F18*I18*$J$3*P18) -> 0 | O18: =SUM(H18+J18)+L18+N18 -> 0
A19: E00000807041210104 | B19: 케이블 | C19: 전력케이블 구내설치 (PVC 및 고무절연외장 케이블) | D19: 600V 50㎟이하×1C | E19: (m 당) | H19: =F19*G19*$H$3 -> 0 | I19: 12718 | J19: =IF(P19="",F19*I19*$J$3*$P$3,F19*I19*$J$3*P19) -> 0 | O19: =SUM(H19+J19)+L19+N19 -> 0
A20: M045041310780101 | B20: 케이블 | C20: FW-CV케이블 | D20: 0.6/1KV 4C 2.5㎟ | E20: m | G20: 2513 | H20: =F20*G20*$H$3 -> 0 | J20: =IF(P20="",F20*I20*$J$3*$P$3,F20*I20*$J$3*P20) -> 0 | O20: =SUM(H20+J20)+L20+N20 -> 0
A21: E00000807041230116 | B21: 케이블 | C21: 제어용 케이블 설치 | D21: 4C 2.5㎟ | E21: (m 당) | H21: =F21*G21*$H$3 -> 0 | I21: 7690 | J21: =IF(P21="",F21*I21*$J$3*$P$3,F21*I21*$J$3*P21) -> 0 | O21: =SUM(H21+J21)+L21+N21 -> 0
A22: M045041310790101 | B22: 케이블 | C22: FW-CV케이블 | D22: 0.6/1KV 4C 4㎟ | E22: m | G22: 3604 | H22: =F22*G22*$H$3 -> 0 | J22: =IF(P22="",F22*I22*$J$3*$P$3,F22*I22*$J$3*P22) -> 0 | O22: =SUM(H22+J22)+L22+N22 -> 0
A23: E00000807041230117 | B23: 케이블 | C23: 제어용 케이블 설치 | D23: 4C 4.0㎟ | E23: (m 당) | H23: =F23*G23*$H$3 -> 0 | I23: 8577 | J23: =IF(P23="",F23*I23*$J$3*$P$3,F23*I23*$J$3*P23) -> 0 | O23: =SUM(H23+J23)+L23+N23 -> 0
A24: M045041310800101 | B24: 케이블 | C24: FW-CV케이블 | D24: 0.6/1KV 4C 6㎟ | E24: m | G24: 5058 | H24: =F24*G24*$H$3 -> 0 | J24: =IF(P24="",F24*I24*$J$3*$P$3,F24*I24*$J$3*P24) -> 0 | O24: =SUM(H24+J24)+L24+N24 -> 0
A25: E00000807041230118 | B25: 케이블 | C25: 제어용 케이블 설치 | D25: 4C 6.0㎟ | E25: (m 당) | H25: =F25*G25*$H$3 -> 0 | I25: 10056 | J25: =IF(P25="",F25*I25*$J$3*$P$3,F25*I25*$J$3*P25) -> 0 | O25: =SUM(H25+J25)+L25+N25 -> 0
A26: M045041310810101 | B26: 케이블 | C26: FW-CV케이블 | D26: 0.6/1KV 4C 10㎟ | E26: m | G26: 8027 | H26: =F26*G26*$H$3 -> 0 | J26: =IF(P26="",F26*I26*$J$3*$P$3,F26*I26*$J$3*P26) -> 0 | O26: =SUM(H26+J26)+L26+N26 -> 0
A27: E00000807041230120 | B27: 케이블 | C27: 제어용 케이블 설치 | D27: 4C 10㎟이하 | E27: (m 당) | H27: =F27*G27*$H$3 -> 0 | I27: 14493 | J27: =IF(P27="",F27*I27*$J$3*$P$3,F27*I27*$J$3*P27) -> 0 | O27: =SUM(H27+J27)+L27+N27 -> 0
A28: M045041310820101 | B28: 케이블 | C28: FW-CV케이블 | D28: 0.6/1KV 4C 16㎟ | E28: m | G28: 12911 | H28: =F28*G28*$H$3 -> 0 | J28: =IF(P28="",F28*I28*$J$3*$P$3,F28*I28*$J$3*P28) -> 0 | O28: =SUM(H28+J28)+L28+N28 -> 0
A29: E00000807041210101 | B29: 케이블 | C29: 전력케이블 구내설치 (PVC 및 고무절연외장 케이블) | D29: 600V 16㎟이하×1C | E29: (m 당) | H29: =F29*G29*$H$3 -> 0 | I29: 6803 | J29: =IF(P29="",F29*I29*$J$3*$P$3,F29*I29*$J$3*P29) -> 0 | O29: =SUM(H29+J29)+L29+N29 -> 0 | P29: 2.6 | Q29: 4P할증260%
A30: M045041310830101 | B30: 케이블 | C30: FW-CV케이블 | D30: 0.6/1KV 4C 25㎟ | E30: m | G30: 19933 | H30: =F30*G30*$H$3 -> 0 | J30: =IF(P30="",F30*I30*$J$3*$P$3,F30*I30*$J$3*P30) -> 0 | O30: =SUM(H30+J30)+L30+N30 -> 0
A31: E00000807041210102 | B31: 케이블 | C31: 전력케이블 구내설치 (PVC 및 고무절연외장 케이블) | D31: 600V 25㎟이하×1C | E31: (m 당) | H31: =F31*G31*$H$3 -> 0 | I31: 8873 | J31: =IF(P31="",F31*I31*$J$3*$P$3,F31*I31*$J$3*P31) -> 0 | O31: =SUM(H31+J31)+L31+N31 -> 0 | P31: 2.6 | Q31: 4P할증260%
A32: M045041310840101 | B32: 케이블 | C32: FW-CV케이블 | D32: 0.6/1KV 4C 35㎟ | E32: m | G32: 26616 | H32: =F32*G32*$H$3 -> 0 | J32: =IF(P32="",F32*I32*$J$3*$P$3,F32*I32*$J$3*P32) -> 0 | O32: =SUM(H32+J32)+L32+N32 -> 0
A33: E00000807041210103 | B33: 케이블 | C33: 전력케이블 구내설치 (PVC 및 고무절연외장 케이블) | D33: 600V 38㎟이하×1C | E33: (m 당) | H33: =F33*G33*$H$3 -> 0 | I33: 10648 | J33: =IF(P33="",F33*I33*$J$3*$P$3,F33*I33*$J$3*P33) -> 0 | O33: =SUM(H33+J33)+L33+N33 -> 0 | P33: 2.6 | Q33: 4P할증260%
A34: M045041310850101 | B34: 케이블 | C34: FW-CV케이블 | D34: 0.6/1KV 4C 50㎟ | E34: m | G34: 36649 | H34: =F34*G34*$H$3 -> 0 | J34: =IF(P34="",F34*I34*$J$3*$P$3,F34*I34*$J$3*P34) -> 0 | O34: =SUM(H34+J34)+L34+N34 -> 0
A35: E00000807041210104 | B35: 케이블 | C35: 전력케이블 구내설치 (PVC 및 고무절연외장 케이블) | D35: 600V 50㎟이하×1C | E35: (m 당) | H35: =F35*G35*$H$3 -> 0 | I35: 12718 | J35: =IF(P35="",F35*I35*$J$3*$P$3,F35*I35*$J$3*P35) -> 0 | O35: =SUM(H35+J35)+L35+N35 -> 0 | P35: 2.6 | Q35: 4P할증260%
A36: M045041310860101 | B36: 케이블 | C36: FW-CV케이블 | D36: 0.6/1KV 4C 70㎟ | E36: m | G36: 51491 | H36: =F36*G36*$H$3 -> 0 | J36: =IF(P36="",F36*I36*$J$3*$P$3,F36*I36*$J$3*P36) -> 0 | O36: =SUM(H36+J36)+L36+N36 -> 0
A37: E00000807041210106 | B37: 케이블 | C37: 전력케이블 구내설치 (PVC 및 고무절연외장 케이블) | D37: 600V 70㎟이하×1C | E37: (m 당) | H37: =F37*G37*$H$3 -> 0 | I37: 16859 | J37: =IF(P37="",F37*I37*$J$3*$P$3,F37*I37*$J$3*P37) -> 0 | O37: =SUM(H37+J37)+L37+N37 -> 0 | P37: 2.6 | Q37: 4P할증260%
A38: M045041310320101 | B38: 케이블 | C38: FW-CV케이블 | D38: 0.6/1KV 1C 25㎟ | E38: m | G38: 4909 | H38: =F38*G38*$H$3 -> 0 | J38: =IF(P38="",F38*I38*$J$3*$P$3,F38*I38*$J$3*P38) -> 0 | O38: =SUM(H38+J38)+L38+N38 -> 0
A39: M045011410060101 | B39: 전기기기용비닐절연전선(KIV) | C39: 450/700 KIV | D39: 16㎟ | E39: m | F39: 40 | G39: 3356 | H39: =F39*G39*$H$3 -> 111419.2
A40: M045041310330101 | B40: 케이블 | C40: FW-CV케이블 | D40: 0.6/1KV 1C 35㎟ | E40: m | G40: 6699 | H40: =F40*G40*$H$3 -> 0 | J40: =IF(P40="",F40*I40*$J$3*$P$3,F40*I40*$J$3*P40) -> 0 | O40: =SUM(H40+J40)+L40+N40 -> 0
A41: E00000807041210103 | B41: 케이블 | C41: 전력케이블 구내설치 (PVC 및 고무절연외장 케이블) | D41: 600V 38㎟이하×1C | E41: (m 당) | H41: =F41*G41*$H$3 -> 0 | I41: 10648 | J41: =IF(P41="",F41*I41*$J$3*$P$3,F41*I41*$J$3*P41) -> 0 | O41: =SUM(H41+J41)+L41+N41 -> 0
...

Sheet 주요물량산출서
A1: 주요 물량 산출서
A3: 공사명: | B3: =갑지!B7 -> 사택 노후 차단기 교체1안
A4: 품명 | B4: 규격 | C4: 단위 | D4: 수량 | E4: 산출근거 | F4: 내역도면번호 | G4: 비고
A5: F-CV케이블 | B5: 0.6/1KV 3C 4㎟ | C5: M | D5: 60 | E5: 높이5+길이20+높이5=30*2=60

Sheet 공사수립계획서.
B1: 공사수립계획서
B4: 업 체 명 | C4: 대양이엔씨 | D4: 일 시 | E4: =갑지!B9 -> 2025년 03월 일
B5: 공 사 명 | C5: =갑지!B7 -> 사택 노후 차단기 교체1안
B6: 공사 업체 | C6: ■ 공사기간 : 입찰시스템 계약기간에 준함
C7: ■ 인원투입계획 : 총 명(주말 : 명)
C8: ■ 시공방법
C11: 차단기 교체 작업
C12: 계량기.차단기 회로변경
C20: ■ 위험작업 유무 : 고소작업.전기작업
C21: ■ 안전확보 방안 :
C22: -. 고소작업시 2인1조 작업
C23: -. 천정작업시 안전로프 설치
C24: -. 분전반 결선시 위험표지판 설치 및 차단기 락 설치
C25: ■ 주요 사용물질 :
B29: 대양이엔씨 | C29: 성명 : 홍정운 | D29: (인감/서명)
B30: ㈜ S&I Corp. | C30: 성명 : 이용엽 | D30: 서명

Sheet 할증기준
A1: ■ atG 할증기준

Sheet 작성 Guide
B2: ※ 견적작성 Guide
B4: ① 표준단가 코드(D Code), 품셈(E Code), 물정(M Code), 노임단가(L Code)입력기준 품명/규격/단가 입력(1열 입력)
B5: ② 내역 기준 표준단가 낙찰율/ 할증기준 반영
B6: ③ 시중가는 999999로 입력(업로드 파일 제외됨)
B7: ④ 업로드 파일 검토(오류시 Upload검토 순번 재정렬)☞ 숨기기 되어 있음
B8: ④ 담당자 제출 후 시중가/할증 별도 입력 요청

Sheet 내역서업로드
G2: ▼낙찰율 | I2: ▼낙찰율 | K2: ▼낙찰율 | M2: ▼낙찰율
B3: ="공사명"&" "&":"&" "&갑지!B7 -> 공사명 : 사택 노후 차단기 교체1안 | G3: % | I3: % | K3: 0.86 | M3: 0.8
A4: 표준 Code | B4: 주요내역 | D4: 단위 | E4: 수량 | F4: 재료비 | H4: 노무비 | J4: 기계경비 | L4: 기타경비(부자재비) | N4: 합계 | O4: 비고
B5: 품목 | C5: 규격 | F5: 단가 | G5: 금액 | H5: 단가 | I5: 금액 | J5: 단가 | K5: 금액 | L5: 단가 | M5: 금액 | O5: 할증율(%) | P5: 기준
J6: 197736
A7: M045011410060101 | B7: 450/700 KIV | C7: 16㎟ | D7: m | E7: 40 | J7: 295464.15
A8: E00000807041210101 | B8: 전력케이블 구내설치 (PVC 및 고무절연외장 케이블) | C8: 600V 16㎟이하×1C )계량기=>차단기 = 차단기=>계량기 메인회로 교체) | D8: (m 당) | E8: 40 | J8: 131653
A9: E00000808475160101 | B9: 통신용 전력케이블 직선접속 (1) | C9: 600V, 16㎟이하 1C | D9: (개소당) | E9: 40 | J9: 1909218
A10: M045330711190101 | B10: 분전반용누전차단기 | C10: EBS53Fb, 극수:2P3E 정격전류:5,10,15,20,30,40,50 차단전류(220V):5kA 분전반용 | D10: 대 | E10: 20 | J10: -1044.4
A11: E00000807041290102 | B11: 배선용차단기 | C11: 50AF 이하 (1층 메인전원1개 세대메인전원1개 10세대 5층기준) | D11: (개당) | E11: 20 | J11: -178344
A12: M045330710020101 | B12: 분전반용누전차단기 | C12: 32GRc, 극수:2P2E 정격전류:15,20,30 차단전류(220V):1.5kA 분전반용 | D12: 대 | E12: 50 | J12: 276580
A13: E00000807041290101 | B13: 배선용차단기 | C13: 30AF 이하 (세대부하차단기5개씩 10세대 5층기준) | D13: (개당) | E13: 50
J14: 2631262.8
J15: 2917000
J16: 20750
J17: 175081
J18: 153960
J19: 142201
J20: 285813
J21: 218105
G101: =SUM(G6:G100) -> 0 | I101: =SUM(I6:I100) -> 0 | K101: =SUM(K6:K100) -> 0 | M101: =SUM(M6:M100) -> 0

Sheet Upload(참조) (2)
A1: 구분 | B1: 표준단가 | C1: 표준품셈 | D1: 물가정보 | E1: 노임단가 | F1: 수량 | I1: 예가내역서 코드 | J1: 코드구분 | L1: 표준단가 | M1: 표준품셈 | N1: 물가정보 | O1: 노임단가 | Q1: 최종구분 | R1: 표준단가 | S1: 표준품셈 | T1: 물가정보 | U1: 노임단가 | V1: 수량 | W1: 표준단가 | X1: 표준품셈 | Y1: *(공란) | Z1: ><(텍스트) | AA1: <>(수식모두)
F2: 2 | G2: 표준단가 품목 | H2: 노무비 | I2: =IF(내역서업로드!A5<>"",내역서업로드!A5,"") | J2: =LEFT(I2,1) | L2: =IF(OR(J2="E",J2="L",J2="M"),"",I2) | M2: =IF(OR(J2="D",J2="L",J2="M"),"",I2) | N2: =IF(OR(J2="D",J2="E",J2="L"),"",I2) | O2: =IF(OR(J2="D",J2="E",J2="M"),"",I2) | Q2: =IF(Z2=0,"",IF(Z2=1,R2&S2&T2&U2,"E99999")) | R2: =IF(L2="","",L2) | S2: =IF(M2="","",M2) | T2: =IF(W2=1,"",N2) | U2: =IF(OR(W2=1,X2=1),"",O2) | V2: =내역서업로드!E5 -> 0 | W2: =COUNTIFS(R2,"><") -> 0 | X2: =COUNTIFS(S2,"><") -> 0 | Y2: =COUNTIFS(R2:U2,"*") -> 4 | Z2: =COUNTIFS(R2:U2,"><") -> 0 | AA2: =COUNTIFS(R2:U2,"<>") -> 4
F3: 3 | G3: 표준품셈+물가정보 품목 | H3: 자재비 | I3: =IF(내역서업로드!A6<>"",내역서업로드!A6,"") | J3: =LEFT(I3,1) | L3: =IF(OR(J3="E",J3="L",J3="M"),"",I3) | M3: =IF(OR(J3="D",J3="L",J3="M"),"",I3) | N3: =IF(OR(J3="D",J3="E",J3="L"),"",I3) | O3: =IF(OR(J3="D",J3="E",J3="M"),"",I3) | Q3: =IF(Z3=0,"",IF(Z3=1,R3&S3&T3&U3,"E99999")) | R3: =IF(L3="","",L3) | S3: =IF(M3="","",M3) | T3: =IF(W3=1,"",N3) | U3: =IF(OR(W3=1,X3=1),"",O3) | V3: =내역서업로드!E6 -> 0 | W3: =COUNTIFS(R3,"><") -> 0 | X3: =COUNTIFS(S3,"><") -> 0 | Y3: =COUNTIFS(R3:U3,"*") -> 4 | Z3: =COUNTIFS(R3:U3,"><") -> 0 | AA3: =COUNTIFS(R3:U3,"<>") -> 4
F4: 4 | G4: 표준품셈만 있을떄 | H4: 표준단가 | I4: =IF(내역서업로드!A7<>"",내역서업로드!A7,"") -> M045011410060101 | J4: =LEFT(I4,1) -> M | L4: =IF(OR(J4="E",J4="L",J4="M"),"",I4) | M4: =IF(OR(J4="D",J4="L",J4="M"),"",I4) | N4: =IF(OR(J4="D",J4="E",J4="L"),"",I4) -> M045011410060101 | O4: =IF(OR(J4="D",J4="E",J4="M"),"",I4) | Q4: =IF(Z4=0,"",IF(Z4=1,R4&S4&T4&U4,"E99999")) -> M045011410060101 | R4: =IF(L4="","",L4) | S4: =IF(M4="","",M4) | T4: =IF(W4=1,"",N4) -> M045011410060101 | U4: =IF(OR(W4=1,X4=1),"",O4) | V4: =내역서업로드!E7 -> 40 | W4: =COUNTIFS(R4,"><") -> 0 | X4: =COUNTIFS(S4,"><") -> 0 | Y4: =COUNTIFS(R4:U4,"*") -> 4 | Z4: =COUNTIFS(R4:U4,"><") -> 1 | AA4: =COUNTIFS(R4:U4,"<>") -> 4
F5: 5 | G5: 물가정보만 있을때 | H5: 표준품셈 | I5: =IF(내역서업로드!A8<>"",내역서업로드!A8,"") -> E00000807041210101 | J5: =LEFT(I5,1) -> E | L5: =IF(OR(J5="E",J5="L",J5="M"),"",I5) | M5: =IF(OR(J5="D",J5="L",J5="M"),"",I5) -> E00000807041210101 | N5: =IF(OR(J5="D",J5="E",J5="L"),"",I5) | O5: =IF(OR(J5="D",J5="E",J5="M"),"",I5) | Q5: =IF(Z5=0,"",IF(Z5=1,R5&S5&T5&U5,"E99999")) -> E00000807041210101 | R5: =IF(L5="","",L5) | S5: =IF(M5="","",M5) -> E00000807041210101 | T5: =IF(W5=1,"",N5) | U5: =IF(OR(W5=1,X5=1),"",O5) | V5: =내역서업로드!E8 -> 40 | W5: =COUNTIFS(R5,"><") -> 0 | X5: =COUNTIFS(S5,"><") -> 1 | Y5: =COUNTIFS(R5:U5,"*") -> 4 | Z5: =COUNTIFS(R5:U5,"><") -> 1 | AA5: =COUNTIFS(R5:U5,"<>") -> 4
F6: 6 | G6: 노임단가만 있을떄 | I6: =IF(내역서업로드!A9<>"",내역서업로드!A9,"") -> E00000808475160101 | J6: =LEFT(I6,1) -> E | L6: =IF(OR(J6="E",J6="L",J6="M"),"",I6) | M6: =IF(OR(J6="D",J6="L",J6="M"),"",I6) -> E00000808475160101 | N6: =IF(OR(J6="D",J6="E",J6="L"),"",I6) | O6: =IF(OR(J6="D",J6="E",J6="M"),"",I6) | Q6: =IF(Z6=0,"",IF(Z6=1,R6&S6&T6&U6,"E99999")) -> E00000808475160101 | R6: =IF(L6="","",L6) | S6: =IF(M6="","",M6) -> E00000808475160101 | T6: =IF(W6=1,"",N6) | U6: =IF(OR(W6=1,X6=1),"",O6) | V6: =내역서업로드!E9 -> 40 | W6: =COUNTIFS(R6,"><") -> 0 | X6: =COUNTIFS(S6,"><") -> 1 | Y6: =COUNTIFS(R6:U6,"*") -> 4 | Z6: =COUNTIFS(R6:U6,"><") -> 1 | AA6: =COUNTIFS(R6:U6,"<>") -> 4
I7: =IF(내역서업로드!A10<>"",내역서업로드!A10,"") -> M045330711190101 | J7: =LEFT(I7,1) -> M | L7: =IF(OR(J7="E",J7="L",J7="M"),"",I7) | M7: =IF(OR(J7="D",J7="L",J7="M"),"",I7) | N7: =IF(OR(J7="D",J7="E",J7="L"),"",I7) -> M045330711190101 | O7: =IF(OR(J7="D",J7="E",J7="M"),"",I7) | Q7: =IF(Z7=0,"",IF(Z7=1,R7&S7&T7&U7,"E99999")) -> M045330711190101 | R7: =IF(L7="","",L7) | S7: =IF(M7="","",M7) | T7: =IF(W7=1,"",N7) -> M045330711190101 | U7: =IF(OR(W7=1,X7=1),"",O7) | V7: =내역서업로드!E10 -> 20 | W7: =COUNTIFS(R7,"><") -> 0 | X7: =COUNTIFS(S7,"><") -> 0 | Y7: =COUNTIFS(R7:U7,"*") -> 4 | Z7: =COUNTIFS(R7:U7,"><") -> 1 | AA7: =COUNTIFS(R7:U7,"<>") -> 4
G8: 표준단가 D | I8: =IF(내역서업로드!A11<>"",내역서업로드!A11,"") -> E00000807041290102 | J8: =LEFT(I8,1) -> E | L8: =IF(OR(J8="E",J8="L",J8="M"),"",I8) | M8: =IF(OR(J8="D",J8="L",J8="M"),"",I8) -> E00000807041290102 | N8: =IF(OR(J8="D",J8="E",J8="L"),"",I8) | O8: =IF(OR(J8="D",J8="E",J8="M"),"",I8) | Q8: =IF(Z8=0,"",IF(Z8=1,R8&S8&T8&U8,"E99999")) -> E00000807041290102 | R8: =IF(L8="","",L8) | S8: =IF(M8="","",M8) -> E00000807041290102 | T8: =IF(W8=1,"",N8) | U8: =IF(OR(W8=1,X8=1),"",O8) | V8: =내역서업로드!E11 -> 20 | W8: =COUNTIFS(R8,"><") -> 0 | X8: =COUNTIFS(S8,"><") -> 1 | Y8: =COUNTIFS(R8:U8,"*") -> 4 | Z8: =COUNTIFS(R8:U8,"><") -> 1 | AA8: =COUNTIFS(R8:U8,"<>") -> 4
I9: =IF(내역서업로드!A12<>"",내역서업로드!A12,"") -> M045330710020101 | J9: =LEFT(I9,1) -> M | L9: =IF(OR(J9="E",J9="L",J9="M"),"",I9) | M9: =IF(OR(J9="D",J9="L",J9="M"),"",I9) | N9: =IF(OR(J9="D",J9="E",J9="L"),"",I9) -> M045330710020101 | O9: =IF(OR(J9="D",J9="E",J9="M"),"",I9) | Q9: =IF(Z9=0,"",IF(Z9=1,R9&S9&T9&U9,"E99999")) -> M045330710020101 | R9: =IF(L9="","",L9) | S9: =IF(M9="","",M9) | T9: =IF(W9=1,"",N9) -> M045330710020101 | U9: =IF(OR(W9=1,X9=1),"",O9) | V9: =내역서업로드!E12 -> 50 | W9: =COUNTIFS(R9,"><") -> 0 | X9: =COUNTIFS(S9,"><") -> 0 | Y9: =COUNTIFS(R9:U9,"*") -> 4 | Z9: =COUNTIFS(R9:U9,"><") -> 1 | AA9: =COUNTIFS(R9:U9,"<>") -> 4
I10: =IF(내역서업로드!A13<>"",내역서업로드!A13,"") -> E00000807041290101 | J10: =LEFT(I10,1) -> E | L10: =IF(OR(J10="E",J10="L",J10="M"),"",I10) | M10: =IF(OR(J10="D",J10="L",J10="M"),"",I10) -> E00000807041290101 | N10: =IF(OR(J10="D",J10="E",J10="L"),"",I10) | O10: =IF(OR(J10="D",J10="E",J10="M"),"",I10) | Q10: =IF(Z10=0,"",IF(Z10=1,R10&S10&T10&U10,"E99999")) -> E00000807041290101 | R10: =IF(L10="","",L10) | S10: =IF(M10="","",M10) -> E00000807041290101 | T10: =IF(W10=1,"",N10) | U10: =IF(OR(W10=1,X10=1),"",O10) | V10: =내역서업로드!E13 -> 50 | W10: =COUNTIFS(R10,"><") -> 0 | X10: =COUNTIFS(S10,"><") -> 1 | Y10: =COUNTIFS(R10:U10,"*") -> 4 | Z10: =COUNTIFS(R10:U10,"><") -> 1 | AA10: =COUNTIFS(R10:U10,"<>") -> 4
I11: =IF(내역서업로드!A14<>"",내역서업로드!A14,"") | J11: =LEFT(I11,1) | L11: =IF(OR(J11="E",J11="L",J11="M"),"",I11) | M11: =IF(OR(J11="D",J11="L",J11="M"),"",I11) | N11: =IF(OR(J11="D",J11="E",J11="L"),"",I11) | O11: =IF(OR(J11="D",J11="E",J11="M"),"",I11) | Q11: =IF(Z11=0,"",IF(Z11=1,R11&S11&T11&U11,"E99999")) | R11: =IF(L11="","",L11) | S11: =IF(M11="","",M11) | T11: =IF(W11=1,"",N11) | U11: =IF(OR(W11=1,X11=1),"",O11) | V11: =내역서업로드!E14 -> 0 | W11: =COUNTIFS(R11,"><") -> 0 | X11: =COUNTIFS(S11,"><") -> 0 | Y11: =COUNTIFS(R11:U11,"*") -> 4 | Z11: =COUNTIFS(R11:U11,"><") -> 0 | AA11: =COUNTIFS(R11:U11,"<>") -> 4
I12: =IF(내역서업로드!A15<>"",내역서업로드!A15,"") | J12: =LEFT(I12,1) | L12: =IF(OR(J12="E",J12="L",J12="M"),"",I12) | M12: =IF(OR(J12="D",J12="L",J12="M"),"",I12) | N12: =IF(OR(J12="D",J12="E",J12="L"),"",I12) | O12: =IF(OR(J12="D",J12="E",J12="M"),"",I12) | Q12: =IF(Z12=0,"",IF(Z12=1,R12&S12&T12&U12,"E99999")) | R12: =IF(L12="","",L12) | S12: =IF(M12="","",M12) | T12: =IF(W12=1,"",N12) | U12: =IF(OR(W12=1,X12=1),"",O12) | V12: =내역서업로드!E15 -> 0 | W12: =COUNTIFS(R12,"><") -> 0 | X12: =COUNTIFS(S12,"><") -> 0 | Y12: =COUNTIFS(R12:U12,"*") -> 4 | Z12: =COUNTIFS(R12:U12,"><") -> 0 | AA12: =COUNTIFS(R12:U12,"<>") -> 4
I13: =IF(내역서업로드!A16<>"",내역서업로드!A16,"") | J13: =LEFT(I13,1) | L13: =IF(OR(J13="E",J13="L",J13="M"),"",I13) | M13: =IF(OR(J13="D",J13="L",J13="M"),"",I13) | N13: =IF(OR(J13="D",J13="E",J13="L"),"",I13) | O13: =IF(OR(J13="D",J13="E",J13="M"),"",I13) | Q13: =IF(Z13=0,"",IF(Z13=1,R13&S13&T13&U13,"E99999")) | R13: =IF(L13="","",L13) | S13: =IF(M13="","",M13) | T13: =IF(W13=1,"",N13) | U13: =IF(OR(W13=1,X13=1),"",O13) | V13: =내역서업로드!E16 -> 0 | W13: =COUNTIFS(R13,"><") -> 0 | X13: =COUNTIFS(S13,"><") -> 0 | Y13: =COUNTIFS(R13:U13,"*") -> 4 | Z13: =COUNTIFS(R13:U13,"><") -> 0 | AA13: =COUNTIFS(R13:U13,"<>") -> 4
I14: =IF(내역서업로드!A17<>"",내역서업로드!A17,"") | J14: =LEFT(I14,1) | L14: =IF(OR(J14="E",J14="L",J14="M"),"",I14) | M14: =IF(OR(J14="D",J14="L",J14="M"),"",I14) | N14: =IF(OR(J14="D",J14="E",J14="L"),"",I14) | O14: =IF(OR(J14="D",J14="E",J14="M"),"",I14) | Q14: =IF(Z14=0,"",IF(Z14=1,R14&S14&T14&U14,"E99999")) | R14: =IF(L14="","",L14) | S14: =IF(M14="","",M14) | T14: =IF(W14=1,"",N14) | U14: =IF(OR(W14=1,X14=1),"",O14) | V14: =내역서업로드!E17 -> 0 | W14: =COUNTIFS(R14,"><") -> 0 | X14: =COUNTIFS(S14,"><") -> 0 | Y14: =COUNTIFS(R14:U14,"*") -> 4 | Z14: =COUNTIFS(R14:U14,"><") -> 0 | AA14: =COUNTIFS(R14:U14,"<>") -> 4
I15: =IF(내역서업로드!A18<>"",내역서업로드!A18,"") | J15: =LEFT(I15,1) | L15: =IF(OR(J15="E",J15="L",J15="M"),"",I15) | M15: =IF(OR(J15="D",J15="L",J15="M"),"",I15) | N15: =IF(OR(J15="D",J15="E",J15="L"),"",I15) | O15: =IF(OR(J15="D",J15="E",J15="M"),"",I15) | Q15: =IF(Z15=0,"",IF(Z15=1,R15&S15&T15&U15,"E99999")) | R15: =IF(L15="","",L15) | S15: =IF(M15="","",M15) | T15: =IF(W15=1,"",N15) | U15: =IF(OR(W15=1,X15=1),"",O15) | V15: =내역서업로드!E18 -> 0 | W15: =COUNTIFS(R15,"><") -> 0 | X15: =COUNTIFS(S15,"><") -> 0 | Y15: =COUNTIFS(R15:U15,"*") -> 4 | Z15: =COUNTIFS(R15:U15,"><") -> 0 | AA15: =COUNTIFS(R15:U15,"<>") -> 4
I16: =IF(내역서업로드!A19<>"",내역서업로드!A19,"") | J16: =LEFT(I16,1) | L16: =IF(OR(J16="E",J16="L",J16="M"),"",I16) | M16: =IF(OR(J16="D",J16="L",J16="M"),"",I16) | N16: =IF(OR(J16="D",J16="E",J16="L"),"",I16) | O16: =IF(OR(J16="D",J16="E",J16="M"),"",I16) | Q16: =IF(Z16=0,"",IF(Z16=1,R16&S16&T16&U16,"E99999")) | R16: =IF(L16="","",L16) | S16: =IF(M16="","",M16) | T16: =IF(W16=1,"",N16) | U16: =IF(OR(W16=1,X16=1),"",O16) | V16: =내역서업로드!E19 -> 0 | W16: =COUNTIFS(R16,"><") -> 0 | X16: =COUNTIFS(S16,"><") -> 0 | Y16: =COUNTIFS(R16:U16,"*") -> 4 | Z16: =COUNTIFS(R16:U16,"><") -> 0 | AA16: =COUNTIFS(R16:U16,"<>") -> 4
I17: =IF(내역서업로드!A20<>"",내역서업로드!A20,"") | J17: =LEFT(I17,1) | L17: =IF(OR(J17="E",J17="L",J17="M"),"",I17) | M17: =IF(OR(J17="D",J17="L",J17="M"),"",I17) | N17: =IF(OR(J17="D",J17="E",J17="L"),"",I17) | O17: =IF(OR(J17="D",J17="E",J17="M"),"",I17) | Q17: =IF(Z17=0,"",IF(Z17=1,R17&S17&T17&U17,"E99999")) | R17: =IF(L17="","",L17) | S17: =IF(M17="","",M17) | T17: =IF(W17=1,"",N17) | U17: =IF(OR(W17=1,X17=1),"",O17) | V17: =내역서업로드!E20 -> 0 | W17: =COUNTIFS(R17,"><") -> 0 | X17: =COUNTIFS(S17,"><") -> 0 | Y17: =COUNTIFS(R17:U17,"*") -> 4 | Z17: =COUNTIFS(R17:U17,"><") -> 0 | AA17: =COUNTIFS(R17:U17,"<>") -> 4
I18: =IF(내역서업로드!A21<>"",내역서업로드!A21,"") | J18: =LEFT(I18,1) | L18: =IF(OR(J18="E",J18="L",J18="M"),"",I18) | M18: =IF(OR(J18="D",J18="L",J18="M"),"",I18) | N18: =IF(OR(J18="D",J18="E",J18="L"),"",I18) | O18: =IF(OR(J18="D",J18="E",J18="M"),"",I18) | Q18: =IF(Z18=0,"",IF(Z18=1,R18&S18&T18&U18,"E99999")) | R18: =IF(L18="","",L18) | S18: =IF(M18="","",M18) | T18: =IF(W18=1,"",N18) | U18: =IF(OR(W18=1,X18=1),"",O18) | V18: =내역서업로드!E21 -> 0 | W18: =COUNTIFS(R18,"><") -> 0 | X18: =COUNTIFS(S18,"><") -> 0 | Y18: =COUNTIFS(R18:U18,"*") -> 4 | Z18: =COUNTIFS(R18:U18,"><") -> 0 | AA18: =COUNTIFS(R18:U18,"<>") -> 4
I19: =IF(내역서업로드!A22<>"",내역서업로드!A22,"") | J19: =LEFT(I19,1) | L19: =IF(OR(J19="E",J19="L",J19="M"),"",I19) | M19: =IF(OR(J19="D",J19="L",J19="M"),"",I19) | N19: =IF(OR(J19="D",J19="E",J19="L"),"",I19) | O19: =IF(OR(J19="D",J19="E",J19="M"),"",I19) | Q19: =IF(Z19=0,"",IF(Z19=1,R19&S19&T19&U19,"E99999")) | R19: =IF(L19="","",L19) | S19: =IF(M19="","",M19) | T19: =IF(W19=1,"",N19) | U19: =IF(OR(W19=1,X19=1),"",O19) | V19: =내역서업로드!E22 -> 0 | W19: =COUNTIFS(R19,"><") -> 0 | X19: =COUNTIFS(S19,"><") -> 0 | Y19: =COUNTIFS(R19:U19,"*") -> 4 | Z19: =COUNTIFS(R19:U19,"><") -> 0 | AA19: =COUNTIFS(R19:U19,"<>") -> 4
I20: =IF(내역서업로드!A23<>"",내역서업로드!A23,"") | J20: =LEFT(I20,1) | L20: =IF(OR(J20="E",J20="L",J20="M"),"",I20) | M20: =IF(OR(J20="D",J20="L",J20="M"),"",I20) | N20: =IF(OR(J20="D",J20="E",J20="L"),"",I20) | O20: =IF(OR(J20="D",J20="E",J20="M"),"",I20) | Q20: =IF(Z20=0,"",IF(Z20=1,R20&S20&T20&U20,"E99999")) | R20: =IF(L20="","",L20) | S20: =IF(M20="","",M20) | T20: =IF(W20=1,"",N20) | U20: =IF(OR(W20=1,X20=1),"",O20) | V20: =내역서업로드!E23 -> 0 | W20: =COUNTIFS(R20,"><") -> 0 | X20: =COUNTIFS(S20,"><") -> 0 | Y20: =COUNTIFS(R20:U20,"*") -> 4 | Z20: =COUNTIFS(R20:U20,"><") -> 0 | AA20: =COUNTIFS(R20:U20,"<>") -> 4
... I116: =IF(내역서업로드!A119<>"",내역서업로드!A119,"") | J116: =LEFT(I116,1) | L116: =IF(OR(J116="E",J116="L",J116="M"),"",I116) | M116: =IF(OR(J116="D",J116="L",J116="M"),"",I116) | N116: =IF(OR(J116="D",J116="E",J116="L"),"",I116) | O116: =IF(OR(J116="D",J116="E",J116="M"),"",I116) | Q116: =IF(Z116=0,"",IF(Z116=1,R116&S116&T116&U116,"E99999")) | R116: =IF(L116="","",L116) | S116: =IF(M116="","",M116) | T116: =IF(W116=1,"",N116) | U116: =IF(OR(W116=1,X116=1),"",O116) | V116: =내역서업로드!E119 -> 0 | W116: =COUNTIFS(R116,"><") -> 0 | X116: =COUNTIFS(S116,"><") -> 0 | Y116: =COUNTIFS(R116:U116,"*") -> 4 | Z116: =COUNTIFS(R116:U116,"><") -> 0 | AA116: =COUNTIFS(R116:U116,"<>") -> 4

Sheet Upload(참조)
A1: 구분 | B1: 표준단가 | C1: 표준품셈 | D1: 물가정보 | E1: 노임단가 | F1: 수량 | I1: 예가내역서 코드 | J1: 코드구분 | L1: 표준단가 | M1: 표준품셈 | N1: 물가정보 | O1: 노임단가 | Q1: 최종구분 | R1: 표준단가 | S1: 표준품셈 | T1: 물가정보 | U1: 노임단가 | V1: 수량 | W1: 표준단가 | X1: 표준품셈 | Y1: *(공란) | Z1: ><(텍스트) | AA1: <>(수식모두)
F2: 2 | G2: 표준단가 품목 | H2: 노무비 | I2: =IF(#REF!<>"",#REF!,"") -> #REF! | J2: =LEFT(I2,1) -> #REF! | L2: =IF(OR(J2="E",J2="L",J2="M"),"",I2) -> #REF! | M2: =IF(OR(J2="D",J2="L",J2="M"),"",I2) -> #REF! | N2: =IF(OR(J2="D",J2="E",J2="L"),"",I2) -> #REF! | O2: =IF(OR(J2="D",J2="E",J2="M"),"",I2) -> #REF! | Q2: =IF(Z2=0,"",IF(Z2=1,R2&S2&T2&U2,"E99999")) | R2: =IF(L2="","",L2) -> #REF! | S2: =IF(M2="","",M2) -> #REF! | T2: =IF(W2=1,"",N2) -> #REF! | U2: =IF(OR(W2=1,X2=1),"",O2) -> #REF! | V2: =#REF! -> #REF! | W2: =COUNTIFS(R2,"><") -> 0 | X2: =COUNTIFS(S2,"><") -> 0 | Y2: =COUNTIFS(R2:U2,"*") -> 0 | Z2: =COUNTIFS(R2:U2,"><") -> 0 | AA2: =COUNTIFS(R2:U2,"<>") -> 4
F3: 3 | G3: 표준품셈+물가정보 품목 | H3: 자재비 | I3: =IF(#REF!<>"",#REF!,"") -> #REF! | J3: =LEFT(I3,1) -> #REF! | L3: =IF(OR(J3="E",J3="L",J3="M"),"",I3) -> #REF! | M3: =IF(OR(J3="D",J3="L",J3="M"),"",I3) -> #REF! | N3: =IF(OR(J3="D",J3="E",J3="L"),"",I3) -> #REF! | O3: =IF(OR(J3="D",J3="E",J3="M"),"",I3) -> #REF! | Q3: =IF(Z3=0,"",IF(Z3=1,R3&S3&T3&U3,"E99999")) | R3: =IF(L3="","",L3) -> #REF! | S3: =IF(M3="","",M3) -> #REF! | T3: =IF(W3=1,"",N3) -> #REF! | U3: =IF(OR(W3=1,X3=1),"",O3) -> #REF! | V3: =#REF! -> #REF! | W3: =COUNTIFS(R3,"><") -> 0 | X3: =COUNTIFS(S3,"><") -> 0 | Y3: =COUNTIFS(R3:U3,"*") -> 0 | Z3: =COUNTIFS(R3:U3,"><") -> 0 | AA3: =COUNTIFS(R3:U3,"<>") -> 4
F4: 4 | G4: 표준품셈만 있을떄 | H4: 표준단가 | I4: =IF(#REF!<>"",#REF!,"") -> #REF! | J4: =LEFT(I4,1) -> #REF! | L4: =IF(OR(J4="E",J4="L",J4="M"),"",I4) -> #REF! | M4: =IF(OR(J4="D",J4="L",J4="M"),"",I4) -> #REF! | N4: =IF(OR(J4="D",J4="E",J4="L"),"",I4) -> #REF! | O4: =IF(OR(J4="D",J4="E",J4="M"),"",I4) -> #REF! | Q4: =IF(Z4=0,"",IF(Z4=1,R4&S4&T4&U4,"E99999")) | R4: =IF(L4="","",L4) -> #REF! | S4: =IF(M4="","",M4) -> #REF! | T4: =IF(W4=1,"",N4) -> #REF! | U4: =IF(OR(W4=1,X4=1),"",O4) -> #REF! | V4: =#REF! -> #REF! | W4: =COUNTIFS(R4,"><") -> 0 | X4: =COUNTIFS(S4,"><") -> 0 | Y4: =COUNTIFS(R4:U4,"*") -> 0 | Z4: =COUNTIFS(R4:U4,"><") -> 0 | AA4: =COUNTIFS(R4:U4,"<>") -> 4
F5: 5 | G5: 물가정보만 있을때 | H5: 표준품셈 | I5: =IF(#REF!<>"",#REF!,"") -> #REF! | J5: =LEFT(I5,1) -> #REF! | L5: =IF(OR(J5="E",J5="L",J5="M"),"",I5) -> #REF! | M5: =IF(OR(J5="D",J5="L",J5="M"),"",I5) -> #REF! | N5: =IF(OR(J5="D",J5="E",J5="L"),"",I5) -> #REF! | O5: =IF(OR(J5="D",J5="E",J5="M"),"",I5) -> #REF! | Q5: =IF(Z5=0,"",IF(Z5=1,R5&S5&T5&U5,"E99999")) | R5: =IF(L5="","",L5) -> #REF! | S5: =IF(M5="","",M5) -> #REF! | T5: =IF(W5=1,"",N5) -> #REF! | U5: =IF(OR(W5=1,X5=1),"",O5) -> #REF! | V5: =#REF! -> #REF! | W5: =COUNTIFS(R5,"><") -> 0 | X5: =COUNTIFS(S5,"><") -> 0 | Y5: =COUNTIFS(R5:U5,"*") -> 0 | Z5: =COUNTIFS(R5:U5,"><") -> 0 | AA5: =COUNTIFS(R5:U5,"<>") -> 4
F6: 6 | G6: 노임단가만 있을떄 | I6: =IF(#REF!<>"",#REF!,"") -> #REF! | J6: =LEFT(I6,1) -> #REF! | L6: =IF(OR(J6="E",J6="L",J6="M"),"",I6) -> #REF! | M6: =IF(OR(J6="D",J6="L",J6="M"),"",I6) -> #REF! | N6: =IF(OR(J6="D",J6="E",J6="L"),"",I6) -> #REF! | O6: =IF(OR(J6="D",J6="E",J6="M"),"",I6) -> #REF! | Q6: =IF(Z6=0,"",IF(Z6=1,R6&S6&T6&U6,"E99999")) | R6: =IF(L6="","",L6) -> #REF! | S6: =IF(M6="","",M6) -> #REF! | T6: =IF(W6=1,"",N6) -> #REF! | U6: =IF(OR(W6=1,X6=1),"",O6) -> #REF! | V6: =#REF! -> #REF! | W6: =COUNTIFS(R6,"><") -> 0 | X6: =COUNTIFS(S6,"><") -> 0 | Y6: =COUNTIFS(R6:U6,"*") -> 0 | Z6: =COUNTIFS(R6:U6,"><") -> 0 | AA6: =COUNTIFS(R6:U6,"<>") -> 4
I7: =IF(#REF!<>"",#REF!,"") -> #REF! | J7: =LEFT(I7,1) -> #REF! | L7: =IF(OR(J7="E",J7="L",J7="M"),"",I7) -> #REF! | M7: =IF(OR(J7="D",J7="L",J7="M"),"",I7) -> #REF! | N7: =IF(OR(J7="D",J7="E",J7="L"),"",I7) -> #REF! | O7: =IF(OR(J7="D",J7="E",J7="M"),"",I7) -> #REF! | Q7: =IF(Z7=0,"",IF(Z7=1,R7&S7&T7&U7,"E99999")) | R7: =IF(L7="","",L7) -> #REF! | S7: =IF(M7="","",M7) -> #REF! | T7: =IF(W7=1,"",N7) -> #REF! | U7: =IF(OR(W7=1,X7=1),"",O7) -> #REF! | V7: =#REF! -> #REF! | W7: =COUNTIFS(R7,"><") -> 0 | X7: =COUNTIFS(S7,"><") -> 0 | Y7: =COUNTIFS(R7:U7,"*") -> 0 | Z7: =COUNTIFS(R7:U7,"><") -> 0 | AA7: =COUNTIFS(R7:U7,"<>") -> 4
G8: 표준단가 D | I8: =IF(#REF!<>"",#REF!,"") -> #REF! | J8: =LEFT(I8,1) -> #REF! | L8: =IF(OR(J8="E",J8="L",J8="M"),"",I8) -> #REF! | M8: =IF(OR(J8="D",J8="L",J8="M"),"",I8) -> #REF! | N8: =IF(OR(J8="D",J8="E",J8="L"),"",I8) -> #REF! | O8: =IF(OR(J8="D",J8="E",J8="M"),"",I8) -> #REF! | Q8: =IF(Z8=0,"",IF(Z8=1,R8&S8&T8&U8,"E99999")) | R8: =IF(L8="","",L8) -> #REF! | S8: =IF(M8="","",M8) -> #REF! | T8: =IF(W8=1,"",N8) -> #REF! | U8: =IF(OR(W8=1,X8=1),"",O8) -> #REF! | V8: =#REF! -> #REF! | W8: =COUNTIFS(R8,"><") -> 0 | X8: =COUNTIFS(S8,"><") -> 0 | Y8: =COUNTIFS(R8:U8,"*") -> 0 | Z8: =COUNTIFS(R8:U8,"><") -> 0 | AA8: =COUNTIFS(R8:U8,"<>") -> 4
I9: =IF(#REF!<>"",#REF!,"") -> #REF! | J9: =LEFT(I9,1) -> #REF! | L9: =IF(OR(J9="E",J9="L",J9="M"),"",I9) -> #REF! | M9: =IF(OR(J9="D",J9="L",J9="M"),"",I9) -> #REF! | N9: =IF(OR(J9="D",J9="E",J9="L"),"",I9) -> #REF! | O9: =IF(OR(J9="D",J9="E",J9="M"),"",I9) -> #REF! | Q9: =IF(Z9=0,"",IF(Z9=1,R9&S9&T9&U9,"E99999")) | R9: =IF(L9="","",L9) -> #REF! | S9: =IF(M9="","",M9) -> #REF! | T9: =IF(W9=1,"",N9) -> #REF! | U9: =IF(OR(W9=1,X9=1),"",O9) -> #REF! | V9: =#REF! -> #REF! | W9: =COUNTIFS(R9,"><") -> 0 | X9: =COUNTIFS(S9,"><") -> 0 | Y9: =COUNTIFS(R9:U9,"*") -> 0 | Z9: =COUNTIFS(R9:U9,"><") -> 0 | AA9: =COUNTIFS(R9:U9,"<>") -> 4
I10: =IF(#REF!<>"",#REF!,"") -> #REF! | J10: =LEFT(I10,1) -> #REF! | L10: =IF(OR(J10="E",J10="L",J10="M"),"",I10) -> #REF! | M10: =IF(OR(J10="D",J10="L",J10="M"),"",I10) -> #REF! | N10: =IF(OR(J10="D",J10="E",J10="L"),"",I10) -> #REF! | O10: =IF(OR(J10="D",J10="E",J10="M"),"",I10) -> #REF! | Q10: =IF(Z10=0,"",IF(Z10=1,R10&S10&T10&U10,"E99999")) | R10: =IF(L10="","",L10) -> #REF! | S10: =IF(M10="","",M10) -> #REF! | T10: =IF(W10=1,"",N10) -> #REF! | U10: =IF(OR(W10=1,X10=1),"",O10) -> #REF! | V10: =#REF! -> #REF! | W10: =COUNTIFS(R10,"><") -> 0 | X10: =COUNTIFS(S10,"><") -> 0 | Y10: =COUNTIFS(R10:U10,"*") -> 0 | Z10: =COUNTIFS(R10:U10,"><") -> 0 | AA10: =COUNTIFS(R10:U10,"<>") -> 4
I11: =IF(#REF!<>"",#REF!,"") -> #REF! | J11: =LEFT(I11,1) -> #REF! | L11: =IF(OR(J11="E",J11="L",J11="M"),"",I11) -> #REF! | M11: =IF(OR(J11="D",J11="L",J11="M"),"",I11) -> #REF! | N11: =IF(OR(J11="D",J11="E",J11="L"),"",I11) -> #REF! | O11: =IF(OR(J11="D",J11="E",J11="M"),"",I11) -> #REF! | Q11: =IF(Z11=0,"",IF(Z11=1,R11&S11&T11&U11,"E99999")) | R11: =IF(L11="","",L11) -> #REF! | S11: =IF(M11="","",M11) -> #REF! | T11: =IF(W11=1,"",N11) -> #REF! | U11: =IF(OR(W11=1,X11=1),"",O11) -> #REF! | V11: =#REF! -> #REF! | W11: =COUNTIFS(R11,"><") -> 0 | X11: =COUNTIFS(S11,"><") -> 0 | Y11: =COUNTIFS(R11:U11,"*") -> 0 | Z11: =COUNTIFS(R11:U11,"><") -> 0 | AA11: =COUNTIFS(R11:U11,"<>") -> 4
I12: =IF(#REF!<>"",#REF!,"") -> #REF! | J12: =LEFT(I12,1) -> #REF! | L12: =IF(OR(J12="E",J12="L",J12="M"),"",I12) -> #REF! | M12: =IF(OR(J12="D",J12="L",J12="M"),"",I12) -> #REF! | N12: =IF(OR(J12="D",J12="E",J12="L"),"",I12) -> #REF! | O12: =IF(OR(J12="D",J12="E",J12="M"),"",I12) -> #REF! | Q12: =IF(Z12=0,"",IF(Z12=1,R12&S12&T12&U12,"E99999")) | R12: =IF(L12="","",L12) -> #REF! | S12: =IF(M12="","",M12) -> #REF! | T12: =IF(W12=1,"",N12) -> #REF! | U12: =IF(OR(W12=1,X12=1),"",O12) -> #REF! | V12: =#REF! -> #REF! | W12: =COUNTIFS(R12,"><") -> 0 | X12: =COUNTIFS(S12,"><") -> 0 | Y12: =COUNTIFS(R12:U12,"*") -> 0 | Z12: =COUNTIFS(R12:U12,"><") -> 0 | AA12: =COUNTIFS(R12:U12,"<>") -> 4
I13: =IF(#REF!<>"",#REF!,"") -> #REF! | J13: =LEFT(I13,1) -> #REF! | L13: =IF(OR(J13="E",J13="L",J13="M"),"",I13) -> #REF! | M13: =IF(OR(J13="D",J13="L",J13="M"),"",I13) -> #REF! | N13: =IF(OR(J13="D",J13="E",J13="L"),"",I13) -> #REF! | O13: =IF(OR(J13="D",J13="E",J13="M"),"",I13) -> #REF! | Q13: =IF(Z13=0,"",IF(Z13=1,R13&S13&T13&U13,"E99999")) | R13: =IF(L13="","",L13) -> #REF! | S13: =IF(M13="","",M13) -> #REF! | T13: =IF(W13=1,"",N13) -> #REF! | U13: =IF(OR(W13=1,X13=1),"",O13) -> #REF! | V13: =#REF! -> #REF! | W13: =COUNTIFS(R13,"><") -> 0 | X13: =COUNTIFS(S13,"><") -> 0 | Y13: =COUNTIFS(R13:U13,"*") -> 0 | Z13: =COUNTIFS(R13:U13,"><") -> 0 | AA13: =COUNTIFS(R13:U13,"<>") -> 4
I14: =IF(#REF!<>"",#REF!,"") -> #REF! | J14: =LEFT(I14,1) -> #REF! | L14: =IF(OR(J14="E",J14="L",J14="M"),"",I14) -> #REF! | M14: =IF(OR(J14="D",J14="L",J14="M"),"",I14) -> #REF! | N14: =IF(OR(J14="D",J14="E",J14="L"),"",I14) -> #REF! | O14: =IF(OR(J14="D",J14="E",J14="M"),"",I14) -> #REF! | Q14: =IF(Z14=0,"",IF(Z14=1,R14&S14&T14&U14,"E99999")) | R14: =IF(L14="","",L14) -> #REF! | S14: =IF(M14="","",M14) -> #REF! | T14: =IF(W14=1,"",N14) -> #REF! | U14: =IF(OR(W14=1,X14=1),"",O14) -> #REF! | V14: =#REF! -> #REF! | W14: =COUNTIFS(R14,"><") -> 0 | X14: =COUNTIFS(S14,"><") -> 0 | Y14: =COUNTIFS(R14:U14,"*") -> 0 | Z14: =COUNTIFS(R14:U14,"><") -> 0 | AA14: =COUNTIFS(R14:U14,"<>") -> 4
I15: =IF(#REF!<>"",#REF!,"") -> #REF! | J15: =LEFT(I15,1) -> #REF! | L15: =IF(OR(J15="E",J15="L",J15="M"),"",I15) -> #REF! | M15: =IF(OR(J15="D",J15="L",J15="M"),"",I15) -> #REF! | N15: =IF(OR(J15="D",J15="E",J15="L"),"",I15) -> #REF! | O15: =IF(OR(J15="D",J15="E",J15="M"),"",I15) -> #REF! | Q15: =IF(Z15=0,"",IF(Z15=1,R15&S15&T15&U15,"E99999")) | R15: =IF(L15="","",L15) -> #REF! | S15: =IF(M15="","",M15) -> #REF! | T15: =IF(W15=1,"",N15) -> #REF! | U15: =IF(OR(W15=1,X15=1),"",O15) -> #REF! | V15: =#REF! -> #REF! | W15: =COUNTIFS(R15,"><") -> 0 | X15: =COUNTIFS(S15,"><") -> 0 | Y15: =COUNTIFS(R15:U15,"*") -> 0 | Z15: =COUNTIFS(R15:U15,"><") -> 0 | AA15: =COUNTIFS(R15:U15,"<>") -> 4
I16: =IF(#REF!<>"",#REF!,"") -> #REF! | J16: =LEFT(I16,1) -> #REF! | L16: =IF(OR(J16="E",J16="L",J16="M"),"",I16) -> #REF! | M16: =IF(OR(J16="D",J16="L",J16="M"),"",I16) -> #REF! | N16: =IF(OR(J16="D",J16="E",J16="L"),"",I16) -> #REF! | O16: =IF(OR(J16="D",J16="E",J16="M"),"",I16) -> #REF! | Q16: =IF(Z16=0,"",IF(Z16=1,R16&S16&T16&U16,"E99999")) | R16: =IF(L16="","",L16) -> #REF! | S16: =IF(M16="","",M16) -> #REF! | T16: =IF(W16=1,"",N16) -> #REF! | U16: =IF(OR(W16=1,X16=1),"",O16) -> #REF! | V16: =#REF! -> #REF! | W16: =COUNTIFS(R16,"><") -> 0 | X16: =COUNTIFS(S16,"><") -> 0 | Y16: =COUNTIFS(R16:U16,"*") -> 0 | Z16: =COUNTIFS(R16:U16,"><") -> 0 | AA16: =COUNTIFS(R16:U16,"<>") -> 4
I17: =IF(#REF!<>"",#REF!,"") -> #REF! | J17: =LEFT(I17,1) -> #REF! | L17: =IF(OR(J17="E",J17="L",J17="M"),"",I17) -> #REF! | M17: =IF(OR(J17="D",J17="L",J17="M"),"",I17) -> #REF! | N17: =IF(OR(J17="D",J17="E",J17="L"),"",I17) -> #REF! | O17: =IF(OR(J17="D",J17="E",J17="M"),"",I17) -> #REF! | Q17: =IF(Z17=0,"",IF(Z17=1,R17&S17&T17&U17,"E99999")) | R17: =IF(L17="","",L17) -> #REF! | S17: =IF(M17="","",M17) -> #REF! | T17: =IF(W17=1,"",N17) -> #REF! | U17: =IF(OR(W17=1,X17=1),"",O17) -> #REF! | V17: =#REF! -> #REF! | W17: =COUNTIFS(R17,"><") -> 0 | X17: =COUNTIFS(S17,"><") -> 0 | Y17: =COUNTIFS(R17:U17,"*") -> 0 | Z17: =COUNTIFS(R17:U17,"><") -> 0 | AA17: =COUNTIFS(R17:U17,"<>") -> 4
I18: =IF(#REF!<>"",#REF!,"") -> #REF! | J18: =LEFT(I18,1) -> #REF! | L18: =IF(OR(J18="E",J18="L",J18="M"),"",I18) -> #REF! | M18: =IF(OR(J18="D",J18="L",J18="M"),"",I18) -> #REF! | N18: =IF(OR(J18="D",J18="E",J18="L"),"",I18) -> #REF! | O18: =IF(OR(J18="D",J18="E",J18="M"),"",I18) -> #REF! | Q18: =IF(Z18=0,"",IF(Z18=1,R18&S18&T18&U18,"E99999")) | R18: =IF(L18="","",L18) -> #REF! | S18: =IF(M18="","",M18) -> #REF! | T18: =IF(W18=1,"",N18) -> #REF! | U18: =IF(OR(W18=1,X18=1),"",O18) -> #REF! | V18: =#REF! -> #REF! | W18: =COUNTIFS(R18,"><") -> 0 | X18: =COUNTIFS(S18,"><") -> 0 | Y18: =COUNTIFS(R18:U18,"*") -> 0 | Z18: =COUNTIFS(R18:U18,"><") -> 0 | AA18: =COUNTIFS(R18:U18,"<>") -> 4
I19: =IF(#REF!<>"",#REF!,"") -> #REF! | J19: =LEFT(I19,1) -> #REF! | L19: =IF(OR(J19="E",J19="L",J19="M"),"",I19) -> #REF! | M19: =IF(OR(J19="D",J19="L",J19="M"),"",I19) -> #REF! | N19: =IF(OR(J19="D",J19="E",J19="L"),"",I19) -> #REF! | O19: =IF(OR(J19="D",J19="E",J19="M"),"",I19) -> #REF! | Q19: =IF(Z19=0,"",IF(Z19=1,R19&S19&T19&U19,"E99999")) | R19: =IF(L19="","",L19) -> #REF! | S19: =IF(M19="","",M19) -> #REF! | T19: =IF(W19=1,"",N19) -> #REF! | U19: =IF(OR(W19=1,X19=1),"",O19) -> #REF! | V19: =#REF! -> #REF! | W19: =COUNTIFS(R19,"><") -> 0 | X19: =COUNTIFS(S19,"><") -> 0 | Y19: =COUNTIFS(R19:U19,"*") -> 0 | Z19: =COUNTIFS(R19:U19,"><") -> 0 | AA19: =COUNTIFS(R19:U19,"<>") -> 4
I20: =IF(#REF!<>"",#REF!,"") -> #REF! | J20: =LEFT(I20,1) -> #REF! | L20: =IF(OR(J20="E",J20="L",J20="M"),"",I20) -> #REF! | M20: =IF(OR(J20="D",J20="L",J20="M"),"",I20) -> #REF! | N20: =IF(OR(J20="D",J20="E",J20="L"),"",I20) -> #REF! | O20: =IF(OR(J20="D",J20="E",J20="M"),"",I20) -> #REF! | Q20: =IF(Z20=0,"",IF(Z20=1,R20&S20&T20&U20,"E99999")) | R20: =IF(L20="","",L20) -> #REF! | S20: =IF(M20="","",M20) -> #REF! | T20: =IF(W20=1,"",N20) -> #REF! | U20: =IF(OR(W20=1,X20=1),"",O20) -> #REF! | V20: =#REF! -> #REF! | W20: =COUNTIFS(R20,"><") -> 0 | X20: =COUNTIFS(S20,"><") -> 0 | Y20: =COUNTIFS(R20:U20,"*") -> 0 | Z20: =COUNTIFS(R20:U20,"><") -> 0 | AA20: =COUNTIFS(R20:U20,"<>") -> 4
... I22: =IF(#REF!<>"",#REF!,"") -> #REF! | J22: =LEFT(I22,1) -> #REF! | L22: =IF(OR(J22="E",J22="L",J22="M"),"",I22) -> #REF! | M22: =IF(OR(J22="D",J22="L",J22="M"),"",I22) -> #REF! | N22: =IF(OR(J22="D",J22="E",J22="L"),"",I22) -> #REF! | O22: =IF(OR(J22="D",J22="E",J22="M"),"",I22) -> #REF! | Q22: =IF(Z22=0,"",IF(Z22=1,R22&S22&T22&U22,"E99999")) | R22: =IF(L22="","",L22) -> #REF! | S22: =IF(M22="","",M22) -> #REF! | T22: =IF(W22=1,"",N22) -> #REF! | U22: =IF(OR(W22=1,X22=1),"",O22) -> #REF! | V22: =#REF! -> #REF! | W22: =COUNTIFS(R22,"><") -> 0 | X22: =COUNTIFS(S22,"><") -> 0 | Y22: =COUNTIFS(R22:U22,"*") -> 0 | Z22: =COUNTIFS(R22:U22,"><") -> 0 | AA22: =COUNTIFS(R22:U22,"<>") -> 4
I23: =IF(#REF!<>"",#REF!,"") -> #REF! | J23: =LEFT(I23,1) -> #REF! | L23: =IF(OR(J23="E",J23="L",J23="M"),"",I23) -> #REF! | M23: =IF(OR(J23="D",J23="L",J23="M"),"",I23) -> #REF! | N23: =IF(OR(J23="D",J23="E",J23="L"),"",I23) -> #REF! | O23: =IF(OR(J23="D",J23="E",J23="M"),"",I23) -> #REF! | Q23: =IF(Z23=0,"",IF(Z23=1,R23&S23,"E99999")) | R23: =IF(L23="","",L23) -> #REF! | S23: =IF(M23="","",M23) -> #REF! | T23: =IF(W23=1,"",N23) -> #REF! | U23: =IF(OR(W23=1,X23=1),"",O23) -> #REF! | V23: =#REF! -> #REF! | W23: =COUNTIFS(R23,"><") -> 0 | X23: =COUNTIFS(S23,"><") -> 0 | Y23: =COUNTIFS(R23:U23,"*") -> 0 | Z23: =COUNTIFS(R23:U23,"><") -> 0 | AA23: =COUNTIFS(R23:U23,"<>") -> 4
I24: =IF(#REF!<>"",#REF!,"") -> #REF! | J24: =LEFT(I24,1) -> #REF! | L24: =IF(OR(J24="E",J24="L",J24="M"),"",I24) -> #REF! | M24: =IF(OR(J24="D",J24="L",J24="M"),"",I24) -> #REF! | N24: =IF(OR(J24="D",J24="E",J24="L"),"",I24) -> #REF! | O24: =IF(OR(J24="D",J24="E",J24="M"),"",I24) -> #REF! | Q24: =IF(Z24=0,"",IF(Z24=1,R24&S24,"E99999")) | R24: =IF(L24="","",L24) -> #REF! | S24: =IF(M24="","",M24) -> #REF! | T24: =IF(W24=1,"",N24) -> #REF! | U24: =IF(OR(W24=1,X24=1),"",O24) -> #REF! | V24: =#REF! -> #REF! | W24: =COUNTIFS(R24,"><") -> 0 | X24: =COUNTIFS(S24,"><") -> 0 | Y24: =COUNTIFS(R24:U24,"*") -> 0 | Z24: =COUNTIFS(R24:U24,"><") -> 0 | AA24: =COUNTIFS(R24:U24,"<>") -> 4
I25: =IF(#REF!<>"",#REF!,"") -> #REF! | J25: =LEFT(I25,1) -> #REF! | L25: =IF(OR(J25="E",J25="L",J25="M"),"",I25) -> #REF! | M25: =IF(OR(J25="D",J25="L",J25="M"),"",I25) -> #REF! | N25: =IF(OR(J25="D",J25="E",J25="L"),"",I25) -> #REF! | O25: =IF(OR(J25="D",J25="E",J25="M"),"",I25) -> #REF! | Q25: =IF(Z25=0,"",IF(Z25=1,R25&S25,"E99999")) | R25: =IF(L25="","",L25) -> #REF! | S25: =IF(M25="","",M25) -> #REF! | T25: =IF(W25=1,"",N25) -> #REF! | U25: =IF(OR(W25=1,X25=1),"",O25) -> #REF! | V25: =#REF! -> #REF! | W25: =COUNTIFS(R25,"><") -> 0 | X25: =COUNTIFS(S25,"><") -> 0 | Y25: =COUNTIFS(R25:U25,"*") -> 0 | Z25: =COUNTIFS(R25:U25,"><") -> 0 | AA25: =COUNTIFS(R25:U25,"<>") -> 4
I26: =IF(#REF!<>"",#REF!,"") -> #REF! | J26: =LEFT(I26,1) -> #REF! | L26: =IF(OR(J26="E",J26="L",J26="M"),"",I26) -> #REF! | M26: =IF(OR(J26="D",J26="L",J26="M"),"",I26) -> #REF! | N26: =IF(OR(J26="D",J26="E",J26="L"),"",I26) -> #REF! | O26: =IF(OR(J26="D",J26="E",J26="M"),"",I26) -> #REF! | Q26: =IF(Z26=0,"",IF(Z26=1,R26&S26,"E99999")) | R26: =IF(L26="","",L26) -> #REF! | S26: =IF(M26="","",M26) -> #REF! | T26: =IF(W26=1,"",N26) -> #REF! | U26: =IF(OR(W26=1,X26=1),"",O26) -> #REF! | V26: =#REF! -> #REF! | W26: =COUNTIFS(R26,"><") -> 0 | X26: =COUNTIFS(S26,"><") -> 0 | Y26: =COUNTIFS(R26:U26,"*") -> 0 | Z26: =COUNTIFS(R26:U26,"><") -> 0 | AA26: =COUNTIFS(R26:U26,"<>") -> 4
I27: =IF(#REF!<>"",#REF!,"") -> #REF! | J27: =LEFT(I27,1) -> #REF! | L27: =IF(OR(J27="E",J27="L",J27="M"),"",I27) -> #REF! | M27: =IF(OR(J27="D",J27="L",J27="M"),"",I27) -> #REF! | N27: =IF(OR(J27="D",J27="E",J27="L"),"",I27) -> #REF! | O27: =IF(OR(J27="D",J27="E",J27="M"),"",I27) -> #REF! | Q27: =IF(Z27=0,"",IF(Z27=1,R27&S27,"E99999")) | R27: =IF(L27="","",L27) -> #REF! | S27: =IF(M27="","",M27) -> #REF! | T27: =IF(W27=1,"",N27) -> #REF! | U27: =IF(OR(W27=1,X27=1),"",O27) -> #REF! | V27: =#REF! -> #REF! | W27: =COUNTIFS(R27,"><") -> 0 | X27: =COUNTIFS(S27,"><") -> 0 | Y27: =COUNTIFS(R27:U27,"*") -> 0 | Z27: =COUNTIFS(R27:U27,"><") -> 0 | AA27: =COUNTIFS(R27:U27,"<>") -> 4
I28: =IF(#REF!<>"",#REF!,"") -> #REF! | J28: =LEFT(I28,1) -> #REF! | L28: =IF(OR(J28="E",J28="L",J28="M"),"",I28) -> #REF! | M28: =IF(OR(J28="D",J28="L",J28="M"),"",I28) -> #REF! | N28: =IF(OR(J28="D",J28="E",J28="L"),"",I28) -> #REF! | O28: =IF(OR(J28="D",J28="E",J28="M"),"",I28) -> #REF! | Q28: =IF(Z28=0,"",IF(Z28=1,R28&S28,"E99999")) | R28: =IF(L28="","",L28) -> #REF! | S28: =IF(M28="","",M28) -> #REF! | T28: =IF(W28=1,"",N28) -> #REF! | U28: =IF(OR(W28=1,X28=1),"",O28) -> #REF! | V28: =#REF! -> #REF! | W28: =COUNTIFS(R28,"><") -> 0 | X28: =COUNTIFS(S28,"><") -> 0 | Y28: =COUNTIFS(R28:U28,"*") -> 0 | Z28: =COUNTIFS(R28:U28,"><") -> 0 | AA28: =COUNTIFS(R28:U28,"<>") -> 4
I29: =IF(#REF!<>"",#REF!,"") -> #REF! | J29: =LEFT(I29,1) -> #REF! | L29: =IF(OR(J29="E",J29="L",J29="M"),"",I29) -> #REF! | M29: =IF(OR(J29="D",J29="L",J29="M"),"",I29) -> #REF! | N29: =IF(OR(J29="D",J29="E",J29="L"),"",I29) -> #REF! | O29: =IF(OR(J29="D",J29="E",J29="M"),"",I29) -> #REF! | Q29: =IF(Z29=0,"",IF(Z29=1,R29&S29,"E99999")) | R29: =IF(L29="","",L29) -> #REF! | S29: =IF(M29="","",M29) -> #REF! | T29: =IF(W29=1,"",N29) -> #REF! | U29: =IF(OR(W29=1,X29=1),"",O29) -> #REF! | V29: =#REF! -> #REF! | W29: =COUNTIFS(R29,"><") -> 0 | X29: =COUNTIFS(S29,"><") -> 0 | Y29: =COUNTIFS(R29:U29,"*") -> 0 | Z29: =COUNTIFS(R29:U29,"><") -> 0 | AA29: =COUNTIFS(R29:U29,"<>") -> 4
I30: =IF(#REF!<>"",#REF!,"") -> #REF! | J30: =LEFT(I30,1) -> #REF! | L30: =IF(OR(J30="E",J30="L",J30="M"),"",I30) -> #REF! | M30: =IF(OR(J30="D",J30="L",J30="M"),"",I30) -> #REF! | N30: =IF(OR(J30="D",J30="E",J30="L"),"",I30) -> #REF! | O30: =IF(OR(J30="D",J30="E",J30="M"),"",I30) -> #REF! | Q30: =IF(Z30=0,"",IF(Z30=1,R30&S30,"E99999")) | R30: =IF(L30="","",L30) -> #REF! | S30: =IF(M30="","",M30) -> #REF! | T30: =IF(W30=1,"",N30) -> #REF! | U30: =IF(OR(W30=1,X30=1),"",O30) -> #REF! | V30: =#REF! -> #REF! | W30: =COUNTIFS(R30,"><") -> 0 | X30: =COUNTIFS(S30,"><") -> 0 | Y30: =COUNTIFS(R30:U30,"*") -> 0 | Z30: =COUNTIFS(R30:U30,"><") -> 0 | AA30: =COUNTIFS(R30:U30,"<>") -> 4
I31: =IF(#REF!<>"",#REF!,"") -> #REF! | J31: =LEFT(I31,1) -> #REF! | L31: =IF(OR(J31="E",J31="L",J31="M"),"",I31) -> #REF! | M31: =IF(OR(J31="D",J31="L",J31="M"),"",I31) -> #REF! | N31: =IF(OR(J31="D",J31="E",J31="L"),"",I31) -> #REF! | O31: =IF(OR(J31="D",J31="E",J31="M"),"",I31) -> #REF! | Q31: =IF(Z31=0,"",IF(Z31=1,R31&S31,"E99999")) | R31: =IF(L31="","",L31) -> #REF! | S31: =IF(M31="","",M31) -> #REF! | T31: =IF(W31=1,"",N31) -> #REF! | U31: =IF(OR(W31=1,X31=1),"",O31) -> #REF! | V31: =#REF! -> #REF! | W31: =COUNTIFS(R31,"><") -> 0 | X31: =COUNTIFS(S31,"><") -> 0 | Y31: =COUNTIFS(R31:U31,"*") -> 0 | Z31: =COUNTIFS(R31:U31,"><") -> 0 | AA31: =COUNTIFS(R31:U31,"<>") -> 4
I32: =IF(#REF!<>"",#REF!,"") -> #REF! | J32: =LEFT(I32,1) -> #REF! | L32: =IF(OR(J32="E",J32="L",J32="M"),"",I32) -> #REF! | M32: =IF(OR(J32="D",J32="L",J32="M"),"",I32) -> #REF! | N32: =IF(OR(J32="D",J32="E",J32="L"),"",I32) -> #REF! | O32: =IF(OR(J32="D",J32="E",J32="M"),"",I32) -> #REF! | Q32: =IF(Z32=0,"",IF(Z32=1,R32&S32,"E99999")) | R32: =IF(L32="","",L32) -> #REF! | S32: =IF(M32="","",M32) -> #REF! | T32: =IF(W32=1,"",N32) -> #REF! | U32: =IF(OR(W32=1,X32=1),"",O32) -> #REF! | V32: =#REF! -> #REF! | W32: =COUNTIFS(R32,"><") -> 0 | X32: =COUNTIFS(S32,"><") -> 0 | Y32: =COUNTIFS(R32:U32,"*") -> 0 | Z32: =COUNTIFS(R32:U32,"><") -> 0 | AA32: =COUNTIFS(R32:U32,"<>") -> 4
I33: =IF(#REF!<>"",#REF!,"") -> #REF! | J33: =LEFT(I33,1) -> #REF! | L33: =IF(OR(J33="E",J33="L",J33="M"),"",I33) -> #REF! | M33: =IF(OR(J33="D",J33="L",J33="M"),"",I33) -> #REF! | N33: =IF(OR(J33="D",J33="E",J33="L"),"",I33) -> #REF! | O33: =IF(OR(J33="D",J33="E",J33="M"),"",I33) -> #REF! | Q33: =IF(Z33=0,"",IF(Z33=1,R33&S33,"E99999")) | R33: =IF(L33="","",L33) -> #REF! | S33: =IF(M33="","",M33) -> #REF! | T33: =IF(W33=1,"",N33) -> #REF! | U33: =IF(OR(W33=1,X33=1),"",O33) -> #REF! | V33: =#REF! -> #REF! | W33: =COUNTIFS(R33,"><") -> 0 | X33: =COUNTIFS(S33,"><") -> 0 | Y33: =COUNTIFS(R33:U33,"*") -> 0 | Z33: =COUNTIFS(R33:U33,"><") -> 0 | AA33: =COUNTIFS(R33:U33,"<>") -> 4
I34: =IF(#REF!<>"",#REF!,"") -> #REF! | J34: =LEFT(I34,1) -> #REF! | L34: =IF(OR(J34="E",J34="L",J34="M"),"",I34) -> #REF! | M34: =IF(OR(J34="D",J34="L",J34="M"),"",I34) -> #REF! | N34: =IF(OR(J34="D",J34="E",J34="L"),"",I34) -> #REF! | O34: =IF(OR(J34="D",J34="E",J34="M"),"",I34) -> #REF! | Q34: =IF(Z34=0,"",IF(Z34=1,R34&S34,"E99999")) | R34: =IF(L34="","",L34) -> #REF! | S34: =IF(M34="","",M34) -> #REF! | T34: =IF(W34=1,"",N34) -> #REF! | U34: =IF(OR(W34=1,X34=1),"",O34) -> #REF! | V34: =#REF! -> #REF! | W34: =COUNTIFS(R34,"><") -> 0 | X34: =COUNTIFS(S34,"><") -> 0 | Y34: =COUNTIFS(R34:U34,"*") -> 0 | Z34: =COUNTIFS(R34:U34,"><") -> 0 | AA34: =COUNTIFS(R34:U34,"<>") -> 4
... I986: =IF(#REF!<>"",#REF!,"") -> #REF! | J986: =LEFT(I986,1) -> #REF! | L986: =IF(OR(J986="E",J986="L",J986="M"),"",I986) -> #REF! | M986: =IF(OR(J986="D",J986="L",J986="M"),"",I986) -> #REF! | N986: =IF(OR(J986="D",J986="E",J986="L"),"",I986) -> #REF! | O986: =IF(OR(J986="D",J986="E",J986="M"),"",I986) -> #REF! | Q986: =IF(Z986=0,"",IF(Z986=1,R986&S986,"E99999")) | R986: =IF(L986="","",L986) -> #REF! | S986: =IF(M986="","",M986) -> #REF! | T986: =IF(W986=1,"",N986) -> #REF! | U986: =IF(OR(W986=1,X986=1),"",O986) -> #REF! | V986: =#REF! -> #REF! | W986: =COUNTIFS(R986,"><") -> 0 | X986: =COUNTIFS(S986,"><") -> 0 | Y986: =COUNTIFS(R986:U986,"*") -> 0 | Z986: =COUNTIFS(R986:U986,"><") -> 0 | AA986: =COUNTIFS(R986:U986,"<>") -> 4
I987: =IF(#REF!<>"",#REF!,"") -> #REF! | J987: =LEFT(I987,1) -> #REF!
I988: =IF(#REF!<>"",#REF!,"") -> #REF! | J988: =LEFT(I988,1) -> #REF!
